{
  "artifacts": [],
  "command": "main",
  "experiment": {
    "base_dir": "/work/home/fd15hava/tinypaper-mpt/src",
    "dependencies": [
      "numpy==1.26.4",
      "sacred==0.8.5"
    ],
    "mainfile": "experiment.py",
    "name": "tinypaper",
    "repositories": [
      {
        "commit": "83ebc21b46932da830ceff1fef51511962253d6b",
        "dirty": false,
        "url": "ssh://github/fdamken/tinypaper_code.git"
      },
      {
        "commit": "83ebc21b46932da830ceff1fef51511962253d6b",
        "dirty": false,
        "url": "ssh://github/fdamken/tinypaper_code.git"
      }
    ],
    "sources": [
      [
        "experiment.py",
        "_sources/experiment_7ab7c4f9e536be33bd5f71ad8c083f8f.py"
      ],
      [
        "path_util.py",
        "_sources/path_util_ce5f4012c098f79adf2c1204811dca0a.py"
      ]
    ]
  },
  "heartbeat": "2024-04-30T04:22:31.380780",
  "host": {
    "ENV": {},
    "cpu": "Intel(R) Xeon(R) Platinum 8470Q",
    "hostname": "mpsd0130",
    "os": [
      "Linux",
      "Linux-4.18.0-477.27.1.el8_8.x86_64-x86_64-with-glibc2.28"
    ],
    "python_version": "3.11.9"
  },
  "meta": {
    "command": "main",
    "config_updates": {
      "from_session_id": 150,
      "language": "ru",
      "model_name": "falcon-180B-chat",
      "to_session_id": 200
    },
    "named_configs": [],
    "options": {
      "--beat-interval": null,
      "--capture": null,
      "--comment": null,
      "--debug": false,
      "--enforce_clean": false,
      "--file_storage": null,
      "--force": false,
      "--help": false,
      "--id": null,
      "--loglevel": null,
      "--mongo_db": null,
      "--name": null,
      "--pdb": false,
      "--print-config": false,
      "--priority": null,
      "--queue": false,
      "--s3": null,
      "--sql": null,
      "--tiny_db": null,
      "--unobserved": false,
      "COMMAND": null,
      "UPDATE": [
        "from_session_id=150",
        "to_session_id=200",
        "model_name=falcon-180B-chat",
        "language=ru"
      ],
      "help": false,
      "with": true
    }
  },
  "resources": [],
  "result": {
    "answers": [
      "Traceback (most recent call last):\n  File \"/home/fd15hava/.cache/pypoetry/virtualenvs/non-package-mode-zjkKA0Ca-py3.11/lib/python3.11/site-packages/tenacity/__init__.py\", line 382, in __call__\n    result = fn(*args, **kwargs)\n             ^^^^^^^^^^^^^^^^^^^\n  File \"/work/home/fd15hava/tinypaper-mpt/src/agent.py\", line 26, in play\n    answer = self._prompt(self._make_prompt(scenario))\n             ^^^^^^^^^^^^^^^^^^^^^^^^^^^^^^^^^^^^^^^^^\n  File \"/work/home/fd15hava/tinypaper-mpt/src/agent.py\", line 40, in _prompt\n    raise UnexpectedAnswerException(f\"expected 1 or 2, got {result}\")\nutil.UnexpectedAnswerException: expected 1 or 2, got  \n\nThe above exception was the direct cause of the following exception:\n\nTraceback (most recent call last):\n  File \"/work/home/fd15hava/tinypaper-mpt/scripts/experiments/run.py\", line 16, in _run_session\n    result = agent.play(session)\n             ^^^^^^^^^^^^^^^^^^^\n  File \"/home/fd15hava/.cache/pypoetry/virtualenvs/non-package-mode-zjkKA0Ca-py3.11/lib/python3.11/site-packages/tenacity/__init__.py\", line 289, in wrapped_f\n    return self(f, *args, **kw)\n           ^^^^^^^^^^^^^^^^^^^^\n  File \"/home/fd15hava/.cache/pypoetry/virtualenvs/non-package-mode-zjkKA0Ca-py3.11/lib/python3.11/site-packages/tenacity/__init__.py\", line 379, in __call__\n    do = self.iter(retry_state=retry_state)\n         ^^^^^^^^^^^^^^^^^^^^^^^^^^^^^^^^^^\n  File \"/home/fd15hava/.cache/pypoetry/virtualenvs/non-package-mode-zjkKA0Ca-py3.11/lib/python3.11/site-packages/tenacity/__init__.py\", line 326, in iter\n    raise retry_exc from fut.exception()\ntenacity.RetryError: RetryError[<Future at 0x14e6ac1866d0 state=finished raised UnexpectedAnswerException>]\n",
      "Traceback (most recent call last):\n  File \"/home/fd15hava/.cache/pypoetry/virtualenvs/non-package-mode-zjkKA0Ca-py3.11/lib/python3.11/site-packages/tenacity/__init__.py\", line 382, in __call__\n    result = fn(*args, **kwargs)\n             ^^^^^^^^^^^^^^^^^^^\n  File \"/work/home/fd15hava/tinypaper-mpt/src/agent.py\", line 26, in play\n    answer = self._prompt(self._make_prompt(scenario))\n             ^^^^^^^^^^^^^^^^^^^^^^^^^^^^^^^^^^^^^^^^^\n  File \"/work/home/fd15hava/tinypaper-mpt/src/agent.py\", line 40, in _prompt\n    raise UnexpectedAnswerException(f\"expected 1 or 2, got {result}\")\nutil.UnexpectedAnswerException: expected 1 or 2, got  \n\nThe above exception was the direct cause of the following exception:\n\nTraceback (most recent call last):\n  File \"/work/home/fd15hava/tinypaper-mpt/scripts/experiments/run.py\", line 16, in _run_session\n    result = agent.play(session)\n             ^^^^^^^^^^^^^^^^^^^\n  File \"/home/fd15hava/.cache/pypoetry/virtualenvs/non-package-mode-zjkKA0Ca-py3.11/lib/python3.11/site-packages/tenacity/__init__.py\", line 289, in wrapped_f\n    return self(f, *args, **kw)\n           ^^^^^^^^^^^^^^^^^^^^\n  File \"/home/fd15hava/.cache/pypoetry/virtualenvs/non-package-mode-zjkKA0Ca-py3.11/lib/python3.11/site-packages/tenacity/__init__.py\", line 379, in __call__\n    do = self.iter(retry_state=retry_state)\n         ^^^^^^^^^^^^^^^^^^^^^^^^^^^^^^^^^^\n  File \"/home/fd15hava/.cache/pypoetry/virtualenvs/non-package-mode-zjkKA0Ca-py3.11/lib/python3.11/site-packages/tenacity/__init__.py\", line 326, in iter\n    raise retry_exc from fut.exception()\ntenacity.RetryError: RetryError[<Future at 0x14e62dd69c50 state=finished raised UnexpectedAnswerException>]\n",
      "Traceback (most recent call last):\n  File \"/home/fd15hava/.cache/pypoetry/virtualenvs/non-package-mode-zjkKA0Ca-py3.11/lib/python3.11/site-packages/tenacity/__init__.py\", line 382, in __call__\n    result = fn(*args, **kwargs)\n             ^^^^^^^^^^^^^^^^^^^\n  File \"/work/home/fd15hava/tinypaper-mpt/src/agent.py\", line 26, in play\n    answer = self._prompt(self._make_prompt(scenario))\n             ^^^^^^^^^^^^^^^^^^^^^^^^^^^^^^^^^^^^^^^^^\n  File \"/work/home/fd15hava/tinypaper-mpt/src/agent.py\", line 40, in _prompt\n    raise UnexpectedAnswerException(f\"expected 1 or 2, got {result}\")\nutil.UnexpectedAnswerException: expected 1 or 2, got  \n\nThe above exception was the direct cause of the following exception:\n\nTraceback (most recent call last):\n  File \"/work/home/fd15hava/tinypaper-mpt/scripts/experiments/run.py\", line 16, in _run_session\n    result = agent.play(session)\n             ^^^^^^^^^^^^^^^^^^^\n  File \"/home/fd15hava/.cache/pypoetry/virtualenvs/non-package-mode-zjkKA0Ca-py3.11/lib/python3.11/site-packages/tenacity/__init__.py\", line 289, in wrapped_f\n    return self(f, *args, **kw)\n           ^^^^^^^^^^^^^^^^^^^^\n  File \"/home/fd15hava/.cache/pypoetry/virtualenvs/non-package-mode-zjkKA0Ca-py3.11/lib/python3.11/site-packages/tenacity/__init__.py\", line 379, in __call__\n    do = self.iter(retry_state=retry_state)\n         ^^^^^^^^^^^^^^^^^^^^^^^^^^^^^^^^^^\n  File \"/home/fd15hava/.cache/pypoetry/virtualenvs/non-package-mode-zjkKA0Ca-py3.11/lib/python3.11/site-packages/tenacity/__init__.py\", line 326, in iter\n    raise retry_exc from fut.exception()\ntenacity.RetryError: RetryError[<Future at 0x14e62de0a310 state=finished raised UnexpectedAnswerException>]\n",
      "Traceback (most recent call last):\n  File \"/home/fd15hava/.cache/pypoetry/virtualenvs/non-package-mode-zjkKA0Ca-py3.11/lib/python3.11/site-packages/tenacity/__init__.py\", line 382, in __call__\n    result = fn(*args, **kwargs)\n             ^^^^^^^^^^^^^^^^^^^\n  File \"/work/home/fd15hava/tinypaper-mpt/src/agent.py\", line 26, in play\n    answer = self._prompt(self._make_prompt(scenario))\n             ^^^^^^^^^^^^^^^^^^^^^^^^^^^^^^^^^^^^^^^^^\n  File \"/work/home/fd15hava/tinypaper-mpt/src/agent.py\", line 40, in _prompt\n    raise UnexpectedAnswerException(f\"expected 1 or 2, got {result}\")\nutil.UnexpectedAnswerException: expected 1 or 2, got  \n\nThe above exception was the direct cause of the following exception:\n\nTraceback (most recent call last):\n  File \"/work/home/fd15hava/tinypaper-mpt/scripts/experiments/run.py\", line 16, in _run_session\n    result = agent.play(session)\n             ^^^^^^^^^^^^^^^^^^^\n  File \"/home/fd15hava/.cache/pypoetry/virtualenvs/non-package-mode-zjkKA0Ca-py3.11/lib/python3.11/site-packages/tenacity/__init__.py\", line 289, in wrapped_f\n    return self(f, *args, **kw)\n           ^^^^^^^^^^^^^^^^^^^^\n  File \"/home/fd15hava/.cache/pypoetry/virtualenvs/non-package-mode-zjkKA0Ca-py3.11/lib/python3.11/site-packages/tenacity/__init__.py\", line 379, in __call__\n    do = self.iter(retry_state=retry_state)\n         ^^^^^^^^^^^^^^^^^^^^^^^^^^^^^^^^^^\n  File \"/home/fd15hava/.cache/pypoetry/virtualenvs/non-package-mode-zjkKA0Ca-py3.11/lib/python3.11/site-packages/tenacity/__init__.py\", line 326, in iter\n    raise retry_exc from fut.exception()\ntenacity.RetryError: RetryError[<Future at 0x14e6b5b785d0 state=finished raised UnexpectedAnswerException>]\n",
      "Traceback (most recent call last):\n  File \"/home/fd15hava/.cache/pypoetry/virtualenvs/non-package-mode-zjkKA0Ca-py3.11/lib/python3.11/site-packages/tenacity/__init__.py\", line 382, in __call__\n    result = fn(*args, **kwargs)\n             ^^^^^^^^^^^^^^^^^^^\n  File \"/work/home/fd15hava/tinypaper-mpt/src/agent.py\", line 26, in play\n    answer = self._prompt(self._make_prompt(scenario))\n             ^^^^^^^^^^^^^^^^^^^^^^^^^^^^^^^^^^^^^^^^^\n  File \"/work/home/fd15hava/tinypaper-mpt/src/agent.py\", line 40, in _prompt\n    raise UnexpectedAnswerException(f\"expected 1 or 2, got {result}\")\nutil.UnexpectedAnswerException: expected 1 or 2, got  \n\nThe above exception was the direct cause of the following exception:\n\nTraceback (most recent call last):\n  File \"/work/home/fd15hava/tinypaper-mpt/scripts/experiments/run.py\", line 16, in _run_session\n    result = agent.play(session)\n             ^^^^^^^^^^^^^^^^^^^\n  File \"/home/fd15hava/.cache/pypoetry/virtualenvs/non-package-mode-zjkKA0Ca-py3.11/lib/python3.11/site-packages/tenacity/__init__.py\", line 289, in wrapped_f\n    return self(f, *args, **kw)\n           ^^^^^^^^^^^^^^^^^^^^\n  File \"/home/fd15hava/.cache/pypoetry/virtualenvs/non-package-mode-zjkKA0Ca-py3.11/lib/python3.11/site-packages/tenacity/__init__.py\", line 379, in __call__\n    do = self.iter(retry_state=retry_state)\n         ^^^^^^^^^^^^^^^^^^^^^^^^^^^^^^^^^^\n  File \"/home/fd15hava/.cache/pypoetry/virtualenvs/non-package-mode-zjkKA0Ca-py3.11/lib/python3.11/site-packages/tenacity/__init__.py\", line 326, in iter\n    raise retry_exc from fut.exception()\ntenacity.RetryError: RetryError[<Future at 0x14e62dd698d0 state=finished raised UnexpectedAnswerException>]\n",
      "Traceback (most recent call last):\n  File \"/home/fd15hava/.cache/pypoetry/virtualenvs/non-package-mode-zjkKA0Ca-py3.11/lib/python3.11/site-packages/tenacity/__init__.py\", line 382, in __call__\n    result = fn(*args, **kwargs)\n             ^^^^^^^^^^^^^^^^^^^\n  File \"/work/home/fd15hava/tinypaper-mpt/src/agent.py\", line 26, in play\n    answer = self._prompt(self._make_prompt(scenario))\n             ^^^^^^^^^^^^^^^^^^^^^^^^^^^^^^^^^^^^^^^^^\n  File \"/work/home/fd15hava/tinypaper-mpt/src/agent.py\", line 40, in _prompt\n    raise UnexpectedAnswerException(f\"expected 1 or 2, got {result}\")\nutil.UnexpectedAnswerException: expected 1 or 2, got  \n\nThe above exception was the direct cause of the following exception:\n\nTraceback (most recent call last):\n  File \"/work/home/fd15hava/tinypaper-mpt/scripts/experiments/run.py\", line 16, in _run_session\n    result = agent.play(session)\n             ^^^^^^^^^^^^^^^^^^^\n  File \"/home/fd15hava/.cache/pypoetry/virtualenvs/non-package-mode-zjkKA0Ca-py3.11/lib/python3.11/site-packages/tenacity/__init__.py\", line 289, in wrapped_f\n    return self(f, *args, **kw)\n           ^^^^^^^^^^^^^^^^^^^^\n  File \"/home/fd15hava/.cache/pypoetry/virtualenvs/non-package-mode-zjkKA0Ca-py3.11/lib/python3.11/site-packages/tenacity/__init__.py\", line 379, in __call__\n    do = self.iter(retry_state=retry_state)\n         ^^^^^^^^^^^^^^^^^^^^^^^^^^^^^^^^^^\n  File \"/home/fd15hava/.cache/pypoetry/virtualenvs/non-package-mode-zjkKA0Ca-py3.11/lib/python3.11/site-packages/tenacity/__init__.py\", line 326, in iter\n    raise retry_exc from fut.exception()\ntenacity.RetryError: RetryError[<Future at 0x14e6ac14a090 state=finished raised UnexpectedAnswerException>]\n",
      "Traceback (most recent call last):\n  File \"/home/fd15hava/.cache/pypoetry/virtualenvs/non-package-mode-zjkKA0Ca-py3.11/lib/python3.11/site-packages/tenacity/__init__.py\", line 382, in __call__\n    result = fn(*args, **kwargs)\n             ^^^^^^^^^^^^^^^^^^^\n  File \"/work/home/fd15hava/tinypaper-mpt/src/agent.py\", line 26, in play\n    answer = self._prompt(self._make_prompt(scenario))\n             ^^^^^^^^^^^^^^^^^^^^^^^^^^^^^^^^^^^^^^^^^\n  File \"/work/home/fd15hava/tinypaper-mpt/src/agent.py\", line 40, in _prompt\n    raise UnexpectedAnswerException(f\"expected 1 or 2, got {result}\")\nutil.UnexpectedAnswerException: expected 1 or 2, got  \n\nThe above exception was the direct cause of the following exception:\n\nTraceback (most recent call last):\n  File \"/work/home/fd15hava/tinypaper-mpt/scripts/experiments/run.py\", line 16, in _run_session\n    result = agent.play(session)\n             ^^^^^^^^^^^^^^^^^^^\n  File \"/home/fd15hava/.cache/pypoetry/virtualenvs/non-package-mode-zjkKA0Ca-py3.11/lib/python3.11/site-packages/tenacity/__init__.py\", line 289, in wrapped_f\n    return self(f, *args, **kw)\n           ^^^^^^^^^^^^^^^^^^^^\n  File \"/home/fd15hava/.cache/pypoetry/virtualenvs/non-package-mode-zjkKA0Ca-py3.11/lib/python3.11/site-packages/tenacity/__init__.py\", line 379, in __call__\n    do = self.iter(retry_state=retry_state)\n         ^^^^^^^^^^^^^^^^^^^^^^^^^^^^^^^^^^\n  File \"/home/fd15hava/.cache/pypoetry/virtualenvs/non-package-mode-zjkKA0Ca-py3.11/lib/python3.11/site-packages/tenacity/__init__.py\", line 326, in iter\n    raise retry_exc from fut.exception()\ntenacity.RetryError: RetryError[<Future at 0x14e62df1c290 state=finished raised UnexpectedAnswerException>]\n",
      "Traceback (most recent call last):\n  File \"/home/fd15hava/.cache/pypoetry/virtualenvs/non-package-mode-zjkKA0Ca-py3.11/lib/python3.11/site-packages/tenacity/__init__.py\", line 382, in __call__\n    result = fn(*args, **kwargs)\n             ^^^^^^^^^^^^^^^^^^^\n  File \"/work/home/fd15hava/tinypaper-mpt/src/agent.py\", line 26, in play\n    answer = self._prompt(self._make_prompt(scenario))\n             ^^^^^^^^^^^^^^^^^^^^^^^^^^^^^^^^^^^^^^^^^\n  File \"/work/home/fd15hava/tinypaper-mpt/src/agent.py\", line 40, in _prompt\n    raise UnexpectedAnswerException(f\"expected 1 or 2, got {result}\")\nutil.UnexpectedAnswerException: expected 1 or 2, got  \n\nThe above exception was the direct cause of the following exception:\n\nTraceback (most recent call last):\n  File \"/work/home/fd15hava/tinypaper-mpt/scripts/experiments/run.py\", line 16, in _run_session\n    result = agent.play(session)\n             ^^^^^^^^^^^^^^^^^^^\n  File \"/home/fd15hava/.cache/pypoetry/virtualenvs/non-package-mode-zjkKA0Ca-py3.11/lib/python3.11/site-packages/tenacity/__init__.py\", line 289, in wrapped_f\n    return self(f, *args, **kw)\n           ^^^^^^^^^^^^^^^^^^^^\n  File \"/home/fd15hava/.cache/pypoetry/virtualenvs/non-package-mode-zjkKA0Ca-py3.11/lib/python3.11/site-packages/tenacity/__init__.py\", line 379, in __call__\n    do = self.iter(retry_state=retry_state)\n         ^^^^^^^^^^^^^^^^^^^^^^^^^^^^^^^^^^\n  File \"/home/fd15hava/.cache/pypoetry/virtualenvs/non-package-mode-zjkKA0Ca-py3.11/lib/python3.11/site-packages/tenacity/__init__.py\", line 326, in iter\n    raise retry_exc from fut.exception()\ntenacity.RetryError: RetryError[<Future at 0x14e62df1c0d0 state=finished raised UnexpectedAnswerException>]\n",
      "Traceback (most recent call last):\n  File \"/home/fd15hava/.cache/pypoetry/virtualenvs/non-package-mode-zjkKA0Ca-py3.11/lib/python3.11/site-packages/tenacity/__init__.py\", line 382, in __call__\n    result = fn(*args, **kwargs)\n             ^^^^^^^^^^^^^^^^^^^\n  File \"/work/home/fd15hava/tinypaper-mpt/src/agent.py\", line 26, in play\n    answer = self._prompt(self._make_prompt(scenario))\n             ^^^^^^^^^^^^^^^^^^^^^^^^^^^^^^^^^^^^^^^^^\n  File \"/work/home/fd15hava/tinypaper-mpt/src/agent.py\", line 40, in _prompt\n    raise UnexpectedAnswerException(f\"expected 1 or 2, got {result}\")\nutil.UnexpectedAnswerException: expected 1 or 2, got  \n\nThe above exception was the direct cause of the following exception:\n\nTraceback (most recent call last):\n  File \"/work/home/fd15hava/tinypaper-mpt/scripts/experiments/run.py\", line 16, in _run_session\n    result = agent.play(session)\n             ^^^^^^^^^^^^^^^^^^^\n  File \"/home/fd15hava/.cache/pypoetry/virtualenvs/non-package-mode-zjkKA0Ca-py3.11/lib/python3.11/site-packages/tenacity/__init__.py\", line 289, in wrapped_f\n    return self(f, *args, **kw)\n           ^^^^^^^^^^^^^^^^^^^^\n  File \"/home/fd15hava/.cache/pypoetry/virtualenvs/non-package-mode-zjkKA0Ca-py3.11/lib/python3.11/site-packages/tenacity/__init__.py\", line 379, in __call__\n    do = self.iter(retry_state=retry_state)\n         ^^^^^^^^^^^^^^^^^^^^^^^^^^^^^^^^^^\n  File \"/home/fd15hava/.cache/pypoetry/virtualenvs/non-package-mode-zjkKA0Ca-py3.11/lib/python3.11/site-packages/tenacity/__init__.py\", line 326, in iter\n    raise retry_exc from fut.exception()\ntenacity.RetryError: RetryError[<Future at 0x14e62de089d0 state=finished raised UnexpectedAnswerException>]\n",
      "Traceback (most recent call last):\n  File \"/home/fd15hava/.cache/pypoetry/virtualenvs/non-package-mode-zjkKA0Ca-py3.11/lib/python3.11/site-packages/tenacity/__init__.py\", line 382, in __call__\n    result = fn(*args, **kwargs)\n             ^^^^^^^^^^^^^^^^^^^\n  File \"/work/home/fd15hava/tinypaper-mpt/src/agent.py\", line 26, in play\n    answer = self._prompt(self._make_prompt(scenario))\n             ^^^^^^^^^^^^^^^^^^^^^^^^^^^^^^^^^^^^^^^^^\n  File \"/work/home/fd15hava/tinypaper-mpt/src/agent.py\", line 40, in _prompt\n    raise UnexpectedAnswerException(f\"expected 1 or 2, got {result}\")\nutil.UnexpectedAnswerException: expected 1 or 2, got  \n\nThe above exception was the direct cause of the following exception:\n\nTraceback (most recent call last):\n  File \"/work/home/fd15hava/tinypaper-mpt/scripts/experiments/run.py\", line 16, in _run_session\n    result = agent.play(session)\n             ^^^^^^^^^^^^^^^^^^^\n  File \"/home/fd15hava/.cache/pypoetry/virtualenvs/non-package-mode-zjkKA0Ca-py3.11/lib/python3.11/site-packages/tenacity/__init__.py\", line 289, in wrapped_f\n    return self(f, *args, **kw)\n           ^^^^^^^^^^^^^^^^^^^^\n  File \"/home/fd15hava/.cache/pypoetry/virtualenvs/non-package-mode-zjkKA0Ca-py3.11/lib/python3.11/site-packages/tenacity/__init__.py\", line 379, in __call__\n    do = self.iter(retry_state=retry_state)\n         ^^^^^^^^^^^^^^^^^^^^^^^^^^^^^^^^^^\n  File \"/home/fd15hava/.cache/pypoetry/virtualenvs/non-package-mode-zjkKA0Ca-py3.11/lib/python3.11/site-packages/tenacity/__init__.py\", line 326, in iter\n    raise retry_exc from fut.exception()\ntenacity.RetryError: RetryError[<Future at 0x14e62de0cf10 state=finished raised UnexpectedAnswerException>]\n",
      "Traceback (most recent call last):\n  File \"/home/fd15hava/.cache/pypoetry/virtualenvs/non-package-mode-zjkKA0Ca-py3.11/lib/python3.11/site-packages/tenacity/__init__.py\", line 382, in __call__\n    result = fn(*args, **kwargs)\n             ^^^^^^^^^^^^^^^^^^^\n  File \"/work/home/fd15hava/tinypaper-mpt/src/agent.py\", line 26, in play\n    answer = self._prompt(self._make_prompt(scenario))\n             ^^^^^^^^^^^^^^^^^^^^^^^^^^^^^^^^^^^^^^^^^\n  File \"/work/home/fd15hava/tinypaper-mpt/src/agent.py\", line 40, in _prompt\n    raise UnexpectedAnswerException(f\"expected 1 or 2, got {result}\")\nutil.UnexpectedAnswerException: expected 1 or 2, got  \n\nThe above exception was the direct cause of the following exception:\n\nTraceback (most recent call last):\n  File \"/work/home/fd15hava/tinypaper-mpt/scripts/experiments/run.py\", line 16, in _run_session\n    result = agent.play(session)\n             ^^^^^^^^^^^^^^^^^^^\n  File \"/home/fd15hava/.cache/pypoetry/virtualenvs/non-package-mode-zjkKA0Ca-py3.11/lib/python3.11/site-packages/tenacity/__init__.py\", line 289, in wrapped_f\n    return self(f, *args, **kw)\n           ^^^^^^^^^^^^^^^^^^^^\n  File \"/home/fd15hava/.cache/pypoetry/virtualenvs/non-package-mode-zjkKA0Ca-py3.11/lib/python3.11/site-packages/tenacity/__init__.py\", line 379, in __call__\n    do = self.iter(retry_state=retry_state)\n         ^^^^^^^^^^^^^^^^^^^^^^^^^^^^^^^^^^\n  File \"/home/fd15hava/.cache/pypoetry/virtualenvs/non-package-mode-zjkKA0Ca-py3.11/lib/python3.11/site-packages/tenacity/__init__.py\", line 326, in iter\n    raise retry_exc from fut.exception()\ntenacity.RetryError: RetryError[<Future at 0x14e62de08e50 state=finished raised UnexpectedAnswerException>]\n",
      "Traceback (most recent call last):\n  File \"/home/fd15hava/.cache/pypoetry/virtualenvs/non-package-mode-zjkKA0Ca-py3.11/lib/python3.11/site-packages/tenacity/__init__.py\", line 382, in __call__\n    result = fn(*args, **kwargs)\n             ^^^^^^^^^^^^^^^^^^^\n  File \"/work/home/fd15hava/tinypaper-mpt/src/agent.py\", line 26, in play\n    answer = self._prompt(self._make_prompt(scenario))\n             ^^^^^^^^^^^^^^^^^^^^^^^^^^^^^^^^^^^^^^^^^\n  File \"/work/home/fd15hava/tinypaper-mpt/src/agent.py\", line 40, in _prompt\n    raise UnexpectedAnswerException(f\"expected 1 or 2, got {result}\")\nutil.UnexpectedAnswerException: expected 1 or 2, got  \n\nThe above exception was the direct cause of the following exception:\n\nTraceback (most recent call last):\n  File \"/work/home/fd15hava/tinypaper-mpt/scripts/experiments/run.py\", line 16, in _run_session\n    result = agent.play(session)\n             ^^^^^^^^^^^^^^^^^^^\n  File \"/home/fd15hava/.cache/pypoetry/virtualenvs/non-package-mode-zjkKA0Ca-py3.11/lib/python3.11/site-packages/tenacity/__init__.py\", line 289, in wrapped_f\n    return self(f, *args, **kw)\n           ^^^^^^^^^^^^^^^^^^^^\n  File \"/home/fd15hava/.cache/pypoetry/virtualenvs/non-package-mode-zjkKA0Ca-py3.11/lib/python3.11/site-packages/tenacity/__init__.py\", line 379, in __call__\n    do = self.iter(retry_state=retry_state)\n         ^^^^^^^^^^^^^^^^^^^^^^^^^^^^^^^^^^\n  File \"/home/fd15hava/.cache/pypoetry/virtualenvs/non-package-mode-zjkKA0Ca-py3.11/lib/python3.11/site-packages/tenacity/__init__.py\", line 326, in iter\n    raise retry_exc from fut.exception()\ntenacity.RetryError: RetryError[<Future at 0x14e62de0bb10 state=finished raised UnexpectedAnswerException>]\n",
      "Traceback (most recent call last):\n  File \"/home/fd15hava/.cache/pypoetry/virtualenvs/non-package-mode-zjkKA0Ca-py3.11/lib/python3.11/site-packages/tenacity/__init__.py\", line 382, in __call__\n    result = fn(*args, **kwargs)\n             ^^^^^^^^^^^^^^^^^^^\n  File \"/work/home/fd15hava/tinypaper-mpt/src/agent.py\", line 26, in play\n    answer = self._prompt(self._make_prompt(scenario))\n             ^^^^^^^^^^^^^^^^^^^^^^^^^^^^^^^^^^^^^^^^^\n  File \"/work/home/fd15hava/tinypaper-mpt/src/agent.py\", line 40, in _prompt\n    raise UnexpectedAnswerException(f\"expected 1 or 2, got {result}\")\nutil.UnexpectedAnswerException: expected 1 or 2, got  \n\nThe above exception was the direct cause of the following exception:\n\nTraceback (most recent call last):\n  File \"/work/home/fd15hava/tinypaper-mpt/scripts/experiments/run.py\", line 16, in _run_session\n    result = agent.play(session)\n             ^^^^^^^^^^^^^^^^^^^\n  File \"/home/fd15hava/.cache/pypoetry/virtualenvs/non-package-mode-zjkKA0Ca-py3.11/lib/python3.11/site-packages/tenacity/__init__.py\", line 289, in wrapped_f\n    return self(f, *args, **kw)\n           ^^^^^^^^^^^^^^^^^^^^\n  File \"/home/fd15hava/.cache/pypoetry/virtualenvs/non-package-mode-zjkKA0Ca-py3.11/lib/python3.11/site-packages/tenacity/__init__.py\", line 379, in __call__\n    do = self.iter(retry_state=retry_state)\n         ^^^^^^^^^^^^^^^^^^^^^^^^^^^^^^^^^^\n  File \"/home/fd15hava/.cache/pypoetry/virtualenvs/non-package-mode-zjkKA0Ca-py3.11/lib/python3.11/site-packages/tenacity/__init__.py\", line 326, in iter\n    raise retry_exc from fut.exception()\ntenacity.RetryError: RetryError[<Future at 0x14e62de0df90 state=finished raised UnexpectedAnswerException>]\n",
      "Traceback (most recent call last):\n  File \"/home/fd15hava/.cache/pypoetry/virtualenvs/non-package-mode-zjkKA0Ca-py3.11/lib/python3.11/site-packages/tenacity/__init__.py\", line 382, in __call__\n    result = fn(*args, **kwargs)\n             ^^^^^^^^^^^^^^^^^^^\n  File \"/work/home/fd15hava/tinypaper-mpt/src/agent.py\", line 26, in play\n    answer = self._prompt(self._make_prompt(scenario))\n             ^^^^^^^^^^^^^^^^^^^^^^^^^^^^^^^^^^^^^^^^^\n  File \"/work/home/fd15hava/tinypaper-mpt/src/agent.py\", line 40, in _prompt\n    raise UnexpectedAnswerException(f\"expected 1 or 2, got {result}\")\nutil.UnexpectedAnswerException: expected 1 or 2, got  \n\nThe above exception was the direct cause of the following exception:\n\nTraceback (most recent call last):\n  File \"/work/home/fd15hava/tinypaper-mpt/scripts/experiments/run.py\", line 16, in _run_session\n    result = agent.play(session)\n             ^^^^^^^^^^^^^^^^^^^\n  File \"/home/fd15hava/.cache/pypoetry/virtualenvs/non-package-mode-zjkKA0Ca-py3.11/lib/python3.11/site-packages/tenacity/__init__.py\", line 289, in wrapped_f\n    return self(f, *args, **kw)\n           ^^^^^^^^^^^^^^^^^^^^\n  File \"/home/fd15hava/.cache/pypoetry/virtualenvs/non-package-mode-zjkKA0Ca-py3.11/lib/python3.11/site-packages/tenacity/__init__.py\", line 379, in __call__\n    do = self.iter(retry_state=retry_state)\n         ^^^^^^^^^^^^^^^^^^^^^^^^^^^^^^^^^^\n  File \"/home/fd15hava/.cache/pypoetry/virtualenvs/non-package-mode-zjkKA0Ca-py3.11/lib/python3.11/site-packages/tenacity/__init__.py\", line 326, in iter\n    raise retry_exc from fut.exception()\ntenacity.RetryError: RetryError[<Future at 0x14e62de7c590 state=finished raised UnexpectedAnswerException>]\n",
      "Traceback (most recent call last):\n  File \"/home/fd15hava/.cache/pypoetry/virtualenvs/non-package-mode-zjkKA0Ca-py3.11/lib/python3.11/site-packages/tenacity/__init__.py\", line 382, in __call__\n    result = fn(*args, **kwargs)\n             ^^^^^^^^^^^^^^^^^^^\n  File \"/work/home/fd15hava/tinypaper-mpt/src/agent.py\", line 26, in play\n    answer = self._prompt(self._make_prompt(scenario))\n             ^^^^^^^^^^^^^^^^^^^^^^^^^^^^^^^^^^^^^^^^^\n  File \"/work/home/fd15hava/tinypaper-mpt/src/agent.py\", line 40, in _prompt\n    raise UnexpectedAnswerException(f\"expected 1 or 2, got {result}\")\nutil.UnexpectedAnswerException: expected 1 or 2, got  \n\nThe above exception was the direct cause of the following exception:\n\nTraceback (most recent call last):\n  File \"/work/home/fd15hava/tinypaper-mpt/scripts/experiments/run.py\", line 16, in _run_session\n    result = agent.play(session)\n             ^^^^^^^^^^^^^^^^^^^\n  File \"/home/fd15hava/.cache/pypoetry/virtualenvs/non-package-mode-zjkKA0Ca-py3.11/lib/python3.11/site-packages/tenacity/__init__.py\", line 289, in wrapped_f\n    return self(f, *args, **kw)\n           ^^^^^^^^^^^^^^^^^^^^\n  File \"/home/fd15hava/.cache/pypoetry/virtualenvs/non-package-mode-zjkKA0Ca-py3.11/lib/python3.11/site-packages/tenacity/__init__.py\", line 379, in __call__\n    do = self.iter(retry_state=retry_state)\n         ^^^^^^^^^^^^^^^^^^^^^^^^^^^^^^^^^^\n  File \"/home/fd15hava/.cache/pypoetry/virtualenvs/non-package-mode-zjkKA0Ca-py3.11/lib/python3.11/site-packages/tenacity/__init__.py\", line 326, in iter\n    raise retry_exc from fut.exception()\ntenacity.RetryError: RetryError[<Future at 0x14e62de7c590 state=finished raised UnexpectedAnswerException>]\n",
      "Traceback (most recent call last):\n  File \"/home/fd15hava/.cache/pypoetry/virtualenvs/non-package-mode-zjkKA0Ca-py3.11/lib/python3.11/site-packages/tenacity/__init__.py\", line 382, in __call__\n    result = fn(*args, **kwargs)\n             ^^^^^^^^^^^^^^^^^^^\n  File \"/work/home/fd15hava/tinypaper-mpt/src/agent.py\", line 26, in play\n    answer = self._prompt(self._make_prompt(scenario))\n             ^^^^^^^^^^^^^^^^^^^^^^^^^^^^^^^^^^^^^^^^^\n  File \"/work/home/fd15hava/tinypaper-mpt/src/agent.py\", line 40, in _prompt\n    raise UnexpectedAnswerException(f\"expected 1 or 2, got {result}\")\nutil.UnexpectedAnswerException: expected 1 or 2, got  \n\nThe above exception was the direct cause of the following exception:\n\nTraceback (most recent call last):\n  File \"/work/home/fd15hava/tinypaper-mpt/scripts/experiments/run.py\", line 16, in _run_session\n    result = agent.play(session)\n             ^^^^^^^^^^^^^^^^^^^\n  File \"/home/fd15hava/.cache/pypoetry/virtualenvs/non-package-mode-zjkKA0Ca-py3.11/lib/python3.11/site-packages/tenacity/__init__.py\", line 289, in wrapped_f\n    return self(f, *args, **kw)\n           ^^^^^^^^^^^^^^^^^^^^\n  File \"/home/fd15hava/.cache/pypoetry/virtualenvs/non-package-mode-zjkKA0Ca-py3.11/lib/python3.11/site-packages/tenacity/__init__.py\", line 379, in __call__\n    do = self.iter(retry_state=retry_state)\n         ^^^^^^^^^^^^^^^^^^^^^^^^^^^^^^^^^^\n  File \"/home/fd15hava/.cache/pypoetry/virtualenvs/non-package-mode-zjkKA0Ca-py3.11/lib/python3.11/site-packages/tenacity/__init__.py\", line 326, in iter\n    raise retry_exc from fut.exception()\ntenacity.RetryError: RetryError[<Future at 0x14e62de0a090 state=finished raised UnexpectedAnswerException>]\n",
      "Traceback (most recent call last):\n  File \"/home/fd15hava/.cache/pypoetry/virtualenvs/non-package-mode-zjkKA0Ca-py3.11/lib/python3.11/site-packages/tenacity/__init__.py\", line 382, in __call__\n    result = fn(*args, **kwargs)\n             ^^^^^^^^^^^^^^^^^^^\n  File \"/work/home/fd15hava/tinypaper-mpt/src/agent.py\", line 26, in play\n    answer = self._prompt(self._make_prompt(scenario))\n             ^^^^^^^^^^^^^^^^^^^^^^^^^^^^^^^^^^^^^^^^^\n  File \"/work/home/fd15hava/tinypaper-mpt/src/agent.py\", line 40, in _prompt\n    raise UnexpectedAnswerException(f\"expected 1 or 2, got {result}\")\nutil.UnexpectedAnswerException: expected 1 or 2, got  \n\nThe above exception was the direct cause of the following exception:\n\nTraceback (most recent call last):\n  File \"/work/home/fd15hava/tinypaper-mpt/scripts/experiments/run.py\", line 16, in _run_session\n    result = agent.play(session)\n             ^^^^^^^^^^^^^^^^^^^\n  File \"/home/fd15hava/.cache/pypoetry/virtualenvs/non-package-mode-zjkKA0Ca-py3.11/lib/python3.11/site-packages/tenacity/__init__.py\", line 289, in wrapped_f\n    return self(f, *args, **kw)\n           ^^^^^^^^^^^^^^^^^^^^\n  File \"/home/fd15hava/.cache/pypoetry/virtualenvs/non-package-mode-zjkKA0Ca-py3.11/lib/python3.11/site-packages/tenacity/__init__.py\", line 379, in __call__\n    do = self.iter(retry_state=retry_state)\n         ^^^^^^^^^^^^^^^^^^^^^^^^^^^^^^^^^^\n  File \"/home/fd15hava/.cache/pypoetry/virtualenvs/non-package-mode-zjkKA0Ca-py3.11/lib/python3.11/site-packages/tenacity/__init__.py\", line 326, in iter\n    raise retry_exc from fut.exception()\ntenacity.RetryError: RetryError[<Future at 0x14e62de0e510 state=finished raised UnexpectedAnswerException>]\n",
      "Traceback (most recent call last):\n  File \"/home/fd15hava/.cache/pypoetry/virtualenvs/non-package-mode-zjkKA0Ca-py3.11/lib/python3.11/site-packages/tenacity/__init__.py\", line 382, in __call__\n    result = fn(*args, **kwargs)\n             ^^^^^^^^^^^^^^^^^^^\n  File \"/work/home/fd15hava/tinypaper-mpt/src/agent.py\", line 26, in play\n    answer = self._prompt(self._make_prompt(scenario))\n             ^^^^^^^^^^^^^^^^^^^^^^^^^^^^^^^^^^^^^^^^^\n  File \"/work/home/fd15hava/tinypaper-mpt/src/agent.py\", line 40, in _prompt\n    raise UnexpectedAnswerException(f\"expected 1 or 2, got {result}\")\nutil.UnexpectedAnswerException: expected 1 or 2, got  \n\nThe above exception was the direct cause of the following exception:\n\nTraceback (most recent call last):\n  File \"/work/home/fd15hava/tinypaper-mpt/scripts/experiments/run.py\", line 16, in _run_session\n    result = agent.play(session)\n             ^^^^^^^^^^^^^^^^^^^\n  File \"/home/fd15hava/.cache/pypoetry/virtualenvs/non-package-mode-zjkKA0Ca-py3.11/lib/python3.11/site-packages/tenacity/__init__.py\", line 289, in wrapped_f\n    return self(f, *args, **kw)\n           ^^^^^^^^^^^^^^^^^^^^\n  File \"/home/fd15hava/.cache/pypoetry/virtualenvs/non-package-mode-zjkKA0Ca-py3.11/lib/python3.11/site-packages/tenacity/__init__.py\", line 379, in __call__\n    do = self.iter(retry_state=retry_state)\n         ^^^^^^^^^^^^^^^^^^^^^^^^^^^^^^^^^^\n  File \"/home/fd15hava/.cache/pypoetry/virtualenvs/non-package-mode-zjkKA0Ca-py3.11/lib/python3.11/site-packages/tenacity/__init__.py\", line 326, in iter\n    raise retry_exc from fut.exception()\ntenacity.RetryError: RetryError[<Future at 0x14e62de0ee90 state=finished raised UnexpectedAnswerException>]\n",
      "Traceback (most recent call last):\n  File \"/home/fd15hava/.cache/pypoetry/virtualenvs/non-package-mode-zjkKA0Ca-py3.11/lib/python3.11/site-packages/tenacity/__init__.py\", line 382, in __call__\n    result = fn(*args, **kwargs)\n             ^^^^^^^^^^^^^^^^^^^\n  File \"/work/home/fd15hava/tinypaper-mpt/src/agent.py\", line 26, in play\n    answer = self._prompt(self._make_prompt(scenario))\n             ^^^^^^^^^^^^^^^^^^^^^^^^^^^^^^^^^^^^^^^^^\n  File \"/work/home/fd15hava/tinypaper-mpt/src/agent.py\", line 40, in _prompt\n    raise UnexpectedAnswerException(f\"expected 1 or 2, got {result}\")\nutil.UnexpectedAnswerException: expected 1 or 2, got  \n\nThe above exception was the direct cause of the following exception:\n\nTraceback (most recent call last):\n  File \"/work/home/fd15hava/tinypaper-mpt/scripts/experiments/run.py\", line 16, in _run_session\n    result = agent.play(session)\n             ^^^^^^^^^^^^^^^^^^^\n  File \"/home/fd15hava/.cache/pypoetry/virtualenvs/non-package-mode-zjkKA0Ca-py3.11/lib/python3.11/site-packages/tenacity/__init__.py\", line 289, in wrapped_f\n    return self(f, *args, **kw)\n           ^^^^^^^^^^^^^^^^^^^^\n  File \"/home/fd15hava/.cache/pypoetry/virtualenvs/non-package-mode-zjkKA0Ca-py3.11/lib/python3.11/site-packages/tenacity/__init__.py\", line 379, in __call__\n    do = self.iter(retry_state=retry_state)\n         ^^^^^^^^^^^^^^^^^^^^^^^^^^^^^^^^^^\n  File \"/home/fd15hava/.cache/pypoetry/virtualenvs/non-package-mode-zjkKA0Ca-py3.11/lib/python3.11/site-packages/tenacity/__init__.py\", line 326, in iter\n    raise retry_exc from fut.exception()\ntenacity.RetryError: RetryError[<Future at 0x14e62de0cf90 state=finished raised UnexpectedAnswerException>]\n",
      "Traceback (most recent call last):\n  File \"/home/fd15hava/.cache/pypoetry/virtualenvs/non-package-mode-zjkKA0Ca-py3.11/lib/python3.11/site-packages/tenacity/__init__.py\", line 382, in __call__\n    result = fn(*args, **kwargs)\n             ^^^^^^^^^^^^^^^^^^^\n  File \"/work/home/fd15hava/tinypaper-mpt/src/agent.py\", line 26, in play\n    answer = self._prompt(self._make_prompt(scenario))\n             ^^^^^^^^^^^^^^^^^^^^^^^^^^^^^^^^^^^^^^^^^\n  File \"/work/home/fd15hava/tinypaper-mpt/src/agent.py\", line 40, in _prompt\n    raise UnexpectedAnswerException(f\"expected 1 or 2, got {result}\")\nutil.UnexpectedAnswerException: expected 1 or 2, got  \n\nThe above exception was the direct cause of the following exception:\n\nTraceback (most recent call last):\n  File \"/work/home/fd15hava/tinypaper-mpt/scripts/experiments/run.py\", line 16, in _run_session\n    result = agent.play(session)\n             ^^^^^^^^^^^^^^^^^^^\n  File \"/home/fd15hava/.cache/pypoetry/virtualenvs/non-package-mode-zjkKA0Ca-py3.11/lib/python3.11/site-packages/tenacity/__init__.py\", line 289, in wrapped_f\n    return self(f, *args, **kw)\n           ^^^^^^^^^^^^^^^^^^^^\n  File \"/home/fd15hava/.cache/pypoetry/virtualenvs/non-package-mode-zjkKA0Ca-py3.11/lib/python3.11/site-packages/tenacity/__init__.py\", line 379, in __call__\n    do = self.iter(retry_state=retry_state)\n         ^^^^^^^^^^^^^^^^^^^^^^^^^^^^^^^^^^\n  File \"/home/fd15hava/.cache/pypoetry/virtualenvs/non-package-mode-zjkKA0Ca-py3.11/lib/python3.11/site-packages/tenacity/__init__.py\", line 326, in iter\n    raise retry_exc from fut.exception()\ntenacity.RetryError: RetryError[<Future at 0x14e62de0bf50 state=finished raised UnexpectedAnswerException>]\n",
      "Traceback (most recent call last):\n  File \"/home/fd15hava/.cache/pypoetry/virtualenvs/non-package-mode-zjkKA0Ca-py3.11/lib/python3.11/site-packages/tenacity/__init__.py\", line 382, in __call__\n    result = fn(*args, **kwargs)\n             ^^^^^^^^^^^^^^^^^^^\n  File \"/work/home/fd15hava/tinypaper-mpt/src/agent.py\", line 26, in play\n    answer = self._prompt(self._make_prompt(scenario))\n             ^^^^^^^^^^^^^^^^^^^^^^^^^^^^^^^^^^^^^^^^^\n  File \"/work/home/fd15hava/tinypaper-mpt/src/agent.py\", line 40, in _prompt\n    raise UnexpectedAnswerException(f\"expected 1 or 2, got {result}\")\nutil.UnexpectedAnswerException: expected 1 or 2, got  \n\nThe above exception was the direct cause of the following exception:\n\nTraceback (most recent call last):\n  File \"/work/home/fd15hava/tinypaper-mpt/scripts/experiments/run.py\", line 16, in _run_session\n    result = agent.play(session)\n             ^^^^^^^^^^^^^^^^^^^\n  File \"/home/fd15hava/.cache/pypoetry/virtualenvs/non-package-mode-zjkKA0Ca-py3.11/lib/python3.11/site-packages/tenacity/__init__.py\", line 289, in wrapped_f\n    return self(f, *args, **kw)\n           ^^^^^^^^^^^^^^^^^^^^\n  File \"/home/fd15hava/.cache/pypoetry/virtualenvs/non-package-mode-zjkKA0Ca-py3.11/lib/python3.11/site-packages/tenacity/__init__.py\", line 379, in __call__\n    do = self.iter(retry_state=retry_state)\n         ^^^^^^^^^^^^^^^^^^^^^^^^^^^^^^^^^^\n  File \"/home/fd15hava/.cache/pypoetry/virtualenvs/non-package-mode-zjkKA0Ca-py3.11/lib/python3.11/site-packages/tenacity/__init__.py\", line 326, in iter\n    raise retry_exc from fut.exception()\ntenacity.RetryError: RetryError[<Future at 0x14e62de0d550 state=finished raised UnexpectedAnswerException>]\n",
      "Traceback (most recent call last):\n  File \"/home/fd15hava/.cache/pypoetry/virtualenvs/non-package-mode-zjkKA0Ca-py3.11/lib/python3.11/site-packages/tenacity/__init__.py\", line 382, in __call__\n    result = fn(*args, **kwargs)\n             ^^^^^^^^^^^^^^^^^^^\n  File \"/work/home/fd15hava/tinypaper-mpt/src/agent.py\", line 26, in play\n    answer = self._prompt(self._make_prompt(scenario))\n             ^^^^^^^^^^^^^^^^^^^^^^^^^^^^^^^^^^^^^^^^^\n  File \"/work/home/fd15hava/tinypaper-mpt/src/agent.py\", line 40, in _prompt\n    raise UnexpectedAnswerException(f\"expected 1 or 2, got {result}\")\nutil.UnexpectedAnswerException: expected 1 or 2, got  \n\nThe above exception was the direct cause of the following exception:\n\nTraceback (most recent call last):\n  File \"/work/home/fd15hava/tinypaper-mpt/scripts/experiments/run.py\", line 16, in _run_session\n    result = agent.play(session)\n             ^^^^^^^^^^^^^^^^^^^\n  File \"/home/fd15hava/.cache/pypoetry/virtualenvs/non-package-mode-zjkKA0Ca-py3.11/lib/python3.11/site-packages/tenacity/__init__.py\", line 289, in wrapped_f\n    return self(f, *args, **kw)\n           ^^^^^^^^^^^^^^^^^^^^\n  File \"/home/fd15hava/.cache/pypoetry/virtualenvs/non-package-mode-zjkKA0Ca-py3.11/lib/python3.11/site-packages/tenacity/__init__.py\", line 379, in __call__\n    do = self.iter(retry_state=retry_state)\n         ^^^^^^^^^^^^^^^^^^^^^^^^^^^^^^^^^^\n  File \"/home/fd15hava/.cache/pypoetry/virtualenvs/non-package-mode-zjkKA0Ca-py3.11/lib/python3.11/site-packages/tenacity/__init__.py\", line 326, in iter\n    raise retry_exc from fut.exception()\ntenacity.RetryError: RetryError[<Future at 0x14e62de0c110 state=finished raised UnexpectedAnswerException>]\n",
      "Traceback (most recent call last):\n  File \"/home/fd15hava/.cache/pypoetry/virtualenvs/non-package-mode-zjkKA0Ca-py3.11/lib/python3.11/site-packages/tenacity/__init__.py\", line 382, in __call__\n    result = fn(*args, **kwargs)\n             ^^^^^^^^^^^^^^^^^^^\n  File \"/work/home/fd15hava/tinypaper-mpt/src/agent.py\", line 26, in play\n    answer = self._prompt(self._make_prompt(scenario))\n             ^^^^^^^^^^^^^^^^^^^^^^^^^^^^^^^^^^^^^^^^^\n  File \"/work/home/fd15hava/tinypaper-mpt/src/agent.py\", line 40, in _prompt\n    raise UnexpectedAnswerException(f\"expected 1 or 2, got {result}\")\nutil.UnexpectedAnswerException: expected 1 or 2, got  \n\nThe above exception was the direct cause of the following exception:\n\nTraceback (most recent call last):\n  File \"/work/home/fd15hava/tinypaper-mpt/scripts/experiments/run.py\", line 16, in _run_session\n    result = agent.play(session)\n             ^^^^^^^^^^^^^^^^^^^\n  File \"/home/fd15hava/.cache/pypoetry/virtualenvs/non-package-mode-zjkKA0Ca-py3.11/lib/python3.11/site-packages/tenacity/__init__.py\", line 289, in wrapped_f\n    return self(f, *args, **kw)\n           ^^^^^^^^^^^^^^^^^^^^\n  File \"/home/fd15hava/.cache/pypoetry/virtualenvs/non-package-mode-zjkKA0Ca-py3.11/lib/python3.11/site-packages/tenacity/__init__.py\", line 379, in __call__\n    do = self.iter(retry_state=retry_state)\n         ^^^^^^^^^^^^^^^^^^^^^^^^^^^^^^^^^^\n  File \"/home/fd15hava/.cache/pypoetry/virtualenvs/non-package-mode-zjkKA0Ca-py3.11/lib/python3.11/site-packages/tenacity/__init__.py\", line 326, in iter\n    raise retry_exc from fut.exception()\ntenacity.RetryError: RetryError[<Future at 0x14e62ddcd850 state=finished raised UnexpectedAnswerException>]\n",
      "Traceback (most recent call last):\n  File \"/home/fd15hava/.cache/pypoetry/virtualenvs/non-package-mode-zjkKA0Ca-py3.11/lib/python3.11/site-packages/tenacity/__init__.py\", line 382, in __call__\n    result = fn(*args, **kwargs)\n             ^^^^^^^^^^^^^^^^^^^\n  File \"/work/home/fd15hava/tinypaper-mpt/src/agent.py\", line 26, in play\n    answer = self._prompt(self._make_prompt(scenario))\n             ^^^^^^^^^^^^^^^^^^^^^^^^^^^^^^^^^^^^^^^^^\n  File \"/work/home/fd15hava/tinypaper-mpt/src/agent.py\", line 40, in _prompt\n    raise UnexpectedAnswerException(f\"expected 1 or 2, got {result}\")\nutil.UnexpectedAnswerException: expected 1 or 2, got  \n\nThe above exception was the direct cause of the following exception:\n\nTraceback (most recent call last):\n  File \"/work/home/fd15hava/tinypaper-mpt/scripts/experiments/run.py\", line 16, in _run_session\n    result = agent.play(session)\n             ^^^^^^^^^^^^^^^^^^^\n  File \"/home/fd15hava/.cache/pypoetry/virtualenvs/non-package-mode-zjkKA0Ca-py3.11/lib/python3.11/site-packages/tenacity/__init__.py\", line 289, in wrapped_f\n    return self(f, *args, **kw)\n           ^^^^^^^^^^^^^^^^^^^^\n  File \"/home/fd15hava/.cache/pypoetry/virtualenvs/non-package-mode-zjkKA0Ca-py3.11/lib/python3.11/site-packages/tenacity/__init__.py\", line 379, in __call__\n    do = self.iter(retry_state=retry_state)\n         ^^^^^^^^^^^^^^^^^^^^^^^^^^^^^^^^^^\n  File \"/home/fd15hava/.cache/pypoetry/virtualenvs/non-package-mode-zjkKA0Ca-py3.11/lib/python3.11/site-packages/tenacity/__init__.py\", line 326, in iter\n    raise retry_exc from fut.exception()\ntenacity.RetryError: RetryError[<Future at 0x14e62de0c910 state=finished raised UnexpectedAnswerException>]\n",
      "Traceback (most recent call last):\n  File \"/home/fd15hava/.cache/pypoetry/virtualenvs/non-package-mode-zjkKA0Ca-py3.11/lib/python3.11/site-packages/tenacity/__init__.py\", line 382, in __call__\n    result = fn(*args, **kwargs)\n             ^^^^^^^^^^^^^^^^^^^\n  File \"/work/home/fd15hava/tinypaper-mpt/src/agent.py\", line 26, in play\n    answer = self._prompt(self._make_prompt(scenario))\n             ^^^^^^^^^^^^^^^^^^^^^^^^^^^^^^^^^^^^^^^^^\n  File \"/work/home/fd15hava/tinypaper-mpt/src/agent.py\", line 40, in _prompt\n    raise UnexpectedAnswerException(f\"expected 1 or 2, got {result}\")\nutil.UnexpectedAnswerException: expected 1 or 2, got  \n\nThe above exception was the direct cause of the following exception:\n\nTraceback (most recent call last):\n  File \"/work/home/fd15hava/tinypaper-mpt/scripts/experiments/run.py\", line 16, in _run_session\n    result = agent.play(session)\n             ^^^^^^^^^^^^^^^^^^^\n  File \"/home/fd15hava/.cache/pypoetry/virtualenvs/non-package-mode-zjkKA0Ca-py3.11/lib/python3.11/site-packages/tenacity/__init__.py\", line 289, in wrapped_f\n    return self(f, *args, **kw)\n           ^^^^^^^^^^^^^^^^^^^^\n  File \"/home/fd15hava/.cache/pypoetry/virtualenvs/non-package-mode-zjkKA0Ca-py3.11/lib/python3.11/site-packages/tenacity/__init__.py\", line 379, in __call__\n    do = self.iter(retry_state=retry_state)\n         ^^^^^^^^^^^^^^^^^^^^^^^^^^^^^^^^^^\n  File \"/home/fd15hava/.cache/pypoetry/virtualenvs/non-package-mode-zjkKA0Ca-py3.11/lib/python3.11/site-packages/tenacity/__init__.py\", line 326, in iter\n    raise retry_exc from fut.exception()\ntenacity.RetryError: RetryError[<Future at 0x14e62ddcd6d0 state=finished raised UnexpectedAnswerException>]\n",
      "Traceback (most recent call last):\n  File \"/home/fd15hava/.cache/pypoetry/virtualenvs/non-package-mode-zjkKA0Ca-py3.11/lib/python3.11/site-packages/tenacity/__init__.py\", line 382, in __call__\n    result = fn(*args, **kwargs)\n             ^^^^^^^^^^^^^^^^^^^\n  File \"/work/home/fd15hava/tinypaper-mpt/src/agent.py\", line 26, in play\n    answer = self._prompt(self._make_prompt(scenario))\n             ^^^^^^^^^^^^^^^^^^^^^^^^^^^^^^^^^^^^^^^^^\n  File \"/work/home/fd15hava/tinypaper-mpt/src/agent.py\", line 40, in _prompt\n    raise UnexpectedAnswerException(f\"expected 1 or 2, got {result}\")\nutil.UnexpectedAnswerException: expected 1 or 2, got  \n\nThe above exception was the direct cause of the following exception:\n\nTraceback (most recent call last):\n  File \"/work/home/fd15hava/tinypaper-mpt/scripts/experiments/run.py\", line 16, in _run_session\n    result = agent.play(session)\n             ^^^^^^^^^^^^^^^^^^^\n  File \"/home/fd15hava/.cache/pypoetry/virtualenvs/non-package-mode-zjkKA0Ca-py3.11/lib/python3.11/site-packages/tenacity/__init__.py\", line 289, in wrapped_f\n    return self(f, *args, **kw)\n           ^^^^^^^^^^^^^^^^^^^^\n  File \"/home/fd15hava/.cache/pypoetry/virtualenvs/non-package-mode-zjkKA0Ca-py3.11/lib/python3.11/site-packages/tenacity/__init__.py\", line 379, in __call__\n    do = self.iter(retry_state=retry_state)\n         ^^^^^^^^^^^^^^^^^^^^^^^^^^^^^^^^^^\n  File \"/home/fd15hava/.cache/pypoetry/virtualenvs/non-package-mode-zjkKA0Ca-py3.11/lib/python3.11/site-packages/tenacity/__init__.py\", line 326, in iter\n    raise retry_exc from fut.exception()\ntenacity.RetryError: RetryError[<Future at 0x14e62ddad890 state=finished raised UnexpectedAnswerException>]\n",
      "Traceback (most recent call last):\n  File \"/home/fd15hava/.cache/pypoetry/virtualenvs/non-package-mode-zjkKA0Ca-py3.11/lib/python3.11/site-packages/tenacity/__init__.py\", line 382, in __call__\n    result = fn(*args, **kwargs)\n             ^^^^^^^^^^^^^^^^^^^\n  File \"/work/home/fd15hava/tinypaper-mpt/src/agent.py\", line 26, in play\n    answer = self._prompt(self._make_prompt(scenario))\n             ^^^^^^^^^^^^^^^^^^^^^^^^^^^^^^^^^^^^^^^^^\n  File \"/work/home/fd15hava/tinypaper-mpt/src/agent.py\", line 40, in _prompt\n    raise UnexpectedAnswerException(f\"expected 1 or 2, got {result}\")\nutil.UnexpectedAnswerException: expected 1 or 2, got  \n\nThe above exception was the direct cause of the following exception:\n\nTraceback (most recent call last):\n  File \"/work/home/fd15hava/tinypaper-mpt/scripts/experiments/run.py\", line 16, in _run_session\n    result = agent.play(session)\n             ^^^^^^^^^^^^^^^^^^^\n  File \"/home/fd15hava/.cache/pypoetry/virtualenvs/non-package-mode-zjkKA0Ca-py3.11/lib/python3.11/site-packages/tenacity/__init__.py\", line 289, in wrapped_f\n    return self(f, *args, **kw)\n           ^^^^^^^^^^^^^^^^^^^^\n  File \"/home/fd15hava/.cache/pypoetry/virtualenvs/non-package-mode-zjkKA0Ca-py3.11/lib/python3.11/site-packages/tenacity/__init__.py\", line 379, in __call__\n    do = self.iter(retry_state=retry_state)\n         ^^^^^^^^^^^^^^^^^^^^^^^^^^^^^^^^^^\n  File \"/home/fd15hava/.cache/pypoetry/virtualenvs/non-package-mode-zjkKA0Ca-py3.11/lib/python3.11/site-packages/tenacity/__init__.py\", line 326, in iter\n    raise retry_exc from fut.exception()\ntenacity.RetryError: RetryError[<Future at 0x14e62de0d110 state=finished raised UnexpectedAnswerException>]\n",
      "Traceback (most recent call last):\n  File \"/home/fd15hava/.cache/pypoetry/virtualenvs/non-package-mode-zjkKA0Ca-py3.11/lib/python3.11/site-packages/tenacity/__init__.py\", line 382, in __call__\n    result = fn(*args, **kwargs)\n             ^^^^^^^^^^^^^^^^^^^\n  File \"/work/home/fd15hava/tinypaper-mpt/src/agent.py\", line 26, in play\n    answer = self._prompt(self._make_prompt(scenario))\n             ^^^^^^^^^^^^^^^^^^^^^^^^^^^^^^^^^^^^^^^^^\n  File \"/work/home/fd15hava/tinypaper-mpt/src/agent.py\", line 40, in _prompt\n    raise UnexpectedAnswerException(f\"expected 1 or 2, got {result}\")\nutil.UnexpectedAnswerException: expected 1 or 2, got  \n\nThe above exception was the direct cause of the following exception:\n\nTraceback (most recent call last):\n  File \"/work/home/fd15hava/tinypaper-mpt/scripts/experiments/run.py\", line 16, in _run_session\n    result = agent.play(session)\n             ^^^^^^^^^^^^^^^^^^^\n  File \"/home/fd15hava/.cache/pypoetry/virtualenvs/non-package-mode-zjkKA0Ca-py3.11/lib/python3.11/site-packages/tenacity/__init__.py\", line 289, in wrapped_f\n    return self(f, *args, **kw)\n           ^^^^^^^^^^^^^^^^^^^^\n  File \"/home/fd15hava/.cache/pypoetry/virtualenvs/non-package-mode-zjkKA0Ca-py3.11/lib/python3.11/site-packages/tenacity/__init__.py\", line 379, in __call__\n    do = self.iter(retry_state=retry_state)\n         ^^^^^^^^^^^^^^^^^^^^^^^^^^^^^^^^^^\n  File \"/home/fd15hava/.cache/pypoetry/virtualenvs/non-package-mode-zjkKA0Ca-py3.11/lib/python3.11/site-packages/tenacity/__init__.py\", line 326, in iter\n    raise retry_exc from fut.exception()\ntenacity.RetryError: RetryError[<Future at 0x14e62ddcde50 state=finished raised UnexpectedAnswerException>]\n",
      "Traceback (most recent call last):\n  File \"/home/fd15hava/.cache/pypoetry/virtualenvs/non-package-mode-zjkKA0Ca-py3.11/lib/python3.11/site-packages/tenacity/__init__.py\", line 382, in __call__\n    result = fn(*args, **kwargs)\n             ^^^^^^^^^^^^^^^^^^^\n  File \"/work/home/fd15hava/tinypaper-mpt/src/agent.py\", line 26, in play\n    answer = self._prompt(self._make_prompt(scenario))\n             ^^^^^^^^^^^^^^^^^^^^^^^^^^^^^^^^^^^^^^^^^\n  File \"/work/home/fd15hava/tinypaper-mpt/src/agent.py\", line 40, in _prompt\n    raise UnexpectedAnswerException(f\"expected 1 or 2, got {result}\")\nutil.UnexpectedAnswerException: expected 1 or 2, got  \n\nThe above exception was the direct cause of the following exception:\n\nTraceback (most recent call last):\n  File \"/work/home/fd15hava/tinypaper-mpt/scripts/experiments/run.py\", line 16, in _run_session\n    result = agent.play(session)\n             ^^^^^^^^^^^^^^^^^^^\n  File \"/home/fd15hava/.cache/pypoetry/virtualenvs/non-package-mode-zjkKA0Ca-py3.11/lib/python3.11/site-packages/tenacity/__init__.py\", line 289, in wrapped_f\n    return self(f, *args, **kw)\n           ^^^^^^^^^^^^^^^^^^^^\n  File \"/home/fd15hava/.cache/pypoetry/virtualenvs/non-package-mode-zjkKA0Ca-py3.11/lib/python3.11/site-packages/tenacity/__init__.py\", line 379, in __call__\n    do = self.iter(retry_state=retry_state)\n         ^^^^^^^^^^^^^^^^^^^^^^^^^^^^^^^^^^\n  File \"/home/fd15hava/.cache/pypoetry/virtualenvs/non-package-mode-zjkKA0Ca-py3.11/lib/python3.11/site-packages/tenacity/__init__.py\", line 326, in iter\n    raise retry_exc from fut.exception()\ntenacity.RetryError: RetryError[<Future at 0x14e62ddec410 state=finished raised UnexpectedAnswerException>]\n",
      "Traceback (most recent call last):\n  File \"/home/fd15hava/.cache/pypoetry/virtualenvs/non-package-mode-zjkKA0Ca-py3.11/lib/python3.11/site-packages/tenacity/__init__.py\", line 382, in __call__\n    result = fn(*args, **kwargs)\n             ^^^^^^^^^^^^^^^^^^^\n  File \"/work/home/fd15hava/tinypaper-mpt/src/agent.py\", line 26, in play\n    answer = self._prompt(self._make_prompt(scenario))\n             ^^^^^^^^^^^^^^^^^^^^^^^^^^^^^^^^^^^^^^^^^\n  File \"/work/home/fd15hava/tinypaper-mpt/src/agent.py\", line 40, in _prompt\n    raise UnexpectedAnswerException(f\"expected 1 or 2, got {result}\")\nutil.UnexpectedAnswerException: expected 1 or 2, got  \n\nThe above exception was the direct cause of the following exception:\n\nTraceback (most recent call last):\n  File \"/work/home/fd15hava/tinypaper-mpt/scripts/experiments/run.py\", line 16, in _run_session\n    result = agent.play(session)\n             ^^^^^^^^^^^^^^^^^^^\n  File \"/home/fd15hava/.cache/pypoetry/virtualenvs/non-package-mode-zjkKA0Ca-py3.11/lib/python3.11/site-packages/tenacity/__init__.py\", line 289, in wrapped_f\n    return self(f, *args, **kw)\n           ^^^^^^^^^^^^^^^^^^^^\n  File \"/home/fd15hava/.cache/pypoetry/virtualenvs/non-package-mode-zjkKA0Ca-py3.11/lib/python3.11/site-packages/tenacity/__init__.py\", line 379, in __call__\n    do = self.iter(retry_state=retry_state)\n         ^^^^^^^^^^^^^^^^^^^^^^^^^^^^^^^^^^\n  File \"/home/fd15hava/.cache/pypoetry/virtualenvs/non-package-mode-zjkKA0Ca-py3.11/lib/python3.11/site-packages/tenacity/__init__.py\", line 326, in iter\n    raise retry_exc from fut.exception()\ntenacity.RetryError: RetryError[<Future at 0x14e62de0e550 state=finished raised UnexpectedAnswerException>]\n",
      "Traceback (most recent call last):\n  File \"/home/fd15hava/.cache/pypoetry/virtualenvs/non-package-mode-zjkKA0Ca-py3.11/lib/python3.11/site-packages/tenacity/__init__.py\", line 382, in __call__\n    result = fn(*args, **kwargs)\n             ^^^^^^^^^^^^^^^^^^^\n  File \"/work/home/fd15hava/tinypaper-mpt/src/agent.py\", line 26, in play\n    answer = self._prompt(self._make_prompt(scenario))\n             ^^^^^^^^^^^^^^^^^^^^^^^^^^^^^^^^^^^^^^^^^\n  File \"/work/home/fd15hava/tinypaper-mpt/src/agent.py\", line 40, in _prompt\n    raise UnexpectedAnswerException(f\"expected 1 or 2, got {result}\")\nutil.UnexpectedAnswerException: expected 1 or 2, got  \n\nThe above exception was the direct cause of the following exception:\n\nTraceback (most recent call last):\n  File \"/work/home/fd15hava/tinypaper-mpt/scripts/experiments/run.py\", line 16, in _run_session\n    result = agent.play(session)\n             ^^^^^^^^^^^^^^^^^^^\n  File \"/home/fd15hava/.cache/pypoetry/virtualenvs/non-package-mode-zjkKA0Ca-py3.11/lib/python3.11/site-packages/tenacity/__init__.py\", line 289, in wrapped_f\n    return self(f, *args, **kw)\n           ^^^^^^^^^^^^^^^^^^^^\n  File \"/home/fd15hava/.cache/pypoetry/virtualenvs/non-package-mode-zjkKA0Ca-py3.11/lib/python3.11/site-packages/tenacity/__init__.py\", line 379, in __call__\n    do = self.iter(retry_state=retry_state)\n         ^^^^^^^^^^^^^^^^^^^^^^^^^^^^^^^^^^\n  File \"/home/fd15hava/.cache/pypoetry/virtualenvs/non-package-mode-zjkKA0Ca-py3.11/lib/python3.11/site-packages/tenacity/__init__.py\", line 326, in iter\n    raise retry_exc from fut.exception()\ntenacity.RetryError: RetryError[<Future at 0x14e62de0e1d0 state=finished raised UnexpectedAnswerException>]\n",
      "Traceback (most recent call last):\n  File \"/home/fd15hava/.cache/pypoetry/virtualenvs/non-package-mode-zjkKA0Ca-py3.11/lib/python3.11/site-packages/tenacity/__init__.py\", line 382, in __call__\n    result = fn(*args, **kwargs)\n             ^^^^^^^^^^^^^^^^^^^\n  File \"/work/home/fd15hava/tinypaper-mpt/src/agent.py\", line 26, in play\n    answer = self._prompt(self._make_prompt(scenario))\n             ^^^^^^^^^^^^^^^^^^^^^^^^^^^^^^^^^^^^^^^^^\n  File \"/work/home/fd15hava/tinypaper-mpt/src/agent.py\", line 40, in _prompt\n    raise UnexpectedAnswerException(f\"expected 1 or 2, got {result}\")\nutil.UnexpectedAnswerException: expected 1 or 2, got  \n\nThe above exception was the direct cause of the following exception:\n\nTraceback (most recent call last):\n  File \"/work/home/fd15hava/tinypaper-mpt/scripts/experiments/run.py\", line 16, in _run_session\n    result = agent.play(session)\n             ^^^^^^^^^^^^^^^^^^^\n  File \"/home/fd15hava/.cache/pypoetry/virtualenvs/non-package-mode-zjkKA0Ca-py3.11/lib/python3.11/site-packages/tenacity/__init__.py\", line 289, in wrapped_f\n    return self(f, *args, **kw)\n           ^^^^^^^^^^^^^^^^^^^^\n  File \"/home/fd15hava/.cache/pypoetry/virtualenvs/non-package-mode-zjkKA0Ca-py3.11/lib/python3.11/site-packages/tenacity/__init__.py\", line 379, in __call__\n    do = self.iter(retry_state=retry_state)\n         ^^^^^^^^^^^^^^^^^^^^^^^^^^^^^^^^^^\n  File \"/home/fd15hava/.cache/pypoetry/virtualenvs/non-package-mode-zjkKA0Ca-py3.11/lib/python3.11/site-packages/tenacity/__init__.py\", line 326, in iter\n    raise retry_exc from fut.exception()\ntenacity.RetryError: RetryError[<Future at 0x14e62de0d690 state=finished raised UnexpectedAnswerException>]\n",
      "Traceback (most recent call last):\n  File \"/home/fd15hava/.cache/pypoetry/virtualenvs/non-package-mode-zjkKA0Ca-py3.11/lib/python3.11/site-packages/tenacity/__init__.py\", line 382, in __call__\n    result = fn(*args, **kwargs)\n             ^^^^^^^^^^^^^^^^^^^\n  File \"/work/home/fd15hava/tinypaper-mpt/src/agent.py\", line 26, in play\n    answer = self._prompt(self._make_prompt(scenario))\n             ^^^^^^^^^^^^^^^^^^^^^^^^^^^^^^^^^^^^^^^^^\n  File \"/work/home/fd15hava/tinypaper-mpt/src/agent.py\", line 40, in _prompt\n    raise UnexpectedAnswerException(f\"expected 1 or 2, got {result}\")\nutil.UnexpectedAnswerException: expected 1 or 2, got  \n\nThe above exception was the direct cause of the following exception:\n\nTraceback (most recent call last):\n  File \"/work/home/fd15hava/tinypaper-mpt/scripts/experiments/run.py\", line 16, in _run_session\n    result = agent.play(session)\n             ^^^^^^^^^^^^^^^^^^^\n  File \"/home/fd15hava/.cache/pypoetry/virtualenvs/non-package-mode-zjkKA0Ca-py3.11/lib/python3.11/site-packages/tenacity/__init__.py\", line 289, in wrapped_f\n    return self(f, *args, **kw)\n           ^^^^^^^^^^^^^^^^^^^^\n  File \"/home/fd15hava/.cache/pypoetry/virtualenvs/non-package-mode-zjkKA0Ca-py3.11/lib/python3.11/site-packages/tenacity/__init__.py\", line 379, in __call__\n    do = self.iter(retry_state=retry_state)\n         ^^^^^^^^^^^^^^^^^^^^^^^^^^^^^^^^^^\n  File \"/home/fd15hava/.cache/pypoetry/virtualenvs/non-package-mode-zjkKA0Ca-py3.11/lib/python3.11/site-packages/tenacity/__init__.py\", line 326, in iter\n    raise retry_exc from fut.exception()\ntenacity.RetryError: RetryError[<Future at 0x14e62de08cd0 state=finished raised UnexpectedAnswerException>]\n",
      "Traceback (most recent call last):\n  File \"/home/fd15hava/.cache/pypoetry/virtualenvs/non-package-mode-zjkKA0Ca-py3.11/lib/python3.11/site-packages/tenacity/__init__.py\", line 382, in __call__\n    result = fn(*args, **kwargs)\n             ^^^^^^^^^^^^^^^^^^^\n  File \"/work/home/fd15hava/tinypaper-mpt/src/agent.py\", line 26, in play\n    answer = self._prompt(self._make_prompt(scenario))\n             ^^^^^^^^^^^^^^^^^^^^^^^^^^^^^^^^^^^^^^^^^\n  File \"/work/home/fd15hava/tinypaper-mpt/src/agent.py\", line 40, in _prompt\n    raise UnexpectedAnswerException(f\"expected 1 or 2, got {result}\")\nutil.UnexpectedAnswerException: expected 1 or 2, got  \n\nThe above exception was the direct cause of the following exception:\n\nTraceback (most recent call last):\n  File \"/work/home/fd15hava/tinypaper-mpt/scripts/experiments/run.py\", line 16, in _run_session\n    result = agent.play(session)\n             ^^^^^^^^^^^^^^^^^^^\n  File \"/home/fd15hava/.cache/pypoetry/virtualenvs/non-package-mode-zjkKA0Ca-py3.11/lib/python3.11/site-packages/tenacity/__init__.py\", line 289, in wrapped_f\n    return self(f, *args, **kw)\n           ^^^^^^^^^^^^^^^^^^^^\n  File \"/home/fd15hava/.cache/pypoetry/virtualenvs/non-package-mode-zjkKA0Ca-py3.11/lib/python3.11/site-packages/tenacity/__init__.py\", line 379, in __call__\n    do = self.iter(retry_state=retry_state)\n         ^^^^^^^^^^^^^^^^^^^^^^^^^^^^^^^^^^\n  File \"/home/fd15hava/.cache/pypoetry/virtualenvs/non-package-mode-zjkKA0Ca-py3.11/lib/python3.11/site-packages/tenacity/__init__.py\", line 326, in iter\n    raise retry_exc from fut.exception()\ntenacity.RetryError: RetryError[<Future at 0x14e62de09710 state=finished raised UnexpectedAnswerException>]\n",
      "Traceback (most recent call last):\n  File \"/home/fd15hava/.cache/pypoetry/virtualenvs/non-package-mode-zjkKA0Ca-py3.11/lib/python3.11/site-packages/tenacity/__init__.py\", line 382, in __call__\n    result = fn(*args, **kwargs)\n             ^^^^^^^^^^^^^^^^^^^\n  File \"/work/home/fd15hava/tinypaper-mpt/src/agent.py\", line 26, in play\n    answer = self._prompt(self._make_prompt(scenario))\n             ^^^^^^^^^^^^^^^^^^^^^^^^^^^^^^^^^^^^^^^^^\n  File \"/work/home/fd15hava/tinypaper-mpt/src/agent.py\", line 40, in _prompt\n    raise UnexpectedAnswerException(f\"expected 1 or 2, got {result}\")\nutil.UnexpectedAnswerException: expected 1 or 2, got  \n\nThe above exception was the direct cause of the following exception:\n\nTraceback (most recent call last):\n  File \"/work/home/fd15hava/tinypaper-mpt/scripts/experiments/run.py\", line 16, in _run_session\n    result = agent.play(session)\n             ^^^^^^^^^^^^^^^^^^^\n  File \"/home/fd15hava/.cache/pypoetry/virtualenvs/non-package-mode-zjkKA0Ca-py3.11/lib/python3.11/site-packages/tenacity/__init__.py\", line 289, in wrapped_f\n    return self(f, *args, **kw)\n           ^^^^^^^^^^^^^^^^^^^^\n  File \"/home/fd15hava/.cache/pypoetry/virtualenvs/non-package-mode-zjkKA0Ca-py3.11/lib/python3.11/site-packages/tenacity/__init__.py\", line 379, in __call__\n    do = self.iter(retry_state=retry_state)\n         ^^^^^^^^^^^^^^^^^^^^^^^^^^^^^^^^^^\n  File \"/home/fd15hava/.cache/pypoetry/virtualenvs/non-package-mode-zjkKA0Ca-py3.11/lib/python3.11/site-packages/tenacity/__init__.py\", line 326, in iter\n    raise retry_exc from fut.exception()\ntenacity.RetryError: RetryError[<Future at 0x14e62de09f50 state=finished raised UnexpectedAnswerException>]\n",
      "Traceback (most recent call last):\n  File \"/home/fd15hava/.cache/pypoetry/virtualenvs/non-package-mode-zjkKA0Ca-py3.11/lib/python3.11/site-packages/tenacity/__init__.py\", line 382, in __call__\n    result = fn(*args, **kwargs)\n             ^^^^^^^^^^^^^^^^^^^\n  File \"/work/home/fd15hava/tinypaper-mpt/src/agent.py\", line 26, in play\n    answer = self._prompt(self._make_prompt(scenario))\n             ^^^^^^^^^^^^^^^^^^^^^^^^^^^^^^^^^^^^^^^^^\n  File \"/work/home/fd15hava/tinypaper-mpt/src/agent.py\", line 40, in _prompt\n    raise UnexpectedAnswerException(f\"expected 1 or 2, got {result}\")\nutil.UnexpectedAnswerException: expected 1 or 2, got  \n\nThe above exception was the direct cause of the following exception:\n\nTraceback (most recent call last):\n  File \"/work/home/fd15hava/tinypaper-mpt/scripts/experiments/run.py\", line 16, in _run_session\n    result = agent.play(session)\n             ^^^^^^^^^^^^^^^^^^^\n  File \"/home/fd15hava/.cache/pypoetry/virtualenvs/non-package-mode-zjkKA0Ca-py3.11/lib/python3.11/site-packages/tenacity/__init__.py\", line 289, in wrapped_f\n    return self(f, *args, **kw)\n           ^^^^^^^^^^^^^^^^^^^^\n  File \"/home/fd15hava/.cache/pypoetry/virtualenvs/non-package-mode-zjkKA0Ca-py3.11/lib/python3.11/site-packages/tenacity/__init__.py\", line 379, in __call__\n    do = self.iter(retry_state=retry_state)\n         ^^^^^^^^^^^^^^^^^^^^^^^^^^^^^^^^^^\n  File \"/home/fd15hava/.cache/pypoetry/virtualenvs/non-package-mode-zjkKA0Ca-py3.11/lib/python3.11/site-packages/tenacity/__init__.py\", line 326, in iter\n    raise retry_exc from fut.exception()\ntenacity.RetryError: RetryError[<Future at 0x14e62ddcf610 state=finished raised UnexpectedAnswerException>]\n",
      "Traceback (most recent call last):\n  File \"/home/fd15hava/.cache/pypoetry/virtualenvs/non-package-mode-zjkKA0Ca-py3.11/lib/python3.11/site-packages/tenacity/__init__.py\", line 382, in __call__\n    result = fn(*args, **kwargs)\n             ^^^^^^^^^^^^^^^^^^^\n  File \"/work/home/fd15hava/tinypaper-mpt/src/agent.py\", line 26, in play\n    answer = self._prompt(self._make_prompt(scenario))\n             ^^^^^^^^^^^^^^^^^^^^^^^^^^^^^^^^^^^^^^^^^\n  File \"/work/home/fd15hava/tinypaper-mpt/src/agent.py\", line 40, in _prompt\n    raise UnexpectedAnswerException(f\"expected 1 or 2, got {result}\")\nutil.UnexpectedAnswerException: expected 1 or 2, got  \n\nThe above exception was the direct cause of the following exception:\n\nTraceback (most recent call last):\n  File \"/work/home/fd15hava/tinypaper-mpt/scripts/experiments/run.py\", line 16, in _run_session\n    result = agent.play(session)\n             ^^^^^^^^^^^^^^^^^^^\n  File \"/home/fd15hava/.cache/pypoetry/virtualenvs/non-package-mode-zjkKA0Ca-py3.11/lib/python3.11/site-packages/tenacity/__init__.py\", line 289, in wrapped_f\n    return self(f, *args, **kw)\n           ^^^^^^^^^^^^^^^^^^^^\n  File \"/home/fd15hava/.cache/pypoetry/virtualenvs/non-package-mode-zjkKA0Ca-py3.11/lib/python3.11/site-packages/tenacity/__init__.py\", line 379, in __call__\n    do = self.iter(retry_state=retry_state)\n         ^^^^^^^^^^^^^^^^^^^^^^^^^^^^^^^^^^\n  File \"/home/fd15hava/.cache/pypoetry/virtualenvs/non-package-mode-zjkKA0Ca-py3.11/lib/python3.11/site-packages/tenacity/__init__.py\", line 326, in iter\n    raise retry_exc from fut.exception()\ntenacity.RetryError: RetryError[<Future at 0x14e62de0c090 state=finished raised UnexpectedAnswerException>]\n",
      "Traceback (most recent call last):\n  File \"/home/fd15hava/.cache/pypoetry/virtualenvs/non-package-mode-zjkKA0Ca-py3.11/lib/python3.11/site-packages/tenacity/__init__.py\", line 382, in __call__\n    result = fn(*args, **kwargs)\n             ^^^^^^^^^^^^^^^^^^^\n  File \"/work/home/fd15hava/tinypaper-mpt/src/agent.py\", line 26, in play\n    answer = self._prompt(self._make_prompt(scenario))\n             ^^^^^^^^^^^^^^^^^^^^^^^^^^^^^^^^^^^^^^^^^\n  File \"/work/home/fd15hava/tinypaper-mpt/src/agent.py\", line 40, in _prompt\n    raise UnexpectedAnswerException(f\"expected 1 or 2, got {result}\")\nutil.UnexpectedAnswerException: expected 1 or 2, got  \n\nThe above exception was the direct cause of the following exception:\n\nTraceback (most recent call last):\n  File \"/work/home/fd15hava/tinypaper-mpt/scripts/experiments/run.py\", line 16, in _run_session\n    result = agent.play(session)\n             ^^^^^^^^^^^^^^^^^^^\n  File \"/home/fd15hava/.cache/pypoetry/virtualenvs/non-package-mode-zjkKA0Ca-py3.11/lib/python3.11/site-packages/tenacity/__init__.py\", line 289, in wrapped_f\n    return self(f, *args, **kw)\n           ^^^^^^^^^^^^^^^^^^^^\n  File \"/home/fd15hava/.cache/pypoetry/virtualenvs/non-package-mode-zjkKA0Ca-py3.11/lib/python3.11/site-packages/tenacity/__init__.py\", line 379, in __call__\n    do = self.iter(retry_state=retry_state)\n         ^^^^^^^^^^^^^^^^^^^^^^^^^^^^^^^^^^\n  File \"/home/fd15hava/.cache/pypoetry/virtualenvs/non-package-mode-zjkKA0Ca-py3.11/lib/python3.11/site-packages/tenacity/__init__.py\", line 326, in iter\n    raise retry_exc from fut.exception()\ntenacity.RetryError: RetryError[<Future at 0x14e6ac1b9b50 state=finished raised UnexpectedAnswerException>]\n",
      "Traceback (most recent call last):\n  File \"/home/fd15hava/.cache/pypoetry/virtualenvs/non-package-mode-zjkKA0Ca-py3.11/lib/python3.11/site-packages/tenacity/__init__.py\", line 382, in __call__\n    result = fn(*args, **kwargs)\n             ^^^^^^^^^^^^^^^^^^^\n  File \"/work/home/fd15hava/tinypaper-mpt/src/agent.py\", line 26, in play\n    answer = self._prompt(self._make_prompt(scenario))\n             ^^^^^^^^^^^^^^^^^^^^^^^^^^^^^^^^^^^^^^^^^\n  File \"/work/home/fd15hava/tinypaper-mpt/src/agent.py\", line 40, in _prompt\n    raise UnexpectedAnswerException(f\"expected 1 or 2, got {result}\")\nutil.UnexpectedAnswerException: expected 1 or 2, got  \n\nThe above exception was the direct cause of the following exception:\n\nTraceback (most recent call last):\n  File \"/work/home/fd15hava/tinypaper-mpt/scripts/experiments/run.py\", line 16, in _run_session\n    result = agent.play(session)\n             ^^^^^^^^^^^^^^^^^^^\n  File \"/home/fd15hava/.cache/pypoetry/virtualenvs/non-package-mode-zjkKA0Ca-py3.11/lib/python3.11/site-packages/tenacity/__init__.py\", line 289, in wrapped_f\n    return self(f, *args, **kw)\n           ^^^^^^^^^^^^^^^^^^^^\n  File \"/home/fd15hava/.cache/pypoetry/virtualenvs/non-package-mode-zjkKA0Ca-py3.11/lib/python3.11/site-packages/tenacity/__init__.py\", line 379, in __call__\n    do = self.iter(retry_state=retry_state)\n         ^^^^^^^^^^^^^^^^^^^^^^^^^^^^^^^^^^\n  File \"/home/fd15hava/.cache/pypoetry/virtualenvs/non-package-mode-zjkKA0Ca-py3.11/lib/python3.11/site-packages/tenacity/__init__.py\", line 326, in iter\n    raise retry_exc from fut.exception()\ntenacity.RetryError: RetryError[<Future at 0x14e6b609bad0 state=finished raised UnexpectedAnswerException>]\n",
      "Traceback (most recent call last):\n  File \"/home/fd15hava/.cache/pypoetry/virtualenvs/non-package-mode-zjkKA0Ca-py3.11/lib/python3.11/site-packages/tenacity/__init__.py\", line 382, in __call__\n    result = fn(*args, **kwargs)\n             ^^^^^^^^^^^^^^^^^^^\n  File \"/work/home/fd15hava/tinypaper-mpt/src/agent.py\", line 26, in play\n    answer = self._prompt(self._make_prompt(scenario))\n             ^^^^^^^^^^^^^^^^^^^^^^^^^^^^^^^^^^^^^^^^^\n  File \"/work/home/fd15hava/tinypaper-mpt/src/agent.py\", line 40, in _prompt\n    raise UnexpectedAnswerException(f\"expected 1 or 2, got {result}\")\nutil.UnexpectedAnswerException: expected 1 or 2, got  \n\nThe above exception was the direct cause of the following exception:\n\nTraceback (most recent call last):\n  File \"/work/home/fd15hava/tinypaper-mpt/scripts/experiments/run.py\", line 16, in _run_session\n    result = agent.play(session)\n             ^^^^^^^^^^^^^^^^^^^\n  File \"/home/fd15hava/.cache/pypoetry/virtualenvs/non-package-mode-zjkKA0Ca-py3.11/lib/python3.11/site-packages/tenacity/__init__.py\", line 289, in wrapped_f\n    return self(f, *args, **kw)\n           ^^^^^^^^^^^^^^^^^^^^\n  File \"/home/fd15hava/.cache/pypoetry/virtualenvs/non-package-mode-zjkKA0Ca-py3.11/lib/python3.11/site-packages/tenacity/__init__.py\", line 379, in __call__\n    do = self.iter(retry_state=retry_state)\n         ^^^^^^^^^^^^^^^^^^^^^^^^^^^^^^^^^^\n  File \"/home/fd15hava/.cache/pypoetry/virtualenvs/non-package-mode-zjkKA0Ca-py3.11/lib/python3.11/site-packages/tenacity/__init__.py\", line 326, in iter\n    raise retry_exc from fut.exception()\ntenacity.RetryError: RetryError[<Future at 0x14e62de0d310 state=finished raised UnexpectedAnswerException>]\n",
      "Traceback (most recent call last):\n  File \"/home/fd15hava/.cache/pypoetry/virtualenvs/non-package-mode-zjkKA0Ca-py3.11/lib/python3.11/site-packages/tenacity/__init__.py\", line 382, in __call__\n    result = fn(*args, **kwargs)\n             ^^^^^^^^^^^^^^^^^^^\n  File \"/work/home/fd15hava/tinypaper-mpt/src/agent.py\", line 26, in play\n    answer = self._prompt(self._make_prompt(scenario))\n             ^^^^^^^^^^^^^^^^^^^^^^^^^^^^^^^^^^^^^^^^^\n  File \"/work/home/fd15hava/tinypaper-mpt/src/agent.py\", line 40, in _prompt\n    raise UnexpectedAnswerException(f\"expected 1 or 2, got {result}\")\nutil.UnexpectedAnswerException: expected 1 or 2, got  \n\nThe above exception was the direct cause of the following exception:\n\nTraceback (most recent call last):\n  File \"/work/home/fd15hava/tinypaper-mpt/scripts/experiments/run.py\", line 16, in _run_session\n    result = agent.play(session)\n             ^^^^^^^^^^^^^^^^^^^\n  File \"/home/fd15hava/.cache/pypoetry/virtualenvs/non-package-mode-zjkKA0Ca-py3.11/lib/python3.11/site-packages/tenacity/__init__.py\", line 289, in wrapped_f\n    return self(f, *args, **kw)\n           ^^^^^^^^^^^^^^^^^^^^\n  File \"/home/fd15hava/.cache/pypoetry/virtualenvs/non-package-mode-zjkKA0Ca-py3.11/lib/python3.11/site-packages/tenacity/__init__.py\", line 379, in __call__\n    do = self.iter(retry_state=retry_state)\n         ^^^^^^^^^^^^^^^^^^^^^^^^^^^^^^^^^^\n  File \"/home/fd15hava/.cache/pypoetry/virtualenvs/non-package-mode-zjkKA0Ca-py3.11/lib/python3.11/site-packages/tenacity/__init__.py\", line 326, in iter\n    raise retry_exc from fut.exception()\ntenacity.RetryError: RetryError[<Future at 0x14e62de0a050 state=finished raised UnexpectedAnswerException>]\n",
      "Traceback (most recent call last):\n  File \"/home/fd15hava/.cache/pypoetry/virtualenvs/non-package-mode-zjkKA0Ca-py3.11/lib/python3.11/site-packages/tenacity/__init__.py\", line 382, in __call__\n    result = fn(*args, **kwargs)\n             ^^^^^^^^^^^^^^^^^^^\n  File \"/work/home/fd15hava/tinypaper-mpt/src/agent.py\", line 26, in play\n    answer = self._prompt(self._make_prompt(scenario))\n             ^^^^^^^^^^^^^^^^^^^^^^^^^^^^^^^^^^^^^^^^^\n  File \"/work/home/fd15hava/tinypaper-mpt/src/agent.py\", line 40, in _prompt\n    raise UnexpectedAnswerException(f\"expected 1 or 2, got {result}\")\nutil.UnexpectedAnswerException: expected 1 or 2, got  \n\nThe above exception was the direct cause of the following exception:\n\nTraceback (most recent call last):\n  File \"/work/home/fd15hava/tinypaper-mpt/scripts/experiments/run.py\", line 16, in _run_session\n    result = agent.play(session)\n             ^^^^^^^^^^^^^^^^^^^\n  File \"/home/fd15hava/.cache/pypoetry/virtualenvs/non-package-mode-zjkKA0Ca-py3.11/lib/python3.11/site-packages/tenacity/__init__.py\", line 289, in wrapped_f\n    return self(f, *args, **kw)\n           ^^^^^^^^^^^^^^^^^^^^\n  File \"/home/fd15hava/.cache/pypoetry/virtualenvs/non-package-mode-zjkKA0Ca-py3.11/lib/python3.11/site-packages/tenacity/__init__.py\", line 379, in __call__\n    do = self.iter(retry_state=retry_state)\n         ^^^^^^^^^^^^^^^^^^^^^^^^^^^^^^^^^^\n  File \"/home/fd15hava/.cache/pypoetry/virtualenvs/non-package-mode-zjkKA0Ca-py3.11/lib/python3.11/site-packages/tenacity/__init__.py\", line 326, in iter\n    raise retry_exc from fut.exception()\ntenacity.RetryError: RetryError[<Future at 0x14e62e00bf90 state=finished raised UnexpectedAnswerException>]\n",
      "Traceback (most recent call last):\n  File \"/home/fd15hava/.cache/pypoetry/virtualenvs/non-package-mode-zjkKA0Ca-py3.11/lib/python3.11/site-packages/tenacity/__init__.py\", line 382, in __call__\n    result = fn(*args, **kwargs)\n             ^^^^^^^^^^^^^^^^^^^\n  File \"/work/home/fd15hava/tinypaper-mpt/src/agent.py\", line 26, in play\n    answer = self._prompt(self._make_prompt(scenario))\n             ^^^^^^^^^^^^^^^^^^^^^^^^^^^^^^^^^^^^^^^^^\n  File \"/work/home/fd15hava/tinypaper-mpt/src/agent.py\", line 40, in _prompt\n    raise UnexpectedAnswerException(f\"expected 1 or 2, got {result}\")\nutil.UnexpectedAnswerException: expected 1 or 2, got  \n\nThe above exception was the direct cause of the following exception:\n\nTraceback (most recent call last):\n  File \"/work/home/fd15hava/tinypaper-mpt/scripts/experiments/run.py\", line 16, in _run_session\n    result = agent.play(session)\n             ^^^^^^^^^^^^^^^^^^^\n  File \"/home/fd15hava/.cache/pypoetry/virtualenvs/non-package-mode-zjkKA0Ca-py3.11/lib/python3.11/site-packages/tenacity/__init__.py\", line 289, in wrapped_f\n    return self(f, *args, **kw)\n           ^^^^^^^^^^^^^^^^^^^^\n  File \"/home/fd15hava/.cache/pypoetry/virtualenvs/non-package-mode-zjkKA0Ca-py3.11/lib/python3.11/site-packages/tenacity/__init__.py\", line 379, in __call__\n    do = self.iter(retry_state=retry_state)\n         ^^^^^^^^^^^^^^^^^^^^^^^^^^^^^^^^^^\n  File \"/home/fd15hava/.cache/pypoetry/virtualenvs/non-package-mode-zjkKA0Ca-py3.11/lib/python3.11/site-packages/tenacity/__init__.py\", line 326, in iter\n    raise retry_exc from fut.exception()\ntenacity.RetryError: RetryError[<Future at 0x14e6b5b7b3d0 state=finished raised UnexpectedAnswerException>]\n",
      "Traceback (most recent call last):\n  File \"/home/fd15hava/.cache/pypoetry/virtualenvs/non-package-mode-zjkKA0Ca-py3.11/lib/python3.11/site-packages/tenacity/__init__.py\", line 382, in __call__\n    result = fn(*args, **kwargs)\n             ^^^^^^^^^^^^^^^^^^^\n  File \"/work/home/fd15hava/tinypaper-mpt/src/agent.py\", line 26, in play\n    answer = self._prompt(self._make_prompt(scenario))\n             ^^^^^^^^^^^^^^^^^^^^^^^^^^^^^^^^^^^^^^^^^\n  File \"/work/home/fd15hava/tinypaper-mpt/src/agent.py\", line 40, in _prompt\n    raise UnexpectedAnswerException(f\"expected 1 or 2, got {result}\")\nutil.UnexpectedAnswerException: expected 1 or 2, got  \n\nThe above exception was the direct cause of the following exception:\n\nTraceback (most recent call last):\n  File \"/work/home/fd15hava/tinypaper-mpt/scripts/experiments/run.py\", line 16, in _run_session\n    result = agent.play(session)\n             ^^^^^^^^^^^^^^^^^^^\n  File \"/home/fd15hava/.cache/pypoetry/virtualenvs/non-package-mode-zjkKA0Ca-py3.11/lib/python3.11/site-packages/tenacity/__init__.py\", line 289, in wrapped_f\n    return self(f, *args, **kw)\n           ^^^^^^^^^^^^^^^^^^^^\n  File \"/home/fd15hava/.cache/pypoetry/virtualenvs/non-package-mode-zjkKA0Ca-py3.11/lib/python3.11/site-packages/tenacity/__init__.py\", line 379, in __call__\n    do = self.iter(retry_state=retry_state)\n         ^^^^^^^^^^^^^^^^^^^^^^^^^^^^^^^^^^\n  File \"/home/fd15hava/.cache/pypoetry/virtualenvs/non-package-mode-zjkKA0Ca-py3.11/lib/python3.11/site-packages/tenacity/__init__.py\", line 326, in iter\n    raise retry_exc from fut.exception()\ntenacity.RetryError: RetryError[<Future at 0x14e62de0f350 state=finished raised UnexpectedAnswerException>]\n",
      "Traceback (most recent call last):\n  File \"/home/fd15hava/.cache/pypoetry/virtualenvs/non-package-mode-zjkKA0Ca-py3.11/lib/python3.11/site-packages/tenacity/__init__.py\", line 382, in __call__\n    result = fn(*args, **kwargs)\n             ^^^^^^^^^^^^^^^^^^^\n  File \"/work/home/fd15hava/tinypaper-mpt/src/agent.py\", line 26, in play\n    answer = self._prompt(self._make_prompt(scenario))\n             ^^^^^^^^^^^^^^^^^^^^^^^^^^^^^^^^^^^^^^^^^\n  File \"/work/home/fd15hava/tinypaper-mpt/src/agent.py\", line 40, in _prompt\n    raise UnexpectedAnswerException(f\"expected 1 or 2, got {result}\")\nutil.UnexpectedAnswerException: expected 1 or 2, got  \n\nThe above exception was the direct cause of the following exception:\n\nTraceback (most recent call last):\n  File \"/work/home/fd15hava/tinypaper-mpt/scripts/experiments/run.py\", line 16, in _run_session\n    result = agent.play(session)\n             ^^^^^^^^^^^^^^^^^^^\n  File \"/home/fd15hava/.cache/pypoetry/virtualenvs/non-package-mode-zjkKA0Ca-py3.11/lib/python3.11/site-packages/tenacity/__init__.py\", line 289, in wrapped_f\n    return self(f, *args, **kw)\n           ^^^^^^^^^^^^^^^^^^^^\n  File \"/home/fd15hava/.cache/pypoetry/virtualenvs/non-package-mode-zjkKA0Ca-py3.11/lib/python3.11/site-packages/tenacity/__init__.py\", line 379, in __call__\n    do = self.iter(retry_state=retry_state)\n         ^^^^^^^^^^^^^^^^^^^^^^^^^^^^^^^^^^\n  File \"/home/fd15hava/.cache/pypoetry/virtualenvs/non-package-mode-zjkKA0Ca-py3.11/lib/python3.11/site-packages/tenacity/__init__.py\", line 326, in iter\n    raise retry_exc from fut.exception()\ntenacity.RetryError: RetryError[<Future at 0x14e62ddc9590 state=finished raised UnexpectedAnswerException>]\n",
      "Traceback (most recent call last):\n  File \"/home/fd15hava/.cache/pypoetry/virtualenvs/non-package-mode-zjkKA0Ca-py3.11/lib/python3.11/site-packages/tenacity/__init__.py\", line 382, in __call__\n    result = fn(*args, **kwargs)\n             ^^^^^^^^^^^^^^^^^^^\n  File \"/work/home/fd15hava/tinypaper-mpt/src/agent.py\", line 26, in play\n    answer = self._prompt(self._make_prompt(scenario))\n             ^^^^^^^^^^^^^^^^^^^^^^^^^^^^^^^^^^^^^^^^^\n  File \"/work/home/fd15hava/tinypaper-mpt/src/agent.py\", line 40, in _prompt\n    raise UnexpectedAnswerException(f\"expected 1 or 2, got {result}\")\nutil.UnexpectedAnswerException: expected 1 or 2, got  \n\nThe above exception was the direct cause of the following exception:\n\nTraceback (most recent call last):\n  File \"/work/home/fd15hava/tinypaper-mpt/scripts/experiments/run.py\", line 16, in _run_session\n    result = agent.play(session)\n             ^^^^^^^^^^^^^^^^^^^\n  File \"/home/fd15hava/.cache/pypoetry/virtualenvs/non-package-mode-zjkKA0Ca-py3.11/lib/python3.11/site-packages/tenacity/__init__.py\", line 289, in wrapped_f\n    return self(f, *args, **kw)\n           ^^^^^^^^^^^^^^^^^^^^\n  File \"/home/fd15hava/.cache/pypoetry/virtualenvs/non-package-mode-zjkKA0Ca-py3.11/lib/python3.11/site-packages/tenacity/__init__.py\", line 379, in __call__\n    do = self.iter(retry_state=retry_state)\n         ^^^^^^^^^^^^^^^^^^^^^^^^^^^^^^^^^^\n  File \"/home/fd15hava/.cache/pypoetry/virtualenvs/non-package-mode-zjkKA0Ca-py3.11/lib/python3.11/site-packages/tenacity/__init__.py\", line 326, in iter\n    raise retry_exc from fut.exception()\ntenacity.RetryError: RetryError[<Future at 0x14e62de0b610 state=finished raised UnexpectedAnswerException>]\n",
      "Traceback (most recent call last):\n  File \"/home/fd15hava/.cache/pypoetry/virtualenvs/non-package-mode-zjkKA0Ca-py3.11/lib/python3.11/site-packages/tenacity/__init__.py\", line 382, in __call__\n    result = fn(*args, **kwargs)\n             ^^^^^^^^^^^^^^^^^^^\n  File \"/work/home/fd15hava/tinypaper-mpt/src/agent.py\", line 26, in play\n    answer = self._prompt(self._make_prompt(scenario))\n             ^^^^^^^^^^^^^^^^^^^^^^^^^^^^^^^^^^^^^^^^^\n  File \"/work/home/fd15hava/tinypaper-mpt/src/agent.py\", line 40, in _prompt\n    raise UnexpectedAnswerException(f\"expected 1 or 2, got {result}\")\nutil.UnexpectedAnswerException: expected 1 or 2, got  \n\nThe above exception was the direct cause of the following exception:\n\nTraceback (most recent call last):\n  File \"/work/home/fd15hava/tinypaper-mpt/scripts/experiments/run.py\", line 16, in _run_session\n    result = agent.play(session)\n             ^^^^^^^^^^^^^^^^^^^\n  File \"/home/fd15hava/.cache/pypoetry/virtualenvs/non-package-mode-zjkKA0Ca-py3.11/lib/python3.11/site-packages/tenacity/__init__.py\", line 289, in wrapped_f\n    return self(f, *args, **kw)\n           ^^^^^^^^^^^^^^^^^^^^\n  File \"/home/fd15hava/.cache/pypoetry/virtualenvs/non-package-mode-zjkKA0Ca-py3.11/lib/python3.11/site-packages/tenacity/__init__.py\", line 379, in __call__\n    do = self.iter(retry_state=retry_state)\n         ^^^^^^^^^^^^^^^^^^^^^^^^^^^^^^^^^^\n  File \"/home/fd15hava/.cache/pypoetry/virtualenvs/non-package-mode-zjkKA0Ca-py3.11/lib/python3.11/site-packages/tenacity/__init__.py\", line 326, in iter\n    raise retry_exc from fut.exception()\ntenacity.RetryError: RetryError[<Future at 0x14e62ddcba10 state=finished raised UnexpectedAnswerException>]\n",
      "Traceback (most recent call last):\n  File \"/home/fd15hava/.cache/pypoetry/virtualenvs/non-package-mode-zjkKA0Ca-py3.11/lib/python3.11/site-packages/tenacity/__init__.py\", line 382, in __call__\n    result = fn(*args, **kwargs)\n             ^^^^^^^^^^^^^^^^^^^\n  File \"/work/home/fd15hava/tinypaper-mpt/src/agent.py\", line 26, in play\n    answer = self._prompt(self._make_prompt(scenario))\n             ^^^^^^^^^^^^^^^^^^^^^^^^^^^^^^^^^^^^^^^^^\n  File \"/work/home/fd15hava/tinypaper-mpt/src/agent.py\", line 40, in _prompt\n    raise UnexpectedAnswerException(f\"expected 1 or 2, got {result}\")\nutil.UnexpectedAnswerException: expected 1 or 2, got  \n\nThe above exception was the direct cause of the following exception:\n\nTraceback (most recent call last):\n  File \"/work/home/fd15hava/tinypaper-mpt/scripts/experiments/run.py\", line 16, in _run_session\n    result = agent.play(session)\n             ^^^^^^^^^^^^^^^^^^^\n  File \"/home/fd15hava/.cache/pypoetry/virtualenvs/non-package-mode-zjkKA0Ca-py3.11/lib/python3.11/site-packages/tenacity/__init__.py\", line 289, in wrapped_f\n    return self(f, *args, **kw)\n           ^^^^^^^^^^^^^^^^^^^^\n  File \"/home/fd15hava/.cache/pypoetry/virtualenvs/non-package-mode-zjkKA0Ca-py3.11/lib/python3.11/site-packages/tenacity/__init__.py\", line 379, in __call__\n    do = self.iter(retry_state=retry_state)\n         ^^^^^^^^^^^^^^^^^^^^^^^^^^^^^^^^^^\n  File \"/home/fd15hava/.cache/pypoetry/virtualenvs/non-package-mode-zjkKA0Ca-py3.11/lib/python3.11/site-packages/tenacity/__init__.py\", line 326, in iter\n    raise retry_exc from fut.exception()\ntenacity.RetryError: RetryError[<Future at 0x14e62de080d0 state=finished raised UnexpectedAnswerException>]\n",
      "Traceback (most recent call last):\n  File \"/home/fd15hava/.cache/pypoetry/virtualenvs/non-package-mode-zjkKA0Ca-py3.11/lib/python3.11/site-packages/tenacity/__init__.py\", line 382, in __call__\n    result = fn(*args, **kwargs)\n             ^^^^^^^^^^^^^^^^^^^\n  File \"/work/home/fd15hava/tinypaper-mpt/src/agent.py\", line 26, in play\n    answer = self._prompt(self._make_prompt(scenario))\n             ^^^^^^^^^^^^^^^^^^^^^^^^^^^^^^^^^^^^^^^^^\n  File \"/work/home/fd15hava/tinypaper-mpt/src/agent.py\", line 40, in _prompt\n    raise UnexpectedAnswerException(f\"expected 1 or 2, got {result}\")\nutil.UnexpectedAnswerException: expected 1 or 2, got  \n\nThe above exception was the direct cause of the following exception:\n\nTraceback (most recent call last):\n  File \"/work/home/fd15hava/tinypaper-mpt/scripts/experiments/run.py\", line 16, in _run_session\n    result = agent.play(session)\n             ^^^^^^^^^^^^^^^^^^^\n  File \"/home/fd15hava/.cache/pypoetry/virtualenvs/non-package-mode-zjkKA0Ca-py3.11/lib/python3.11/site-packages/tenacity/__init__.py\", line 289, in wrapped_f\n    return self(f, *args, **kw)\n           ^^^^^^^^^^^^^^^^^^^^\n  File \"/home/fd15hava/.cache/pypoetry/virtualenvs/non-package-mode-zjkKA0Ca-py3.11/lib/python3.11/site-packages/tenacity/__init__.py\", line 379, in __call__\n    do = self.iter(retry_state=retry_state)\n         ^^^^^^^^^^^^^^^^^^^^^^^^^^^^^^^^^^\n  File \"/home/fd15hava/.cache/pypoetry/virtualenvs/non-package-mode-zjkKA0Ca-py3.11/lib/python3.11/site-packages/tenacity/__init__.py\", line 326, in iter\n    raise retry_exc from fut.exception()\ntenacity.RetryError: RetryError[<Future at 0x14e62ddcb250 state=finished raised UnexpectedAnswerException>]\n",
      "Traceback (most recent call last):\n  File \"/home/fd15hava/.cache/pypoetry/virtualenvs/non-package-mode-zjkKA0Ca-py3.11/lib/python3.11/site-packages/tenacity/__init__.py\", line 382, in __call__\n    result = fn(*args, **kwargs)\n             ^^^^^^^^^^^^^^^^^^^\n  File \"/work/home/fd15hava/tinypaper-mpt/src/agent.py\", line 26, in play\n    answer = self._prompt(self._make_prompt(scenario))\n             ^^^^^^^^^^^^^^^^^^^^^^^^^^^^^^^^^^^^^^^^^\n  File \"/work/home/fd15hava/tinypaper-mpt/src/agent.py\", line 40, in _prompt\n    raise UnexpectedAnswerException(f\"expected 1 or 2, got {result}\")\nutil.UnexpectedAnswerException: expected 1 or 2, got  \n\nThe above exception was the direct cause of the following exception:\n\nTraceback (most recent call last):\n  File \"/work/home/fd15hava/tinypaper-mpt/scripts/experiments/run.py\", line 16, in _run_session\n    result = agent.play(session)\n             ^^^^^^^^^^^^^^^^^^^\n  File \"/home/fd15hava/.cache/pypoetry/virtualenvs/non-package-mode-zjkKA0Ca-py3.11/lib/python3.11/site-packages/tenacity/__init__.py\", line 289, in wrapped_f\n    return self(f, *args, **kw)\n           ^^^^^^^^^^^^^^^^^^^^\n  File \"/home/fd15hava/.cache/pypoetry/virtualenvs/non-package-mode-zjkKA0Ca-py3.11/lib/python3.11/site-packages/tenacity/__init__.py\", line 379, in __call__\n    do = self.iter(retry_state=retry_state)\n         ^^^^^^^^^^^^^^^^^^^^^^^^^^^^^^^^^^\n  File \"/home/fd15hava/.cache/pypoetry/virtualenvs/non-package-mode-zjkKA0Ca-py3.11/lib/python3.11/site-packages/tenacity/__init__.py\", line 326, in iter\n    raise retry_exc from fut.exception()\ntenacity.RetryError: RetryError[<Future at 0x14e6ac14a950 state=finished raised UnexpectedAnswerException>]\n"
    ],
    "api_usage": [
      {
        "cost": 0.0,
        "name": "falcon-180B-chat",
        "num_input_tokens": -1,
        "num_output_tokens": -1,
        "py/object": "api_usage.APIUsage"
      },
      {
        "cost": 0.0,
        "name": "falcon-180B-chat",
        "num_input_tokens": -1,
        "num_output_tokens": -1,
        "py/object": "api_usage.APIUsage"
      },
      {
        "cost": 0.0,
        "name": "falcon-180B-chat",
        "num_input_tokens": -1,
        "num_output_tokens": -1,
        "py/object": "api_usage.APIUsage"
      },
      {
        "cost": 0.0,
        "name": "falcon-180B-chat",
        "num_input_tokens": -1,
        "num_output_tokens": -1,
        "py/object": "api_usage.APIUsage"
      },
      {
        "cost": 0.0,
        "name": "falcon-180B-chat",
        "num_input_tokens": -1,
        "num_output_tokens": -1,
        "py/object": "api_usage.APIUsage"
      },
      {
        "cost": 0.0,
        "name": "falcon-180B-chat",
        "num_input_tokens": -1,
        "num_output_tokens": -1,
        "py/object": "api_usage.APIUsage"
      },
      {
        "cost": 0.0,
        "name": "falcon-180B-chat",
        "num_input_tokens": -1,
        "num_output_tokens": -1,
        "py/object": "api_usage.APIUsage"
      },
      {
        "cost": 0.0,
        "name": "falcon-180B-chat",
        "num_input_tokens": -1,
        "num_output_tokens": -1,
        "py/object": "api_usage.APIUsage"
      },
      {
        "cost": 0.0,
        "name": "falcon-180B-chat",
        "num_input_tokens": -1,
        "num_output_tokens": -1,
        "py/object": "api_usage.APIUsage"
      },
      {
        "cost": 0.0,
        "name": "falcon-180B-chat",
        "num_input_tokens": -1,
        "num_output_tokens": -1,
        "py/object": "api_usage.APIUsage"
      },
      {
        "cost": 0.0,
        "name": "falcon-180B-chat",
        "num_input_tokens": -1,
        "num_output_tokens": -1,
        "py/object": "api_usage.APIUsage"
      },
      {
        "cost": 0.0,
        "name": "falcon-180B-chat",
        "num_input_tokens": -1,
        "num_output_tokens": -1,
        "py/object": "api_usage.APIUsage"
      },
      {
        "cost": 0.0,
        "name": "falcon-180B-chat",
        "num_input_tokens": -1,
        "num_output_tokens": -1,
        "py/object": "api_usage.APIUsage"
      },
      {
        "cost": 0.0,
        "name": "falcon-180B-chat",
        "num_input_tokens": -1,
        "num_output_tokens": -1,
        "py/object": "api_usage.APIUsage"
      },
      {
        "cost": 0.0,
        "name": "falcon-180B-chat",
        "num_input_tokens": -1,
        "num_output_tokens": -1,
        "py/object": "api_usage.APIUsage"
      },
      {
        "cost": 0.0,
        "name": "falcon-180B-chat",
        "num_input_tokens": -1,
        "num_output_tokens": -1,
        "py/object": "api_usage.APIUsage"
      },
      {
        "cost": 0.0,
        "name": "falcon-180B-chat",
        "num_input_tokens": -1,
        "num_output_tokens": -1,
        "py/object": "api_usage.APIUsage"
      },
      {
        "cost": 0.0,
        "name": "falcon-180B-chat",
        "num_input_tokens": -1,
        "num_output_tokens": -1,
        "py/object": "api_usage.APIUsage"
      },
      {
        "cost": 0.0,
        "name": "falcon-180B-chat",
        "num_input_tokens": -1,
        "num_output_tokens": -1,
        "py/object": "api_usage.APIUsage"
      },
      {
        "cost": 0.0,
        "name": "falcon-180B-chat",
        "num_input_tokens": -1,
        "num_output_tokens": -1,
        "py/object": "api_usage.APIUsage"
      },
      {
        "cost": 0.0,
        "name": "falcon-180B-chat",
        "num_input_tokens": -1,
        "num_output_tokens": -1,
        "py/object": "api_usage.APIUsage"
      },
      {
        "cost": 0.0,
        "name": "falcon-180B-chat",
        "num_input_tokens": -1,
        "num_output_tokens": -1,
        "py/object": "api_usage.APIUsage"
      },
      {
        "cost": 0.0,
        "name": "falcon-180B-chat",
        "num_input_tokens": -1,
        "num_output_tokens": -1,
        "py/object": "api_usage.APIUsage"
      },
      {
        "cost": 0.0,
        "name": "falcon-180B-chat",
        "num_input_tokens": -1,
        "num_output_tokens": -1,
        "py/object": "api_usage.APIUsage"
      },
      {
        "cost": 0.0,
        "name": "falcon-180B-chat",
        "num_input_tokens": -1,
        "num_output_tokens": -1,
        "py/object": "api_usage.APIUsage"
      },
      {
        "cost": 0.0,
        "name": "falcon-180B-chat",
        "num_input_tokens": -1,
        "num_output_tokens": -1,
        "py/object": "api_usage.APIUsage"
      },
      {
        "cost": 0.0,
        "name": "falcon-180B-chat",
        "num_input_tokens": -1,
        "num_output_tokens": -1,
        "py/object": "api_usage.APIUsage"
      },
      {
        "cost": 0.0,
        "name": "falcon-180B-chat",
        "num_input_tokens": -1,
        "num_output_tokens": -1,
        "py/object": "api_usage.APIUsage"
      },
      {
        "cost": 0.0,
        "name": "falcon-180B-chat",
        "num_input_tokens": -1,
        "num_output_tokens": -1,
        "py/object": "api_usage.APIUsage"
      },
      {
        "cost": 0.0,
        "name": "falcon-180B-chat",
        "num_input_tokens": -1,
        "num_output_tokens": -1,
        "py/object": "api_usage.APIUsage"
      },
      {
        "cost": 0.0,
        "name": "falcon-180B-chat",
        "num_input_tokens": -1,
        "num_output_tokens": -1,
        "py/object": "api_usage.APIUsage"
      },
      {
        "cost": 0.0,
        "name": "falcon-180B-chat",
        "num_input_tokens": -1,
        "num_output_tokens": -1,
        "py/object": "api_usage.APIUsage"
      },
      {
        "cost": 0.0,
        "name": "falcon-180B-chat",
        "num_input_tokens": -1,
        "num_output_tokens": -1,
        "py/object": "api_usage.APIUsage"
      },
      {
        "cost": 0.0,
        "name": "falcon-180B-chat",
        "num_input_tokens": -1,
        "num_output_tokens": -1,
        "py/object": "api_usage.APIUsage"
      },
      {
        "cost": 0.0,
        "name": "falcon-180B-chat",
        "num_input_tokens": -1,
        "num_output_tokens": -1,
        "py/object": "api_usage.APIUsage"
      },
      {
        "cost": 0.0,
        "name": "falcon-180B-chat",
        "num_input_tokens": -1,
        "num_output_tokens": -1,
        "py/object": "api_usage.APIUsage"
      },
      {
        "cost": 0.0,
        "name": "falcon-180B-chat",
        "num_input_tokens": -1,
        "num_output_tokens": -1,
        "py/object": "api_usage.APIUsage"
      },
      {
        "cost": 0.0,
        "name": "falcon-180B-chat",
        "num_input_tokens": -1,
        "num_output_tokens": -1,
        "py/object": "api_usage.APIUsage"
      },
      {
        "cost": 0.0,
        "name": "falcon-180B-chat",
        "num_input_tokens": -1,
        "num_output_tokens": -1,
        "py/object": "api_usage.APIUsage"
      },
      {
        "cost": 0.0,
        "name": "falcon-180B-chat",
        "num_input_tokens": -1,
        "num_output_tokens": -1,
        "py/object": "api_usage.APIUsage"
      },
      {
        "cost": 0.0,
        "name": "falcon-180B-chat",
        "num_input_tokens": -1,
        "num_output_tokens": -1,
        "py/object": "api_usage.APIUsage"
      },
      {
        "cost": 0.0,
        "name": "falcon-180B-chat",
        "num_input_tokens": -1,
        "num_output_tokens": -1,
        "py/object": "api_usage.APIUsage"
      },
      {
        "cost": 0.0,
        "name": "falcon-180B-chat",
        "num_input_tokens": -1,
        "num_output_tokens": -1,
        "py/object": "api_usage.APIUsage"
      },
      {
        "cost": 0.0,
        "name": "falcon-180B-chat",
        "num_input_tokens": -1,
        "num_output_tokens": -1,
        "py/object": "api_usage.APIUsage"
      },
      {
        "cost": 0.0,
        "name": "falcon-180B-chat",
        "num_input_tokens": -1,
        "num_output_tokens": -1,
        "py/object": "api_usage.APIUsage"
      },
      {
        "cost": 0.0,
        "name": "falcon-180B-chat",
        "num_input_tokens": -1,
        "num_output_tokens": -1,
        "py/object": "api_usage.APIUsage"
      },
      {
        "cost": 0.0,
        "name": "falcon-180B-chat",
        "num_input_tokens": -1,
        "num_output_tokens": -1,
        "py/object": "api_usage.APIUsage"
      },
      {
        "cost": 0.0,
        "name": "falcon-180B-chat",
        "num_input_tokens": -1,
        "num_output_tokens": -1,
        "py/object": "api_usage.APIUsage"
      },
      {
        "cost": 0.0,
        "name": "falcon-180B-chat",
        "num_input_tokens": -1,
        "num_output_tokens": -1,
        "py/object": "api_usage.APIUsage"
      },
      {
        "cost": 0.0,
        "name": "falcon-180B-chat",
        "num_input_tokens": -1,
        "num_output_tokens": -1,
        "py/object": "api_usage.APIUsage"
      }
    ],
    "api_usage_total": {
      "cost": 0.0,
      "name": "falcon-180B-chat",
      "num_input_tokens": -50,
      "num_output_tokens": -50,
      "py/object": "api_usage.APIUsage"
    }
  },
  "start_time": "2024-04-30T02:16:16.380991",
  "status": "COMPLETED",
  "stop_time": "2024-04-30T04:22:31.377948"
}