{
  "artifacts": [],
  "command": "main",
  "experiment": {
    "base_dir": "/work/home/fd15hava/tinypaper-mpt/src",
    "dependencies": [
      "numpy==1.26.4",
      "sacred==0.8.5"
    ],
    "mainfile": "experiment.py",
    "name": "tinypaper",
    "repositories": [
      {
        "commit": "83ebc21b46932da830ceff1fef51511962253d6b",
        "dirty": false,
        "url": "ssh://github/fdamken/tinypaper_code.git"
      },
      {
        "commit": "83ebc21b46932da830ceff1fef51511962253d6b",
        "dirty": false,
        "url": "ssh://github/fdamken/tinypaper_code.git"
      }
    ],
    "sources": [
      [
        "experiment.py",
        "_sources/experiment_7ab7c4f9e536be33bd5f71ad8c083f8f.py"
      ],
      [
        "path_util.py",
        "_sources/path_util_ce5f4012c098f79adf2c1204811dca0a.py"
      ]
    ]
  },
  "heartbeat": "2024-04-29T22:46:42.548417",
  "host": {
    "ENV": {},
    "cpu": "Intel(R) Xeon(R) Platinum 8470Q",
    "hostname": "mpsd0130",
    "os": [
      "Linux",
      "Linux-4.18.0-477.27.1.el8_8.x86_64-x86_64-with-glibc2.28"
    ],
    "python_version": "3.11.9"
  },
  "meta": {
    "command": "main",
    "config_updates": {
      "from_session_id": 200,
      "language": "ru",
      "model_name": "mpt-7b-chat",
      "to_session_id": 250
    },
    "named_configs": [],
    "options": {
      "--beat-interval": null,
      "--capture": null,
      "--comment": null,
      "--debug": false,
      "--enforce_clean": false,
      "--file_storage": null,
      "--force": false,
      "--help": false,
      "--id": null,
      "--loglevel": null,
      "--mongo_db": null,
      "--name": null,
      "--pdb": false,
      "--print-config": false,
      "--priority": null,
      "--queue": false,
      "--s3": null,
      "--sql": null,
      "--tiny_db": null,
      "--unobserved": false,
      "COMMAND": null,
      "UPDATE": [
        "from_session_id=200",
        "to_session_id=250",
        "model_name=mpt-7b-chat",
        "language=ru"
      ],
      "help": false,
      "with": true
    }
  },
  "resources": [],
  "result": {
    "answers": [
      "Traceback (most recent call last):\n  File \"/home/fd15hava/.cache/pypoetry/virtualenvs/non-package-mode-zjkKA0Ca-py3.11/lib/python3.11/site-packages/tenacity/__init__.py\", line 382, in __call__\n    result = fn(*args, **kwargs)\n             ^^^^^^^^^^^^^^^^^^^\n  File \"/work/home/fd15hava/tinypaper-mpt/src/agent.py\", line 26, in play\n    answer = self._prompt(self._make_prompt(scenario))\n             ^^^^^^^^^^^^^^^^^^^^^^^^^^^^^^^^^^^^^^^^^\n  File \"/work/home/fd15hava/tinypaper-mpt/src/agent.py\", line 40, in _prompt\n    raise UnexpectedAnswerException(f\"expected 1 or 2, got {result}\")\nutil.UnexpectedAnswerException: expected 1 or 2, got \n\n\nThe above exception was the direct cause of the following exception:\n\nTraceback (most recent call last):\n  File \"/work/home/fd15hava/tinypaper-mpt/scripts/experiments/run.py\", line 16, in _run_session\n    result = agent.play(session)\n             ^^^^^^^^^^^^^^^^^^^\n  File \"/home/fd15hava/.cache/pypoetry/virtualenvs/non-package-mode-zjkKA0Ca-py3.11/lib/python3.11/site-packages/tenacity/__init__.py\", line 289, in wrapped_f\n    return self(f, *args, **kw)\n           ^^^^^^^^^^^^^^^^^^^^\n  File \"/home/fd15hava/.cache/pypoetry/virtualenvs/non-package-mode-zjkKA0Ca-py3.11/lib/python3.11/site-packages/tenacity/__init__.py\", line 379, in __call__\n    do = self.iter(retry_state=retry_state)\n         ^^^^^^^^^^^^^^^^^^^^^^^^^^^^^^^^^^\n  File \"/home/fd15hava/.cache/pypoetry/virtualenvs/non-package-mode-zjkKA0Ca-py3.11/lib/python3.11/site-packages/tenacity/__init__.py\", line 326, in iter\n    raise retry_exc from fut.exception()\ntenacity.RetryError: RetryError[<Future at 0x14b525cdd590 state=finished raised UnexpectedAnswerException>]\n",
      "Traceback (most recent call last):\n  File \"/home/fd15hava/.cache/pypoetry/virtualenvs/non-package-mode-zjkKA0Ca-py3.11/lib/python3.11/site-packages/tenacity/__init__.py\", line 382, in __call__\n    result = fn(*args, **kwargs)\n             ^^^^^^^^^^^^^^^^^^^\n  File \"/work/home/fd15hava/tinypaper-mpt/src/agent.py\", line 26, in play\n    answer = self._prompt(self._make_prompt(scenario))\n             ^^^^^^^^^^^^^^^^^^^^^^^^^^^^^^^^^^^^^^^^^\n  File \"/work/home/fd15hava/tinypaper-mpt/src/agent.py\", line 40, in _prompt\n    raise UnexpectedAnswerException(f\"expected 1 or 2, got {result}\")\nutil.UnexpectedAnswerException: expected 1 or 2, got \n\n\nThe above exception was the direct cause of the following exception:\n\nTraceback (most recent call last):\n  File \"/work/home/fd15hava/tinypaper-mpt/scripts/experiments/run.py\", line 16, in _run_session\n    result = agent.play(session)\n             ^^^^^^^^^^^^^^^^^^^\n  File \"/home/fd15hava/.cache/pypoetry/virtualenvs/non-package-mode-zjkKA0Ca-py3.11/lib/python3.11/site-packages/tenacity/__init__.py\", line 289, in wrapped_f\n    return self(f, *args, **kw)\n           ^^^^^^^^^^^^^^^^^^^^\n  File \"/home/fd15hava/.cache/pypoetry/virtualenvs/non-package-mode-zjkKA0Ca-py3.11/lib/python3.11/site-packages/tenacity/__init__.py\", line 379, in __call__\n    do = self.iter(retry_state=retry_state)\n         ^^^^^^^^^^^^^^^^^^^^^^^^^^^^^^^^^^\n  File \"/home/fd15hava/.cache/pypoetry/virtualenvs/non-package-mode-zjkKA0Ca-py3.11/lib/python3.11/site-packages/tenacity/__init__.py\", line 326, in iter\n    raise retry_exc from fut.exception()\ntenacity.RetryError: RetryError[<Future at 0x14b525ce9d90 state=finished raised UnexpectedAnswerException>]\n",
      "Traceback (most recent call last):\n  File \"/home/fd15hava/.cache/pypoetry/virtualenvs/non-package-mode-zjkKA0Ca-py3.11/lib/python3.11/site-packages/tenacity/__init__.py\", line 382, in __call__\n    result = fn(*args, **kwargs)\n             ^^^^^^^^^^^^^^^^^^^\n  File \"/work/home/fd15hava/tinypaper-mpt/src/agent.py\", line 26, in play\n    answer = self._prompt(self._make_prompt(scenario))\n             ^^^^^^^^^^^^^^^^^^^^^^^^^^^^^^^^^^^^^^^^^\n  File \"/work/home/fd15hava/tinypaper-mpt/src/agent.py\", line 40, in _prompt\n    raise UnexpectedAnswerException(f\"expected 1 or 2, got {result}\")\nutil.UnexpectedAnswerException: expected 1 or 2, got \n\n\nThe above exception was the direct cause of the following exception:\n\nTraceback (most recent call last):\n  File \"/work/home/fd15hava/tinypaper-mpt/scripts/experiments/run.py\", line 16, in _run_session\n    result = agent.play(session)\n             ^^^^^^^^^^^^^^^^^^^\n  File \"/home/fd15hava/.cache/pypoetry/virtualenvs/non-package-mode-zjkKA0Ca-py3.11/lib/python3.11/site-packages/tenacity/__init__.py\", line 289, in wrapped_f\n    return self(f, *args, **kw)\n           ^^^^^^^^^^^^^^^^^^^^\n  File \"/home/fd15hava/.cache/pypoetry/virtualenvs/non-package-mode-zjkKA0Ca-py3.11/lib/python3.11/site-packages/tenacity/__init__.py\", line 379, in __call__\n    do = self.iter(retry_state=retry_state)\n         ^^^^^^^^^^^^^^^^^^^^^^^^^^^^^^^^^^\n  File \"/home/fd15hava/.cache/pypoetry/virtualenvs/non-package-mode-zjkKA0Ca-py3.11/lib/python3.11/site-packages/tenacity/__init__.py\", line 326, in iter\n    raise retry_exc from fut.exception()\ntenacity.RetryError: RetryError[<Future at 0x14b1f777b590 state=finished raised UnexpectedAnswerException>]\n",
      "Traceback (most recent call last):\n  File \"/home/fd15hava/.cache/pypoetry/virtualenvs/non-package-mode-zjkKA0Ca-py3.11/lib/python3.11/site-packages/tenacity/__init__.py\", line 382, in __call__\n    result = fn(*args, **kwargs)\n             ^^^^^^^^^^^^^^^^^^^\n  File \"/work/home/fd15hava/tinypaper-mpt/src/agent.py\", line 26, in play\n    answer = self._prompt(self._make_prompt(scenario))\n             ^^^^^^^^^^^^^^^^^^^^^^^^^^^^^^^^^^^^^^^^^\n  File \"/work/home/fd15hava/tinypaper-mpt/src/agent.py\", line 40, in _prompt\n    raise UnexpectedAnswerException(f\"expected 1 or 2, got {result}\")\nutil.UnexpectedAnswerException: expected 1 or 2, got \n\n\nThe above exception was the direct cause of the following exception:\n\nTraceback (most recent call last):\n  File \"/work/home/fd15hava/tinypaper-mpt/scripts/experiments/run.py\", line 16, in _run_session\n    result = agent.play(session)\n             ^^^^^^^^^^^^^^^^^^^\n  File \"/home/fd15hava/.cache/pypoetry/virtualenvs/non-package-mode-zjkKA0Ca-py3.11/lib/python3.11/site-packages/tenacity/__init__.py\", line 289, in wrapped_f\n    return self(f, *args, **kw)\n           ^^^^^^^^^^^^^^^^^^^^\n  File \"/home/fd15hava/.cache/pypoetry/virtualenvs/non-package-mode-zjkKA0Ca-py3.11/lib/python3.11/site-packages/tenacity/__init__.py\", line 379, in __call__\n    do = self.iter(retry_state=retry_state)\n         ^^^^^^^^^^^^^^^^^^^^^^^^^^^^^^^^^^\n  File \"/home/fd15hava/.cache/pypoetry/virtualenvs/non-package-mode-zjkKA0Ca-py3.11/lib/python3.11/site-packages/tenacity/__init__.py\", line 326, in iter\n    raise retry_exc from fut.exception()\ntenacity.RetryError: RetryError[<Future at 0x14b1f777ba10 state=finished raised UnexpectedAnswerException>]\n",
      "Traceback (most recent call last):\n  File \"/home/fd15hava/.cache/pypoetry/virtualenvs/non-package-mode-zjkKA0Ca-py3.11/lib/python3.11/site-packages/tenacity/__init__.py\", line 382, in __call__\n    result = fn(*args, **kwargs)\n             ^^^^^^^^^^^^^^^^^^^\n  File \"/work/home/fd15hava/tinypaper-mpt/src/agent.py\", line 26, in play\n    answer = self._prompt(self._make_prompt(scenario))\n             ^^^^^^^^^^^^^^^^^^^^^^^^^^^^^^^^^^^^^^^^^\n  File \"/work/home/fd15hava/tinypaper-mpt/src/agent.py\", line 40, in _prompt\n    raise UnexpectedAnswerException(f\"expected 1 or 2, got {result}\")\nutil.UnexpectedAnswerException: expected 1 or 2, got \n\n\nThe above exception was the direct cause of the following exception:\n\nTraceback (most recent call last):\n  File \"/work/home/fd15hava/tinypaper-mpt/scripts/experiments/run.py\", line 16, in _run_session\n    result = agent.play(session)\n             ^^^^^^^^^^^^^^^^^^^\n  File \"/home/fd15hava/.cache/pypoetry/virtualenvs/non-package-mode-zjkKA0Ca-py3.11/lib/python3.11/site-packages/tenacity/__init__.py\", line 289, in wrapped_f\n    return self(f, *args, **kw)\n           ^^^^^^^^^^^^^^^^^^^^\n  File \"/home/fd15hava/.cache/pypoetry/virtualenvs/non-package-mode-zjkKA0Ca-py3.11/lib/python3.11/site-packages/tenacity/__init__.py\", line 379, in __call__\n    do = self.iter(retry_state=retry_state)\n         ^^^^^^^^^^^^^^^^^^^^^^^^^^^^^^^^^^\n  File \"/home/fd15hava/.cache/pypoetry/virtualenvs/non-package-mode-zjkKA0Ca-py3.11/lib/python3.11/site-packages/tenacity/__init__.py\", line 326, in iter\n    raise retry_exc from fut.exception()\ntenacity.RetryError: RetryError[<Future at 0x14b1f77b4410 state=finished raised UnexpectedAnswerException>]\n",
      "Traceback (most recent call last):\n  File \"/home/fd15hava/.cache/pypoetry/virtualenvs/non-package-mode-zjkKA0Ca-py3.11/lib/python3.11/site-packages/tenacity/__init__.py\", line 382, in __call__\n    result = fn(*args, **kwargs)\n             ^^^^^^^^^^^^^^^^^^^\n  File \"/work/home/fd15hava/tinypaper-mpt/src/agent.py\", line 26, in play\n    answer = self._prompt(self._make_prompt(scenario))\n             ^^^^^^^^^^^^^^^^^^^^^^^^^^^^^^^^^^^^^^^^^\n  File \"/work/home/fd15hava/tinypaper-mpt/src/agent.py\", line 40, in _prompt\n    raise UnexpectedAnswerException(f\"expected 1 or 2, got {result}\")\nutil.UnexpectedAnswerException: expected 1 or 2, got \n\n\nThe above exception was the direct cause of the following exception:\n\nTraceback (most recent call last):\n  File \"/work/home/fd15hava/tinypaper-mpt/scripts/experiments/run.py\", line 16, in _run_session\n    result = agent.play(session)\n             ^^^^^^^^^^^^^^^^^^^\n  File \"/home/fd15hava/.cache/pypoetry/virtualenvs/non-package-mode-zjkKA0Ca-py3.11/lib/python3.11/site-packages/tenacity/__init__.py\", line 289, in wrapped_f\n    return self(f, *args, **kw)\n           ^^^^^^^^^^^^^^^^^^^^\n  File \"/home/fd15hava/.cache/pypoetry/virtualenvs/non-package-mode-zjkKA0Ca-py3.11/lib/python3.11/site-packages/tenacity/__init__.py\", line 379, in __call__\n    do = self.iter(retry_state=retry_state)\n         ^^^^^^^^^^^^^^^^^^^^^^^^^^^^^^^^^^\n  File \"/home/fd15hava/.cache/pypoetry/virtualenvs/non-package-mode-zjkKA0Ca-py3.11/lib/python3.11/site-packages/tenacity/__init__.py\", line 326, in iter\n    raise retry_exc from fut.exception()\ntenacity.RetryError: RetryError[<Future at 0x14b1f77b6690 state=finished raised UnexpectedAnswerException>]\n",
      [
        1,
        2,
        2,
        2,
        1,
        1,
        2,
        1,
        1,
        1,
        2,
        1,
        1
      ],
      "Traceback (most recent call last):\n  File \"/home/fd15hava/.cache/pypoetry/virtualenvs/non-package-mode-zjkKA0Ca-py3.11/lib/python3.11/site-packages/tenacity/__init__.py\", line 382, in __call__\n    result = fn(*args, **kwargs)\n             ^^^^^^^^^^^^^^^^^^^\n  File \"/work/home/fd15hava/tinypaper-mpt/src/agent.py\", line 26, in play\n    answer = self._prompt(self._make_prompt(scenario))\n             ^^^^^^^^^^^^^^^^^^^^^^^^^^^^^^^^^^^^^^^^^\n  File \"/work/home/fd15hava/tinypaper-mpt/src/agent.py\", line 40, in _prompt\n    raise UnexpectedAnswerException(f\"expected 1 or 2, got {result}\")\nutil.UnexpectedAnswerException: expected 1 or 2, got \n\n\nThe above exception was the direct cause of the following exception:\n\nTraceback (most recent call last):\n  File \"/work/home/fd15hava/tinypaper-mpt/scripts/experiments/run.py\", line 16, in _run_session\n    result = agent.play(session)\n             ^^^^^^^^^^^^^^^^^^^\n  File \"/home/fd15hava/.cache/pypoetry/virtualenvs/non-package-mode-zjkKA0Ca-py3.11/lib/python3.11/site-packages/tenacity/__init__.py\", line 289, in wrapped_f\n    return self(f, *args, **kw)\n           ^^^^^^^^^^^^^^^^^^^^\n  File \"/home/fd15hava/.cache/pypoetry/virtualenvs/non-package-mode-zjkKA0Ca-py3.11/lib/python3.11/site-packages/tenacity/__init__.py\", line 379, in __call__\n    do = self.iter(retry_state=retry_state)\n         ^^^^^^^^^^^^^^^^^^^^^^^^^^^^^^^^^^\n  File \"/home/fd15hava/.cache/pypoetry/virtualenvs/non-package-mode-zjkKA0Ca-py3.11/lib/python3.11/site-packages/tenacity/__init__.py\", line 326, in iter\n    raise retry_exc from fut.exception()\ntenacity.RetryError: RetryError[<Future at 0x14b1f7795690 state=finished raised UnexpectedAnswerException>]\n",
      "Traceback (most recent call last):\n  File \"/home/fd15hava/.cache/pypoetry/virtualenvs/non-package-mode-zjkKA0Ca-py3.11/lib/python3.11/site-packages/tenacity/__init__.py\", line 382, in __call__\n    result = fn(*args, **kwargs)\n             ^^^^^^^^^^^^^^^^^^^\n  File \"/work/home/fd15hava/tinypaper-mpt/src/agent.py\", line 26, in play\n    answer = self._prompt(self._make_prompt(scenario))\n             ^^^^^^^^^^^^^^^^^^^^^^^^^^^^^^^^^^^^^^^^^\n  File \"/work/home/fd15hava/tinypaper-mpt/src/agent.py\", line 40, in _prompt\n    raise UnexpectedAnswerException(f\"expected 1 or 2, got {result}\")\nutil.UnexpectedAnswerException: expected 1 or 2, got \n\n\nThe above exception was the direct cause of the following exception:\n\nTraceback (most recent call last):\n  File \"/work/home/fd15hava/tinypaper-mpt/scripts/experiments/run.py\", line 16, in _run_session\n    result = agent.play(session)\n             ^^^^^^^^^^^^^^^^^^^\n  File \"/home/fd15hava/.cache/pypoetry/virtualenvs/non-package-mode-zjkKA0Ca-py3.11/lib/python3.11/site-packages/tenacity/__init__.py\", line 289, in wrapped_f\n    return self(f, *args, **kw)\n           ^^^^^^^^^^^^^^^^^^^^\n  File \"/home/fd15hava/.cache/pypoetry/virtualenvs/non-package-mode-zjkKA0Ca-py3.11/lib/python3.11/site-packages/tenacity/__init__.py\", line 379, in __call__\n    do = self.iter(retry_state=retry_state)\n         ^^^^^^^^^^^^^^^^^^^^^^^^^^^^^^^^^^\n  File \"/home/fd15hava/.cache/pypoetry/virtualenvs/non-package-mode-zjkKA0Ca-py3.11/lib/python3.11/site-packages/tenacity/__init__.py\", line 326, in iter\n    raise retry_exc from fut.exception()\ntenacity.RetryError: RetryError[<Future at 0x14b1f77e7450 state=finished raised UnexpectedAnswerException>]\n",
      "Traceback (most recent call last):\n  File \"/home/fd15hava/.cache/pypoetry/virtualenvs/non-package-mode-zjkKA0Ca-py3.11/lib/python3.11/site-packages/tenacity/__init__.py\", line 382, in __call__\n    result = fn(*args, **kwargs)\n             ^^^^^^^^^^^^^^^^^^^\n  File \"/work/home/fd15hava/tinypaper-mpt/src/agent.py\", line 26, in play\n    answer = self._prompt(self._make_prompt(scenario))\n             ^^^^^^^^^^^^^^^^^^^^^^^^^^^^^^^^^^^^^^^^^\n  File \"/work/home/fd15hava/tinypaper-mpt/src/agent.py\", line 40, in _prompt\n    raise UnexpectedAnswerException(f\"expected 1 or 2, got {result}\")\nutil.UnexpectedAnswerException: expected 1 or 2, got \n\n\nThe above exception was the direct cause of the following exception:\n\nTraceback (most recent call last):\n  File \"/work/home/fd15hava/tinypaper-mpt/scripts/experiments/run.py\", line 16, in _run_session\n    result = agent.play(session)\n             ^^^^^^^^^^^^^^^^^^^\n  File \"/home/fd15hava/.cache/pypoetry/virtualenvs/non-package-mode-zjkKA0Ca-py3.11/lib/python3.11/site-packages/tenacity/__init__.py\", line 289, in wrapped_f\n    return self(f, *args, **kw)\n           ^^^^^^^^^^^^^^^^^^^^\n  File \"/home/fd15hava/.cache/pypoetry/virtualenvs/non-package-mode-zjkKA0Ca-py3.11/lib/python3.11/site-packages/tenacity/__init__.py\", line 379, in __call__\n    do = self.iter(retry_state=retry_state)\n         ^^^^^^^^^^^^^^^^^^^^^^^^^^^^^^^^^^\n  File \"/home/fd15hava/.cache/pypoetry/virtualenvs/non-package-mode-zjkKA0Ca-py3.11/lib/python3.11/site-packages/tenacity/__init__.py\", line 326, in iter\n    raise retry_exc from fut.exception()\ntenacity.RetryError: RetryError[<Future at 0x14b1f77e4b90 state=finished raised UnexpectedAnswerException>]\n",
      "Traceback (most recent call last):\n  File \"/home/fd15hava/.cache/pypoetry/virtualenvs/non-package-mode-zjkKA0Ca-py3.11/lib/python3.11/site-packages/tenacity/__init__.py\", line 382, in __call__\n    result = fn(*args, **kwargs)\n             ^^^^^^^^^^^^^^^^^^^\n  File \"/work/home/fd15hava/tinypaper-mpt/src/agent.py\", line 26, in play\n    answer = self._prompt(self._make_prompt(scenario))\n             ^^^^^^^^^^^^^^^^^^^^^^^^^^^^^^^^^^^^^^^^^\n  File \"/work/home/fd15hava/tinypaper-mpt/src/agent.py\", line 40, in _prompt\n    raise UnexpectedAnswerException(f\"expected 1 or 2, got {result}\")\nutil.UnexpectedAnswerException: expected 1 or 2, got \n\n\nThe above exception was the direct cause of the following exception:\n\nTraceback (most recent call last):\n  File \"/work/home/fd15hava/tinypaper-mpt/scripts/experiments/run.py\", line 16, in _run_session\n    result = agent.play(session)\n             ^^^^^^^^^^^^^^^^^^^\n  File \"/home/fd15hava/.cache/pypoetry/virtualenvs/non-package-mode-zjkKA0Ca-py3.11/lib/python3.11/site-packages/tenacity/__init__.py\", line 289, in wrapped_f\n    return self(f, *args, **kw)\n           ^^^^^^^^^^^^^^^^^^^^\n  File \"/home/fd15hava/.cache/pypoetry/virtualenvs/non-package-mode-zjkKA0Ca-py3.11/lib/python3.11/site-packages/tenacity/__init__.py\", line 379, in __call__\n    do = self.iter(retry_state=retry_state)\n         ^^^^^^^^^^^^^^^^^^^^^^^^^^^^^^^^^^\n  File \"/home/fd15hava/.cache/pypoetry/virtualenvs/non-package-mode-zjkKA0Ca-py3.11/lib/python3.11/site-packages/tenacity/__init__.py\", line 326, in iter\n    raise retry_exc from fut.exception()\ntenacity.RetryError: RetryError[<Future at 0x14b1f77b7bd0 state=finished raised UnexpectedAnswerException>]\n",
      "Traceback (most recent call last):\n  File \"/home/fd15hava/.cache/pypoetry/virtualenvs/non-package-mode-zjkKA0Ca-py3.11/lib/python3.11/site-packages/tenacity/__init__.py\", line 382, in __call__\n    result = fn(*args, **kwargs)\n             ^^^^^^^^^^^^^^^^^^^\n  File \"/work/home/fd15hava/tinypaper-mpt/src/agent.py\", line 26, in play\n    answer = self._prompt(self._make_prompt(scenario))\n             ^^^^^^^^^^^^^^^^^^^^^^^^^^^^^^^^^^^^^^^^^\n  File \"/work/home/fd15hava/tinypaper-mpt/src/agent.py\", line 40, in _prompt\n    raise UnexpectedAnswerException(f\"expected 1 or 2, got {result}\")\nutil.UnexpectedAnswerException: expected 1 or 2, got \n\n\nThe above exception was the direct cause of the following exception:\n\nTraceback (most recent call last):\n  File \"/work/home/fd15hava/tinypaper-mpt/scripts/experiments/run.py\", line 16, in _run_session\n    result = agent.play(session)\n             ^^^^^^^^^^^^^^^^^^^\n  File \"/home/fd15hava/.cache/pypoetry/virtualenvs/non-package-mode-zjkKA0Ca-py3.11/lib/python3.11/site-packages/tenacity/__init__.py\", line 289, in wrapped_f\n    return self(f, *args, **kw)\n           ^^^^^^^^^^^^^^^^^^^^\n  File \"/home/fd15hava/.cache/pypoetry/virtualenvs/non-package-mode-zjkKA0Ca-py3.11/lib/python3.11/site-packages/tenacity/__init__.py\", line 379, in __call__\n    do = self.iter(retry_state=retry_state)\n         ^^^^^^^^^^^^^^^^^^^^^^^^^^^^^^^^^^\n  File \"/home/fd15hava/.cache/pypoetry/virtualenvs/non-package-mode-zjkKA0Ca-py3.11/lib/python3.11/site-packages/tenacity/__init__.py\", line 326, in iter\n    raise retry_exc from fut.exception()\ntenacity.RetryError: RetryError[<Future at 0x14b1f77c3810 state=finished raised UnexpectedAnswerException>]\n",
      [
        2,
        2,
        1,
        1,
        1,
        2,
        2,
        2,
        1,
        1,
        2,
        2,
        2
      ],
      "Traceback (most recent call last):\n  File \"/home/fd15hava/.cache/pypoetry/virtualenvs/non-package-mode-zjkKA0Ca-py3.11/lib/python3.11/site-packages/tenacity/__init__.py\", line 382, in __call__\n    result = fn(*args, **kwargs)\n             ^^^^^^^^^^^^^^^^^^^\n  File \"/work/home/fd15hava/tinypaper-mpt/src/agent.py\", line 26, in play\n    answer = self._prompt(self._make_prompt(scenario))\n             ^^^^^^^^^^^^^^^^^^^^^^^^^^^^^^^^^^^^^^^^^\n  File \"/work/home/fd15hava/tinypaper-mpt/src/agent.py\", line 40, in _prompt\n    raise UnexpectedAnswerException(f\"expected 1 or 2, got {result}\")\nutil.UnexpectedAnswerException: expected 1 or 2, got \n\n\nThe above exception was the direct cause of the following exception:\n\nTraceback (most recent call last):\n  File \"/work/home/fd15hava/tinypaper-mpt/scripts/experiments/run.py\", line 16, in _run_session\n    result = agent.play(session)\n             ^^^^^^^^^^^^^^^^^^^\n  File \"/home/fd15hava/.cache/pypoetry/virtualenvs/non-package-mode-zjkKA0Ca-py3.11/lib/python3.11/site-packages/tenacity/__init__.py\", line 289, in wrapped_f\n    return self(f, *args, **kw)\n           ^^^^^^^^^^^^^^^^^^^^\n  File \"/home/fd15hava/.cache/pypoetry/virtualenvs/non-package-mode-zjkKA0Ca-py3.11/lib/python3.11/site-packages/tenacity/__init__.py\", line 379, in __call__\n    do = self.iter(retry_state=retry_state)\n         ^^^^^^^^^^^^^^^^^^^^^^^^^^^^^^^^^^\n  File \"/home/fd15hava/.cache/pypoetry/virtualenvs/non-package-mode-zjkKA0Ca-py3.11/lib/python3.11/site-packages/tenacity/__init__.py\", line 326, in iter\n    raise retry_exc from fut.exception()\ntenacity.RetryError: RetryError[<Future at 0x14b1f7795090 state=finished raised UnexpectedAnswerException>]\n",
      "Traceback (most recent call last):\n  File \"/home/fd15hava/.cache/pypoetry/virtualenvs/non-package-mode-zjkKA0Ca-py3.11/lib/python3.11/site-packages/tenacity/__init__.py\", line 382, in __call__\n    result = fn(*args, **kwargs)\n             ^^^^^^^^^^^^^^^^^^^\n  File \"/work/home/fd15hava/tinypaper-mpt/src/agent.py\", line 26, in play\n    answer = self._prompt(self._make_prompt(scenario))\n             ^^^^^^^^^^^^^^^^^^^^^^^^^^^^^^^^^^^^^^^^^\n  File \"/work/home/fd15hava/tinypaper-mpt/src/agent.py\", line 40, in _prompt\n    raise UnexpectedAnswerException(f\"expected 1 or 2, got {result}\")\nutil.UnexpectedAnswerException: expected 1 or 2, got \n\nThe above exception was the direct cause of the following exception:\n\nTraceback (most recent call last):\n  File \"/work/home/fd15hava/tinypaper-mpt/scripts/experiments/run.py\", line 16, in _run_session\n    result = agent.play(session)\n             ^^^^^^^^^^^^^^^^^^^\n  File \"/home/fd15hava/.cache/pypoetry/virtualenvs/non-package-mode-zjkKA0Ca-py3.11/lib/python3.11/site-packages/tenacity/__init__.py\", line 289, in wrapped_f\n    return self(f, *args, **kw)\n           ^^^^^^^^^^^^^^^^^^^^\n  File \"/home/fd15hava/.cache/pypoetry/virtualenvs/non-package-mode-zjkKA0Ca-py3.11/lib/python3.11/site-packages/tenacity/__init__.py\", line 379, in __call__\n    do = self.iter(retry_state=retry_state)\n         ^^^^^^^^^^^^^^^^^^^^^^^^^^^^^^^^^^\n  File \"/home/fd15hava/.cache/pypoetry/virtualenvs/non-package-mode-zjkKA0Ca-py3.11/lib/python3.11/site-packages/tenacity/__init__.py\", line 326, in iter\n    raise retry_exc from fut.exception()\ntenacity.RetryError: RetryError[<Future at 0x14b1f7795450 state=finished raised UnexpectedAnswerException>]\n",
      "Traceback (most recent call last):\n  File \"/home/fd15hava/.cache/pypoetry/virtualenvs/non-package-mode-zjkKA0Ca-py3.11/lib/python3.11/site-packages/tenacity/__init__.py\", line 382, in __call__\n    result = fn(*args, **kwargs)\n             ^^^^^^^^^^^^^^^^^^^\n  File \"/work/home/fd15hava/tinypaper-mpt/src/agent.py\", line 26, in play\n    answer = self._prompt(self._make_prompt(scenario))\n             ^^^^^^^^^^^^^^^^^^^^^^^^^^^^^^^^^^^^^^^^^\n  File \"/work/home/fd15hava/tinypaper-mpt/src/agent.py\", line 40, in _prompt\n    raise UnexpectedAnswerException(f\"expected 1 or 2, got {result}\")\nutil.UnexpectedAnswerException: expected 1 or 2, got \n\n\nThe above exception was the direct cause of the following exception:\n\nTraceback (most recent call last):\n  File \"/work/home/fd15hava/tinypaper-mpt/scripts/experiments/run.py\", line 16, in _run_session\n    result = agent.play(session)\n             ^^^^^^^^^^^^^^^^^^^\n  File \"/home/fd15hava/.cache/pypoetry/virtualenvs/non-package-mode-zjkKA0Ca-py3.11/lib/python3.11/site-packages/tenacity/__init__.py\", line 289, in wrapped_f\n    return self(f, *args, **kw)\n           ^^^^^^^^^^^^^^^^^^^^\n  File \"/home/fd15hava/.cache/pypoetry/virtualenvs/non-package-mode-zjkKA0Ca-py3.11/lib/python3.11/site-packages/tenacity/__init__.py\", line 379, in __call__\n    do = self.iter(retry_state=retry_state)\n         ^^^^^^^^^^^^^^^^^^^^^^^^^^^^^^^^^^\n  File \"/home/fd15hava/.cache/pypoetry/virtualenvs/non-package-mode-zjkKA0Ca-py3.11/lib/python3.11/site-packages/tenacity/__init__.py\", line 326, in iter\n    raise retry_exc from fut.exception()\ntenacity.RetryError: RetryError[<Future at 0x14b1f777b190 state=finished raised UnexpectedAnswerException>]\n",
      "Traceback (most recent call last):\n  File \"/home/fd15hava/.cache/pypoetry/virtualenvs/non-package-mode-zjkKA0Ca-py3.11/lib/python3.11/site-packages/tenacity/__init__.py\", line 382, in __call__\n    result = fn(*args, **kwargs)\n             ^^^^^^^^^^^^^^^^^^^\n  File \"/work/home/fd15hava/tinypaper-mpt/src/agent.py\", line 26, in play\n    answer = self._prompt(self._make_prompt(scenario))\n             ^^^^^^^^^^^^^^^^^^^^^^^^^^^^^^^^^^^^^^^^^\n  File \"/work/home/fd15hava/tinypaper-mpt/src/agent.py\", line 40, in _prompt\n    raise UnexpectedAnswerException(f\"expected 1 or 2, got {result}\")\nutil.UnexpectedAnswerException: expected 1 or 2, got \n\n\nThe above exception was the direct cause of the following exception:\n\nTraceback (most recent call last):\n  File \"/work/home/fd15hava/tinypaper-mpt/scripts/experiments/run.py\", line 16, in _run_session\n    result = agent.play(session)\n             ^^^^^^^^^^^^^^^^^^^\n  File \"/home/fd15hava/.cache/pypoetry/virtualenvs/non-package-mode-zjkKA0Ca-py3.11/lib/python3.11/site-packages/tenacity/__init__.py\", line 289, in wrapped_f\n    return self(f, *args, **kw)\n           ^^^^^^^^^^^^^^^^^^^^\n  File \"/home/fd15hava/.cache/pypoetry/virtualenvs/non-package-mode-zjkKA0Ca-py3.11/lib/python3.11/site-packages/tenacity/__init__.py\", line 379, in __call__\n    do = self.iter(retry_state=retry_state)\n         ^^^^^^^^^^^^^^^^^^^^^^^^^^^^^^^^^^\n  File \"/home/fd15hava/.cache/pypoetry/virtualenvs/non-package-mode-zjkKA0Ca-py3.11/lib/python3.11/site-packages/tenacity/__init__.py\", line 326, in iter\n    raise retry_exc from fut.exception()\ntenacity.RetryError: RetryError[<Future at 0x14b1f7815510 state=finished raised UnexpectedAnswerException>]\n",
      "Traceback (most recent call last):\n  File \"/home/fd15hava/.cache/pypoetry/virtualenvs/non-package-mode-zjkKA0Ca-py3.11/lib/python3.11/site-packages/tenacity/__init__.py\", line 382, in __call__\n    result = fn(*args, **kwargs)\n             ^^^^^^^^^^^^^^^^^^^\n  File \"/work/home/fd15hava/tinypaper-mpt/src/agent.py\", line 26, in play\n    answer = self._prompt(self._make_prompt(scenario))\n             ^^^^^^^^^^^^^^^^^^^^^^^^^^^^^^^^^^^^^^^^^\n  File \"/work/home/fd15hava/tinypaper-mpt/src/agent.py\", line 40, in _prompt\n    raise UnexpectedAnswerException(f\"expected 1 or 2, got {result}\")\nutil.UnexpectedAnswerException: expected 1 or 2, got \n\n\nThe above exception was the direct cause of the following exception:\n\nTraceback (most recent call last):\n  File \"/work/home/fd15hava/tinypaper-mpt/scripts/experiments/run.py\", line 16, in _run_session\n    result = agent.play(session)\n             ^^^^^^^^^^^^^^^^^^^\n  File \"/home/fd15hava/.cache/pypoetry/virtualenvs/non-package-mode-zjkKA0Ca-py3.11/lib/python3.11/site-packages/tenacity/__init__.py\", line 289, in wrapped_f\n    return self(f, *args, **kw)\n           ^^^^^^^^^^^^^^^^^^^^\n  File \"/home/fd15hava/.cache/pypoetry/virtualenvs/non-package-mode-zjkKA0Ca-py3.11/lib/python3.11/site-packages/tenacity/__init__.py\", line 379, in __call__\n    do = self.iter(retry_state=retry_state)\n         ^^^^^^^^^^^^^^^^^^^^^^^^^^^^^^^^^^\n  File \"/home/fd15hava/.cache/pypoetry/virtualenvs/non-package-mode-zjkKA0Ca-py3.11/lib/python3.11/site-packages/tenacity/__init__.py\", line 326, in iter\n    raise retry_exc from fut.exception()\ntenacity.RetryError: RetryError[<Future at 0x14b1f7bde3d0 state=finished raised UnexpectedAnswerException>]\n",
      "Traceback (most recent call last):\n  File \"/home/fd15hava/.cache/pypoetry/virtualenvs/non-package-mode-zjkKA0Ca-py3.11/lib/python3.11/site-packages/tenacity/__init__.py\", line 382, in __call__\n    result = fn(*args, **kwargs)\n             ^^^^^^^^^^^^^^^^^^^\n  File \"/work/home/fd15hava/tinypaper-mpt/src/agent.py\", line 26, in play\n    answer = self._prompt(self._make_prompt(scenario))\n             ^^^^^^^^^^^^^^^^^^^^^^^^^^^^^^^^^^^^^^^^^\n  File \"/work/home/fd15hava/tinypaper-mpt/src/agent.py\", line 40, in _prompt\n    raise UnexpectedAnswerException(f\"expected 1 or 2, got {result}\")\nutil.UnexpectedAnswerException: expected 1 or 2, got \n\n\nThe above exception was the direct cause of the following exception:\n\nTraceback (most recent call last):\n  File \"/work/home/fd15hava/tinypaper-mpt/scripts/experiments/run.py\", line 16, in _run_session\n    result = agent.play(session)\n             ^^^^^^^^^^^^^^^^^^^\n  File \"/home/fd15hava/.cache/pypoetry/virtualenvs/non-package-mode-zjkKA0Ca-py3.11/lib/python3.11/site-packages/tenacity/__init__.py\", line 289, in wrapped_f\n    return self(f, *args, **kw)\n           ^^^^^^^^^^^^^^^^^^^^\n  File \"/home/fd15hava/.cache/pypoetry/virtualenvs/non-package-mode-zjkKA0Ca-py3.11/lib/python3.11/site-packages/tenacity/__init__.py\", line 379, in __call__\n    do = self.iter(retry_state=retry_state)\n         ^^^^^^^^^^^^^^^^^^^^^^^^^^^^^^^^^^\n  File \"/home/fd15hava/.cache/pypoetry/virtualenvs/non-package-mode-zjkKA0Ca-py3.11/lib/python3.11/site-packages/tenacity/__init__.py\", line 326, in iter\n    raise retry_exc from fut.exception()\ntenacity.RetryError: RetryError[<Future at 0x14b1f7bde210 state=finished raised UnexpectedAnswerException>]\n",
      "Traceback (most recent call last):\n  File \"/home/fd15hava/.cache/pypoetry/virtualenvs/non-package-mode-zjkKA0Ca-py3.11/lib/python3.11/site-packages/tenacity/__init__.py\", line 382, in __call__\n    result = fn(*args, **kwargs)\n             ^^^^^^^^^^^^^^^^^^^\n  File \"/work/home/fd15hava/tinypaper-mpt/src/agent.py\", line 26, in play\n    answer = self._prompt(self._make_prompt(scenario))\n             ^^^^^^^^^^^^^^^^^^^^^^^^^^^^^^^^^^^^^^^^^\n  File \"/work/home/fd15hava/tinypaper-mpt/src/agent.py\", line 40, in _prompt\n    raise UnexpectedAnswerException(f\"expected 1 or 2, got {result}\")\nutil.UnexpectedAnswerException: expected 1 or 2, got \n\n\nThe above exception was the direct cause of the following exception:\n\nTraceback (most recent call last):\n  File \"/work/home/fd15hava/tinypaper-mpt/scripts/experiments/run.py\", line 16, in _run_session\n    result = agent.play(session)\n             ^^^^^^^^^^^^^^^^^^^\n  File \"/home/fd15hava/.cache/pypoetry/virtualenvs/non-package-mode-zjkKA0Ca-py3.11/lib/python3.11/site-packages/tenacity/__init__.py\", line 289, in wrapped_f\n    return self(f, *args, **kw)\n           ^^^^^^^^^^^^^^^^^^^^\n  File \"/home/fd15hava/.cache/pypoetry/virtualenvs/non-package-mode-zjkKA0Ca-py3.11/lib/python3.11/site-packages/tenacity/__init__.py\", line 379, in __call__\n    do = self.iter(retry_state=retry_state)\n         ^^^^^^^^^^^^^^^^^^^^^^^^^^^^^^^^^^\n  File \"/home/fd15hava/.cache/pypoetry/virtualenvs/non-package-mode-zjkKA0Ca-py3.11/lib/python3.11/site-packages/tenacity/__init__.py\", line 326, in iter\n    raise retry_exc from fut.exception()\ntenacity.RetryError: RetryError[<Future at 0x14b1f7815450 state=finished raised UnexpectedAnswerException>]\n",
      "Traceback (most recent call last):\n  File \"/home/fd15hava/.cache/pypoetry/virtualenvs/non-package-mode-zjkKA0Ca-py3.11/lib/python3.11/site-packages/tenacity/__init__.py\", line 382, in __call__\n    result = fn(*args, **kwargs)\n             ^^^^^^^^^^^^^^^^^^^\n  File \"/work/home/fd15hava/tinypaper-mpt/src/agent.py\", line 26, in play\n    answer = self._prompt(self._make_prompt(scenario))\n             ^^^^^^^^^^^^^^^^^^^^^^^^^^^^^^^^^^^^^^^^^\n  File \"/work/home/fd15hava/tinypaper-mpt/src/agent.py\", line 40, in _prompt\n    raise UnexpectedAnswerException(f\"expected 1 or 2, got {result}\")\nutil.UnexpectedAnswerException: expected 1 or 2, got \n\n\nThe above exception was the direct cause of the following exception:\n\nTraceback (most recent call last):\n  File \"/work/home/fd15hava/tinypaper-mpt/scripts/experiments/run.py\", line 16, in _run_session\n    result = agent.play(session)\n             ^^^^^^^^^^^^^^^^^^^\n  File \"/home/fd15hava/.cache/pypoetry/virtualenvs/non-package-mode-zjkKA0Ca-py3.11/lib/python3.11/site-packages/tenacity/__init__.py\", line 289, in wrapped_f\n    return self(f, *args, **kw)\n           ^^^^^^^^^^^^^^^^^^^^\n  File \"/home/fd15hava/.cache/pypoetry/virtualenvs/non-package-mode-zjkKA0Ca-py3.11/lib/python3.11/site-packages/tenacity/__init__.py\", line 379, in __call__\n    do = self.iter(retry_state=retry_state)\n         ^^^^^^^^^^^^^^^^^^^^^^^^^^^^^^^^^^\n  File \"/home/fd15hava/.cache/pypoetry/virtualenvs/non-package-mode-zjkKA0Ca-py3.11/lib/python3.11/site-packages/tenacity/__init__.py\", line 326, in iter\n    raise retry_exc from fut.exception()\ntenacity.RetryError: RetryError[<Future at 0x14b1f7bdc390 state=finished raised UnexpectedAnswerException>]\n",
      "Traceback (most recent call last):\n  File \"/home/fd15hava/.cache/pypoetry/virtualenvs/non-package-mode-zjkKA0Ca-py3.11/lib/python3.11/site-packages/tenacity/__init__.py\", line 382, in __call__\n    result = fn(*args, **kwargs)\n             ^^^^^^^^^^^^^^^^^^^\n  File \"/work/home/fd15hava/tinypaper-mpt/src/agent.py\", line 26, in play\n    answer = self._prompt(self._make_prompt(scenario))\n             ^^^^^^^^^^^^^^^^^^^^^^^^^^^^^^^^^^^^^^^^^\n  File \"/work/home/fd15hava/tinypaper-mpt/src/agent.py\", line 40, in _prompt\n    raise UnexpectedAnswerException(f\"expected 1 or 2, got {result}\")\nutil.UnexpectedAnswerException: expected 1 or 2, got \n\n\nThe above exception was the direct cause of the following exception:\n\nTraceback (most recent call last):\n  File \"/work/home/fd15hava/tinypaper-mpt/scripts/experiments/run.py\", line 16, in _run_session\n    result = agent.play(session)\n             ^^^^^^^^^^^^^^^^^^^\n  File \"/home/fd15hava/.cache/pypoetry/virtualenvs/non-package-mode-zjkKA0Ca-py3.11/lib/python3.11/site-packages/tenacity/__init__.py\", line 289, in wrapped_f\n    return self(f, *args, **kw)\n           ^^^^^^^^^^^^^^^^^^^^\n  File \"/home/fd15hava/.cache/pypoetry/virtualenvs/non-package-mode-zjkKA0Ca-py3.11/lib/python3.11/site-packages/tenacity/__init__.py\", line 379, in __call__\n    do = self.iter(retry_state=retry_state)\n         ^^^^^^^^^^^^^^^^^^^^^^^^^^^^^^^^^^\n  File \"/home/fd15hava/.cache/pypoetry/virtualenvs/non-package-mode-zjkKA0Ca-py3.11/lib/python3.11/site-packages/tenacity/__init__.py\", line 326, in iter\n    raise retry_exc from fut.exception()\ntenacity.RetryError: RetryError[<Future at 0x14b1f78267d0 state=finished raised UnexpectedAnswerException>]\n",
      "Traceback (most recent call last):\n  File \"/home/fd15hava/.cache/pypoetry/virtualenvs/non-package-mode-zjkKA0Ca-py3.11/lib/python3.11/site-packages/tenacity/__init__.py\", line 382, in __call__\n    result = fn(*args, **kwargs)\n             ^^^^^^^^^^^^^^^^^^^\n  File \"/work/home/fd15hava/tinypaper-mpt/src/agent.py\", line 26, in play\n    answer = self._prompt(self._make_prompt(scenario))\n             ^^^^^^^^^^^^^^^^^^^^^^^^^^^^^^^^^^^^^^^^^\n  File \"/work/home/fd15hava/tinypaper-mpt/src/agent.py\", line 40, in _prompt\n    raise UnexpectedAnswerException(f\"expected 1 or 2, got {result}\")\nutil.UnexpectedAnswerException: expected 1 or 2, got \n\n\nThe above exception was the direct cause of the following exception:\n\nTraceback (most recent call last):\n  File \"/work/home/fd15hava/tinypaper-mpt/scripts/experiments/run.py\", line 16, in _run_session\n    result = agent.play(session)\n             ^^^^^^^^^^^^^^^^^^^\n  File \"/home/fd15hava/.cache/pypoetry/virtualenvs/non-package-mode-zjkKA0Ca-py3.11/lib/python3.11/site-packages/tenacity/__init__.py\", line 289, in wrapped_f\n    return self(f, *args, **kw)\n           ^^^^^^^^^^^^^^^^^^^^\n  File \"/home/fd15hava/.cache/pypoetry/virtualenvs/non-package-mode-zjkKA0Ca-py3.11/lib/python3.11/site-packages/tenacity/__init__.py\", line 379, in __call__\n    do = self.iter(retry_state=retry_state)\n         ^^^^^^^^^^^^^^^^^^^^^^^^^^^^^^^^^^\n  File \"/home/fd15hava/.cache/pypoetry/virtualenvs/non-package-mode-zjkKA0Ca-py3.11/lib/python3.11/site-packages/tenacity/__init__.py\", line 326, in iter\n    raise retry_exc from fut.exception()\ntenacity.RetryError: RetryError[<Future at 0x14b1f7814490 state=finished raised UnexpectedAnswerException>]\n",
      "Traceback (most recent call last):\n  File \"/home/fd15hava/.cache/pypoetry/virtualenvs/non-package-mode-zjkKA0Ca-py3.11/lib/python3.11/site-packages/tenacity/__init__.py\", line 382, in __call__\n    result = fn(*args, **kwargs)\n             ^^^^^^^^^^^^^^^^^^^\n  File \"/work/home/fd15hava/tinypaper-mpt/src/agent.py\", line 26, in play\n    answer = self._prompt(self._make_prompt(scenario))\n             ^^^^^^^^^^^^^^^^^^^^^^^^^^^^^^^^^^^^^^^^^\n  File \"/work/home/fd15hava/tinypaper-mpt/src/agent.py\", line 40, in _prompt\n    raise UnexpectedAnswerException(f\"expected 1 or 2, got {result}\")\nutil.UnexpectedAnswerException: expected 1 or 2, got \n\n\nThe above exception was the direct cause of the following exception:\n\nTraceback (most recent call last):\n  File \"/work/home/fd15hava/tinypaper-mpt/scripts/experiments/run.py\", line 16, in _run_session\n    result = agent.play(session)\n             ^^^^^^^^^^^^^^^^^^^\n  File \"/home/fd15hava/.cache/pypoetry/virtualenvs/non-package-mode-zjkKA0Ca-py3.11/lib/python3.11/site-packages/tenacity/__init__.py\", line 289, in wrapped_f\n    return self(f, *args, **kw)\n           ^^^^^^^^^^^^^^^^^^^^\n  File \"/home/fd15hava/.cache/pypoetry/virtualenvs/non-package-mode-zjkKA0Ca-py3.11/lib/python3.11/site-packages/tenacity/__init__.py\", line 379, in __call__\n    do = self.iter(retry_state=retry_state)\n         ^^^^^^^^^^^^^^^^^^^^^^^^^^^^^^^^^^\n  File \"/home/fd15hava/.cache/pypoetry/virtualenvs/non-package-mode-zjkKA0Ca-py3.11/lib/python3.11/site-packages/tenacity/__init__.py\", line 326, in iter\n    raise retry_exc from fut.exception()\ntenacity.RetryError: RetryError[<Future at 0x14b1f78296d0 state=finished raised UnexpectedAnswerException>]\n",
      [
        1,
        1,
        2,
        1,
        2,
        1,
        1,
        2,
        1,
        1,
        1,
        1,
        1
      ],
      "Traceback (most recent call last):\n  File \"/home/fd15hava/.cache/pypoetry/virtualenvs/non-package-mode-zjkKA0Ca-py3.11/lib/python3.11/site-packages/tenacity/__init__.py\", line 382, in __call__\n    result = fn(*args, **kwargs)\n             ^^^^^^^^^^^^^^^^^^^\n  File \"/work/home/fd15hava/tinypaper-mpt/src/agent.py\", line 26, in play\n    answer = self._prompt(self._make_prompt(scenario))\n             ^^^^^^^^^^^^^^^^^^^^^^^^^^^^^^^^^^^^^^^^^\n  File \"/work/home/fd15hava/tinypaper-mpt/src/agent.py\", line 40, in _prompt\n    raise UnexpectedAnswerException(f\"expected 1 or 2, got {result}\")\nutil.UnexpectedAnswerException: expected 1 or 2, got \n\n\nThe above exception was the direct cause of the following exception:\n\nTraceback (most recent call last):\n  File \"/work/home/fd15hava/tinypaper-mpt/scripts/experiments/run.py\", line 16, in _run_session\n    result = agent.play(session)\n             ^^^^^^^^^^^^^^^^^^^\n  File \"/home/fd15hava/.cache/pypoetry/virtualenvs/non-package-mode-zjkKA0Ca-py3.11/lib/python3.11/site-packages/tenacity/__init__.py\", line 289, in wrapped_f\n    return self(f, *args, **kw)\n           ^^^^^^^^^^^^^^^^^^^^\n  File \"/home/fd15hava/.cache/pypoetry/virtualenvs/non-package-mode-zjkKA0Ca-py3.11/lib/python3.11/site-packages/tenacity/__init__.py\", line 379, in __call__\n    do = self.iter(retry_state=retry_state)\n         ^^^^^^^^^^^^^^^^^^^^^^^^^^^^^^^^^^\n  File \"/home/fd15hava/.cache/pypoetry/virtualenvs/non-package-mode-zjkKA0Ca-py3.11/lib/python3.11/site-packages/tenacity/__init__.py\", line 326, in iter\n    raise retry_exc from fut.exception()\ntenacity.RetryError: RetryError[<Future at 0x14b1f7c22fd0 state=finished raised UnexpectedAnswerException>]\n",
      "Traceback (most recent call last):\n  File \"/home/fd15hava/.cache/pypoetry/virtualenvs/non-package-mode-zjkKA0Ca-py3.11/lib/python3.11/site-packages/tenacity/__init__.py\", line 382, in __call__\n    result = fn(*args, **kwargs)\n             ^^^^^^^^^^^^^^^^^^^\n  File \"/work/home/fd15hava/tinypaper-mpt/src/agent.py\", line 26, in play\n    answer = self._prompt(self._make_prompt(scenario))\n             ^^^^^^^^^^^^^^^^^^^^^^^^^^^^^^^^^^^^^^^^^\n  File \"/work/home/fd15hava/tinypaper-mpt/src/agent.py\", line 40, in _prompt\n    raise UnexpectedAnswerException(f\"expected 1 or 2, got {result}\")\nutil.UnexpectedAnswerException: expected 1 or 2, got \n\n\nThe above exception was the direct cause of the following exception:\n\nTraceback (most recent call last):\n  File \"/work/home/fd15hava/tinypaper-mpt/scripts/experiments/run.py\", line 16, in _run_session\n    result = agent.play(session)\n             ^^^^^^^^^^^^^^^^^^^\n  File \"/home/fd15hava/.cache/pypoetry/virtualenvs/non-package-mode-zjkKA0Ca-py3.11/lib/python3.11/site-packages/tenacity/__init__.py\", line 289, in wrapped_f\n    return self(f, *args, **kw)\n           ^^^^^^^^^^^^^^^^^^^^\n  File \"/home/fd15hava/.cache/pypoetry/virtualenvs/non-package-mode-zjkKA0Ca-py3.11/lib/python3.11/site-packages/tenacity/__init__.py\", line 379, in __call__\n    do = self.iter(retry_state=retry_state)\n         ^^^^^^^^^^^^^^^^^^^^^^^^^^^^^^^^^^\n  File \"/home/fd15hava/.cache/pypoetry/virtualenvs/non-package-mode-zjkKA0Ca-py3.11/lib/python3.11/site-packages/tenacity/__init__.py\", line 326, in iter\n    raise retry_exc from fut.exception()\ntenacity.RetryError: RetryError[<Future at 0x14b1f78165d0 state=finished raised UnexpectedAnswerException>]\n",
      "Traceback (most recent call last):\n  File \"/home/fd15hava/.cache/pypoetry/virtualenvs/non-package-mode-zjkKA0Ca-py3.11/lib/python3.11/site-packages/tenacity/__init__.py\", line 382, in __call__\n    result = fn(*args, **kwargs)\n             ^^^^^^^^^^^^^^^^^^^\n  File \"/work/home/fd15hava/tinypaper-mpt/src/agent.py\", line 26, in play\n    answer = self._prompt(self._make_prompt(scenario))\n             ^^^^^^^^^^^^^^^^^^^^^^^^^^^^^^^^^^^^^^^^^\n  File \"/work/home/fd15hava/tinypaper-mpt/src/agent.py\", line 40, in _prompt\n    raise UnexpectedAnswerException(f\"expected 1 or 2, got {result}\")\nutil.UnexpectedAnswerException: expected 1 or 2, got \n\n\nThe above exception was the direct cause of the following exception:\n\nTraceback (most recent call last):\n  File \"/work/home/fd15hava/tinypaper-mpt/scripts/experiments/run.py\", line 16, in _run_session\n    result = agent.play(session)\n             ^^^^^^^^^^^^^^^^^^^\n  File \"/home/fd15hava/.cache/pypoetry/virtualenvs/non-package-mode-zjkKA0Ca-py3.11/lib/python3.11/site-packages/tenacity/__init__.py\", line 289, in wrapped_f\n    return self(f, *args, **kw)\n           ^^^^^^^^^^^^^^^^^^^^\n  File \"/home/fd15hava/.cache/pypoetry/virtualenvs/non-package-mode-zjkKA0Ca-py3.11/lib/python3.11/site-packages/tenacity/__init__.py\", line 379, in __call__\n    do = self.iter(retry_state=retry_state)\n         ^^^^^^^^^^^^^^^^^^^^^^^^^^^^^^^^^^\n  File \"/home/fd15hava/.cache/pypoetry/virtualenvs/non-package-mode-zjkKA0Ca-py3.11/lib/python3.11/site-packages/tenacity/__init__.py\", line 326, in iter\n    raise retry_exc from fut.exception()\ntenacity.RetryError: RetryError[<Future at 0x14b1f7bfb650 state=finished raised UnexpectedAnswerException>]\n",
      "Traceback (most recent call last):\n  File \"/home/fd15hava/.cache/pypoetry/virtualenvs/non-package-mode-zjkKA0Ca-py3.11/lib/python3.11/site-packages/tenacity/__init__.py\", line 382, in __call__\n    result = fn(*args, **kwargs)\n             ^^^^^^^^^^^^^^^^^^^\n  File \"/work/home/fd15hava/tinypaper-mpt/src/agent.py\", line 26, in play\n    answer = self._prompt(self._make_prompt(scenario))\n             ^^^^^^^^^^^^^^^^^^^^^^^^^^^^^^^^^^^^^^^^^\n  File \"/work/home/fd15hava/tinypaper-mpt/src/agent.py\", line 40, in _prompt\n    raise UnexpectedAnswerException(f\"expected 1 or 2, got {result}\")\nutil.UnexpectedAnswerException: expected 1 or 2, got \n\n\nThe above exception was the direct cause of the following exception:\n\nTraceback (most recent call last):\n  File \"/work/home/fd15hava/tinypaper-mpt/scripts/experiments/run.py\", line 16, in _run_session\n    result = agent.play(session)\n             ^^^^^^^^^^^^^^^^^^^\n  File \"/home/fd15hava/.cache/pypoetry/virtualenvs/non-package-mode-zjkKA0Ca-py3.11/lib/python3.11/site-packages/tenacity/__init__.py\", line 289, in wrapped_f\n    return self(f, *args, **kw)\n           ^^^^^^^^^^^^^^^^^^^^\n  File \"/home/fd15hava/.cache/pypoetry/virtualenvs/non-package-mode-zjkKA0Ca-py3.11/lib/python3.11/site-packages/tenacity/__init__.py\", line 379, in __call__\n    do = self.iter(retry_state=retry_state)\n         ^^^^^^^^^^^^^^^^^^^^^^^^^^^^^^^^^^\n  File \"/home/fd15hava/.cache/pypoetry/virtualenvs/non-package-mode-zjkKA0Ca-py3.11/lib/python3.11/site-packages/tenacity/__init__.py\", line 326, in iter\n    raise retry_exc from fut.exception()\ntenacity.RetryError: RetryError[<Future at 0x14b1f7bc9b50 state=finished raised UnexpectedAnswerException>]\n",
      "Traceback (most recent call last):\n  File \"/home/fd15hava/.cache/pypoetry/virtualenvs/non-package-mode-zjkKA0Ca-py3.11/lib/python3.11/site-packages/tenacity/__init__.py\", line 382, in __call__\n    result = fn(*args, **kwargs)\n             ^^^^^^^^^^^^^^^^^^^\n  File \"/work/home/fd15hava/tinypaper-mpt/src/agent.py\", line 26, in play\n    answer = self._prompt(self._make_prompt(scenario))\n             ^^^^^^^^^^^^^^^^^^^^^^^^^^^^^^^^^^^^^^^^^\n  File \"/work/home/fd15hava/tinypaper-mpt/src/agent.py\", line 40, in _prompt\n    raise UnexpectedAnswerException(f\"expected 1 or 2, got {result}\")\nutil.UnexpectedAnswerException: expected 1 or 2, got \n\n\nThe above exception was the direct cause of the following exception:\n\nTraceback (most recent call last):\n  File \"/work/home/fd15hava/tinypaper-mpt/scripts/experiments/run.py\", line 16, in _run_session\n    result = agent.play(session)\n             ^^^^^^^^^^^^^^^^^^^\n  File \"/home/fd15hava/.cache/pypoetry/virtualenvs/non-package-mode-zjkKA0Ca-py3.11/lib/python3.11/site-packages/tenacity/__init__.py\", line 289, in wrapped_f\n    return self(f, *args, **kw)\n           ^^^^^^^^^^^^^^^^^^^^\n  File \"/home/fd15hava/.cache/pypoetry/virtualenvs/non-package-mode-zjkKA0Ca-py3.11/lib/python3.11/site-packages/tenacity/__init__.py\", line 379, in __call__\n    do = self.iter(retry_state=retry_state)\n         ^^^^^^^^^^^^^^^^^^^^^^^^^^^^^^^^^^\n  File \"/home/fd15hava/.cache/pypoetry/virtualenvs/non-package-mode-zjkKA0Ca-py3.11/lib/python3.11/site-packages/tenacity/__init__.py\", line 326, in iter\n    raise retry_exc from fut.exception()\ntenacity.RetryError: RetryError[<Future at 0x14b1f782b110 state=finished raised UnexpectedAnswerException>]\n",
      "Traceback (most recent call last):\n  File \"/home/fd15hava/.cache/pypoetry/virtualenvs/non-package-mode-zjkKA0Ca-py3.11/lib/python3.11/site-packages/tenacity/__init__.py\", line 382, in __call__\n    result = fn(*args, **kwargs)\n             ^^^^^^^^^^^^^^^^^^^\n  File \"/work/home/fd15hava/tinypaper-mpt/src/agent.py\", line 26, in play\n    answer = self._prompt(self._make_prompt(scenario))\n             ^^^^^^^^^^^^^^^^^^^^^^^^^^^^^^^^^^^^^^^^^\n  File \"/work/home/fd15hava/tinypaper-mpt/src/agent.py\", line 40, in _prompt\n    raise UnexpectedAnswerException(f\"expected 1 or 2, got {result}\")\nutil.UnexpectedAnswerException: expected 1 or 2, got \n\n\nThe above exception was the direct cause of the following exception:\n\nTraceback (most recent call last):\n  File \"/work/home/fd15hava/tinypaper-mpt/scripts/experiments/run.py\", line 16, in _run_session\n    result = agent.play(session)\n             ^^^^^^^^^^^^^^^^^^^\n  File \"/home/fd15hava/.cache/pypoetry/virtualenvs/non-package-mode-zjkKA0Ca-py3.11/lib/python3.11/site-packages/tenacity/__init__.py\", line 289, in wrapped_f\n    return self(f, *args, **kw)\n           ^^^^^^^^^^^^^^^^^^^^\n  File \"/home/fd15hava/.cache/pypoetry/virtualenvs/non-package-mode-zjkKA0Ca-py3.11/lib/python3.11/site-packages/tenacity/__init__.py\", line 379, in __call__\n    do = self.iter(retry_state=retry_state)\n         ^^^^^^^^^^^^^^^^^^^^^^^^^^^^^^^^^^\n  File \"/home/fd15hava/.cache/pypoetry/virtualenvs/non-package-mode-zjkKA0Ca-py3.11/lib/python3.11/site-packages/tenacity/__init__.py\", line 326, in iter\n    raise retry_exc from fut.exception()\ntenacity.RetryError: RetryError[<Future at 0x14b1f7bcb810 state=finished raised UnexpectedAnswerException>]\n",
      "Traceback (most recent call last):\n  File \"/home/fd15hava/.cache/pypoetry/virtualenvs/non-package-mode-zjkKA0Ca-py3.11/lib/python3.11/site-packages/tenacity/__init__.py\", line 382, in __call__\n    result = fn(*args, **kwargs)\n             ^^^^^^^^^^^^^^^^^^^\n  File \"/work/home/fd15hava/tinypaper-mpt/src/agent.py\", line 26, in play\n    answer = self._prompt(self._make_prompt(scenario))\n             ^^^^^^^^^^^^^^^^^^^^^^^^^^^^^^^^^^^^^^^^^\n  File \"/work/home/fd15hava/tinypaper-mpt/src/agent.py\", line 40, in _prompt\n    raise UnexpectedAnswerException(f\"expected 1 or 2, got {result}\")\nutil.UnexpectedAnswerException: expected 1 or 2, got \n\n\nThe above exception was the direct cause of the following exception:\n\nTraceback (most recent call last):\n  File \"/work/home/fd15hava/tinypaper-mpt/scripts/experiments/run.py\", line 16, in _run_session\n    result = agent.play(session)\n             ^^^^^^^^^^^^^^^^^^^\n  File \"/home/fd15hava/.cache/pypoetry/virtualenvs/non-package-mode-zjkKA0Ca-py3.11/lib/python3.11/site-packages/tenacity/__init__.py\", line 289, in wrapped_f\n    return self(f, *args, **kw)\n           ^^^^^^^^^^^^^^^^^^^^\n  File \"/home/fd15hava/.cache/pypoetry/virtualenvs/non-package-mode-zjkKA0Ca-py3.11/lib/python3.11/site-packages/tenacity/__init__.py\", line 379, in __call__\n    do = self.iter(retry_state=retry_state)\n         ^^^^^^^^^^^^^^^^^^^^^^^^^^^^^^^^^^\n  File \"/home/fd15hava/.cache/pypoetry/virtualenvs/non-package-mode-zjkKA0Ca-py3.11/lib/python3.11/site-packages/tenacity/__init__.py\", line 326, in iter\n    raise retry_exc from fut.exception()\ntenacity.RetryError: RetryError[<Future at 0x14b1f7bd7310 state=finished raised UnexpectedAnswerException>]\n",
      [
        2,
        2,
        1,
        1,
        1,
        2,
        2,
        2,
        1,
        2,
        1,
        1,
        1
      ],
      "Traceback (most recent call last):\n  File \"/home/fd15hava/.cache/pypoetry/virtualenvs/non-package-mode-zjkKA0Ca-py3.11/lib/python3.11/site-packages/tenacity/__init__.py\", line 382, in __call__\n    result = fn(*args, **kwargs)\n             ^^^^^^^^^^^^^^^^^^^\n  File \"/work/home/fd15hava/tinypaper-mpt/src/agent.py\", line 26, in play\n    answer = self._prompt(self._make_prompt(scenario))\n             ^^^^^^^^^^^^^^^^^^^^^^^^^^^^^^^^^^^^^^^^^\n  File \"/work/home/fd15hava/tinypaper-mpt/src/agent.py\", line 40, in _prompt\n    raise UnexpectedAnswerException(f\"expected 1 or 2, got {result}\")\nutil.UnexpectedAnswerException: expected 1 or 2, got \n\n\nThe above exception was the direct cause of the following exception:\n\nTraceback (most recent call last):\n  File \"/work/home/fd15hava/tinypaper-mpt/scripts/experiments/run.py\", line 16, in _run_session\n    result = agent.play(session)\n             ^^^^^^^^^^^^^^^^^^^\n  File \"/home/fd15hava/.cache/pypoetry/virtualenvs/non-package-mode-zjkKA0Ca-py3.11/lib/python3.11/site-packages/tenacity/__init__.py\", line 289, in wrapped_f\n    return self(f, *args, **kw)\n           ^^^^^^^^^^^^^^^^^^^^\n  File \"/home/fd15hava/.cache/pypoetry/virtualenvs/non-package-mode-zjkKA0Ca-py3.11/lib/python3.11/site-packages/tenacity/__init__.py\", line 379, in __call__\n    do = self.iter(retry_state=retry_state)\n         ^^^^^^^^^^^^^^^^^^^^^^^^^^^^^^^^^^\n  File \"/home/fd15hava/.cache/pypoetry/virtualenvs/non-package-mode-zjkKA0Ca-py3.11/lib/python3.11/site-packages/tenacity/__init__.py\", line 326, in iter\n    raise retry_exc from fut.exception()\ntenacity.RetryError: RetryError[<Future at 0x14b1f7c27190 state=finished raised UnexpectedAnswerException>]\n",
      "Traceback (most recent call last):\n  File \"/home/fd15hava/.cache/pypoetry/virtualenvs/non-package-mode-zjkKA0Ca-py3.11/lib/python3.11/site-packages/tenacity/__init__.py\", line 382, in __call__\n    result = fn(*args, **kwargs)\n             ^^^^^^^^^^^^^^^^^^^\n  File \"/work/home/fd15hava/tinypaper-mpt/src/agent.py\", line 26, in play\n    answer = self._prompt(self._make_prompt(scenario))\n             ^^^^^^^^^^^^^^^^^^^^^^^^^^^^^^^^^^^^^^^^^\n  File \"/work/home/fd15hava/tinypaper-mpt/src/agent.py\", line 40, in _prompt\n    raise UnexpectedAnswerException(f\"expected 1 or 2, got {result}\")\nutil.UnexpectedAnswerException: expected 1 or 2, got \n\n\nThe above exception was the direct cause of the following exception:\n\nTraceback (most recent call last):\n  File \"/work/home/fd15hava/tinypaper-mpt/scripts/experiments/run.py\", line 16, in _run_session\n    result = agent.play(session)\n             ^^^^^^^^^^^^^^^^^^^\n  File \"/home/fd15hava/.cache/pypoetry/virtualenvs/non-package-mode-zjkKA0Ca-py3.11/lib/python3.11/site-packages/tenacity/__init__.py\", line 289, in wrapped_f\n    return self(f, *args, **kw)\n           ^^^^^^^^^^^^^^^^^^^^\n  File \"/home/fd15hava/.cache/pypoetry/virtualenvs/non-package-mode-zjkKA0Ca-py3.11/lib/python3.11/site-packages/tenacity/__init__.py\", line 379, in __call__\n    do = self.iter(retry_state=retry_state)\n         ^^^^^^^^^^^^^^^^^^^^^^^^^^^^^^^^^^\n  File \"/home/fd15hava/.cache/pypoetry/virtualenvs/non-package-mode-zjkKA0Ca-py3.11/lib/python3.11/site-packages/tenacity/__init__.py\", line 326, in iter\n    raise retry_exc from fut.exception()\ntenacity.RetryError: RetryError[<Future at 0x14b1f7c21850 state=finished raised UnexpectedAnswerException>]\n",
      "Traceback (most recent call last):\n  File \"/home/fd15hava/.cache/pypoetry/virtualenvs/non-package-mode-zjkKA0Ca-py3.11/lib/python3.11/site-packages/tenacity/__init__.py\", line 382, in __call__\n    result = fn(*args, **kwargs)\n             ^^^^^^^^^^^^^^^^^^^\n  File \"/work/home/fd15hava/tinypaper-mpt/src/agent.py\", line 26, in play\n    answer = self._prompt(self._make_prompt(scenario))\n             ^^^^^^^^^^^^^^^^^^^^^^^^^^^^^^^^^^^^^^^^^\n  File \"/work/home/fd15hava/tinypaper-mpt/src/agent.py\", line 40, in _prompt\n    raise UnexpectedAnswerException(f\"expected 1 or 2, got {result}\")\nutil.UnexpectedAnswerException: expected 1 or 2, got \n\n\nThe above exception was the direct cause of the following exception:\n\nTraceback (most recent call last):\n  File \"/work/home/fd15hava/tinypaper-mpt/scripts/experiments/run.py\", line 16, in _run_session\n    result = agent.play(session)\n             ^^^^^^^^^^^^^^^^^^^\n  File \"/home/fd15hava/.cache/pypoetry/virtualenvs/non-package-mode-zjkKA0Ca-py3.11/lib/python3.11/site-packages/tenacity/__init__.py\", line 289, in wrapped_f\n    return self(f, *args, **kw)\n           ^^^^^^^^^^^^^^^^^^^^\n  File \"/home/fd15hava/.cache/pypoetry/virtualenvs/non-package-mode-zjkKA0Ca-py3.11/lib/python3.11/site-packages/tenacity/__init__.py\", line 379, in __call__\n    do = self.iter(retry_state=retry_state)\n         ^^^^^^^^^^^^^^^^^^^^^^^^^^^^^^^^^^\n  File \"/home/fd15hava/.cache/pypoetry/virtualenvs/non-package-mode-zjkKA0Ca-py3.11/lib/python3.11/site-packages/tenacity/__init__.py\", line 326, in iter\n    raise retry_exc from fut.exception()\ntenacity.RetryError: RetryError[<Future at 0x14b1f7bbfb50 state=finished raised UnexpectedAnswerException>]\n",
      "Traceback (most recent call last):\n  File \"/home/fd15hava/.cache/pypoetry/virtualenvs/non-package-mode-zjkKA0Ca-py3.11/lib/python3.11/site-packages/tenacity/__init__.py\", line 382, in __call__\n    result = fn(*args, **kwargs)\n             ^^^^^^^^^^^^^^^^^^^\n  File \"/work/home/fd15hava/tinypaper-mpt/src/agent.py\", line 26, in play\n    answer = self._prompt(self._make_prompt(scenario))\n             ^^^^^^^^^^^^^^^^^^^^^^^^^^^^^^^^^^^^^^^^^\n  File \"/work/home/fd15hava/tinypaper-mpt/src/agent.py\", line 40, in _prompt\n    raise UnexpectedAnswerException(f\"expected 1 or 2, got {result}\")\nutil.UnexpectedAnswerException: expected 1 or 2, got \n\n\nThe above exception was the direct cause of the following exception:\n\nTraceback (most recent call last):\n  File \"/work/home/fd15hava/tinypaper-mpt/scripts/experiments/run.py\", line 16, in _run_session\n    result = agent.play(session)\n             ^^^^^^^^^^^^^^^^^^^\n  File \"/home/fd15hava/.cache/pypoetry/virtualenvs/non-package-mode-zjkKA0Ca-py3.11/lib/python3.11/site-packages/tenacity/__init__.py\", line 289, in wrapped_f\n    return self(f, *args, **kw)\n           ^^^^^^^^^^^^^^^^^^^^\n  File \"/home/fd15hava/.cache/pypoetry/virtualenvs/non-package-mode-zjkKA0Ca-py3.11/lib/python3.11/site-packages/tenacity/__init__.py\", line 379, in __call__\n    do = self.iter(retry_state=retry_state)\n         ^^^^^^^^^^^^^^^^^^^^^^^^^^^^^^^^^^\n  File \"/home/fd15hava/.cache/pypoetry/virtualenvs/non-package-mode-zjkKA0Ca-py3.11/lib/python3.11/site-packages/tenacity/__init__.py\", line 326, in iter\n    raise retry_exc from fut.exception()\ntenacity.RetryError: RetryError[<Future at 0x14b1f77e5d90 state=finished raised UnexpectedAnswerException>]\n",
      [
        1,
        1,
        2,
        1,
        2,
        2,
        2,
        1,
        1,
        1,
        2,
        2,
        2
      ],
      "Traceback (most recent call last):\n  File \"/home/fd15hava/.cache/pypoetry/virtualenvs/non-package-mode-zjkKA0Ca-py3.11/lib/python3.11/site-packages/tenacity/__init__.py\", line 382, in __call__\n    result = fn(*args, **kwargs)\n             ^^^^^^^^^^^^^^^^^^^\n  File \"/work/home/fd15hava/tinypaper-mpt/src/agent.py\", line 26, in play\n    answer = self._prompt(self._make_prompt(scenario))\n             ^^^^^^^^^^^^^^^^^^^^^^^^^^^^^^^^^^^^^^^^^\n  File \"/work/home/fd15hava/tinypaper-mpt/src/agent.py\", line 40, in _prompt\n    raise UnexpectedAnswerException(f\"expected 1 or 2, got {result}\")\nutil.UnexpectedAnswerException: expected 1 or 2, got \n\n\nThe above exception was the direct cause of the following exception:\n\nTraceback (most recent call last):\n  File \"/work/home/fd15hava/tinypaper-mpt/scripts/experiments/run.py\", line 16, in _run_session\n    result = agent.play(session)\n             ^^^^^^^^^^^^^^^^^^^\n  File \"/home/fd15hava/.cache/pypoetry/virtualenvs/non-package-mode-zjkKA0Ca-py3.11/lib/python3.11/site-packages/tenacity/__init__.py\", line 289, in wrapped_f\n    return self(f, *args, **kw)\n           ^^^^^^^^^^^^^^^^^^^^\n  File \"/home/fd15hava/.cache/pypoetry/virtualenvs/non-package-mode-zjkKA0Ca-py3.11/lib/python3.11/site-packages/tenacity/__init__.py\", line 379, in __call__\n    do = self.iter(retry_state=retry_state)\n         ^^^^^^^^^^^^^^^^^^^^^^^^^^^^^^^^^^\n  File \"/home/fd15hava/.cache/pypoetry/virtualenvs/non-package-mode-zjkKA0Ca-py3.11/lib/python3.11/site-packages/tenacity/__init__.py\", line 326, in iter\n    raise retry_exc from fut.exception()\ntenacity.RetryError: RetryError[<Future at 0x14b1f7bee750 state=finished raised UnexpectedAnswerException>]\n",
      "Traceback (most recent call last):\n  File \"/home/fd15hava/.cache/pypoetry/virtualenvs/non-package-mode-zjkKA0Ca-py3.11/lib/python3.11/site-packages/tenacity/__init__.py\", line 382, in __call__\n    result = fn(*args, **kwargs)\n             ^^^^^^^^^^^^^^^^^^^\n  File \"/work/home/fd15hava/tinypaper-mpt/src/agent.py\", line 26, in play\n    answer = self._prompt(self._make_prompt(scenario))\n             ^^^^^^^^^^^^^^^^^^^^^^^^^^^^^^^^^^^^^^^^^\n  File \"/work/home/fd15hava/tinypaper-mpt/src/agent.py\", line 40, in _prompt\n    raise UnexpectedAnswerException(f\"expected 1 or 2, got {result}\")\nutil.UnexpectedAnswerException: expected 1 or 2, got \n\n\nThe above exception was the direct cause of the following exception:\n\nTraceback (most recent call last):\n  File \"/work/home/fd15hava/tinypaper-mpt/scripts/experiments/run.py\", line 16, in _run_session\n    result = agent.play(session)\n             ^^^^^^^^^^^^^^^^^^^\n  File \"/home/fd15hava/.cache/pypoetry/virtualenvs/non-package-mode-zjkKA0Ca-py3.11/lib/python3.11/site-packages/tenacity/__init__.py\", line 289, in wrapped_f\n    return self(f, *args, **kw)\n           ^^^^^^^^^^^^^^^^^^^^\n  File \"/home/fd15hava/.cache/pypoetry/virtualenvs/non-package-mode-zjkKA0Ca-py3.11/lib/python3.11/site-packages/tenacity/__init__.py\", line 379, in __call__\n    do = self.iter(retry_state=retry_state)\n         ^^^^^^^^^^^^^^^^^^^^^^^^^^^^^^^^^^\n  File \"/home/fd15hava/.cache/pypoetry/virtualenvs/non-package-mode-zjkKA0Ca-py3.11/lib/python3.11/site-packages/tenacity/__init__.py\", line 326, in iter\n    raise retry_exc from fut.exception()\ntenacity.RetryError: RetryError[<Future at 0x14b5257d3150 state=finished raised UnexpectedAnswerException>]\n",
      "Traceback (most recent call last):\n  File \"/home/fd15hava/.cache/pypoetry/virtualenvs/non-package-mode-zjkKA0Ca-py3.11/lib/python3.11/site-packages/tenacity/__init__.py\", line 382, in __call__\n    result = fn(*args, **kwargs)\n             ^^^^^^^^^^^^^^^^^^^\n  File \"/work/home/fd15hava/tinypaper-mpt/src/agent.py\", line 26, in play\n    answer = self._prompt(self._make_prompt(scenario))\n             ^^^^^^^^^^^^^^^^^^^^^^^^^^^^^^^^^^^^^^^^^\n  File \"/work/home/fd15hava/tinypaper-mpt/src/agent.py\", line 40, in _prompt\n    raise UnexpectedAnswerException(f\"expected 1 or 2, got {result}\")\nutil.UnexpectedAnswerException: expected 1 or 2, got \n\n\nThe above exception was the direct cause of the following exception:\n\nTraceback (most recent call last):\n  File \"/work/home/fd15hava/tinypaper-mpt/scripts/experiments/run.py\", line 16, in _run_session\n    result = agent.play(session)\n             ^^^^^^^^^^^^^^^^^^^\n  File \"/home/fd15hava/.cache/pypoetry/virtualenvs/non-package-mode-zjkKA0Ca-py3.11/lib/python3.11/site-packages/tenacity/__init__.py\", line 289, in wrapped_f\n    return self(f, *args, **kw)\n           ^^^^^^^^^^^^^^^^^^^^\n  File \"/home/fd15hava/.cache/pypoetry/virtualenvs/non-package-mode-zjkKA0Ca-py3.11/lib/python3.11/site-packages/tenacity/__init__.py\", line 379, in __call__\n    do = self.iter(retry_state=retry_state)\n         ^^^^^^^^^^^^^^^^^^^^^^^^^^^^^^^^^^\n  File \"/home/fd15hava/.cache/pypoetry/virtualenvs/non-package-mode-zjkKA0Ca-py3.11/lib/python3.11/site-packages/tenacity/__init__.py\", line 326, in iter\n    raise retry_exc from fut.exception()\ntenacity.RetryError: RetryError[<Future at 0x14b1f7bad750 state=finished raised UnexpectedAnswerException>]\n",
      "Traceback (most recent call last):\n  File \"/home/fd15hava/.cache/pypoetry/virtualenvs/non-package-mode-zjkKA0Ca-py3.11/lib/python3.11/site-packages/tenacity/__init__.py\", line 382, in __call__\n    result = fn(*args, **kwargs)\n             ^^^^^^^^^^^^^^^^^^^\n  File \"/work/home/fd15hava/tinypaper-mpt/src/agent.py\", line 26, in play\n    answer = self._prompt(self._make_prompt(scenario))\n             ^^^^^^^^^^^^^^^^^^^^^^^^^^^^^^^^^^^^^^^^^\n  File \"/work/home/fd15hava/tinypaper-mpt/src/agent.py\", line 40, in _prompt\n    raise UnexpectedAnswerException(f\"expected 1 or 2, got {result}\")\nutil.UnexpectedAnswerException: expected 1 or 2, got \n\n\nThe above exception was the direct cause of the following exception:\n\nTraceback (most recent call last):\n  File \"/work/home/fd15hava/tinypaper-mpt/scripts/experiments/run.py\", line 16, in _run_session\n    result = agent.play(session)\n             ^^^^^^^^^^^^^^^^^^^\n  File \"/home/fd15hava/.cache/pypoetry/virtualenvs/non-package-mode-zjkKA0Ca-py3.11/lib/python3.11/site-packages/tenacity/__init__.py\", line 289, in wrapped_f\n    return self(f, *args, **kw)\n           ^^^^^^^^^^^^^^^^^^^^\n  File \"/home/fd15hava/.cache/pypoetry/virtualenvs/non-package-mode-zjkKA0Ca-py3.11/lib/python3.11/site-packages/tenacity/__init__.py\", line 379, in __call__\n    do = self.iter(retry_state=retry_state)\n         ^^^^^^^^^^^^^^^^^^^^^^^^^^^^^^^^^^\n  File \"/home/fd15hava/.cache/pypoetry/virtualenvs/non-package-mode-zjkKA0Ca-py3.11/lib/python3.11/site-packages/tenacity/__init__.py\", line 326, in iter\n    raise retry_exc from fut.exception()\ntenacity.RetryError: RetryError[<Future at 0x14b1f77969d0 state=finished raised UnexpectedAnswerException>]\n",
      "Traceback (most recent call last):\n  File \"/home/fd15hava/.cache/pypoetry/virtualenvs/non-package-mode-zjkKA0Ca-py3.11/lib/python3.11/site-packages/tenacity/__init__.py\", line 382, in __call__\n    result = fn(*args, **kwargs)\n             ^^^^^^^^^^^^^^^^^^^\n  File \"/work/home/fd15hava/tinypaper-mpt/src/agent.py\", line 26, in play\n    answer = self._prompt(self._make_prompt(scenario))\n             ^^^^^^^^^^^^^^^^^^^^^^^^^^^^^^^^^^^^^^^^^\n  File \"/work/home/fd15hava/tinypaper-mpt/src/agent.py\", line 40, in _prompt\n    raise UnexpectedAnswerException(f\"expected 1 or 2, got {result}\")\nutil.UnexpectedAnswerException: expected 1 or 2, got \n\n\nThe above exception was the direct cause of the following exception:\n\nTraceback (most recent call last):\n  File \"/work/home/fd15hava/tinypaper-mpt/scripts/experiments/run.py\", line 16, in _run_session\n    result = agent.play(session)\n             ^^^^^^^^^^^^^^^^^^^\n  File \"/home/fd15hava/.cache/pypoetry/virtualenvs/non-package-mode-zjkKA0Ca-py3.11/lib/python3.11/site-packages/tenacity/__init__.py\", line 289, in wrapped_f\n    return self(f, *args, **kw)\n           ^^^^^^^^^^^^^^^^^^^^\n  File \"/home/fd15hava/.cache/pypoetry/virtualenvs/non-package-mode-zjkKA0Ca-py3.11/lib/python3.11/site-packages/tenacity/__init__.py\", line 379, in __call__\n    do = self.iter(retry_state=retry_state)\n         ^^^^^^^^^^^^^^^^^^^^^^^^^^^^^^^^^^\n  File \"/home/fd15hava/.cache/pypoetry/virtualenvs/non-package-mode-zjkKA0Ca-py3.11/lib/python3.11/site-packages/tenacity/__init__.py\", line 326, in iter\n    raise retry_exc from fut.exception()\ntenacity.RetryError: RetryError[<Future at 0x14b1f7829b50 state=finished raised UnexpectedAnswerException>]\n",
      "Traceback (most recent call last):\n  File \"/home/fd15hava/.cache/pypoetry/virtualenvs/non-package-mode-zjkKA0Ca-py3.11/lib/python3.11/site-packages/tenacity/__init__.py\", line 382, in __call__\n    result = fn(*args, **kwargs)\n             ^^^^^^^^^^^^^^^^^^^\n  File \"/work/home/fd15hava/tinypaper-mpt/src/agent.py\", line 26, in play\n    answer = self._prompt(self._make_prompt(scenario))\n             ^^^^^^^^^^^^^^^^^^^^^^^^^^^^^^^^^^^^^^^^^\n  File \"/work/home/fd15hava/tinypaper-mpt/src/agent.py\", line 40, in _prompt\n    raise UnexpectedAnswerException(f\"expected 1 or 2, got {result}\")\nutil.UnexpectedAnswerException: expected 1 or 2, got \n\n\nThe above exception was the direct cause of the following exception:\n\nTraceback (most recent call last):\n  File \"/work/home/fd15hava/tinypaper-mpt/scripts/experiments/run.py\", line 16, in _run_session\n    result = agent.play(session)\n             ^^^^^^^^^^^^^^^^^^^\n  File \"/home/fd15hava/.cache/pypoetry/virtualenvs/non-package-mode-zjkKA0Ca-py3.11/lib/python3.11/site-packages/tenacity/__init__.py\", line 289, in wrapped_f\n    return self(f, *args, **kw)\n           ^^^^^^^^^^^^^^^^^^^^\n  File \"/home/fd15hava/.cache/pypoetry/virtualenvs/non-package-mode-zjkKA0Ca-py3.11/lib/python3.11/site-packages/tenacity/__init__.py\", line 379, in __call__\n    do = self.iter(retry_state=retry_state)\n         ^^^^^^^^^^^^^^^^^^^^^^^^^^^^^^^^^^\n  File \"/home/fd15hava/.cache/pypoetry/virtualenvs/non-package-mode-zjkKA0Ca-py3.11/lib/python3.11/site-packages/tenacity/__init__.py\", line 326, in iter\n    raise retry_exc from fut.exception()\ntenacity.RetryError: RetryError[<Future at 0x14b1f7810250 state=finished raised UnexpectedAnswerException>]\n",
      "Traceback (most recent call last):\n  File \"/home/fd15hava/.cache/pypoetry/virtualenvs/non-package-mode-zjkKA0Ca-py3.11/lib/python3.11/site-packages/tenacity/__init__.py\", line 382, in __call__\n    result = fn(*args, **kwargs)\n             ^^^^^^^^^^^^^^^^^^^\n  File \"/work/home/fd15hava/tinypaper-mpt/src/agent.py\", line 26, in play\n    answer = self._prompt(self._make_prompt(scenario))\n             ^^^^^^^^^^^^^^^^^^^^^^^^^^^^^^^^^^^^^^^^^\n  File \"/work/home/fd15hava/tinypaper-mpt/src/agent.py\", line 40, in _prompt\n    raise UnexpectedAnswerException(f\"expected 1 or 2, got {result}\")\nutil.UnexpectedAnswerException: expected 1 or 2, got \n\n\nThe above exception was the direct cause of the following exception:\n\nTraceback (most recent call last):\n  File \"/work/home/fd15hava/tinypaper-mpt/scripts/experiments/run.py\", line 16, in _run_session\n    result = agent.play(session)\n             ^^^^^^^^^^^^^^^^^^^\n  File \"/home/fd15hava/.cache/pypoetry/virtualenvs/non-package-mode-zjkKA0Ca-py3.11/lib/python3.11/site-packages/tenacity/__init__.py\", line 289, in wrapped_f\n    return self(f, *args, **kw)\n           ^^^^^^^^^^^^^^^^^^^^\n  File \"/home/fd15hava/.cache/pypoetry/virtualenvs/non-package-mode-zjkKA0Ca-py3.11/lib/python3.11/site-packages/tenacity/__init__.py\", line 379, in __call__\n    do = self.iter(retry_state=retry_state)\n         ^^^^^^^^^^^^^^^^^^^^^^^^^^^^^^^^^^\n  File \"/home/fd15hava/.cache/pypoetry/virtualenvs/non-package-mode-zjkKA0Ca-py3.11/lib/python3.11/site-packages/tenacity/__init__.py\", line 326, in iter\n    raise retry_exc from fut.exception()\ntenacity.RetryError: RetryError[<Future at 0x14b1f7bfb310 state=finished raised UnexpectedAnswerException>]\n",
      "Traceback (most recent call last):\n  File \"/home/fd15hava/.cache/pypoetry/virtualenvs/non-package-mode-zjkKA0Ca-py3.11/lib/python3.11/site-packages/tenacity/__init__.py\", line 382, in __call__\n    result = fn(*args, **kwargs)\n             ^^^^^^^^^^^^^^^^^^^\n  File \"/work/home/fd15hava/tinypaper-mpt/src/agent.py\", line 26, in play\n    answer = self._prompt(self._make_prompt(scenario))\n             ^^^^^^^^^^^^^^^^^^^^^^^^^^^^^^^^^^^^^^^^^\n  File \"/work/home/fd15hava/tinypaper-mpt/src/agent.py\", line 40, in _prompt\n    raise UnexpectedAnswerException(f\"expected 1 or 2, got {result}\")\nutil.UnexpectedAnswerException: expected 1 or 2, got \n\n\nThe above exception was the direct cause of the following exception:\n\nTraceback (most recent call last):\n  File \"/work/home/fd15hava/tinypaper-mpt/scripts/experiments/run.py\", line 16, in _run_session\n    result = agent.play(session)\n             ^^^^^^^^^^^^^^^^^^^\n  File \"/home/fd15hava/.cache/pypoetry/virtualenvs/non-package-mode-zjkKA0Ca-py3.11/lib/python3.11/site-packages/tenacity/__init__.py\", line 289, in wrapped_f\n    return self(f, *args, **kw)\n           ^^^^^^^^^^^^^^^^^^^^\n  File \"/home/fd15hava/.cache/pypoetry/virtualenvs/non-package-mode-zjkKA0Ca-py3.11/lib/python3.11/site-packages/tenacity/__init__.py\", line 379, in __call__\n    do = self.iter(retry_state=retry_state)\n         ^^^^^^^^^^^^^^^^^^^^^^^^^^^^^^^^^^\n  File \"/home/fd15hava/.cache/pypoetry/virtualenvs/non-package-mode-zjkKA0Ca-py3.11/lib/python3.11/site-packages/tenacity/__init__.py\", line 326, in iter\n    raise retry_exc from fut.exception()\ntenacity.RetryError: RetryError[<Future at 0x14b1f777bf90 state=finished raised UnexpectedAnswerException>]\n",
      "Traceback (most recent call last):\n  File \"/home/fd15hava/.cache/pypoetry/virtualenvs/non-package-mode-zjkKA0Ca-py3.11/lib/python3.11/site-packages/tenacity/__init__.py\", line 382, in __call__\n    result = fn(*args, **kwargs)\n             ^^^^^^^^^^^^^^^^^^^\n  File \"/work/home/fd15hava/tinypaper-mpt/src/agent.py\", line 26, in play\n    answer = self._prompt(self._make_prompt(scenario))\n             ^^^^^^^^^^^^^^^^^^^^^^^^^^^^^^^^^^^^^^^^^\n  File \"/work/home/fd15hava/tinypaper-mpt/src/agent.py\", line 40, in _prompt\n    raise UnexpectedAnswerException(f\"expected 1 or 2, got {result}\")\nutil.UnexpectedAnswerException: expected 1 or 2, got \n\n\nThe above exception was the direct cause of the following exception:\n\nTraceback (most recent call last):\n  File \"/work/home/fd15hava/tinypaper-mpt/scripts/experiments/run.py\", line 16, in _run_session\n    result = agent.play(session)\n             ^^^^^^^^^^^^^^^^^^^\n  File \"/home/fd15hava/.cache/pypoetry/virtualenvs/non-package-mode-zjkKA0Ca-py3.11/lib/python3.11/site-packages/tenacity/__init__.py\", line 289, in wrapped_f\n    return self(f, *args, **kw)\n           ^^^^^^^^^^^^^^^^^^^^\n  File \"/home/fd15hava/.cache/pypoetry/virtualenvs/non-package-mode-zjkKA0Ca-py3.11/lib/python3.11/site-packages/tenacity/__init__.py\", line 379, in __call__\n    do = self.iter(retry_state=retry_state)\n         ^^^^^^^^^^^^^^^^^^^^^^^^^^^^^^^^^^\n  File \"/home/fd15hava/.cache/pypoetry/virtualenvs/non-package-mode-zjkKA0Ca-py3.11/lib/python3.11/site-packages/tenacity/__init__.py\", line 326, in iter\n    raise retry_exc from fut.exception()\ntenacity.RetryError: RetryError[<Future at 0x14b1f782bbd0 state=finished raised UnexpectedAnswerException>]\n",
      "Traceback (most recent call last):\n  File \"/home/fd15hava/.cache/pypoetry/virtualenvs/non-package-mode-zjkKA0Ca-py3.11/lib/python3.11/site-packages/tenacity/__init__.py\", line 382, in __call__\n    result = fn(*args, **kwargs)\n             ^^^^^^^^^^^^^^^^^^^\n  File \"/work/home/fd15hava/tinypaper-mpt/src/agent.py\", line 26, in play\n    answer = self._prompt(self._make_prompt(scenario))\n             ^^^^^^^^^^^^^^^^^^^^^^^^^^^^^^^^^^^^^^^^^\n  File \"/work/home/fd15hava/tinypaper-mpt/src/agent.py\", line 40, in _prompt\n    raise UnexpectedAnswerException(f\"expected 1 or 2, got {result}\")\nutil.UnexpectedAnswerException: expected 1 or 2, got \n\n\nThe above exception was the direct cause of the following exception:\n\nTraceback (most recent call last):\n  File \"/work/home/fd15hava/tinypaper-mpt/scripts/experiments/run.py\", line 16, in _run_session\n    result = agent.play(session)\n             ^^^^^^^^^^^^^^^^^^^\n  File \"/home/fd15hava/.cache/pypoetry/virtualenvs/non-package-mode-zjkKA0Ca-py3.11/lib/python3.11/site-packages/tenacity/__init__.py\", line 289, in wrapped_f\n    return self(f, *args, **kw)\n           ^^^^^^^^^^^^^^^^^^^^\n  File \"/home/fd15hava/.cache/pypoetry/virtualenvs/non-package-mode-zjkKA0Ca-py3.11/lib/python3.11/site-packages/tenacity/__init__.py\", line 379, in __call__\n    do = self.iter(retry_state=retry_state)\n         ^^^^^^^^^^^^^^^^^^^^^^^^^^^^^^^^^^\n  File \"/home/fd15hava/.cache/pypoetry/virtualenvs/non-package-mode-zjkKA0Ca-py3.11/lib/python3.11/site-packages/tenacity/__init__.py\", line 326, in iter\n    raise retry_exc from fut.exception()\ntenacity.RetryError: RetryError[<Future at 0x14b1f77de3d0 state=finished raised UnexpectedAnswerException>]\n",
      "Traceback (most recent call last):\n  File \"/home/fd15hava/.cache/pypoetry/virtualenvs/non-package-mode-zjkKA0Ca-py3.11/lib/python3.11/site-packages/tenacity/__init__.py\", line 382, in __call__\n    result = fn(*args, **kwargs)\n             ^^^^^^^^^^^^^^^^^^^\n  File \"/work/home/fd15hava/tinypaper-mpt/src/agent.py\", line 26, in play\n    answer = self._prompt(self._make_prompt(scenario))\n             ^^^^^^^^^^^^^^^^^^^^^^^^^^^^^^^^^^^^^^^^^\n  File \"/work/home/fd15hava/tinypaper-mpt/src/agent.py\", line 40, in _prompt\n    raise UnexpectedAnswerException(f\"expected 1 or 2, got {result}\")\nutil.UnexpectedAnswerException: expected 1 or 2, got \n\n\nThe above exception was the direct cause of the following exception:\n\nTraceback (most recent call last):\n  File \"/work/home/fd15hava/tinypaper-mpt/scripts/experiments/run.py\", line 16, in _run_session\n    result = agent.play(session)\n             ^^^^^^^^^^^^^^^^^^^\n  File \"/home/fd15hava/.cache/pypoetry/virtualenvs/non-package-mode-zjkKA0Ca-py3.11/lib/python3.11/site-packages/tenacity/__init__.py\", line 289, in wrapped_f\n    return self(f, *args, **kw)\n           ^^^^^^^^^^^^^^^^^^^^\n  File \"/home/fd15hava/.cache/pypoetry/virtualenvs/non-package-mode-zjkKA0Ca-py3.11/lib/python3.11/site-packages/tenacity/__init__.py\", line 379, in __call__\n    do = self.iter(retry_state=retry_state)\n         ^^^^^^^^^^^^^^^^^^^^^^^^^^^^^^^^^^\n  File \"/home/fd15hava/.cache/pypoetry/virtualenvs/non-package-mode-zjkKA0Ca-py3.11/lib/python3.11/site-packages/tenacity/__init__.py\", line 326, in iter\n    raise retry_exc from fut.exception()\ntenacity.RetryError: RetryError[<Future at 0x14b1f77ddc90 state=finished raised UnexpectedAnswerException>]\n",
      "Traceback (most recent call last):\n  File \"/home/fd15hava/.cache/pypoetry/virtualenvs/non-package-mode-zjkKA0Ca-py3.11/lib/python3.11/site-packages/tenacity/__init__.py\", line 382, in __call__\n    result = fn(*args, **kwargs)\n             ^^^^^^^^^^^^^^^^^^^\n  File \"/work/home/fd15hava/tinypaper-mpt/src/agent.py\", line 26, in play\n    answer = self._prompt(self._make_prompt(scenario))\n             ^^^^^^^^^^^^^^^^^^^^^^^^^^^^^^^^^^^^^^^^^\n  File \"/work/home/fd15hava/tinypaper-mpt/src/agent.py\", line 40, in _prompt\n    raise UnexpectedAnswerException(f\"expected 1 or 2, got {result}\")\nutil.UnexpectedAnswerException: expected 1 or 2, got \n\n\nThe above exception was the direct cause of the following exception:\n\nTraceback (most recent call last):\n  File \"/work/home/fd15hava/tinypaper-mpt/scripts/experiments/run.py\", line 16, in _run_session\n    result = agent.play(session)\n             ^^^^^^^^^^^^^^^^^^^\n  File \"/home/fd15hava/.cache/pypoetry/virtualenvs/non-package-mode-zjkKA0Ca-py3.11/lib/python3.11/site-packages/tenacity/__init__.py\", line 289, in wrapped_f\n    return self(f, *args, **kw)\n           ^^^^^^^^^^^^^^^^^^^^\n  File \"/home/fd15hava/.cache/pypoetry/virtualenvs/non-package-mode-zjkKA0Ca-py3.11/lib/python3.11/site-packages/tenacity/__init__.py\", line 379, in __call__\n    do = self.iter(retry_state=retry_state)\n         ^^^^^^^^^^^^^^^^^^^^^^^^^^^^^^^^^^\n  File \"/home/fd15hava/.cache/pypoetry/virtualenvs/non-package-mode-zjkKA0Ca-py3.11/lib/python3.11/site-packages/tenacity/__init__.py\", line 326, in iter\n    raise retry_exc from fut.exception()\ntenacity.RetryError: RetryError[<Future at 0x14b1f7795d10 state=finished raised UnexpectedAnswerException>]\n"
    ],
    "api_usage": [
      {
        "cost": 0.0,
        "name": "mpt-7b-chat",
        "num_input_tokens": -1,
        "num_output_tokens": -1,
        "py/object": "api_usage.APIUsage"
      },
      {
        "cost": 0.0,
        "name": "mpt-7b-chat",
        "num_input_tokens": -1,
        "num_output_tokens": -1,
        "py/object": "api_usage.APIUsage"
      },
      {
        "cost": 0.0,
        "name": "mpt-7b-chat",
        "num_input_tokens": -1,
        "num_output_tokens": -1,
        "py/object": "api_usage.APIUsage"
      },
      {
        "cost": 0.0,
        "name": "mpt-7b-chat",
        "num_input_tokens": -1,
        "num_output_tokens": -1,
        "py/object": "api_usage.APIUsage"
      },
      {
        "cost": 0.0,
        "name": "mpt-7b-chat",
        "num_input_tokens": -1,
        "num_output_tokens": -1,
        "py/object": "api_usage.APIUsage"
      },
      {
        "cost": 0.0,
        "name": "mpt-7b-chat",
        "num_input_tokens": -1,
        "num_output_tokens": -1,
        "py/object": "api_usage.APIUsage"
      },
      {
        "cost": 0.0,
        "name": "mpt-7b-chat",
        "num_input_tokens": -1,
        "num_output_tokens": -1,
        "py/object": "api_usage.APIUsage"
      },
      {
        "cost": 0.0,
        "name": "mpt-7b-chat",
        "num_input_tokens": -1,
        "num_output_tokens": -1,
        "py/object": "api_usage.APIUsage"
      },
      {
        "cost": 0.0,
        "name": "mpt-7b-chat",
        "num_input_tokens": -1,
        "num_output_tokens": -1,
        "py/object": "api_usage.APIUsage"
      },
      {
        "cost": 0.0,
        "name": "mpt-7b-chat",
        "num_input_tokens": -1,
        "num_output_tokens": -1,
        "py/object": "api_usage.APIUsage"
      },
      {
        "cost": 0.0,
        "name": "mpt-7b-chat",
        "num_input_tokens": -1,
        "num_output_tokens": -1,
        "py/object": "api_usage.APIUsage"
      },
      {
        "cost": 0.0,
        "name": "mpt-7b-chat",
        "num_input_tokens": -1,
        "num_output_tokens": -1,
        "py/object": "api_usage.APIUsage"
      },
      {
        "cost": 0.0,
        "name": "mpt-7b-chat",
        "num_input_tokens": -1,
        "num_output_tokens": -1,
        "py/object": "api_usage.APIUsage"
      },
      {
        "cost": 0.0,
        "name": "mpt-7b-chat",
        "num_input_tokens": -1,
        "num_output_tokens": -1,
        "py/object": "api_usage.APIUsage"
      },
      {
        "cost": 0.0,
        "name": "mpt-7b-chat",
        "num_input_tokens": -1,
        "num_output_tokens": -1,
        "py/object": "api_usage.APIUsage"
      },
      {
        "cost": 0.0,
        "name": "mpt-7b-chat",
        "num_input_tokens": -1,
        "num_output_tokens": -1,
        "py/object": "api_usage.APIUsage"
      },
      {
        "cost": 0.0,
        "name": "mpt-7b-chat",
        "num_input_tokens": -1,
        "num_output_tokens": -1,
        "py/object": "api_usage.APIUsage"
      },
      {
        "cost": 0.0,
        "name": "mpt-7b-chat",
        "num_input_tokens": -1,
        "num_output_tokens": -1,
        "py/object": "api_usage.APIUsage"
      },
      {
        "cost": 0.0,
        "name": "mpt-7b-chat",
        "num_input_tokens": -1,
        "num_output_tokens": -1,
        "py/object": "api_usage.APIUsage"
      },
      {
        "cost": 0.0,
        "name": "mpt-7b-chat",
        "num_input_tokens": -1,
        "num_output_tokens": -1,
        "py/object": "api_usage.APIUsage"
      },
      {
        "cost": 0.0,
        "name": "mpt-7b-chat",
        "num_input_tokens": -1,
        "num_output_tokens": -1,
        "py/object": "api_usage.APIUsage"
      },
      {
        "cost": 0.0,
        "name": "mpt-7b-chat",
        "num_input_tokens": -1,
        "num_output_tokens": -1,
        "py/object": "api_usage.APIUsage"
      },
      {
        "cost": 0.0,
        "name": "mpt-7b-chat",
        "num_input_tokens": -1,
        "num_output_tokens": -1,
        "py/object": "api_usage.APIUsage"
      },
      {
        "cost": 0.0,
        "name": "mpt-7b-chat",
        "num_input_tokens": -1,
        "num_output_tokens": -1,
        "py/object": "api_usage.APIUsage"
      },
      {
        "cost": 0.0,
        "name": "mpt-7b-chat",
        "num_input_tokens": -1,
        "num_output_tokens": -1,
        "py/object": "api_usage.APIUsage"
      },
      {
        "cost": 0.0,
        "name": "mpt-7b-chat",
        "num_input_tokens": -1,
        "num_output_tokens": -1,
        "py/object": "api_usage.APIUsage"
      },
      {
        "cost": 0.0,
        "name": "mpt-7b-chat",
        "num_input_tokens": -1,
        "num_output_tokens": -1,
        "py/object": "api_usage.APIUsage"
      },
      {
        "cost": 0.0,
        "name": "mpt-7b-chat",
        "num_input_tokens": -1,
        "num_output_tokens": -1,
        "py/object": "api_usage.APIUsage"
      },
      {
        "cost": 0.0,
        "name": "mpt-7b-chat",
        "num_input_tokens": -1,
        "num_output_tokens": -1,
        "py/object": "api_usage.APIUsage"
      },
      {
        "cost": 0.0,
        "name": "mpt-7b-chat",
        "num_input_tokens": -1,
        "num_output_tokens": -1,
        "py/object": "api_usage.APIUsage"
      },
      {
        "cost": 0.0,
        "name": "mpt-7b-chat",
        "num_input_tokens": -1,
        "num_output_tokens": -1,
        "py/object": "api_usage.APIUsage"
      },
      {
        "cost": 0.0,
        "name": "mpt-7b-chat",
        "num_input_tokens": -1,
        "num_output_tokens": -1,
        "py/object": "api_usage.APIUsage"
      },
      {
        "cost": 0.0,
        "name": "mpt-7b-chat",
        "num_input_tokens": -1,
        "num_output_tokens": -1,
        "py/object": "api_usage.APIUsage"
      },
      {
        "cost": 0.0,
        "name": "mpt-7b-chat",
        "num_input_tokens": -1,
        "num_output_tokens": -1,
        "py/object": "api_usage.APIUsage"
      },
      {
        "cost": 0.0,
        "name": "mpt-7b-chat",
        "num_input_tokens": -1,
        "num_output_tokens": -1,
        "py/object": "api_usage.APIUsage"
      },
      {
        "cost": 0.0,
        "name": "mpt-7b-chat",
        "num_input_tokens": -1,
        "num_output_tokens": -1,
        "py/object": "api_usage.APIUsage"
      },
      {
        "cost": 0.0,
        "name": "mpt-7b-chat",
        "num_input_tokens": -1,
        "num_output_tokens": -1,
        "py/object": "api_usage.APIUsage"
      },
      {
        "cost": 0.0,
        "name": "mpt-7b-chat",
        "num_input_tokens": -1,
        "num_output_tokens": -1,
        "py/object": "api_usage.APIUsage"
      },
      {
        "cost": 0.0,
        "name": "mpt-7b-chat",
        "num_input_tokens": -1,
        "num_output_tokens": -1,
        "py/object": "api_usage.APIUsage"
      },
      {
        "cost": 0.0,
        "name": "mpt-7b-chat",
        "num_input_tokens": -1,
        "num_output_tokens": -1,
        "py/object": "api_usage.APIUsage"
      },
      {
        "cost": 0.0,
        "name": "mpt-7b-chat",
        "num_input_tokens": -1,
        "num_output_tokens": -1,
        "py/object": "api_usage.APIUsage"
      },
      {
        "cost": 0.0,
        "name": "mpt-7b-chat",
        "num_input_tokens": -1,
        "num_output_tokens": -1,
        "py/object": "api_usage.APIUsage"
      },
      {
        "cost": 0.0,
        "name": "mpt-7b-chat",
        "num_input_tokens": -1,
        "num_output_tokens": -1,
        "py/object": "api_usage.APIUsage"
      },
      {
        "cost": 0.0,
        "name": "mpt-7b-chat",
        "num_input_tokens": -1,
        "num_output_tokens": -1,
        "py/object": "api_usage.APIUsage"
      },
      {
        "cost": 0.0,
        "name": "mpt-7b-chat",
        "num_input_tokens": -1,
        "num_output_tokens": -1,
        "py/object": "api_usage.APIUsage"
      },
      {
        "cost": 0.0,
        "name": "mpt-7b-chat",
        "num_input_tokens": -1,
        "num_output_tokens": -1,
        "py/object": "api_usage.APIUsage"
      },
      {
        "cost": 0.0,
        "name": "mpt-7b-chat",
        "num_input_tokens": -1,
        "num_output_tokens": -1,
        "py/object": "api_usage.APIUsage"
      },
      {
        "cost": 0.0,
        "name": "mpt-7b-chat",
        "num_input_tokens": -1,
        "num_output_tokens": -1,
        "py/object": "api_usage.APIUsage"
      },
      {
        "cost": 0.0,
        "name": "mpt-7b-chat",
        "num_input_tokens": -1,
        "num_output_tokens": -1,
        "py/object": "api_usage.APIUsage"
      },
      {
        "cost": 0.0,
        "name": "mpt-7b-chat",
        "num_input_tokens": -1,
        "num_output_tokens": -1,
        "py/object": "api_usage.APIUsage"
      }
    ],
    "api_usage_total": {
      "cost": 0.0,
      "name": "mpt-7b-chat",
      "num_input_tokens": -50,
      "num_output_tokens": -50,
      "py/object": "api_usage.APIUsage"
    }
  },
  "start_time": "2024-04-29T17:54:58.167024",
  "status": "COMPLETED",
  "stop_time": "2024-04-29T22:46:42.545920"
}