{
  "artifacts": [],
  "command": "main",
  "experiment": {
    "base_dir": "/work/home/fd15hava/tinypaper-mpt/src",
    "dependencies": [
      "numpy==1.26.4",
      "sacred==0.8.5"
    ],
    "mainfile": "experiment.py",
    "name": "tinypaper",
    "repositories": [
      {
        "commit": "83ebc21b46932da830ceff1fef51511962253d6b",
        "dirty": false,
        "url": "ssh://github/fdamken/tinypaper_code.git"
      },
      {
        "commit": "83ebc21b46932da830ceff1fef51511962253d6b",
        "dirty": false,
        "url": "ssh://github/fdamken/tinypaper_code.git"
      }
    ],
    "sources": [
      [
        "experiment.py",
        "_sources/experiment_7ab7c4f9e536be33bd5f71ad8c083f8f.py"
      ],
      [
        "path_util.py",
        "_sources/path_util_ce5f4012c098f79adf2c1204811dca0a.py"
      ]
    ]
  },
  "heartbeat": "2024-04-30T03:01:40.176078",
  "host": {
    "ENV": {},
    "cpu": "Intel(R) Xeon(R) Platinum 8470Q",
    "hostname": "mpsd0110",
    "os": [
      "Linux",
      "Linux-4.18.0-477.27.1.el8_8.x86_64-x86_64-with-glibc2.28"
    ],
    "python_version": "3.11.9"
  },
  "meta": {
    "command": "main",
    "config_updates": {
      "from_session_id": 200,
      "language": "es",
      "model_name": "falcon-180B-chat",
      "to_session_id": 250
    },
    "named_configs": [],
    "options": {
      "--beat-interval": null,
      "--capture": null,
      "--comment": null,
      "--debug": false,
      "--enforce_clean": false,
      "--file_storage": null,
      "--force": false,
      "--help": false,
      "--id": null,
      "--loglevel": null,
      "--mongo_db": null,
      "--name": null,
      "--pdb": false,
      "--print-config": false,
      "--priority": null,
      "--queue": false,
      "--s3": null,
      "--sql": null,
      "--tiny_db": null,
      "--unobserved": false,
      "COMMAND": null,
      "UPDATE": [
        "from_session_id=200",
        "to_session_id=250",
        "model_name=falcon-180B-chat",
        "language=es"
      ],
      "help": false,
      "with": true
    }
  },
  "resources": [],
  "result": {
    "answers": [
      "Traceback (most recent call last):\n  File \"/home/fd15hava/.cache/pypoetry/virtualenvs/non-package-mode-zjkKA0Ca-py3.11/lib/python3.11/site-packages/tenacity/__init__.py\", line 382, in __call__\n    result = fn(*args, **kwargs)\n             ^^^^^^^^^^^^^^^^^^^\n  File \"/work/home/fd15hava/tinypaper-mpt/src/agent.py\", line 26, in play\n    answer = self._prompt(self._make_prompt(scenario))\n             ^^^^^^^^^^^^^^^^^^^^^^^^^^^^^^^^^^^^^^^^^\n  File \"/work/home/fd15hava/tinypaper-mpt/src/agent.py\", line 40, in _prompt\n    raise UnexpectedAnswerException(f\"expected 1 or 2, got {result}\")\nutil.UnexpectedAnswerException: expected 1 or 2, got  \n\nThe above exception was the direct cause of the following exception:\n\nTraceback (most recent call last):\n  File \"/work/home/fd15hava/tinypaper-mpt/scripts/experiments/run.py\", line 16, in _run_session\n    result = agent.play(session)\n             ^^^^^^^^^^^^^^^^^^^\n  File \"/home/fd15hava/.cache/pypoetry/virtualenvs/non-package-mode-zjkKA0Ca-py3.11/lib/python3.11/site-packages/tenacity/__init__.py\", line 289, in wrapped_f\n    return self(f, *args, **kw)\n           ^^^^^^^^^^^^^^^^^^^^\n  File \"/home/fd15hava/.cache/pypoetry/virtualenvs/non-package-mode-zjkKA0Ca-py3.11/lib/python3.11/site-packages/tenacity/__init__.py\", line 379, in __call__\n    do = self.iter(retry_state=retry_state)\n         ^^^^^^^^^^^^^^^^^^^^^^^^^^^^^^^^^^\n  File \"/home/fd15hava/.cache/pypoetry/virtualenvs/non-package-mode-zjkKA0Ca-py3.11/lib/python3.11/site-packages/tenacity/__init__.py\", line 326, in iter\n    raise retry_exc from fut.exception()\ntenacity.RetryError: RetryError[<Future at 0x14ce5c85add0 state=finished raised UnexpectedAnswerException>]\n",
      "Traceback (most recent call last):\n  File \"/home/fd15hava/.cache/pypoetry/virtualenvs/non-package-mode-zjkKA0Ca-py3.11/lib/python3.11/site-packages/tenacity/__init__.py\", line 382, in __call__\n    result = fn(*args, **kwargs)\n             ^^^^^^^^^^^^^^^^^^^\n  File \"/work/home/fd15hava/tinypaper-mpt/src/agent.py\", line 26, in play\n    answer = self._prompt(self._make_prompt(scenario))\n             ^^^^^^^^^^^^^^^^^^^^^^^^^^^^^^^^^^^^^^^^^\n  File \"/work/home/fd15hava/tinypaper-mpt/src/agent.py\", line 40, in _prompt\n    raise UnexpectedAnswerException(f\"expected 1 or 2, got {result}\")\nutil.UnexpectedAnswerException: expected 1 or 2, got  \n\nThe above exception was the direct cause of the following exception:\n\nTraceback (most recent call last):\n  File \"/work/home/fd15hava/tinypaper-mpt/scripts/experiments/run.py\", line 16, in _run_session\n    result = agent.play(session)\n             ^^^^^^^^^^^^^^^^^^^\n  File \"/home/fd15hava/.cache/pypoetry/virtualenvs/non-package-mode-zjkKA0Ca-py3.11/lib/python3.11/site-packages/tenacity/__init__.py\", line 289, in wrapped_f\n    return self(f, *args, **kw)\n           ^^^^^^^^^^^^^^^^^^^^\n  File \"/home/fd15hava/.cache/pypoetry/virtualenvs/non-package-mode-zjkKA0Ca-py3.11/lib/python3.11/site-packages/tenacity/__init__.py\", line 379, in __call__\n    do = self.iter(retry_state=retry_state)\n         ^^^^^^^^^^^^^^^^^^^^^^^^^^^^^^^^^^\n  File \"/home/fd15hava/.cache/pypoetry/virtualenvs/non-package-mode-zjkKA0Ca-py3.11/lib/python3.11/site-packages/tenacity/__init__.py\", line 326, in iter\n    raise retry_exc from fut.exception()\ntenacity.RetryError: RetryError[<Future at 0x14cdd461b5d0 state=finished raised UnexpectedAnswerException>]\n",
      "Traceback (most recent call last):\n  File \"/home/fd15hava/.cache/pypoetry/virtualenvs/non-package-mode-zjkKA0Ca-py3.11/lib/python3.11/site-packages/tenacity/__init__.py\", line 382, in __call__\n    result = fn(*args, **kwargs)\n             ^^^^^^^^^^^^^^^^^^^\n  File \"/work/home/fd15hava/tinypaper-mpt/src/agent.py\", line 26, in play\n    answer = self._prompt(self._make_prompt(scenario))\n             ^^^^^^^^^^^^^^^^^^^^^^^^^^^^^^^^^^^^^^^^^\n  File \"/work/home/fd15hava/tinypaper-mpt/src/agent.py\", line 40, in _prompt\n    raise UnexpectedAnswerException(f\"expected 1 or 2, got {result}\")\nutil.UnexpectedAnswerException: expected 1 or 2, got  \n\nThe above exception was the direct cause of the following exception:\n\nTraceback (most recent call last):\n  File \"/work/home/fd15hava/tinypaper-mpt/scripts/experiments/run.py\", line 16, in _run_session\n    result = agent.play(session)\n             ^^^^^^^^^^^^^^^^^^^\n  File \"/home/fd15hava/.cache/pypoetry/virtualenvs/non-package-mode-zjkKA0Ca-py3.11/lib/python3.11/site-packages/tenacity/__init__.py\", line 289, in wrapped_f\n    return self(f, *args, **kw)\n           ^^^^^^^^^^^^^^^^^^^^\n  File \"/home/fd15hava/.cache/pypoetry/virtualenvs/non-package-mode-zjkKA0Ca-py3.11/lib/python3.11/site-packages/tenacity/__init__.py\", line 379, in __call__\n    do = self.iter(retry_state=retry_state)\n         ^^^^^^^^^^^^^^^^^^^^^^^^^^^^^^^^^^\n  File \"/home/fd15hava/.cache/pypoetry/virtualenvs/non-package-mode-zjkKA0Ca-py3.11/lib/python3.11/site-packages/tenacity/__init__.py\", line 326, in iter\n    raise retry_exc from fut.exception()\ntenacity.RetryError: RetryError[<Future at 0x14ce5c2e7810 state=finished raised UnexpectedAnswerException>]\n",
      "Traceback (most recent call last):\n  File \"/home/fd15hava/.cache/pypoetry/virtualenvs/non-package-mode-zjkKA0Ca-py3.11/lib/python3.11/site-packages/tenacity/__init__.py\", line 382, in __call__\n    result = fn(*args, **kwargs)\n             ^^^^^^^^^^^^^^^^^^^\n  File \"/work/home/fd15hava/tinypaper-mpt/src/agent.py\", line 26, in play\n    answer = self._prompt(self._make_prompt(scenario))\n             ^^^^^^^^^^^^^^^^^^^^^^^^^^^^^^^^^^^^^^^^^\n  File \"/work/home/fd15hava/tinypaper-mpt/src/agent.py\", line 40, in _prompt\n    raise UnexpectedAnswerException(f\"expected 1 or 2, got {result}\")\nutil.UnexpectedAnswerException: expected 1 or 2, got  \n\nThe above exception was the direct cause of the following exception:\n\nTraceback (most recent call last):\n  File \"/work/home/fd15hava/tinypaper-mpt/scripts/experiments/run.py\", line 16, in _run_session\n    result = agent.play(session)\n             ^^^^^^^^^^^^^^^^^^^\n  File \"/home/fd15hava/.cache/pypoetry/virtualenvs/non-package-mode-zjkKA0Ca-py3.11/lib/python3.11/site-packages/tenacity/__init__.py\", line 289, in wrapped_f\n    return self(f, *args, **kw)\n           ^^^^^^^^^^^^^^^^^^^^\n  File \"/home/fd15hava/.cache/pypoetry/virtualenvs/non-package-mode-zjkKA0Ca-py3.11/lib/python3.11/site-packages/tenacity/__init__.py\", line 379, in __call__\n    do = self.iter(retry_state=retry_state)\n         ^^^^^^^^^^^^^^^^^^^^^^^^^^^^^^^^^^\n  File \"/home/fd15hava/.cache/pypoetry/virtualenvs/non-package-mode-zjkKA0Ca-py3.11/lib/python3.11/site-packages/tenacity/__init__.py\", line 326, in iter\n    raise retry_exc from fut.exception()\ntenacity.RetryError: RetryError[<Future at 0x14ce5c859b90 state=finished raised UnexpectedAnswerException>]\n",
      "Traceback (most recent call last):\n  File \"/home/fd15hava/.cache/pypoetry/virtualenvs/non-package-mode-zjkKA0Ca-py3.11/lib/python3.11/site-packages/tenacity/__init__.py\", line 382, in __call__\n    result = fn(*args, **kwargs)\n             ^^^^^^^^^^^^^^^^^^^\n  File \"/work/home/fd15hava/tinypaper-mpt/src/agent.py\", line 26, in play\n    answer = self._prompt(self._make_prompt(scenario))\n             ^^^^^^^^^^^^^^^^^^^^^^^^^^^^^^^^^^^^^^^^^\n  File \"/work/home/fd15hava/tinypaper-mpt/src/agent.py\", line 40, in _prompt\n    raise UnexpectedAnswerException(f\"expected 1 or 2, got {result}\")\nutil.UnexpectedAnswerException: expected 1 or 2, got  \n\nThe above exception was the direct cause of the following exception:\n\nTraceback (most recent call last):\n  File \"/work/home/fd15hava/tinypaper-mpt/scripts/experiments/run.py\", line 16, in _run_session\n    result = agent.play(session)\n             ^^^^^^^^^^^^^^^^^^^\n  File \"/home/fd15hava/.cache/pypoetry/virtualenvs/non-package-mode-zjkKA0Ca-py3.11/lib/python3.11/site-packages/tenacity/__init__.py\", line 289, in wrapped_f\n    return self(f, *args, **kw)\n           ^^^^^^^^^^^^^^^^^^^^\n  File \"/home/fd15hava/.cache/pypoetry/virtualenvs/non-package-mode-zjkKA0Ca-py3.11/lib/python3.11/site-packages/tenacity/__init__.py\", line 379, in __call__\n    do = self.iter(retry_state=retry_state)\n         ^^^^^^^^^^^^^^^^^^^^^^^^^^^^^^^^^^\n  File \"/home/fd15hava/.cache/pypoetry/virtualenvs/non-package-mode-zjkKA0Ca-py3.11/lib/python3.11/site-packages/tenacity/__init__.py\", line 326, in iter\n    raise retry_exc from fut.exception()\ntenacity.RetryError: RetryError[<Future at 0x14ce57ff6ed0 state=finished raised UnexpectedAnswerException>]\n",
      "Traceback (most recent call last):\n  File \"/home/fd15hava/.cache/pypoetry/virtualenvs/non-package-mode-zjkKA0Ca-py3.11/lib/python3.11/site-packages/tenacity/__init__.py\", line 382, in __call__\n    result = fn(*args, **kwargs)\n             ^^^^^^^^^^^^^^^^^^^\n  File \"/work/home/fd15hava/tinypaper-mpt/src/agent.py\", line 26, in play\n    answer = self._prompt(self._make_prompt(scenario))\n             ^^^^^^^^^^^^^^^^^^^^^^^^^^^^^^^^^^^^^^^^^\n  File \"/work/home/fd15hava/tinypaper-mpt/src/agent.py\", line 40, in _prompt\n    raise UnexpectedAnswerException(f\"expected 1 or 2, got {result}\")\nutil.UnexpectedAnswerException: expected 1 or 2, got  \n\nThe above exception was the direct cause of the following exception:\n\nTraceback (most recent call last):\n  File \"/work/home/fd15hava/tinypaper-mpt/scripts/experiments/run.py\", line 16, in _run_session\n    result = agent.play(session)\n             ^^^^^^^^^^^^^^^^^^^\n  File \"/home/fd15hava/.cache/pypoetry/virtualenvs/non-package-mode-zjkKA0Ca-py3.11/lib/python3.11/site-packages/tenacity/__init__.py\", line 289, in wrapped_f\n    return self(f, *args, **kw)\n           ^^^^^^^^^^^^^^^^^^^^\n  File \"/home/fd15hava/.cache/pypoetry/virtualenvs/non-package-mode-zjkKA0Ca-py3.11/lib/python3.11/site-packages/tenacity/__init__.py\", line 379, in __call__\n    do = self.iter(retry_state=retry_state)\n         ^^^^^^^^^^^^^^^^^^^^^^^^^^^^^^^^^^\n  File \"/home/fd15hava/.cache/pypoetry/virtualenvs/non-package-mode-zjkKA0Ca-py3.11/lib/python3.11/site-packages/tenacity/__init__.py\", line 326, in iter\n    raise retry_exc from fut.exception()\ntenacity.RetryError: RetryError[<Future at 0x14cdd450f6d0 state=finished raised UnexpectedAnswerException>]\n",
      "Traceback (most recent call last):\n  File \"/home/fd15hava/.cache/pypoetry/virtualenvs/non-package-mode-zjkKA0Ca-py3.11/lib/python3.11/site-packages/tenacity/__init__.py\", line 382, in __call__\n    result = fn(*args, **kwargs)\n             ^^^^^^^^^^^^^^^^^^^\n  File \"/work/home/fd15hava/tinypaper-mpt/src/agent.py\", line 26, in play\n    answer = self._prompt(self._make_prompt(scenario))\n             ^^^^^^^^^^^^^^^^^^^^^^^^^^^^^^^^^^^^^^^^^\n  File \"/work/home/fd15hava/tinypaper-mpt/src/agent.py\", line 40, in _prompt\n    raise UnexpectedAnswerException(f\"expected 1 or 2, got {result}\")\nutil.UnexpectedAnswerException: expected 1 or 2, got  \n\nThe above exception was the direct cause of the following exception:\n\nTraceback (most recent call last):\n  File \"/work/home/fd15hava/tinypaper-mpt/scripts/experiments/run.py\", line 16, in _run_session\n    result = agent.play(session)\n             ^^^^^^^^^^^^^^^^^^^\n  File \"/home/fd15hava/.cache/pypoetry/virtualenvs/non-package-mode-zjkKA0Ca-py3.11/lib/python3.11/site-packages/tenacity/__init__.py\", line 289, in wrapped_f\n    return self(f, *args, **kw)\n           ^^^^^^^^^^^^^^^^^^^^\n  File \"/home/fd15hava/.cache/pypoetry/virtualenvs/non-package-mode-zjkKA0Ca-py3.11/lib/python3.11/site-packages/tenacity/__init__.py\", line 379, in __call__\n    do = self.iter(retry_state=retry_state)\n         ^^^^^^^^^^^^^^^^^^^^^^^^^^^^^^^^^^\n  File \"/home/fd15hava/.cache/pypoetry/virtualenvs/non-package-mode-zjkKA0Ca-py3.11/lib/python3.11/site-packages/tenacity/__init__.py\", line 326, in iter\n    raise retry_exc from fut.exception()\ntenacity.RetryError: RetryError[<Future at 0x14ce5cc9a790 state=finished raised UnexpectedAnswerException>]\n",
      "Traceback (most recent call last):\n  File \"/home/fd15hava/.cache/pypoetry/virtualenvs/non-package-mode-zjkKA0Ca-py3.11/lib/python3.11/site-packages/tenacity/__init__.py\", line 382, in __call__\n    result = fn(*args, **kwargs)\n             ^^^^^^^^^^^^^^^^^^^\n  File \"/work/home/fd15hava/tinypaper-mpt/src/agent.py\", line 26, in play\n    answer = self._prompt(self._make_prompt(scenario))\n             ^^^^^^^^^^^^^^^^^^^^^^^^^^^^^^^^^^^^^^^^^\n  File \"/work/home/fd15hava/tinypaper-mpt/src/agent.py\", line 40, in _prompt\n    raise UnexpectedAnswerException(f\"expected 1 or 2, got {result}\")\nutil.UnexpectedAnswerException: expected 1 or 2, got  \n\nThe above exception was the direct cause of the following exception:\n\nTraceback (most recent call last):\n  File \"/work/home/fd15hava/tinypaper-mpt/scripts/experiments/run.py\", line 16, in _run_session\n    result = agent.play(session)\n             ^^^^^^^^^^^^^^^^^^^\n  File \"/home/fd15hava/.cache/pypoetry/virtualenvs/non-package-mode-zjkKA0Ca-py3.11/lib/python3.11/site-packages/tenacity/__init__.py\", line 289, in wrapped_f\n    return self(f, *args, **kw)\n           ^^^^^^^^^^^^^^^^^^^^\n  File \"/home/fd15hava/.cache/pypoetry/virtualenvs/non-package-mode-zjkKA0Ca-py3.11/lib/python3.11/site-packages/tenacity/__init__.py\", line 379, in __call__\n    do = self.iter(retry_state=retry_state)\n         ^^^^^^^^^^^^^^^^^^^^^^^^^^^^^^^^^^\n  File \"/home/fd15hava/.cache/pypoetry/virtualenvs/non-package-mode-zjkKA0Ca-py3.11/lib/python3.11/site-packages/tenacity/__init__.py\", line 326, in iter\n    raise retry_exc from fut.exception()\ntenacity.RetryError: RetryError[<Future at 0x14ce5c2e63d0 state=finished raised UnexpectedAnswerException>]\n",
      "Traceback (most recent call last):\n  File \"/home/fd15hava/.cache/pypoetry/virtualenvs/non-package-mode-zjkKA0Ca-py3.11/lib/python3.11/site-packages/tenacity/__init__.py\", line 382, in __call__\n    result = fn(*args, **kwargs)\n             ^^^^^^^^^^^^^^^^^^^\n  File \"/work/home/fd15hava/tinypaper-mpt/src/agent.py\", line 26, in play\n    answer = self._prompt(self._make_prompt(scenario))\n             ^^^^^^^^^^^^^^^^^^^^^^^^^^^^^^^^^^^^^^^^^\n  File \"/work/home/fd15hava/tinypaper-mpt/src/agent.py\", line 40, in _prompt\n    raise UnexpectedAnswerException(f\"expected 1 or 2, got {result}\")\nutil.UnexpectedAnswerException: expected 1 or 2, got  \n\nThe above exception was the direct cause of the following exception:\n\nTraceback (most recent call last):\n  File \"/work/home/fd15hava/tinypaper-mpt/scripts/experiments/run.py\", line 16, in _run_session\n    result = agent.play(session)\n             ^^^^^^^^^^^^^^^^^^^\n  File \"/home/fd15hava/.cache/pypoetry/virtualenvs/non-package-mode-zjkKA0Ca-py3.11/lib/python3.11/site-packages/tenacity/__init__.py\", line 289, in wrapped_f\n    return self(f, *args, **kw)\n           ^^^^^^^^^^^^^^^^^^^^\n  File \"/home/fd15hava/.cache/pypoetry/virtualenvs/non-package-mode-zjkKA0Ca-py3.11/lib/python3.11/site-packages/tenacity/__init__.py\", line 379, in __call__\n    do = self.iter(retry_state=retry_state)\n         ^^^^^^^^^^^^^^^^^^^^^^^^^^^^^^^^^^\n  File \"/home/fd15hava/.cache/pypoetry/virtualenvs/non-package-mode-zjkKA0Ca-py3.11/lib/python3.11/site-packages/tenacity/__init__.py\", line 326, in iter\n    raise retry_exc from fut.exception()\ntenacity.RetryError: RetryError[<Future at 0x14cdd44fe790 state=finished raised UnexpectedAnswerException>]\n",
      "Traceback (most recent call last):\n  File \"/home/fd15hava/.cache/pypoetry/virtualenvs/non-package-mode-zjkKA0Ca-py3.11/lib/python3.11/site-packages/tenacity/__init__.py\", line 382, in __call__\n    result = fn(*args, **kwargs)\n             ^^^^^^^^^^^^^^^^^^^\n  File \"/work/home/fd15hava/tinypaper-mpt/src/agent.py\", line 26, in play\n    answer = self._prompt(self._make_prompt(scenario))\n             ^^^^^^^^^^^^^^^^^^^^^^^^^^^^^^^^^^^^^^^^^\n  File \"/work/home/fd15hava/tinypaper-mpt/src/agent.py\", line 40, in _prompt\n    raise UnexpectedAnswerException(f\"expected 1 or 2, got {result}\")\nutil.UnexpectedAnswerException: expected 1 or 2, got  \n\nThe above exception was the direct cause of the following exception:\n\nTraceback (most recent call last):\n  File \"/work/home/fd15hava/tinypaper-mpt/scripts/experiments/run.py\", line 16, in _run_session\n    result = agent.play(session)\n             ^^^^^^^^^^^^^^^^^^^\n  File \"/home/fd15hava/.cache/pypoetry/virtualenvs/non-package-mode-zjkKA0Ca-py3.11/lib/python3.11/site-packages/tenacity/__init__.py\", line 289, in wrapped_f\n    return self(f, *args, **kw)\n           ^^^^^^^^^^^^^^^^^^^^\n  File \"/home/fd15hava/.cache/pypoetry/virtualenvs/non-package-mode-zjkKA0Ca-py3.11/lib/python3.11/site-packages/tenacity/__init__.py\", line 379, in __call__\n    do = self.iter(retry_state=retry_state)\n         ^^^^^^^^^^^^^^^^^^^^^^^^^^^^^^^^^^\n  File \"/home/fd15hava/.cache/pypoetry/virtualenvs/non-package-mode-zjkKA0Ca-py3.11/lib/python3.11/site-packages/tenacity/__init__.py\", line 326, in iter\n    raise retry_exc from fut.exception()\ntenacity.RetryError: RetryError[<Future at 0x14cdd450d3d0 state=finished raised UnexpectedAnswerException>]\n",
      "Traceback (most recent call last):\n  File \"/home/fd15hava/.cache/pypoetry/virtualenvs/non-package-mode-zjkKA0Ca-py3.11/lib/python3.11/site-packages/tenacity/__init__.py\", line 382, in __call__\n    result = fn(*args, **kwargs)\n             ^^^^^^^^^^^^^^^^^^^\n  File \"/work/home/fd15hava/tinypaper-mpt/src/agent.py\", line 26, in play\n    answer = self._prompt(self._make_prompt(scenario))\n             ^^^^^^^^^^^^^^^^^^^^^^^^^^^^^^^^^^^^^^^^^\n  File \"/work/home/fd15hava/tinypaper-mpt/src/agent.py\", line 40, in _prompt\n    raise UnexpectedAnswerException(f\"expected 1 or 2, got {result}\")\nutil.UnexpectedAnswerException: expected 1 or 2, got  \n\nThe above exception was the direct cause of the following exception:\n\nTraceback (most recent call last):\n  File \"/work/home/fd15hava/tinypaper-mpt/scripts/experiments/run.py\", line 16, in _run_session\n    result = agent.play(session)\n             ^^^^^^^^^^^^^^^^^^^\n  File \"/home/fd15hava/.cache/pypoetry/virtualenvs/non-package-mode-zjkKA0Ca-py3.11/lib/python3.11/site-packages/tenacity/__init__.py\", line 289, in wrapped_f\n    return self(f, *args, **kw)\n           ^^^^^^^^^^^^^^^^^^^^\n  File \"/home/fd15hava/.cache/pypoetry/virtualenvs/non-package-mode-zjkKA0Ca-py3.11/lib/python3.11/site-packages/tenacity/__init__.py\", line 379, in __call__\n    do = self.iter(retry_state=retry_state)\n         ^^^^^^^^^^^^^^^^^^^^^^^^^^^^^^^^^^\n  File \"/home/fd15hava/.cache/pypoetry/virtualenvs/non-package-mode-zjkKA0Ca-py3.11/lib/python3.11/site-packages/tenacity/__init__.py\", line 326, in iter\n    raise retry_exc from fut.exception()\ntenacity.RetryError: RetryError[<Future at 0x14cdd4493b90 state=finished raised UnexpectedAnswerException>]\n",
      "Traceback (most recent call last):\n  File \"/home/fd15hava/.cache/pypoetry/virtualenvs/non-package-mode-zjkKA0Ca-py3.11/lib/python3.11/site-packages/tenacity/__init__.py\", line 382, in __call__\n    result = fn(*args, **kwargs)\n             ^^^^^^^^^^^^^^^^^^^\n  File \"/work/home/fd15hava/tinypaper-mpt/src/agent.py\", line 26, in play\n    answer = self._prompt(self._make_prompt(scenario))\n             ^^^^^^^^^^^^^^^^^^^^^^^^^^^^^^^^^^^^^^^^^\n  File \"/work/home/fd15hava/tinypaper-mpt/src/agent.py\", line 40, in _prompt\n    raise UnexpectedAnswerException(f\"expected 1 or 2, got {result}\")\nutil.UnexpectedAnswerException: expected 1 or 2, got  \n\nThe above exception was the direct cause of the following exception:\n\nTraceback (most recent call last):\n  File \"/work/home/fd15hava/tinypaper-mpt/scripts/experiments/run.py\", line 16, in _run_session\n    result = agent.play(session)\n             ^^^^^^^^^^^^^^^^^^^\n  File \"/home/fd15hava/.cache/pypoetry/virtualenvs/non-package-mode-zjkKA0Ca-py3.11/lib/python3.11/site-packages/tenacity/__init__.py\", line 289, in wrapped_f\n    return self(f, *args, **kw)\n           ^^^^^^^^^^^^^^^^^^^^\n  File \"/home/fd15hava/.cache/pypoetry/virtualenvs/non-package-mode-zjkKA0Ca-py3.11/lib/python3.11/site-packages/tenacity/__init__.py\", line 379, in __call__\n    do = self.iter(retry_state=retry_state)\n         ^^^^^^^^^^^^^^^^^^^^^^^^^^^^^^^^^^\n  File \"/home/fd15hava/.cache/pypoetry/virtualenvs/non-package-mode-zjkKA0Ca-py3.11/lib/python3.11/site-packages/tenacity/__init__.py\", line 326, in iter\n    raise retry_exc from fut.exception()\ntenacity.RetryError: RetryError[<Future at 0x14ce5c829010 state=finished raised UnexpectedAnswerException>]\n",
      "Traceback (most recent call last):\n  File \"/home/fd15hava/.cache/pypoetry/virtualenvs/non-package-mode-zjkKA0Ca-py3.11/lib/python3.11/site-packages/tenacity/__init__.py\", line 382, in __call__\n    result = fn(*args, **kwargs)\n             ^^^^^^^^^^^^^^^^^^^\n  File \"/work/home/fd15hava/tinypaper-mpt/src/agent.py\", line 26, in play\n    answer = self._prompt(self._make_prompt(scenario))\n             ^^^^^^^^^^^^^^^^^^^^^^^^^^^^^^^^^^^^^^^^^\n  File \"/work/home/fd15hava/tinypaper-mpt/src/agent.py\", line 40, in _prompt\n    raise UnexpectedAnswerException(f\"expected 1 or 2, got {result}\")\nutil.UnexpectedAnswerException: expected 1 or 2, got  \n\nThe above exception was the direct cause of the following exception:\n\nTraceback (most recent call last):\n  File \"/work/home/fd15hava/tinypaper-mpt/scripts/experiments/run.py\", line 16, in _run_session\n    result = agent.play(session)\n             ^^^^^^^^^^^^^^^^^^^\n  File \"/home/fd15hava/.cache/pypoetry/virtualenvs/non-package-mode-zjkKA0Ca-py3.11/lib/python3.11/site-packages/tenacity/__init__.py\", line 289, in wrapped_f\n    return self(f, *args, **kw)\n           ^^^^^^^^^^^^^^^^^^^^\n  File \"/home/fd15hava/.cache/pypoetry/virtualenvs/non-package-mode-zjkKA0Ca-py3.11/lib/python3.11/site-packages/tenacity/__init__.py\", line 379, in __call__\n    do = self.iter(retry_state=retry_state)\n         ^^^^^^^^^^^^^^^^^^^^^^^^^^^^^^^^^^\n  File \"/home/fd15hava/.cache/pypoetry/virtualenvs/non-package-mode-zjkKA0Ca-py3.11/lib/python3.11/site-packages/tenacity/__init__.py\", line 326, in iter\n    raise retry_exc from fut.exception()\ntenacity.RetryError: RetryError[<Future at 0x14ce5c85b9d0 state=finished raised UnexpectedAnswerException>]\n",
      "Traceback (most recent call last):\n  File \"/home/fd15hava/.cache/pypoetry/virtualenvs/non-package-mode-zjkKA0Ca-py3.11/lib/python3.11/site-packages/tenacity/__init__.py\", line 382, in __call__\n    result = fn(*args, **kwargs)\n             ^^^^^^^^^^^^^^^^^^^\n  File \"/work/home/fd15hava/tinypaper-mpt/src/agent.py\", line 26, in play\n    answer = self._prompt(self._make_prompt(scenario))\n             ^^^^^^^^^^^^^^^^^^^^^^^^^^^^^^^^^^^^^^^^^\n  File \"/work/home/fd15hava/tinypaper-mpt/src/agent.py\", line 40, in _prompt\n    raise UnexpectedAnswerException(f\"expected 1 or 2, got {result}\")\nutil.UnexpectedAnswerException: expected 1 or 2, got  \n\nThe above exception was the direct cause of the following exception:\n\nTraceback (most recent call last):\n  File \"/work/home/fd15hava/tinypaper-mpt/scripts/experiments/run.py\", line 16, in _run_session\n    result = agent.play(session)\n             ^^^^^^^^^^^^^^^^^^^\n  File \"/home/fd15hava/.cache/pypoetry/virtualenvs/non-package-mode-zjkKA0Ca-py3.11/lib/python3.11/site-packages/tenacity/__init__.py\", line 289, in wrapped_f\n    return self(f, *args, **kw)\n           ^^^^^^^^^^^^^^^^^^^^\n  File \"/home/fd15hava/.cache/pypoetry/virtualenvs/non-package-mode-zjkKA0Ca-py3.11/lib/python3.11/site-packages/tenacity/__init__.py\", line 379, in __call__\n    do = self.iter(retry_state=retry_state)\n         ^^^^^^^^^^^^^^^^^^^^^^^^^^^^^^^^^^\n  File \"/home/fd15hava/.cache/pypoetry/virtualenvs/non-package-mode-zjkKA0Ca-py3.11/lib/python3.11/site-packages/tenacity/__init__.py\", line 326, in iter\n    raise retry_exc from fut.exception()\ntenacity.RetryError: RetryError[<Future at 0x14cdd450dc10 state=finished raised UnexpectedAnswerException>]\n",
      "Traceback (most recent call last):\n  File \"/home/fd15hava/.cache/pypoetry/virtualenvs/non-package-mode-zjkKA0Ca-py3.11/lib/python3.11/site-packages/tenacity/__init__.py\", line 382, in __call__\n    result = fn(*args, **kwargs)\n             ^^^^^^^^^^^^^^^^^^^\n  File \"/work/home/fd15hava/tinypaper-mpt/src/agent.py\", line 26, in play\n    answer = self._prompt(self._make_prompt(scenario))\n             ^^^^^^^^^^^^^^^^^^^^^^^^^^^^^^^^^^^^^^^^^\n  File \"/work/home/fd15hava/tinypaper-mpt/src/agent.py\", line 40, in _prompt\n    raise UnexpectedAnswerException(f\"expected 1 or 2, got {result}\")\nutil.UnexpectedAnswerException: expected 1 or 2, got  \n\nThe above exception was the direct cause of the following exception:\n\nTraceback (most recent call last):\n  File \"/work/home/fd15hava/tinypaper-mpt/scripts/experiments/run.py\", line 16, in _run_session\n    result = agent.play(session)\n             ^^^^^^^^^^^^^^^^^^^\n  File \"/home/fd15hava/.cache/pypoetry/virtualenvs/non-package-mode-zjkKA0Ca-py3.11/lib/python3.11/site-packages/tenacity/__init__.py\", line 289, in wrapped_f\n    return self(f, *args, **kw)\n           ^^^^^^^^^^^^^^^^^^^^\n  File \"/home/fd15hava/.cache/pypoetry/virtualenvs/non-package-mode-zjkKA0Ca-py3.11/lib/python3.11/site-packages/tenacity/__init__.py\", line 379, in __call__\n    do = self.iter(retry_state=retry_state)\n         ^^^^^^^^^^^^^^^^^^^^^^^^^^^^^^^^^^\n  File \"/home/fd15hava/.cache/pypoetry/virtualenvs/non-package-mode-zjkKA0Ca-py3.11/lib/python3.11/site-packages/tenacity/__init__.py\", line 326, in iter\n    raise retry_exc from fut.exception()\ntenacity.RetryError: RetryError[<Future at 0x14cdd44ff8d0 state=finished raised UnexpectedAnswerException>]\n",
      "Traceback (most recent call last):\n  File \"/home/fd15hava/.cache/pypoetry/virtualenvs/non-package-mode-zjkKA0Ca-py3.11/lib/python3.11/site-packages/tenacity/__init__.py\", line 382, in __call__\n    result = fn(*args, **kwargs)\n             ^^^^^^^^^^^^^^^^^^^\n  File \"/work/home/fd15hava/tinypaper-mpt/src/agent.py\", line 26, in play\n    answer = self._prompt(self._make_prompt(scenario))\n             ^^^^^^^^^^^^^^^^^^^^^^^^^^^^^^^^^^^^^^^^^\n  File \"/work/home/fd15hava/tinypaper-mpt/src/agent.py\", line 40, in _prompt\n    raise UnexpectedAnswerException(f\"expected 1 or 2, got {result}\")\nutil.UnexpectedAnswerException: expected 1 or 2, got  \n\nThe above exception was the direct cause of the following exception:\n\nTraceback (most recent call last):\n  File \"/work/home/fd15hava/tinypaper-mpt/scripts/experiments/run.py\", line 16, in _run_session\n    result = agent.play(session)\n             ^^^^^^^^^^^^^^^^^^^\n  File \"/home/fd15hava/.cache/pypoetry/virtualenvs/non-package-mode-zjkKA0Ca-py3.11/lib/python3.11/site-packages/tenacity/__init__.py\", line 289, in wrapped_f\n    return self(f, *args, **kw)\n           ^^^^^^^^^^^^^^^^^^^^\n  File \"/home/fd15hava/.cache/pypoetry/virtualenvs/non-package-mode-zjkKA0Ca-py3.11/lib/python3.11/site-packages/tenacity/__init__.py\", line 379, in __call__\n    do = self.iter(retry_state=retry_state)\n         ^^^^^^^^^^^^^^^^^^^^^^^^^^^^^^^^^^\n  File \"/home/fd15hava/.cache/pypoetry/virtualenvs/non-package-mode-zjkKA0Ca-py3.11/lib/python3.11/site-packages/tenacity/__init__.py\", line 326, in iter\n    raise retry_exc from fut.exception()\ntenacity.RetryError: RetryError[<Future at 0x14cdd446cd10 state=finished raised UnexpectedAnswerException>]\n",
      "Traceback (most recent call last):\n  File \"/home/fd15hava/.cache/pypoetry/virtualenvs/non-package-mode-zjkKA0Ca-py3.11/lib/python3.11/site-packages/tenacity/__init__.py\", line 382, in __call__\n    result = fn(*args, **kwargs)\n             ^^^^^^^^^^^^^^^^^^^\n  File \"/work/home/fd15hava/tinypaper-mpt/src/agent.py\", line 26, in play\n    answer = self._prompt(self._make_prompt(scenario))\n             ^^^^^^^^^^^^^^^^^^^^^^^^^^^^^^^^^^^^^^^^^\n  File \"/work/home/fd15hava/tinypaper-mpt/src/agent.py\", line 40, in _prompt\n    raise UnexpectedAnswerException(f\"expected 1 or 2, got {result}\")\nutil.UnexpectedAnswerException: expected 1 or 2, got  \n\nThe above exception was the direct cause of the following exception:\n\nTraceback (most recent call last):\n  File \"/work/home/fd15hava/tinypaper-mpt/scripts/experiments/run.py\", line 16, in _run_session\n    result = agent.play(session)\n             ^^^^^^^^^^^^^^^^^^^\n  File \"/home/fd15hava/.cache/pypoetry/virtualenvs/non-package-mode-zjkKA0Ca-py3.11/lib/python3.11/site-packages/tenacity/__init__.py\", line 289, in wrapped_f\n    return self(f, *args, **kw)\n           ^^^^^^^^^^^^^^^^^^^^\n  File \"/home/fd15hava/.cache/pypoetry/virtualenvs/non-package-mode-zjkKA0Ca-py3.11/lib/python3.11/site-packages/tenacity/__init__.py\", line 379, in __call__\n    do = self.iter(retry_state=retry_state)\n         ^^^^^^^^^^^^^^^^^^^^^^^^^^^^^^^^^^\n  File \"/home/fd15hava/.cache/pypoetry/virtualenvs/non-package-mode-zjkKA0Ca-py3.11/lib/python3.11/site-packages/tenacity/__init__.py\", line 326, in iter\n    raise retry_exc from fut.exception()\ntenacity.RetryError: RetryError[<Future at 0x14cdd446f190 state=finished raised UnexpectedAnswerException>]\n",
      "Traceback (most recent call last):\n  File \"/home/fd15hava/.cache/pypoetry/virtualenvs/non-package-mode-zjkKA0Ca-py3.11/lib/python3.11/site-packages/tenacity/__init__.py\", line 382, in __call__\n    result = fn(*args, **kwargs)\n             ^^^^^^^^^^^^^^^^^^^\n  File \"/work/home/fd15hava/tinypaper-mpt/src/agent.py\", line 26, in play\n    answer = self._prompt(self._make_prompt(scenario))\n             ^^^^^^^^^^^^^^^^^^^^^^^^^^^^^^^^^^^^^^^^^\n  File \"/work/home/fd15hava/tinypaper-mpt/src/agent.py\", line 40, in _prompt\n    raise UnexpectedAnswerException(f\"expected 1 or 2, got {result}\")\nutil.UnexpectedAnswerException: expected 1 or 2, got  \n\nThe above exception was the direct cause of the following exception:\n\nTraceback (most recent call last):\n  File \"/work/home/fd15hava/tinypaper-mpt/scripts/experiments/run.py\", line 16, in _run_session\n    result = agent.play(session)\n             ^^^^^^^^^^^^^^^^^^^\n  File \"/home/fd15hava/.cache/pypoetry/virtualenvs/non-package-mode-zjkKA0Ca-py3.11/lib/python3.11/site-packages/tenacity/__init__.py\", line 289, in wrapped_f\n    return self(f, *args, **kw)\n           ^^^^^^^^^^^^^^^^^^^^\n  File \"/home/fd15hava/.cache/pypoetry/virtualenvs/non-package-mode-zjkKA0Ca-py3.11/lib/python3.11/site-packages/tenacity/__init__.py\", line 379, in __call__\n    do = self.iter(retry_state=retry_state)\n         ^^^^^^^^^^^^^^^^^^^^^^^^^^^^^^^^^^\n  File \"/home/fd15hava/.cache/pypoetry/virtualenvs/non-package-mode-zjkKA0Ca-py3.11/lib/python3.11/site-packages/tenacity/__init__.py\", line 326, in iter\n    raise retry_exc from fut.exception()\ntenacity.RetryError: RetryError[<Future at 0x14ce5c112650 state=finished raised UnexpectedAnswerException>]\n",
      "Traceback (most recent call last):\n  File \"/home/fd15hava/.cache/pypoetry/virtualenvs/non-package-mode-zjkKA0Ca-py3.11/lib/python3.11/site-packages/tenacity/__init__.py\", line 382, in __call__\n    result = fn(*args, **kwargs)\n             ^^^^^^^^^^^^^^^^^^^\n  File \"/work/home/fd15hava/tinypaper-mpt/src/agent.py\", line 26, in play\n    answer = self._prompt(self._make_prompt(scenario))\n             ^^^^^^^^^^^^^^^^^^^^^^^^^^^^^^^^^^^^^^^^^\n  File \"/work/home/fd15hava/tinypaper-mpt/src/agent.py\", line 40, in _prompt\n    raise UnexpectedAnswerException(f\"expected 1 or 2, got {result}\")\nutil.UnexpectedAnswerException: expected 1 or 2, got  \n\nThe above exception was the direct cause of the following exception:\n\nTraceback (most recent call last):\n  File \"/work/home/fd15hava/tinypaper-mpt/scripts/experiments/run.py\", line 16, in _run_session\n    result = agent.play(session)\n             ^^^^^^^^^^^^^^^^^^^\n  File \"/home/fd15hava/.cache/pypoetry/virtualenvs/non-package-mode-zjkKA0Ca-py3.11/lib/python3.11/site-packages/tenacity/__init__.py\", line 289, in wrapped_f\n    return self(f, *args, **kw)\n           ^^^^^^^^^^^^^^^^^^^^\n  File \"/home/fd15hava/.cache/pypoetry/virtualenvs/non-package-mode-zjkKA0Ca-py3.11/lib/python3.11/site-packages/tenacity/__init__.py\", line 379, in __call__\n    do = self.iter(retry_state=retry_state)\n         ^^^^^^^^^^^^^^^^^^^^^^^^^^^^^^^^^^\n  File \"/home/fd15hava/.cache/pypoetry/virtualenvs/non-package-mode-zjkKA0Ca-py3.11/lib/python3.11/site-packages/tenacity/__init__.py\", line 326, in iter\n    raise retry_exc from fut.exception()\ntenacity.RetryError: RetryError[<Future at 0x14ce57f80450 state=finished raised UnexpectedAnswerException>]\n",
      "Traceback (most recent call last):\n  File \"/home/fd15hava/.cache/pypoetry/virtualenvs/non-package-mode-zjkKA0Ca-py3.11/lib/python3.11/site-packages/tenacity/__init__.py\", line 382, in __call__\n    result = fn(*args, **kwargs)\n             ^^^^^^^^^^^^^^^^^^^\n  File \"/work/home/fd15hava/tinypaper-mpt/src/agent.py\", line 26, in play\n    answer = self._prompt(self._make_prompt(scenario))\n             ^^^^^^^^^^^^^^^^^^^^^^^^^^^^^^^^^^^^^^^^^\n  File \"/work/home/fd15hava/tinypaper-mpt/src/agent.py\", line 40, in _prompt\n    raise UnexpectedAnswerException(f\"expected 1 or 2, got {result}\")\nutil.UnexpectedAnswerException: expected 1 or 2, got  \n\nThe above exception was the direct cause of the following exception:\n\nTraceback (most recent call last):\n  File \"/work/home/fd15hava/tinypaper-mpt/scripts/experiments/run.py\", line 16, in _run_session\n    result = agent.play(session)\n             ^^^^^^^^^^^^^^^^^^^\n  File \"/home/fd15hava/.cache/pypoetry/virtualenvs/non-package-mode-zjkKA0Ca-py3.11/lib/python3.11/site-packages/tenacity/__init__.py\", line 289, in wrapped_f\n    return self(f, *args, **kw)\n           ^^^^^^^^^^^^^^^^^^^^\n  File \"/home/fd15hava/.cache/pypoetry/virtualenvs/non-package-mode-zjkKA0Ca-py3.11/lib/python3.11/site-packages/tenacity/__init__.py\", line 379, in __call__\n    do = self.iter(retry_state=retry_state)\n         ^^^^^^^^^^^^^^^^^^^^^^^^^^^^^^^^^^\n  File \"/home/fd15hava/.cache/pypoetry/virtualenvs/non-package-mode-zjkKA0Ca-py3.11/lib/python3.11/site-packages/tenacity/__init__.py\", line 326, in iter\n    raise retry_exc from fut.exception()\ntenacity.RetryError: RetryError[<Future at 0x14ce57fbe410 state=finished raised UnexpectedAnswerException>]\n",
      "Traceback (most recent call last):\n  File \"/home/fd15hava/.cache/pypoetry/virtualenvs/non-package-mode-zjkKA0Ca-py3.11/lib/python3.11/site-packages/tenacity/__init__.py\", line 382, in __call__\n    result = fn(*args, **kwargs)\n             ^^^^^^^^^^^^^^^^^^^\n  File \"/work/home/fd15hava/tinypaper-mpt/src/agent.py\", line 26, in play\n    answer = self._prompt(self._make_prompt(scenario))\n             ^^^^^^^^^^^^^^^^^^^^^^^^^^^^^^^^^^^^^^^^^\n  File \"/work/home/fd15hava/tinypaper-mpt/src/agent.py\", line 40, in _prompt\n    raise UnexpectedAnswerException(f\"expected 1 or 2, got {result}\")\nutil.UnexpectedAnswerException: expected 1 or 2, got  \n\nThe above exception was the direct cause of the following exception:\n\nTraceback (most recent call last):\n  File \"/work/home/fd15hava/tinypaper-mpt/scripts/experiments/run.py\", line 16, in _run_session\n    result = agent.play(session)\n             ^^^^^^^^^^^^^^^^^^^\n  File \"/home/fd15hava/.cache/pypoetry/virtualenvs/non-package-mode-zjkKA0Ca-py3.11/lib/python3.11/site-packages/tenacity/__init__.py\", line 289, in wrapped_f\n    return self(f, *args, **kw)\n           ^^^^^^^^^^^^^^^^^^^^\n  File \"/home/fd15hava/.cache/pypoetry/virtualenvs/non-package-mode-zjkKA0Ca-py3.11/lib/python3.11/site-packages/tenacity/__init__.py\", line 379, in __call__\n    do = self.iter(retry_state=retry_state)\n         ^^^^^^^^^^^^^^^^^^^^^^^^^^^^^^^^^^\n  File \"/home/fd15hava/.cache/pypoetry/virtualenvs/non-package-mode-zjkKA0Ca-py3.11/lib/python3.11/site-packages/tenacity/__init__.py\", line 326, in iter\n    raise retry_exc from fut.exception()\ntenacity.RetryError: RetryError[<Future at 0x14ce5c8284d0 state=finished raised UnexpectedAnswerException>]\n",
      "Traceback (most recent call last):\n  File \"/home/fd15hava/.cache/pypoetry/virtualenvs/non-package-mode-zjkKA0Ca-py3.11/lib/python3.11/site-packages/tenacity/__init__.py\", line 382, in __call__\n    result = fn(*args, **kwargs)\n             ^^^^^^^^^^^^^^^^^^^\n  File \"/work/home/fd15hava/tinypaper-mpt/src/agent.py\", line 26, in play\n    answer = self._prompt(self._make_prompt(scenario))\n             ^^^^^^^^^^^^^^^^^^^^^^^^^^^^^^^^^^^^^^^^^\n  File \"/work/home/fd15hava/tinypaper-mpt/src/agent.py\", line 40, in _prompt\n    raise UnexpectedAnswerException(f\"expected 1 or 2, got {result}\")\nutil.UnexpectedAnswerException: expected 1 or 2, got  \n\nThe above exception was the direct cause of the following exception:\n\nTraceback (most recent call last):\n  File \"/work/home/fd15hava/tinypaper-mpt/scripts/experiments/run.py\", line 16, in _run_session\n    result = agent.play(session)\n             ^^^^^^^^^^^^^^^^^^^\n  File \"/home/fd15hava/.cache/pypoetry/virtualenvs/non-package-mode-zjkKA0Ca-py3.11/lib/python3.11/site-packages/tenacity/__init__.py\", line 289, in wrapped_f\n    return self(f, *args, **kw)\n           ^^^^^^^^^^^^^^^^^^^^\n  File \"/home/fd15hava/.cache/pypoetry/virtualenvs/non-package-mode-zjkKA0Ca-py3.11/lib/python3.11/site-packages/tenacity/__init__.py\", line 379, in __call__\n    do = self.iter(retry_state=retry_state)\n         ^^^^^^^^^^^^^^^^^^^^^^^^^^^^^^^^^^\n  File \"/home/fd15hava/.cache/pypoetry/virtualenvs/non-package-mode-zjkKA0Ca-py3.11/lib/python3.11/site-packages/tenacity/__init__.py\", line 326, in iter\n    raise retry_exc from fut.exception()\ntenacity.RetryError: RetryError[<Future at 0x14cdd4493b90 state=finished raised UnexpectedAnswerException>]\n",
      "Traceback (most recent call last):\n  File \"/home/fd15hava/.cache/pypoetry/virtualenvs/non-package-mode-zjkKA0Ca-py3.11/lib/python3.11/site-packages/tenacity/__init__.py\", line 382, in __call__\n    result = fn(*args, **kwargs)\n             ^^^^^^^^^^^^^^^^^^^\n  File \"/work/home/fd15hava/tinypaper-mpt/src/agent.py\", line 26, in play\n    answer = self._prompt(self._make_prompt(scenario))\n             ^^^^^^^^^^^^^^^^^^^^^^^^^^^^^^^^^^^^^^^^^\n  File \"/work/home/fd15hava/tinypaper-mpt/src/agent.py\", line 40, in _prompt\n    raise UnexpectedAnswerException(f\"expected 1 or 2, got {result}\")\nutil.UnexpectedAnswerException: expected 1 or 2, got  \n\nThe above exception was the direct cause of the following exception:\n\nTraceback (most recent call last):\n  File \"/work/home/fd15hava/tinypaper-mpt/scripts/experiments/run.py\", line 16, in _run_session\n    result = agent.play(session)\n             ^^^^^^^^^^^^^^^^^^^\n  File \"/home/fd15hava/.cache/pypoetry/virtualenvs/non-package-mode-zjkKA0Ca-py3.11/lib/python3.11/site-packages/tenacity/__init__.py\", line 289, in wrapped_f\n    return self(f, *args, **kw)\n           ^^^^^^^^^^^^^^^^^^^^\n  File \"/home/fd15hava/.cache/pypoetry/virtualenvs/non-package-mode-zjkKA0Ca-py3.11/lib/python3.11/site-packages/tenacity/__init__.py\", line 379, in __call__\n    do = self.iter(retry_state=retry_state)\n         ^^^^^^^^^^^^^^^^^^^^^^^^^^^^^^^^^^\n  File \"/home/fd15hava/.cache/pypoetry/virtualenvs/non-package-mode-zjkKA0Ca-py3.11/lib/python3.11/site-packages/tenacity/__init__.py\", line 326, in iter\n    raise retry_exc from fut.exception()\ntenacity.RetryError: RetryError[<Future at 0x14cdd4518090 state=finished raised UnexpectedAnswerException>]\n",
      "Traceback (most recent call last):\n  File \"/home/fd15hava/.cache/pypoetry/virtualenvs/non-package-mode-zjkKA0Ca-py3.11/lib/python3.11/site-packages/tenacity/__init__.py\", line 382, in __call__\n    result = fn(*args, **kwargs)\n             ^^^^^^^^^^^^^^^^^^^\n  File \"/work/home/fd15hava/tinypaper-mpt/src/agent.py\", line 26, in play\n    answer = self._prompt(self._make_prompt(scenario))\n             ^^^^^^^^^^^^^^^^^^^^^^^^^^^^^^^^^^^^^^^^^\n  File \"/work/home/fd15hava/tinypaper-mpt/src/agent.py\", line 40, in _prompt\n    raise UnexpectedAnswerException(f\"expected 1 or 2, got {result}\")\nutil.UnexpectedAnswerException: expected 1 or 2, got  \n\nThe above exception was the direct cause of the following exception:\n\nTraceback (most recent call last):\n  File \"/work/home/fd15hava/tinypaper-mpt/scripts/experiments/run.py\", line 16, in _run_session\n    result = agent.play(session)\n             ^^^^^^^^^^^^^^^^^^^\n  File \"/home/fd15hava/.cache/pypoetry/virtualenvs/non-package-mode-zjkKA0Ca-py3.11/lib/python3.11/site-packages/tenacity/__init__.py\", line 289, in wrapped_f\n    return self(f, *args, **kw)\n           ^^^^^^^^^^^^^^^^^^^^\n  File \"/home/fd15hava/.cache/pypoetry/virtualenvs/non-package-mode-zjkKA0Ca-py3.11/lib/python3.11/site-packages/tenacity/__init__.py\", line 379, in __call__\n    do = self.iter(retry_state=retry_state)\n         ^^^^^^^^^^^^^^^^^^^^^^^^^^^^^^^^^^\n  File \"/home/fd15hava/.cache/pypoetry/virtualenvs/non-package-mode-zjkKA0Ca-py3.11/lib/python3.11/site-packages/tenacity/__init__.py\", line 326, in iter\n    raise retry_exc from fut.exception()\ntenacity.RetryError: RetryError[<Future at 0x14cdd44a8450 state=finished raised UnexpectedAnswerException>]\n",
      "Traceback (most recent call last):\n  File \"/home/fd15hava/.cache/pypoetry/virtualenvs/non-package-mode-zjkKA0Ca-py3.11/lib/python3.11/site-packages/tenacity/__init__.py\", line 382, in __call__\n    result = fn(*args, **kwargs)\n             ^^^^^^^^^^^^^^^^^^^\n  File \"/work/home/fd15hava/tinypaper-mpt/src/agent.py\", line 26, in play\n    answer = self._prompt(self._make_prompt(scenario))\n             ^^^^^^^^^^^^^^^^^^^^^^^^^^^^^^^^^^^^^^^^^\n  File \"/work/home/fd15hava/tinypaper-mpt/src/agent.py\", line 40, in _prompt\n    raise UnexpectedAnswerException(f\"expected 1 or 2, got {result}\")\nutil.UnexpectedAnswerException: expected 1 or 2, got  \n\nThe above exception was the direct cause of the following exception:\n\nTraceback (most recent call last):\n  File \"/work/home/fd15hava/tinypaper-mpt/scripts/experiments/run.py\", line 16, in _run_session\n    result = agent.play(session)\n             ^^^^^^^^^^^^^^^^^^^\n  File \"/home/fd15hava/.cache/pypoetry/virtualenvs/non-package-mode-zjkKA0Ca-py3.11/lib/python3.11/site-packages/tenacity/__init__.py\", line 289, in wrapped_f\n    return self(f, *args, **kw)\n           ^^^^^^^^^^^^^^^^^^^^\n  File \"/home/fd15hava/.cache/pypoetry/virtualenvs/non-package-mode-zjkKA0Ca-py3.11/lib/python3.11/site-packages/tenacity/__init__.py\", line 379, in __call__\n    do = self.iter(retry_state=retry_state)\n         ^^^^^^^^^^^^^^^^^^^^^^^^^^^^^^^^^^\n  File \"/home/fd15hava/.cache/pypoetry/virtualenvs/non-package-mode-zjkKA0Ca-py3.11/lib/python3.11/site-packages/tenacity/__init__.py\", line 326, in iter\n    raise retry_exc from fut.exception()\ntenacity.RetryError: RetryError[<Future at 0x14cdd450c090 state=finished raised UnexpectedAnswerException>]\n",
      "Traceback (most recent call last):\n  File \"/home/fd15hava/.cache/pypoetry/virtualenvs/non-package-mode-zjkKA0Ca-py3.11/lib/python3.11/site-packages/tenacity/__init__.py\", line 382, in __call__\n    result = fn(*args, **kwargs)\n             ^^^^^^^^^^^^^^^^^^^\n  File \"/work/home/fd15hava/tinypaper-mpt/src/agent.py\", line 26, in play\n    answer = self._prompt(self._make_prompt(scenario))\n             ^^^^^^^^^^^^^^^^^^^^^^^^^^^^^^^^^^^^^^^^^\n  File \"/work/home/fd15hava/tinypaper-mpt/src/agent.py\", line 40, in _prompt\n    raise UnexpectedAnswerException(f\"expected 1 or 2, got {result}\")\nutil.UnexpectedAnswerException: expected 1 or 2, got  \n\nThe above exception was the direct cause of the following exception:\n\nTraceback (most recent call last):\n  File \"/work/home/fd15hava/tinypaper-mpt/scripts/experiments/run.py\", line 16, in _run_session\n    result = agent.play(session)\n             ^^^^^^^^^^^^^^^^^^^\n  File \"/home/fd15hava/.cache/pypoetry/virtualenvs/non-package-mode-zjkKA0Ca-py3.11/lib/python3.11/site-packages/tenacity/__init__.py\", line 289, in wrapped_f\n    return self(f, *args, **kw)\n           ^^^^^^^^^^^^^^^^^^^^\n  File \"/home/fd15hava/.cache/pypoetry/virtualenvs/non-package-mode-zjkKA0Ca-py3.11/lib/python3.11/site-packages/tenacity/__init__.py\", line 379, in __call__\n    do = self.iter(retry_state=retry_state)\n         ^^^^^^^^^^^^^^^^^^^^^^^^^^^^^^^^^^\n  File \"/home/fd15hava/.cache/pypoetry/virtualenvs/non-package-mode-zjkKA0Ca-py3.11/lib/python3.11/site-packages/tenacity/__init__.py\", line 326, in iter\n    raise retry_exc from fut.exception()\ntenacity.RetryError: RetryError[<Future at 0x14cdd4483590 state=finished raised UnexpectedAnswerException>]\n",
      "Traceback (most recent call last):\n  File \"/home/fd15hava/.cache/pypoetry/virtualenvs/non-package-mode-zjkKA0Ca-py3.11/lib/python3.11/site-packages/tenacity/__init__.py\", line 382, in __call__\n    result = fn(*args, **kwargs)\n             ^^^^^^^^^^^^^^^^^^^\n  File \"/work/home/fd15hava/tinypaper-mpt/src/agent.py\", line 26, in play\n    answer = self._prompt(self._make_prompt(scenario))\n             ^^^^^^^^^^^^^^^^^^^^^^^^^^^^^^^^^^^^^^^^^\n  File \"/work/home/fd15hava/tinypaper-mpt/src/agent.py\", line 40, in _prompt\n    raise UnexpectedAnswerException(f\"expected 1 or 2, got {result}\")\nutil.UnexpectedAnswerException: expected 1 or 2, got  \n\nThe above exception was the direct cause of the following exception:\n\nTraceback (most recent call last):\n  File \"/work/home/fd15hava/tinypaper-mpt/scripts/experiments/run.py\", line 16, in _run_session\n    result = agent.play(session)\n             ^^^^^^^^^^^^^^^^^^^\n  File \"/home/fd15hava/.cache/pypoetry/virtualenvs/non-package-mode-zjkKA0Ca-py3.11/lib/python3.11/site-packages/tenacity/__init__.py\", line 289, in wrapped_f\n    return self(f, *args, **kw)\n           ^^^^^^^^^^^^^^^^^^^^\n  File \"/home/fd15hava/.cache/pypoetry/virtualenvs/non-package-mode-zjkKA0Ca-py3.11/lib/python3.11/site-packages/tenacity/__init__.py\", line 379, in __call__\n    do = self.iter(retry_state=retry_state)\n         ^^^^^^^^^^^^^^^^^^^^^^^^^^^^^^^^^^\n  File \"/home/fd15hava/.cache/pypoetry/virtualenvs/non-package-mode-zjkKA0Ca-py3.11/lib/python3.11/site-packages/tenacity/__init__.py\", line 326, in iter\n    raise retry_exc from fut.exception()\ntenacity.RetryError: RetryError[<Future at 0x14ce57f429d0 state=finished raised UnexpectedAnswerException>]\n",
      "Traceback (most recent call last):\n  File \"/home/fd15hava/.cache/pypoetry/virtualenvs/non-package-mode-zjkKA0Ca-py3.11/lib/python3.11/site-packages/tenacity/__init__.py\", line 382, in __call__\n    result = fn(*args, **kwargs)\n             ^^^^^^^^^^^^^^^^^^^\n  File \"/work/home/fd15hava/tinypaper-mpt/src/agent.py\", line 26, in play\n    answer = self._prompt(self._make_prompt(scenario))\n             ^^^^^^^^^^^^^^^^^^^^^^^^^^^^^^^^^^^^^^^^^\n  File \"/work/home/fd15hava/tinypaper-mpt/src/agent.py\", line 40, in _prompt\n    raise UnexpectedAnswerException(f\"expected 1 or 2, got {result}\")\nutil.UnexpectedAnswerException: expected 1 or 2, got  \n\nThe above exception was the direct cause of the following exception:\n\nTraceback (most recent call last):\n  File \"/work/home/fd15hava/tinypaper-mpt/scripts/experiments/run.py\", line 16, in _run_session\n    result = agent.play(session)\n             ^^^^^^^^^^^^^^^^^^^\n  File \"/home/fd15hava/.cache/pypoetry/virtualenvs/non-package-mode-zjkKA0Ca-py3.11/lib/python3.11/site-packages/tenacity/__init__.py\", line 289, in wrapped_f\n    return self(f, *args, **kw)\n           ^^^^^^^^^^^^^^^^^^^^\n  File \"/home/fd15hava/.cache/pypoetry/virtualenvs/non-package-mode-zjkKA0Ca-py3.11/lib/python3.11/site-packages/tenacity/__init__.py\", line 379, in __call__\n    do = self.iter(retry_state=retry_state)\n         ^^^^^^^^^^^^^^^^^^^^^^^^^^^^^^^^^^\n  File \"/home/fd15hava/.cache/pypoetry/virtualenvs/non-package-mode-zjkKA0Ca-py3.11/lib/python3.11/site-packages/tenacity/__init__.py\", line 326, in iter\n    raise retry_exc from fut.exception()\ntenacity.RetryError: RetryError[<Future at 0x14ce5c828510 state=finished raised UnexpectedAnswerException>]\n",
      "Traceback (most recent call last):\n  File \"/home/fd15hava/.cache/pypoetry/virtualenvs/non-package-mode-zjkKA0Ca-py3.11/lib/python3.11/site-packages/tenacity/__init__.py\", line 382, in __call__\n    result = fn(*args, **kwargs)\n             ^^^^^^^^^^^^^^^^^^^\n  File \"/work/home/fd15hava/tinypaper-mpt/src/agent.py\", line 26, in play\n    answer = self._prompt(self._make_prompt(scenario))\n             ^^^^^^^^^^^^^^^^^^^^^^^^^^^^^^^^^^^^^^^^^\n  File \"/work/home/fd15hava/tinypaper-mpt/src/agent.py\", line 40, in _prompt\n    raise UnexpectedAnswerException(f\"expected 1 or 2, got {result}\")\nutil.UnexpectedAnswerException: expected 1 or 2, got  \n\nThe above exception was the direct cause of the following exception:\n\nTraceback (most recent call last):\n  File \"/work/home/fd15hava/tinypaper-mpt/scripts/experiments/run.py\", line 16, in _run_session\n    result = agent.play(session)\n             ^^^^^^^^^^^^^^^^^^^\n  File \"/home/fd15hava/.cache/pypoetry/virtualenvs/non-package-mode-zjkKA0Ca-py3.11/lib/python3.11/site-packages/tenacity/__init__.py\", line 289, in wrapped_f\n    return self(f, *args, **kw)\n           ^^^^^^^^^^^^^^^^^^^^\n  File \"/home/fd15hava/.cache/pypoetry/virtualenvs/non-package-mode-zjkKA0Ca-py3.11/lib/python3.11/site-packages/tenacity/__init__.py\", line 379, in __call__\n    do = self.iter(retry_state=retry_state)\n         ^^^^^^^^^^^^^^^^^^^^^^^^^^^^^^^^^^\n  File \"/home/fd15hava/.cache/pypoetry/virtualenvs/non-package-mode-zjkKA0Ca-py3.11/lib/python3.11/site-packages/tenacity/__init__.py\", line 326, in iter\n    raise retry_exc from fut.exception()\ntenacity.RetryError: RetryError[<Future at 0x14cdd44fe7d0 state=finished raised UnexpectedAnswerException>]\n",
      "Traceback (most recent call last):\n  File \"/home/fd15hava/.cache/pypoetry/virtualenvs/non-package-mode-zjkKA0Ca-py3.11/lib/python3.11/site-packages/tenacity/__init__.py\", line 382, in __call__\n    result = fn(*args, **kwargs)\n             ^^^^^^^^^^^^^^^^^^^\n  File \"/work/home/fd15hava/tinypaper-mpt/src/agent.py\", line 26, in play\n    answer = self._prompt(self._make_prompt(scenario))\n             ^^^^^^^^^^^^^^^^^^^^^^^^^^^^^^^^^^^^^^^^^\n  File \"/work/home/fd15hava/tinypaper-mpt/src/agent.py\", line 40, in _prompt\n    raise UnexpectedAnswerException(f\"expected 1 or 2, got {result}\")\nutil.UnexpectedAnswerException: expected 1 or 2, got  \n\nThe above exception was the direct cause of the following exception:\n\nTraceback (most recent call last):\n  File \"/work/home/fd15hava/tinypaper-mpt/scripts/experiments/run.py\", line 16, in _run_session\n    result = agent.play(session)\n             ^^^^^^^^^^^^^^^^^^^\n  File \"/home/fd15hava/.cache/pypoetry/virtualenvs/non-package-mode-zjkKA0Ca-py3.11/lib/python3.11/site-packages/tenacity/__init__.py\", line 289, in wrapped_f\n    return self(f, *args, **kw)\n           ^^^^^^^^^^^^^^^^^^^^\n  File \"/home/fd15hava/.cache/pypoetry/virtualenvs/non-package-mode-zjkKA0Ca-py3.11/lib/python3.11/site-packages/tenacity/__init__.py\", line 379, in __call__\n    do = self.iter(retry_state=retry_state)\n         ^^^^^^^^^^^^^^^^^^^^^^^^^^^^^^^^^^\n  File \"/home/fd15hava/.cache/pypoetry/virtualenvs/non-package-mode-zjkKA0Ca-py3.11/lib/python3.11/site-packages/tenacity/__init__.py\", line 326, in iter\n    raise retry_exc from fut.exception()\ntenacity.RetryError: RetryError[<Future at 0x14cdd460be90 state=finished raised UnexpectedAnswerException>]\n",
      "Traceback (most recent call last):\n  File \"/home/fd15hava/.cache/pypoetry/virtualenvs/non-package-mode-zjkKA0Ca-py3.11/lib/python3.11/site-packages/tenacity/__init__.py\", line 382, in __call__\n    result = fn(*args, **kwargs)\n             ^^^^^^^^^^^^^^^^^^^\n  File \"/work/home/fd15hava/tinypaper-mpt/src/agent.py\", line 26, in play\n    answer = self._prompt(self._make_prompt(scenario))\n             ^^^^^^^^^^^^^^^^^^^^^^^^^^^^^^^^^^^^^^^^^\n  File \"/work/home/fd15hava/tinypaper-mpt/src/agent.py\", line 40, in _prompt\n    raise UnexpectedAnswerException(f\"expected 1 or 2, got {result}\")\nutil.UnexpectedAnswerException: expected 1 or 2, got  \n\nThe above exception was the direct cause of the following exception:\n\nTraceback (most recent call last):\n  File \"/work/home/fd15hava/tinypaper-mpt/scripts/experiments/run.py\", line 16, in _run_session\n    result = agent.play(session)\n             ^^^^^^^^^^^^^^^^^^^\n  File \"/home/fd15hava/.cache/pypoetry/virtualenvs/non-package-mode-zjkKA0Ca-py3.11/lib/python3.11/site-packages/tenacity/__init__.py\", line 289, in wrapped_f\n    return self(f, *args, **kw)\n           ^^^^^^^^^^^^^^^^^^^^\n  File \"/home/fd15hava/.cache/pypoetry/virtualenvs/non-package-mode-zjkKA0Ca-py3.11/lib/python3.11/site-packages/tenacity/__init__.py\", line 379, in __call__\n    do = self.iter(retry_state=retry_state)\n         ^^^^^^^^^^^^^^^^^^^^^^^^^^^^^^^^^^\n  File \"/home/fd15hava/.cache/pypoetry/virtualenvs/non-package-mode-zjkKA0Ca-py3.11/lib/python3.11/site-packages/tenacity/__init__.py\", line 326, in iter\n    raise retry_exc from fut.exception()\ntenacity.RetryError: RetryError[<Future at 0x14cdd4482790 state=finished raised UnexpectedAnswerException>]\n",
      "Traceback (most recent call last):\n  File \"/home/fd15hava/.cache/pypoetry/virtualenvs/non-package-mode-zjkKA0Ca-py3.11/lib/python3.11/site-packages/tenacity/__init__.py\", line 382, in __call__\n    result = fn(*args, **kwargs)\n             ^^^^^^^^^^^^^^^^^^^\n  File \"/work/home/fd15hava/tinypaper-mpt/src/agent.py\", line 26, in play\n    answer = self._prompt(self._make_prompt(scenario))\n             ^^^^^^^^^^^^^^^^^^^^^^^^^^^^^^^^^^^^^^^^^\n  File \"/work/home/fd15hava/tinypaper-mpt/src/agent.py\", line 40, in _prompt\n    raise UnexpectedAnswerException(f\"expected 1 or 2, got {result}\")\nutil.UnexpectedAnswerException: expected 1 or 2, got  \n\nThe above exception was the direct cause of the following exception:\n\nTraceback (most recent call last):\n  File \"/work/home/fd15hava/tinypaper-mpt/scripts/experiments/run.py\", line 16, in _run_session\n    result = agent.play(session)\n             ^^^^^^^^^^^^^^^^^^^\n  File \"/home/fd15hava/.cache/pypoetry/virtualenvs/non-package-mode-zjkKA0Ca-py3.11/lib/python3.11/site-packages/tenacity/__init__.py\", line 289, in wrapped_f\n    return self(f, *args, **kw)\n           ^^^^^^^^^^^^^^^^^^^^\n  File \"/home/fd15hava/.cache/pypoetry/virtualenvs/non-package-mode-zjkKA0Ca-py3.11/lib/python3.11/site-packages/tenacity/__init__.py\", line 379, in __call__\n    do = self.iter(retry_state=retry_state)\n         ^^^^^^^^^^^^^^^^^^^^^^^^^^^^^^^^^^\n  File \"/home/fd15hava/.cache/pypoetry/virtualenvs/non-package-mode-zjkKA0Ca-py3.11/lib/python3.11/site-packages/tenacity/__init__.py\", line 326, in iter\n    raise retry_exc from fut.exception()\ntenacity.RetryError: RetryError[<Future at 0x14cdd450d490 state=finished raised UnexpectedAnswerException>]\n",
      "Traceback (most recent call last):\n  File \"/home/fd15hava/.cache/pypoetry/virtualenvs/non-package-mode-zjkKA0Ca-py3.11/lib/python3.11/site-packages/tenacity/__init__.py\", line 382, in __call__\n    result = fn(*args, **kwargs)\n             ^^^^^^^^^^^^^^^^^^^\n  File \"/work/home/fd15hava/tinypaper-mpt/src/agent.py\", line 26, in play\n    answer = self._prompt(self._make_prompt(scenario))\n             ^^^^^^^^^^^^^^^^^^^^^^^^^^^^^^^^^^^^^^^^^\n  File \"/work/home/fd15hava/tinypaper-mpt/src/agent.py\", line 40, in _prompt\n    raise UnexpectedAnswerException(f\"expected 1 or 2, got {result}\")\nutil.UnexpectedAnswerException: expected 1 or 2, got  \n\nThe above exception was the direct cause of the following exception:\n\nTraceback (most recent call last):\n  File \"/work/home/fd15hava/tinypaper-mpt/scripts/experiments/run.py\", line 16, in _run_session\n    result = agent.play(session)\n             ^^^^^^^^^^^^^^^^^^^\n  File \"/home/fd15hava/.cache/pypoetry/virtualenvs/non-package-mode-zjkKA0Ca-py3.11/lib/python3.11/site-packages/tenacity/__init__.py\", line 289, in wrapped_f\n    return self(f, *args, **kw)\n           ^^^^^^^^^^^^^^^^^^^^\n  File \"/home/fd15hava/.cache/pypoetry/virtualenvs/non-package-mode-zjkKA0Ca-py3.11/lib/python3.11/site-packages/tenacity/__init__.py\", line 379, in __call__\n    do = self.iter(retry_state=retry_state)\n         ^^^^^^^^^^^^^^^^^^^^^^^^^^^^^^^^^^\n  File \"/home/fd15hava/.cache/pypoetry/virtualenvs/non-package-mode-zjkKA0Ca-py3.11/lib/python3.11/site-packages/tenacity/__init__.py\", line 326, in iter\n    raise retry_exc from fut.exception()\ntenacity.RetryError: RetryError[<Future at 0x14cdd446ffd0 state=finished raised UnexpectedAnswerException>]\n",
      "Traceback (most recent call last):\n  File \"/home/fd15hava/.cache/pypoetry/virtualenvs/non-package-mode-zjkKA0Ca-py3.11/lib/python3.11/site-packages/tenacity/__init__.py\", line 382, in __call__\n    result = fn(*args, **kwargs)\n             ^^^^^^^^^^^^^^^^^^^\n  File \"/work/home/fd15hava/tinypaper-mpt/src/agent.py\", line 26, in play\n    answer = self._prompt(self._make_prompt(scenario))\n             ^^^^^^^^^^^^^^^^^^^^^^^^^^^^^^^^^^^^^^^^^\n  File \"/work/home/fd15hava/tinypaper-mpt/src/agent.py\", line 40, in _prompt\n    raise UnexpectedAnswerException(f\"expected 1 or 2, got {result}\")\nutil.UnexpectedAnswerException: expected 1 or 2, got  \n\nThe above exception was the direct cause of the following exception:\n\nTraceback (most recent call last):\n  File \"/work/home/fd15hava/tinypaper-mpt/scripts/experiments/run.py\", line 16, in _run_session\n    result = agent.play(session)\n             ^^^^^^^^^^^^^^^^^^^\n  File \"/home/fd15hava/.cache/pypoetry/virtualenvs/non-package-mode-zjkKA0Ca-py3.11/lib/python3.11/site-packages/tenacity/__init__.py\", line 289, in wrapped_f\n    return self(f, *args, **kw)\n           ^^^^^^^^^^^^^^^^^^^^\n  File \"/home/fd15hava/.cache/pypoetry/virtualenvs/non-package-mode-zjkKA0Ca-py3.11/lib/python3.11/site-packages/tenacity/__init__.py\", line 379, in __call__\n    do = self.iter(retry_state=retry_state)\n         ^^^^^^^^^^^^^^^^^^^^^^^^^^^^^^^^^^\n  File \"/home/fd15hava/.cache/pypoetry/virtualenvs/non-package-mode-zjkKA0Ca-py3.11/lib/python3.11/site-packages/tenacity/__init__.py\", line 326, in iter\n    raise retry_exc from fut.exception()\ntenacity.RetryError: RetryError[<Future at 0x14cdd4482f90 state=finished raised UnexpectedAnswerException>]\n",
      "Traceback (most recent call last):\n  File \"/home/fd15hava/.cache/pypoetry/virtualenvs/non-package-mode-zjkKA0Ca-py3.11/lib/python3.11/site-packages/tenacity/__init__.py\", line 382, in __call__\n    result = fn(*args, **kwargs)\n             ^^^^^^^^^^^^^^^^^^^\n  File \"/work/home/fd15hava/tinypaper-mpt/src/agent.py\", line 26, in play\n    answer = self._prompt(self._make_prompt(scenario))\n             ^^^^^^^^^^^^^^^^^^^^^^^^^^^^^^^^^^^^^^^^^\n  File \"/work/home/fd15hava/tinypaper-mpt/src/agent.py\", line 40, in _prompt\n    raise UnexpectedAnswerException(f\"expected 1 or 2, got {result}\")\nutil.UnexpectedAnswerException: expected 1 or 2, got  \n\nThe above exception was the direct cause of the following exception:\n\nTraceback (most recent call last):\n  File \"/work/home/fd15hava/tinypaper-mpt/scripts/experiments/run.py\", line 16, in _run_session\n    result = agent.play(session)\n             ^^^^^^^^^^^^^^^^^^^\n  File \"/home/fd15hava/.cache/pypoetry/virtualenvs/non-package-mode-zjkKA0Ca-py3.11/lib/python3.11/site-packages/tenacity/__init__.py\", line 289, in wrapped_f\n    return self(f, *args, **kw)\n           ^^^^^^^^^^^^^^^^^^^^\n  File \"/home/fd15hava/.cache/pypoetry/virtualenvs/non-package-mode-zjkKA0Ca-py3.11/lib/python3.11/site-packages/tenacity/__init__.py\", line 379, in __call__\n    do = self.iter(retry_state=retry_state)\n         ^^^^^^^^^^^^^^^^^^^^^^^^^^^^^^^^^^\n  File \"/home/fd15hava/.cache/pypoetry/virtualenvs/non-package-mode-zjkKA0Ca-py3.11/lib/python3.11/site-packages/tenacity/__init__.py\", line 326, in iter\n    raise retry_exc from fut.exception()\ntenacity.RetryError: RetryError[<Future at 0x14cdd460bc10 state=finished raised UnexpectedAnswerException>]\n",
      "Traceback (most recent call last):\n  File \"/home/fd15hava/.cache/pypoetry/virtualenvs/non-package-mode-zjkKA0Ca-py3.11/lib/python3.11/site-packages/tenacity/__init__.py\", line 382, in __call__\n    result = fn(*args, **kwargs)\n             ^^^^^^^^^^^^^^^^^^^\n  File \"/work/home/fd15hava/tinypaper-mpt/src/agent.py\", line 26, in play\n    answer = self._prompt(self._make_prompt(scenario))\n             ^^^^^^^^^^^^^^^^^^^^^^^^^^^^^^^^^^^^^^^^^\n  File \"/work/home/fd15hava/tinypaper-mpt/src/agent.py\", line 40, in _prompt\n    raise UnexpectedAnswerException(f\"expected 1 or 2, got {result}\")\nutil.UnexpectedAnswerException: expected 1 or 2, got  \n\nThe above exception was the direct cause of the following exception:\n\nTraceback (most recent call last):\n  File \"/work/home/fd15hava/tinypaper-mpt/scripts/experiments/run.py\", line 16, in _run_session\n    result = agent.play(session)\n             ^^^^^^^^^^^^^^^^^^^\n  File \"/home/fd15hava/.cache/pypoetry/virtualenvs/non-package-mode-zjkKA0Ca-py3.11/lib/python3.11/site-packages/tenacity/__init__.py\", line 289, in wrapped_f\n    return self(f, *args, **kw)\n           ^^^^^^^^^^^^^^^^^^^^\n  File \"/home/fd15hava/.cache/pypoetry/virtualenvs/non-package-mode-zjkKA0Ca-py3.11/lib/python3.11/site-packages/tenacity/__init__.py\", line 379, in __call__\n    do = self.iter(retry_state=retry_state)\n         ^^^^^^^^^^^^^^^^^^^^^^^^^^^^^^^^^^\n  File \"/home/fd15hava/.cache/pypoetry/virtualenvs/non-package-mode-zjkKA0Ca-py3.11/lib/python3.11/site-packages/tenacity/__init__.py\", line 326, in iter\n    raise retry_exc from fut.exception()\ntenacity.RetryError: RetryError[<Future at 0x14ce5cc9a6d0 state=finished raised UnexpectedAnswerException>]\n",
      "Traceback (most recent call last):\n  File \"/home/fd15hava/.cache/pypoetry/virtualenvs/non-package-mode-zjkKA0Ca-py3.11/lib/python3.11/site-packages/tenacity/__init__.py\", line 382, in __call__\n    result = fn(*args, **kwargs)\n             ^^^^^^^^^^^^^^^^^^^\n  File \"/work/home/fd15hava/tinypaper-mpt/src/agent.py\", line 26, in play\n    answer = self._prompt(self._make_prompt(scenario))\n             ^^^^^^^^^^^^^^^^^^^^^^^^^^^^^^^^^^^^^^^^^\n  File \"/work/home/fd15hava/tinypaper-mpt/src/agent.py\", line 40, in _prompt\n    raise UnexpectedAnswerException(f\"expected 1 or 2, got {result}\")\nutil.UnexpectedAnswerException: expected 1 or 2, got  \n\nThe above exception was the direct cause of the following exception:\n\nTraceback (most recent call last):\n  File \"/work/home/fd15hava/tinypaper-mpt/scripts/experiments/run.py\", line 16, in _run_session\n    result = agent.play(session)\n             ^^^^^^^^^^^^^^^^^^^\n  File \"/home/fd15hava/.cache/pypoetry/virtualenvs/non-package-mode-zjkKA0Ca-py3.11/lib/python3.11/site-packages/tenacity/__init__.py\", line 289, in wrapped_f\n    return self(f, *args, **kw)\n           ^^^^^^^^^^^^^^^^^^^^\n  File \"/home/fd15hava/.cache/pypoetry/virtualenvs/non-package-mode-zjkKA0Ca-py3.11/lib/python3.11/site-packages/tenacity/__init__.py\", line 379, in __call__\n    do = self.iter(retry_state=retry_state)\n         ^^^^^^^^^^^^^^^^^^^^^^^^^^^^^^^^^^\n  File \"/home/fd15hava/.cache/pypoetry/virtualenvs/non-package-mode-zjkKA0Ca-py3.11/lib/python3.11/site-packages/tenacity/__init__.py\", line 326, in iter\n    raise retry_exc from fut.exception()\ntenacity.RetryError: RetryError[<Future at 0x14ce5c828510 state=finished raised UnexpectedAnswerException>]\n",
      "Traceback (most recent call last):\n  File \"/home/fd15hava/.cache/pypoetry/virtualenvs/non-package-mode-zjkKA0Ca-py3.11/lib/python3.11/site-packages/tenacity/__init__.py\", line 382, in __call__\n    result = fn(*args, **kwargs)\n             ^^^^^^^^^^^^^^^^^^^\n  File \"/work/home/fd15hava/tinypaper-mpt/src/agent.py\", line 26, in play\n    answer = self._prompt(self._make_prompt(scenario))\n             ^^^^^^^^^^^^^^^^^^^^^^^^^^^^^^^^^^^^^^^^^\n  File \"/work/home/fd15hava/tinypaper-mpt/src/agent.py\", line 40, in _prompt\n    raise UnexpectedAnswerException(f\"expected 1 or 2, got {result}\")\nutil.UnexpectedAnswerException: expected 1 or 2, got  \n\nThe above exception was the direct cause of the following exception:\n\nTraceback (most recent call last):\n  File \"/work/home/fd15hava/tinypaper-mpt/scripts/experiments/run.py\", line 16, in _run_session\n    result = agent.play(session)\n             ^^^^^^^^^^^^^^^^^^^\n  File \"/home/fd15hava/.cache/pypoetry/virtualenvs/non-package-mode-zjkKA0Ca-py3.11/lib/python3.11/site-packages/tenacity/__init__.py\", line 289, in wrapped_f\n    return self(f, *args, **kw)\n           ^^^^^^^^^^^^^^^^^^^^\n  File \"/home/fd15hava/.cache/pypoetry/virtualenvs/non-package-mode-zjkKA0Ca-py3.11/lib/python3.11/site-packages/tenacity/__init__.py\", line 379, in __call__\n    do = self.iter(retry_state=retry_state)\n         ^^^^^^^^^^^^^^^^^^^^^^^^^^^^^^^^^^\n  File \"/home/fd15hava/.cache/pypoetry/virtualenvs/non-package-mode-zjkKA0Ca-py3.11/lib/python3.11/site-packages/tenacity/__init__.py\", line 326, in iter\n    raise retry_exc from fut.exception()\ntenacity.RetryError: RetryError[<Future at 0x14ce5c829b90 state=finished raised UnexpectedAnswerException>]\n",
      "Traceback (most recent call last):\n  File \"/home/fd15hava/.cache/pypoetry/virtualenvs/non-package-mode-zjkKA0Ca-py3.11/lib/python3.11/site-packages/tenacity/__init__.py\", line 382, in __call__\n    result = fn(*args, **kwargs)\n             ^^^^^^^^^^^^^^^^^^^\n  File \"/work/home/fd15hava/tinypaper-mpt/src/agent.py\", line 26, in play\n    answer = self._prompt(self._make_prompt(scenario))\n             ^^^^^^^^^^^^^^^^^^^^^^^^^^^^^^^^^^^^^^^^^\n  File \"/work/home/fd15hava/tinypaper-mpt/src/agent.py\", line 40, in _prompt\n    raise UnexpectedAnswerException(f\"expected 1 or 2, got {result}\")\nutil.UnexpectedAnswerException: expected 1 or 2, got  \n\nThe above exception was the direct cause of the following exception:\n\nTraceback (most recent call last):\n  File \"/work/home/fd15hava/tinypaper-mpt/scripts/experiments/run.py\", line 16, in _run_session\n    result = agent.play(session)\n             ^^^^^^^^^^^^^^^^^^^\n  File \"/home/fd15hava/.cache/pypoetry/virtualenvs/non-package-mode-zjkKA0Ca-py3.11/lib/python3.11/site-packages/tenacity/__init__.py\", line 289, in wrapped_f\n    return self(f, *args, **kw)\n           ^^^^^^^^^^^^^^^^^^^^\n  File \"/home/fd15hava/.cache/pypoetry/virtualenvs/non-package-mode-zjkKA0Ca-py3.11/lib/python3.11/site-packages/tenacity/__init__.py\", line 379, in __call__\n    do = self.iter(retry_state=retry_state)\n         ^^^^^^^^^^^^^^^^^^^^^^^^^^^^^^^^^^\n  File \"/home/fd15hava/.cache/pypoetry/virtualenvs/non-package-mode-zjkKA0Ca-py3.11/lib/python3.11/site-packages/tenacity/__init__.py\", line 326, in iter\n    raise retry_exc from fut.exception()\ntenacity.RetryError: RetryError[<Future at 0x14cdd4481010 state=finished raised UnexpectedAnswerException>]\n",
      "Traceback (most recent call last):\n  File \"/home/fd15hava/.cache/pypoetry/virtualenvs/non-package-mode-zjkKA0Ca-py3.11/lib/python3.11/site-packages/tenacity/__init__.py\", line 382, in __call__\n    result = fn(*args, **kwargs)\n             ^^^^^^^^^^^^^^^^^^^\n  File \"/work/home/fd15hava/tinypaper-mpt/src/agent.py\", line 26, in play\n    answer = self._prompt(self._make_prompt(scenario))\n             ^^^^^^^^^^^^^^^^^^^^^^^^^^^^^^^^^^^^^^^^^\n  File \"/work/home/fd15hava/tinypaper-mpt/src/agent.py\", line 40, in _prompt\n    raise UnexpectedAnswerException(f\"expected 1 or 2, got {result}\")\nutil.UnexpectedAnswerException: expected 1 or 2, got  \n\nThe above exception was the direct cause of the following exception:\n\nTraceback (most recent call last):\n  File \"/work/home/fd15hava/tinypaper-mpt/scripts/experiments/run.py\", line 16, in _run_session\n    result = agent.play(session)\n             ^^^^^^^^^^^^^^^^^^^\n  File \"/home/fd15hava/.cache/pypoetry/virtualenvs/non-package-mode-zjkKA0Ca-py3.11/lib/python3.11/site-packages/tenacity/__init__.py\", line 289, in wrapped_f\n    return self(f, *args, **kw)\n           ^^^^^^^^^^^^^^^^^^^^\n  File \"/home/fd15hava/.cache/pypoetry/virtualenvs/non-package-mode-zjkKA0Ca-py3.11/lib/python3.11/site-packages/tenacity/__init__.py\", line 379, in __call__\n    do = self.iter(retry_state=retry_state)\n         ^^^^^^^^^^^^^^^^^^^^^^^^^^^^^^^^^^\n  File \"/home/fd15hava/.cache/pypoetry/virtualenvs/non-package-mode-zjkKA0Ca-py3.11/lib/python3.11/site-packages/tenacity/__init__.py\", line 326, in iter\n    raise retry_exc from fut.exception()\ntenacity.RetryError: RetryError[<Future at 0x14cdd4480990 state=finished raised UnexpectedAnswerException>]\n",
      "Traceback (most recent call last):\n  File \"/home/fd15hava/.cache/pypoetry/virtualenvs/non-package-mode-zjkKA0Ca-py3.11/lib/python3.11/site-packages/tenacity/__init__.py\", line 382, in __call__\n    result = fn(*args, **kwargs)\n             ^^^^^^^^^^^^^^^^^^^\n  File \"/work/home/fd15hava/tinypaper-mpt/src/agent.py\", line 26, in play\n    answer = self._prompt(self._make_prompt(scenario))\n             ^^^^^^^^^^^^^^^^^^^^^^^^^^^^^^^^^^^^^^^^^\n  File \"/work/home/fd15hava/tinypaper-mpt/src/agent.py\", line 40, in _prompt\n    raise UnexpectedAnswerException(f\"expected 1 or 2, got {result}\")\nutil.UnexpectedAnswerException: expected 1 or 2, got  \n\nThe above exception was the direct cause of the following exception:\n\nTraceback (most recent call last):\n  File \"/work/home/fd15hava/tinypaper-mpt/scripts/experiments/run.py\", line 16, in _run_session\n    result = agent.play(session)\n             ^^^^^^^^^^^^^^^^^^^\n  File \"/home/fd15hava/.cache/pypoetry/virtualenvs/non-package-mode-zjkKA0Ca-py3.11/lib/python3.11/site-packages/tenacity/__init__.py\", line 289, in wrapped_f\n    return self(f, *args, **kw)\n           ^^^^^^^^^^^^^^^^^^^^\n  File \"/home/fd15hava/.cache/pypoetry/virtualenvs/non-package-mode-zjkKA0Ca-py3.11/lib/python3.11/site-packages/tenacity/__init__.py\", line 379, in __call__\n    do = self.iter(retry_state=retry_state)\n         ^^^^^^^^^^^^^^^^^^^^^^^^^^^^^^^^^^\n  File \"/home/fd15hava/.cache/pypoetry/virtualenvs/non-package-mode-zjkKA0Ca-py3.11/lib/python3.11/site-packages/tenacity/__init__.py\", line 326, in iter\n    raise retry_exc from fut.exception()\ntenacity.RetryError: RetryError[<Future at 0x14cdd44fda90 state=finished raised UnexpectedAnswerException>]\n",
      "Traceback (most recent call last):\n  File \"/home/fd15hava/.cache/pypoetry/virtualenvs/non-package-mode-zjkKA0Ca-py3.11/lib/python3.11/site-packages/tenacity/__init__.py\", line 382, in __call__\n    result = fn(*args, **kwargs)\n             ^^^^^^^^^^^^^^^^^^^\n  File \"/work/home/fd15hava/tinypaper-mpt/src/agent.py\", line 26, in play\n    answer = self._prompt(self._make_prompt(scenario))\n             ^^^^^^^^^^^^^^^^^^^^^^^^^^^^^^^^^^^^^^^^^\n  File \"/work/home/fd15hava/tinypaper-mpt/src/agent.py\", line 40, in _prompt\n    raise UnexpectedAnswerException(f\"expected 1 or 2, got {result}\")\nutil.UnexpectedAnswerException: expected 1 or 2, got  \n\nThe above exception was the direct cause of the following exception:\n\nTraceback (most recent call last):\n  File \"/work/home/fd15hava/tinypaper-mpt/scripts/experiments/run.py\", line 16, in _run_session\n    result = agent.play(session)\n             ^^^^^^^^^^^^^^^^^^^\n  File \"/home/fd15hava/.cache/pypoetry/virtualenvs/non-package-mode-zjkKA0Ca-py3.11/lib/python3.11/site-packages/tenacity/__init__.py\", line 289, in wrapped_f\n    return self(f, *args, **kw)\n           ^^^^^^^^^^^^^^^^^^^^\n  File \"/home/fd15hava/.cache/pypoetry/virtualenvs/non-package-mode-zjkKA0Ca-py3.11/lib/python3.11/site-packages/tenacity/__init__.py\", line 379, in __call__\n    do = self.iter(retry_state=retry_state)\n         ^^^^^^^^^^^^^^^^^^^^^^^^^^^^^^^^^^\n  File \"/home/fd15hava/.cache/pypoetry/virtualenvs/non-package-mode-zjkKA0Ca-py3.11/lib/python3.11/site-packages/tenacity/__init__.py\", line 326, in iter\n    raise retry_exc from fut.exception()\ntenacity.RetryError: RetryError[<Future at 0x14cdd44fd6d0 state=finished raised UnexpectedAnswerException>]\n",
      "Traceback (most recent call last):\n  File \"/home/fd15hava/.cache/pypoetry/virtualenvs/non-package-mode-zjkKA0Ca-py3.11/lib/python3.11/site-packages/tenacity/__init__.py\", line 382, in __call__\n    result = fn(*args, **kwargs)\n             ^^^^^^^^^^^^^^^^^^^\n  File \"/work/home/fd15hava/tinypaper-mpt/src/agent.py\", line 26, in play\n    answer = self._prompt(self._make_prompt(scenario))\n             ^^^^^^^^^^^^^^^^^^^^^^^^^^^^^^^^^^^^^^^^^\n  File \"/work/home/fd15hava/tinypaper-mpt/src/agent.py\", line 40, in _prompt\n    raise UnexpectedAnswerException(f\"expected 1 or 2, got {result}\")\nutil.UnexpectedAnswerException: expected 1 or 2, got  \n\nThe above exception was the direct cause of the following exception:\n\nTraceback (most recent call last):\n  File \"/work/home/fd15hava/tinypaper-mpt/scripts/experiments/run.py\", line 16, in _run_session\n    result = agent.play(session)\n             ^^^^^^^^^^^^^^^^^^^\n  File \"/home/fd15hava/.cache/pypoetry/virtualenvs/non-package-mode-zjkKA0Ca-py3.11/lib/python3.11/site-packages/tenacity/__init__.py\", line 289, in wrapped_f\n    return self(f, *args, **kw)\n           ^^^^^^^^^^^^^^^^^^^^\n  File \"/home/fd15hava/.cache/pypoetry/virtualenvs/non-package-mode-zjkKA0Ca-py3.11/lib/python3.11/site-packages/tenacity/__init__.py\", line 379, in __call__\n    do = self.iter(retry_state=retry_state)\n         ^^^^^^^^^^^^^^^^^^^^^^^^^^^^^^^^^^\n  File \"/home/fd15hava/.cache/pypoetry/virtualenvs/non-package-mode-zjkKA0Ca-py3.11/lib/python3.11/site-packages/tenacity/__init__.py\", line 326, in iter\n    raise retry_exc from fut.exception()\ntenacity.RetryError: RetryError[<Future at 0x14cdd446f150 state=finished raised UnexpectedAnswerException>]\n",
      "Traceback (most recent call last):\n  File \"/home/fd15hava/.cache/pypoetry/virtualenvs/non-package-mode-zjkKA0Ca-py3.11/lib/python3.11/site-packages/tenacity/__init__.py\", line 382, in __call__\n    result = fn(*args, **kwargs)\n             ^^^^^^^^^^^^^^^^^^^\n  File \"/work/home/fd15hava/tinypaper-mpt/src/agent.py\", line 26, in play\n    answer = self._prompt(self._make_prompt(scenario))\n             ^^^^^^^^^^^^^^^^^^^^^^^^^^^^^^^^^^^^^^^^^\n  File \"/work/home/fd15hava/tinypaper-mpt/src/agent.py\", line 40, in _prompt\n    raise UnexpectedAnswerException(f\"expected 1 or 2, got {result}\")\nutil.UnexpectedAnswerException: expected 1 or 2, got  \n\nThe above exception was the direct cause of the following exception:\n\nTraceback (most recent call last):\n  File \"/work/home/fd15hava/tinypaper-mpt/scripts/experiments/run.py\", line 16, in _run_session\n    result = agent.play(session)\n             ^^^^^^^^^^^^^^^^^^^\n  File \"/home/fd15hava/.cache/pypoetry/virtualenvs/non-package-mode-zjkKA0Ca-py3.11/lib/python3.11/site-packages/tenacity/__init__.py\", line 289, in wrapped_f\n    return self(f, *args, **kw)\n           ^^^^^^^^^^^^^^^^^^^^\n  File \"/home/fd15hava/.cache/pypoetry/virtualenvs/non-package-mode-zjkKA0Ca-py3.11/lib/python3.11/site-packages/tenacity/__init__.py\", line 379, in __call__\n    do = self.iter(retry_state=retry_state)\n         ^^^^^^^^^^^^^^^^^^^^^^^^^^^^^^^^^^\n  File \"/home/fd15hava/.cache/pypoetry/virtualenvs/non-package-mode-zjkKA0Ca-py3.11/lib/python3.11/site-packages/tenacity/__init__.py\", line 326, in iter\n    raise retry_exc from fut.exception()\ntenacity.RetryError: RetryError[<Future at 0x14ce5c82bc10 state=finished raised UnexpectedAnswerException>]\n",
      "Traceback (most recent call last):\n  File \"/home/fd15hava/.cache/pypoetry/virtualenvs/non-package-mode-zjkKA0Ca-py3.11/lib/python3.11/site-packages/tenacity/__init__.py\", line 382, in __call__\n    result = fn(*args, **kwargs)\n             ^^^^^^^^^^^^^^^^^^^\n  File \"/work/home/fd15hava/tinypaper-mpt/src/agent.py\", line 26, in play\n    answer = self._prompt(self._make_prompt(scenario))\n             ^^^^^^^^^^^^^^^^^^^^^^^^^^^^^^^^^^^^^^^^^\n  File \"/work/home/fd15hava/tinypaper-mpt/src/agent.py\", line 40, in _prompt\n    raise UnexpectedAnswerException(f\"expected 1 or 2, got {result}\")\nutil.UnexpectedAnswerException: expected 1 or 2, got  \n\nThe above exception was the direct cause of the following exception:\n\nTraceback (most recent call last):\n  File \"/work/home/fd15hava/tinypaper-mpt/scripts/experiments/run.py\", line 16, in _run_session\n    result = agent.play(session)\n             ^^^^^^^^^^^^^^^^^^^\n  File \"/home/fd15hava/.cache/pypoetry/virtualenvs/non-package-mode-zjkKA0Ca-py3.11/lib/python3.11/site-packages/tenacity/__init__.py\", line 289, in wrapped_f\n    return self(f, *args, **kw)\n           ^^^^^^^^^^^^^^^^^^^^\n  File \"/home/fd15hava/.cache/pypoetry/virtualenvs/non-package-mode-zjkKA0Ca-py3.11/lib/python3.11/site-packages/tenacity/__init__.py\", line 379, in __call__\n    do = self.iter(retry_state=retry_state)\n         ^^^^^^^^^^^^^^^^^^^^^^^^^^^^^^^^^^\n  File \"/home/fd15hava/.cache/pypoetry/virtualenvs/non-package-mode-zjkKA0Ca-py3.11/lib/python3.11/site-packages/tenacity/__init__.py\", line 326, in iter\n    raise retry_exc from fut.exception()\ntenacity.RetryError: RetryError[<Future at 0x14cdd450e550 state=finished raised UnexpectedAnswerException>]\n",
      "Traceback (most recent call last):\n  File \"/home/fd15hava/.cache/pypoetry/virtualenvs/non-package-mode-zjkKA0Ca-py3.11/lib/python3.11/site-packages/tenacity/__init__.py\", line 382, in __call__\n    result = fn(*args, **kwargs)\n             ^^^^^^^^^^^^^^^^^^^\n  File \"/work/home/fd15hava/tinypaper-mpt/src/agent.py\", line 26, in play\n    answer = self._prompt(self._make_prompt(scenario))\n             ^^^^^^^^^^^^^^^^^^^^^^^^^^^^^^^^^^^^^^^^^\n  File \"/work/home/fd15hava/tinypaper-mpt/src/agent.py\", line 40, in _prompt\n    raise UnexpectedAnswerException(f\"expected 1 or 2, got {result}\")\nutil.UnexpectedAnswerException: expected 1 or 2, got  \n\nThe above exception was the direct cause of the following exception:\n\nTraceback (most recent call last):\n  File \"/work/home/fd15hava/tinypaper-mpt/scripts/experiments/run.py\", line 16, in _run_session\n    result = agent.play(session)\n             ^^^^^^^^^^^^^^^^^^^\n  File \"/home/fd15hava/.cache/pypoetry/virtualenvs/non-package-mode-zjkKA0Ca-py3.11/lib/python3.11/site-packages/tenacity/__init__.py\", line 289, in wrapped_f\n    return self(f, *args, **kw)\n           ^^^^^^^^^^^^^^^^^^^^\n  File \"/home/fd15hava/.cache/pypoetry/virtualenvs/non-package-mode-zjkKA0Ca-py3.11/lib/python3.11/site-packages/tenacity/__init__.py\", line 379, in __call__\n    do = self.iter(retry_state=retry_state)\n         ^^^^^^^^^^^^^^^^^^^^^^^^^^^^^^^^^^\n  File \"/home/fd15hava/.cache/pypoetry/virtualenvs/non-package-mode-zjkKA0Ca-py3.11/lib/python3.11/site-packages/tenacity/__init__.py\", line 326, in iter\n    raise retry_exc from fut.exception()\ntenacity.RetryError: RetryError[<Future at 0x14cdd450f310 state=finished raised UnexpectedAnswerException>]\n",
      "Traceback (most recent call last):\n  File \"/home/fd15hava/.cache/pypoetry/virtualenvs/non-package-mode-zjkKA0Ca-py3.11/lib/python3.11/site-packages/tenacity/__init__.py\", line 382, in __call__\n    result = fn(*args, **kwargs)\n             ^^^^^^^^^^^^^^^^^^^\n  File \"/work/home/fd15hava/tinypaper-mpt/src/agent.py\", line 26, in play\n    answer = self._prompt(self._make_prompt(scenario))\n             ^^^^^^^^^^^^^^^^^^^^^^^^^^^^^^^^^^^^^^^^^\n  File \"/work/home/fd15hava/tinypaper-mpt/src/agent.py\", line 40, in _prompt\n    raise UnexpectedAnswerException(f\"expected 1 or 2, got {result}\")\nutil.UnexpectedAnswerException: expected 1 or 2, got  \n\nThe above exception was the direct cause of the following exception:\n\nTraceback (most recent call last):\n  File \"/work/home/fd15hava/tinypaper-mpt/scripts/experiments/run.py\", line 16, in _run_session\n    result = agent.play(session)\n             ^^^^^^^^^^^^^^^^^^^\n  File \"/home/fd15hava/.cache/pypoetry/virtualenvs/non-package-mode-zjkKA0Ca-py3.11/lib/python3.11/site-packages/tenacity/__init__.py\", line 289, in wrapped_f\n    return self(f, *args, **kw)\n           ^^^^^^^^^^^^^^^^^^^^\n  File \"/home/fd15hava/.cache/pypoetry/virtualenvs/non-package-mode-zjkKA0Ca-py3.11/lib/python3.11/site-packages/tenacity/__init__.py\", line 379, in __call__\n    do = self.iter(retry_state=retry_state)\n         ^^^^^^^^^^^^^^^^^^^^^^^^^^^^^^^^^^\n  File \"/home/fd15hava/.cache/pypoetry/virtualenvs/non-package-mode-zjkKA0Ca-py3.11/lib/python3.11/site-packages/tenacity/__init__.py\", line 326, in iter\n    raise retry_exc from fut.exception()\ntenacity.RetryError: RetryError[<Future at 0x14cdd446e250 state=finished raised UnexpectedAnswerException>]\n",
      "Traceback (most recent call last):\n  File \"/home/fd15hava/.cache/pypoetry/virtualenvs/non-package-mode-zjkKA0Ca-py3.11/lib/python3.11/site-packages/tenacity/__init__.py\", line 382, in __call__\n    result = fn(*args, **kwargs)\n             ^^^^^^^^^^^^^^^^^^^\n  File \"/work/home/fd15hava/tinypaper-mpt/src/agent.py\", line 26, in play\n    answer = self._prompt(self._make_prompt(scenario))\n             ^^^^^^^^^^^^^^^^^^^^^^^^^^^^^^^^^^^^^^^^^\n  File \"/work/home/fd15hava/tinypaper-mpt/src/agent.py\", line 40, in _prompt\n    raise UnexpectedAnswerException(f\"expected 1 or 2, got {result}\")\nutil.UnexpectedAnswerException: expected 1 or 2, got  \n\nThe above exception was the direct cause of the following exception:\n\nTraceback (most recent call last):\n  File \"/work/home/fd15hava/tinypaper-mpt/scripts/experiments/run.py\", line 16, in _run_session\n    result = agent.play(session)\n             ^^^^^^^^^^^^^^^^^^^\n  File \"/home/fd15hava/.cache/pypoetry/virtualenvs/non-package-mode-zjkKA0Ca-py3.11/lib/python3.11/site-packages/tenacity/__init__.py\", line 289, in wrapped_f\n    return self(f, *args, **kw)\n           ^^^^^^^^^^^^^^^^^^^^\n  File \"/home/fd15hava/.cache/pypoetry/virtualenvs/non-package-mode-zjkKA0Ca-py3.11/lib/python3.11/site-packages/tenacity/__init__.py\", line 379, in __call__\n    do = self.iter(retry_state=retry_state)\n         ^^^^^^^^^^^^^^^^^^^^^^^^^^^^^^^^^^\n  File \"/home/fd15hava/.cache/pypoetry/virtualenvs/non-package-mode-zjkKA0Ca-py3.11/lib/python3.11/site-packages/tenacity/__init__.py\", line 326, in iter\n    raise retry_exc from fut.exception()\ntenacity.RetryError: RetryError[<Future at 0x14cdd4480510 state=finished raised UnexpectedAnswerException>]\n",
      "Traceback (most recent call last):\n  File \"/home/fd15hava/.cache/pypoetry/virtualenvs/non-package-mode-zjkKA0Ca-py3.11/lib/python3.11/site-packages/tenacity/__init__.py\", line 382, in __call__\n    result = fn(*args, **kwargs)\n             ^^^^^^^^^^^^^^^^^^^\n  File \"/work/home/fd15hava/tinypaper-mpt/src/agent.py\", line 26, in play\n    answer = self._prompt(self._make_prompt(scenario))\n             ^^^^^^^^^^^^^^^^^^^^^^^^^^^^^^^^^^^^^^^^^\n  File \"/work/home/fd15hava/tinypaper-mpt/src/agent.py\", line 40, in _prompt\n    raise UnexpectedAnswerException(f\"expected 1 or 2, got {result}\")\nutil.UnexpectedAnswerException: expected 1 or 2, got  \n\nThe above exception was the direct cause of the following exception:\n\nTraceback (most recent call last):\n  File \"/work/home/fd15hava/tinypaper-mpt/scripts/experiments/run.py\", line 16, in _run_session\n    result = agent.play(session)\n             ^^^^^^^^^^^^^^^^^^^\n  File \"/home/fd15hava/.cache/pypoetry/virtualenvs/non-package-mode-zjkKA0Ca-py3.11/lib/python3.11/site-packages/tenacity/__init__.py\", line 289, in wrapped_f\n    return self(f, *args, **kw)\n           ^^^^^^^^^^^^^^^^^^^^\n  File \"/home/fd15hava/.cache/pypoetry/virtualenvs/non-package-mode-zjkKA0Ca-py3.11/lib/python3.11/site-packages/tenacity/__init__.py\", line 379, in __call__\n    do = self.iter(retry_state=retry_state)\n         ^^^^^^^^^^^^^^^^^^^^^^^^^^^^^^^^^^\n  File \"/home/fd15hava/.cache/pypoetry/virtualenvs/non-package-mode-zjkKA0Ca-py3.11/lib/python3.11/site-packages/tenacity/__init__.py\", line 326, in iter\n    raise retry_exc from fut.exception()\ntenacity.RetryError: RetryError[<Future at 0x14cdd446ef90 state=finished raised UnexpectedAnswerException>]\n",
      "Traceback (most recent call last):\n  File \"/home/fd15hava/.cache/pypoetry/virtualenvs/non-package-mode-zjkKA0Ca-py3.11/lib/python3.11/site-packages/tenacity/__init__.py\", line 382, in __call__\n    result = fn(*args, **kwargs)\n             ^^^^^^^^^^^^^^^^^^^\n  File \"/work/home/fd15hava/tinypaper-mpt/src/agent.py\", line 26, in play\n    answer = self._prompt(self._make_prompt(scenario))\n             ^^^^^^^^^^^^^^^^^^^^^^^^^^^^^^^^^^^^^^^^^\n  File \"/work/home/fd15hava/tinypaper-mpt/src/agent.py\", line 40, in _prompt\n    raise UnexpectedAnswerException(f\"expected 1 or 2, got {result}\")\nutil.UnexpectedAnswerException: expected 1 or 2, got  \n\nThe above exception was the direct cause of the following exception:\n\nTraceback (most recent call last):\n  File \"/work/home/fd15hava/tinypaper-mpt/scripts/experiments/run.py\", line 16, in _run_session\n    result = agent.play(session)\n             ^^^^^^^^^^^^^^^^^^^\n  File \"/home/fd15hava/.cache/pypoetry/virtualenvs/non-package-mode-zjkKA0Ca-py3.11/lib/python3.11/site-packages/tenacity/__init__.py\", line 289, in wrapped_f\n    return self(f, *args, **kw)\n           ^^^^^^^^^^^^^^^^^^^^\n  File \"/home/fd15hava/.cache/pypoetry/virtualenvs/non-package-mode-zjkKA0Ca-py3.11/lib/python3.11/site-packages/tenacity/__init__.py\", line 379, in __call__\n    do = self.iter(retry_state=retry_state)\n         ^^^^^^^^^^^^^^^^^^^^^^^^^^^^^^^^^^\n  File \"/home/fd15hava/.cache/pypoetry/virtualenvs/non-package-mode-zjkKA0Ca-py3.11/lib/python3.11/site-packages/tenacity/__init__.py\", line 326, in iter\n    raise retry_exc from fut.exception()\ntenacity.RetryError: RetryError[<Future at 0x14cdd44fea10 state=finished raised UnexpectedAnswerException>]\n"
    ],
    "api_usage": [
      {
        "cost": 0.0,
        "name": "falcon-180B-chat",
        "num_input_tokens": -1,
        "num_output_tokens": -1,
        "py/object": "api_usage.APIUsage"
      },
      {
        "cost": 0.0,
        "name": "falcon-180B-chat",
        "num_input_tokens": -1,
        "num_output_tokens": -1,
        "py/object": "api_usage.APIUsage"
      },
      {
        "cost": 0.0,
        "name": "falcon-180B-chat",
        "num_input_tokens": -1,
        "num_output_tokens": -1,
        "py/object": "api_usage.APIUsage"
      },
      {
        "cost": 0.0,
        "name": "falcon-180B-chat",
        "num_input_tokens": -1,
        "num_output_tokens": -1,
        "py/object": "api_usage.APIUsage"
      },
      {
        "cost": 0.0,
        "name": "falcon-180B-chat",
        "num_input_tokens": -1,
        "num_output_tokens": -1,
        "py/object": "api_usage.APIUsage"
      },
      {
        "cost": 0.0,
        "name": "falcon-180B-chat",
        "num_input_tokens": -1,
        "num_output_tokens": -1,
        "py/object": "api_usage.APIUsage"
      },
      {
        "cost": 0.0,
        "name": "falcon-180B-chat",
        "num_input_tokens": -1,
        "num_output_tokens": -1,
        "py/object": "api_usage.APIUsage"
      },
      {
        "cost": 0.0,
        "name": "falcon-180B-chat",
        "num_input_tokens": -1,
        "num_output_tokens": -1,
        "py/object": "api_usage.APIUsage"
      },
      {
        "cost": 0.0,
        "name": "falcon-180B-chat",
        "num_input_tokens": -1,
        "num_output_tokens": -1,
        "py/object": "api_usage.APIUsage"
      },
      {
        "cost": 0.0,
        "name": "falcon-180B-chat",
        "num_input_tokens": -1,
        "num_output_tokens": -1,
        "py/object": "api_usage.APIUsage"
      },
      {
        "cost": 0.0,
        "name": "falcon-180B-chat",
        "num_input_tokens": -1,
        "num_output_tokens": -1,
        "py/object": "api_usage.APIUsage"
      },
      {
        "cost": 0.0,
        "name": "falcon-180B-chat",
        "num_input_tokens": -1,
        "num_output_tokens": -1,
        "py/object": "api_usage.APIUsage"
      },
      {
        "cost": 0.0,
        "name": "falcon-180B-chat",
        "num_input_tokens": -1,
        "num_output_tokens": -1,
        "py/object": "api_usage.APIUsage"
      },
      {
        "cost": 0.0,
        "name": "falcon-180B-chat",
        "num_input_tokens": -1,
        "num_output_tokens": -1,
        "py/object": "api_usage.APIUsage"
      },
      {
        "cost": 0.0,
        "name": "falcon-180B-chat",
        "num_input_tokens": -1,
        "num_output_tokens": -1,
        "py/object": "api_usage.APIUsage"
      },
      {
        "cost": 0.0,
        "name": "falcon-180B-chat",
        "num_input_tokens": -1,
        "num_output_tokens": -1,
        "py/object": "api_usage.APIUsage"
      },
      {
        "cost": 0.0,
        "name": "falcon-180B-chat",
        "num_input_tokens": -1,
        "num_output_tokens": -1,
        "py/object": "api_usage.APIUsage"
      },
      {
        "cost": 0.0,
        "name": "falcon-180B-chat",
        "num_input_tokens": -1,
        "num_output_tokens": -1,
        "py/object": "api_usage.APIUsage"
      },
      {
        "cost": 0.0,
        "name": "falcon-180B-chat",
        "num_input_tokens": -1,
        "num_output_tokens": -1,
        "py/object": "api_usage.APIUsage"
      },
      {
        "cost": 0.0,
        "name": "falcon-180B-chat",
        "num_input_tokens": -1,
        "num_output_tokens": -1,
        "py/object": "api_usage.APIUsage"
      },
      {
        "cost": 0.0,
        "name": "falcon-180B-chat",
        "num_input_tokens": -1,
        "num_output_tokens": -1,
        "py/object": "api_usage.APIUsage"
      },
      {
        "cost": 0.0,
        "name": "falcon-180B-chat",
        "num_input_tokens": -1,
        "num_output_tokens": -1,
        "py/object": "api_usage.APIUsage"
      },
      {
        "cost": 0.0,
        "name": "falcon-180B-chat",
        "num_input_tokens": -1,
        "num_output_tokens": -1,
        "py/object": "api_usage.APIUsage"
      },
      {
        "cost": 0.0,
        "name": "falcon-180B-chat",
        "num_input_tokens": -1,
        "num_output_tokens": -1,
        "py/object": "api_usage.APIUsage"
      },
      {
        "cost": 0.0,
        "name": "falcon-180B-chat",
        "num_input_tokens": -1,
        "num_output_tokens": -1,
        "py/object": "api_usage.APIUsage"
      },
      {
        "cost": 0.0,
        "name": "falcon-180B-chat",
        "num_input_tokens": -1,
        "num_output_tokens": -1,
        "py/object": "api_usage.APIUsage"
      },
      {
        "cost": 0.0,
        "name": "falcon-180B-chat",
        "num_input_tokens": -1,
        "num_output_tokens": -1,
        "py/object": "api_usage.APIUsage"
      },
      {
        "cost": 0.0,
        "name": "falcon-180B-chat",
        "num_input_tokens": -1,
        "num_output_tokens": -1,
        "py/object": "api_usage.APIUsage"
      },
      {
        "cost": 0.0,
        "name": "falcon-180B-chat",
        "num_input_tokens": -1,
        "num_output_tokens": -1,
        "py/object": "api_usage.APIUsage"
      },
      {
        "cost": 0.0,
        "name": "falcon-180B-chat",
        "num_input_tokens": -1,
        "num_output_tokens": -1,
        "py/object": "api_usage.APIUsage"
      },
      {
        "cost": 0.0,
        "name": "falcon-180B-chat",
        "num_input_tokens": -1,
        "num_output_tokens": -1,
        "py/object": "api_usage.APIUsage"
      },
      {
        "cost": 0.0,
        "name": "falcon-180B-chat",
        "num_input_tokens": -1,
        "num_output_tokens": -1,
        "py/object": "api_usage.APIUsage"
      },
      {
        "cost": 0.0,
        "name": "falcon-180B-chat",
        "num_input_tokens": -1,
        "num_output_tokens": -1,
        "py/object": "api_usage.APIUsage"
      },
      {
        "cost": 0.0,
        "name": "falcon-180B-chat",
        "num_input_tokens": -1,
        "num_output_tokens": -1,
        "py/object": "api_usage.APIUsage"
      },
      {
        "cost": 0.0,
        "name": "falcon-180B-chat",
        "num_input_tokens": -1,
        "num_output_tokens": -1,
        "py/object": "api_usage.APIUsage"
      },
      {
        "cost": 0.0,
        "name": "falcon-180B-chat",
        "num_input_tokens": -1,
        "num_output_tokens": -1,
        "py/object": "api_usage.APIUsage"
      },
      {
        "cost": 0.0,
        "name": "falcon-180B-chat",
        "num_input_tokens": -1,
        "num_output_tokens": -1,
        "py/object": "api_usage.APIUsage"
      },
      {
        "cost": 0.0,
        "name": "falcon-180B-chat",
        "num_input_tokens": -1,
        "num_output_tokens": -1,
        "py/object": "api_usage.APIUsage"
      },
      {
        "cost": 0.0,
        "name": "falcon-180B-chat",
        "num_input_tokens": -1,
        "num_output_tokens": -1,
        "py/object": "api_usage.APIUsage"
      },
      {
        "cost": 0.0,
        "name": "falcon-180B-chat",
        "num_input_tokens": -1,
        "num_output_tokens": -1,
        "py/object": "api_usage.APIUsage"
      },
      {
        "cost": 0.0,
        "name": "falcon-180B-chat",
        "num_input_tokens": -1,
        "num_output_tokens": -1,
        "py/object": "api_usage.APIUsage"
      },
      {
        "cost": 0.0,
        "name": "falcon-180B-chat",
        "num_input_tokens": -1,
        "num_output_tokens": -1,
        "py/object": "api_usage.APIUsage"
      },
      {
        "cost": 0.0,
        "name": "falcon-180B-chat",
        "num_input_tokens": -1,
        "num_output_tokens": -1,
        "py/object": "api_usage.APIUsage"
      },
      {
        "cost": 0.0,
        "name": "falcon-180B-chat",
        "num_input_tokens": -1,
        "num_output_tokens": -1,
        "py/object": "api_usage.APIUsage"
      },
      {
        "cost": 0.0,
        "name": "falcon-180B-chat",
        "num_input_tokens": -1,
        "num_output_tokens": -1,
        "py/object": "api_usage.APIUsage"
      },
      {
        "cost": 0.0,
        "name": "falcon-180B-chat",
        "num_input_tokens": -1,
        "num_output_tokens": -1,
        "py/object": "api_usage.APIUsage"
      },
      {
        "cost": 0.0,
        "name": "falcon-180B-chat",
        "num_input_tokens": -1,
        "num_output_tokens": -1,
        "py/object": "api_usage.APIUsage"
      },
      {
        "cost": 0.0,
        "name": "falcon-180B-chat",
        "num_input_tokens": -1,
        "num_output_tokens": -1,
        "py/object": "api_usage.APIUsage"
      },
      {
        "cost": 0.0,
        "name": "falcon-180B-chat",
        "num_input_tokens": -1,
        "num_output_tokens": -1,
        "py/object": "api_usage.APIUsage"
      },
      {
        "cost": 0.0,
        "name": "falcon-180B-chat",
        "num_input_tokens": -1,
        "num_output_tokens": -1,
        "py/object": "api_usage.APIUsage"
      }
    ],
    "api_usage_total": {
      "cost": 0.0,
      "name": "falcon-180B-chat",
      "num_input_tokens": -50,
      "num_output_tokens": -50,
      "py/object": "api_usage.APIUsage"
    }
  },
  "start_time": "2024-04-30T02:10:32.754521",
  "status": "COMPLETED",
  "stop_time": "2024-04-30T03:01:40.172949"
}