{
  "artifacts": [],
  "command": "main",
  "experiment": {
    "base_dir": "/work/home/fd15hava/tinypaper-mpt/src",
    "dependencies": [
      "numpy==1.26.4",
      "sacred==0.8.5"
    ],
    "mainfile": "experiment.py",
    "name": "tinypaper",
    "repositories": [
      {
        "commit": "83ebc21b46932da830ceff1fef51511962253d6b",
        "dirty": false,
        "url": "ssh://github/fdamken/tinypaper_code.git"
      },
      {
        "commit": "83ebc21b46932da830ceff1fef51511962253d6b",
        "dirty": false,
        "url": "ssh://github/fdamken/tinypaper_code.git"
      }
    ],
    "sources": [
      [
        "experiment.py",
        "_sources/experiment_7ab7c4f9e536be33bd5f71ad8c083f8f.py"
      ],
      [
        "path_util.py",
        "_sources/path_util_ce5f4012c098f79adf2c1204811dca0a.py"
      ]
    ]
  },
  "heartbeat": "2024-04-30T03:11:38.780785",
  "host": {
    "ENV": {},
    "cpu": "Intel(R) Xeon(R) Platinum 8470Q",
    "hostname": "mpsd0432",
    "os": [
      "Linux",
      "Linux-4.18.0-477.27.1.el8_8.x86_64-x86_64-with-glibc2.28"
    ],
    "python_version": "3.11.9"
  },
  "meta": {
    "command": "main",
    "config_updates": {
      "from_session_id": 150,
      "language": "fr",
      "model_name": "falcon-180B-chat",
      "to_session_id": 200
    },
    "named_configs": [],
    "options": {
      "--beat-interval": null,
      "--capture": null,
      "--comment": null,
      "--debug": false,
      "--enforce_clean": false,
      "--file_storage": null,
      "--force": false,
      "--help": false,
      "--id": null,
      "--loglevel": null,
      "--mongo_db": null,
      "--name": null,
      "--pdb": false,
      "--print-config": false,
      "--priority": null,
      "--queue": false,
      "--s3": null,
      "--sql": null,
      "--tiny_db": null,
      "--unobserved": false,
      "COMMAND": null,
      "UPDATE": [
        "from_session_id=150",
        "to_session_id=200",
        "model_name=falcon-180B-chat",
        "language=fr"
      ],
      "help": false,
      "with": true
    }
  },
  "resources": [],
  "result": {
    "answers": [
      "Traceback (most recent call last):\n  File \"/home/fd15hava/.cache/pypoetry/virtualenvs/non-package-mode-zjkKA0Ca-py3.11/lib/python3.11/site-packages/tenacity/__init__.py\", line 382, in __call__\n    result = fn(*args, **kwargs)\n             ^^^^^^^^^^^^^^^^^^^\n  File \"/work/home/fd15hava/tinypaper-mpt/src/agent.py\", line 26, in play\n    answer = self._prompt(self._make_prompt(scenario))\n             ^^^^^^^^^^^^^^^^^^^^^^^^^^^^^^^^^^^^^^^^^\n  File \"/work/home/fd15hava/tinypaper-mpt/src/agent.py\", line 40, in _prompt\n    raise UnexpectedAnswerException(f\"expected 1 or 2, got {result}\")\nutil.UnexpectedAnswerException: expected 1 or 2, got  \n\nThe above exception was the direct cause of the following exception:\n\nTraceback (most recent call last):\n  File \"/work/home/fd15hava/tinypaper-mpt/scripts/experiments/run.py\", line 16, in _run_session\n    result = agent.play(session)\n             ^^^^^^^^^^^^^^^^^^^\n  File \"/home/fd15hava/.cache/pypoetry/virtualenvs/non-package-mode-zjkKA0Ca-py3.11/lib/python3.11/site-packages/tenacity/__init__.py\", line 289, in wrapped_f\n    return self(f, *args, **kw)\n           ^^^^^^^^^^^^^^^^^^^^\n  File \"/home/fd15hava/.cache/pypoetry/virtualenvs/non-package-mode-zjkKA0Ca-py3.11/lib/python3.11/site-packages/tenacity/__init__.py\", line 379, in __call__\n    do = self.iter(retry_state=retry_state)\n         ^^^^^^^^^^^^^^^^^^^^^^^^^^^^^^^^^^\n  File \"/home/fd15hava/.cache/pypoetry/virtualenvs/non-package-mode-zjkKA0Ca-py3.11/lib/python3.11/site-packages/tenacity/__init__.py\", line 326, in iter\n    raise retry_exc from fut.exception()\ntenacity.RetryError: RetryError[<Future at 0x14abe60a4b10 state=finished raised UnexpectedAnswerException>]\n",
      "Traceback (most recent call last):\n  File \"/home/fd15hava/.cache/pypoetry/virtualenvs/non-package-mode-zjkKA0Ca-py3.11/lib/python3.11/site-packages/tenacity/__init__.py\", line 382, in __call__\n    result = fn(*args, **kwargs)\n             ^^^^^^^^^^^^^^^^^^^\n  File \"/work/home/fd15hava/tinypaper-mpt/src/agent.py\", line 26, in play\n    answer = self._prompt(self._make_prompt(scenario))\n             ^^^^^^^^^^^^^^^^^^^^^^^^^^^^^^^^^^^^^^^^^\n  File \"/work/home/fd15hava/tinypaper-mpt/src/agent.py\", line 40, in _prompt\n    raise UnexpectedAnswerException(f\"expected 1 or 2, got {result}\")\nutil.UnexpectedAnswerException: expected 1 or 2, got  \n\nThe above exception was the direct cause of the following exception:\n\nTraceback (most recent call last):\n  File \"/work/home/fd15hava/tinypaper-mpt/scripts/experiments/run.py\", line 16, in _run_session\n    result = agent.play(session)\n             ^^^^^^^^^^^^^^^^^^^\n  File \"/home/fd15hava/.cache/pypoetry/virtualenvs/non-package-mode-zjkKA0Ca-py3.11/lib/python3.11/site-packages/tenacity/__init__.py\", line 289, in wrapped_f\n    return self(f, *args, **kw)\n           ^^^^^^^^^^^^^^^^^^^^\n  File \"/home/fd15hava/.cache/pypoetry/virtualenvs/non-package-mode-zjkKA0Ca-py3.11/lib/python3.11/site-packages/tenacity/__init__.py\", line 379, in __call__\n    do = self.iter(retry_state=retry_state)\n         ^^^^^^^^^^^^^^^^^^^^^^^^^^^^^^^^^^\n  File \"/home/fd15hava/.cache/pypoetry/virtualenvs/non-package-mode-zjkKA0Ca-py3.11/lib/python3.11/site-packages/tenacity/__init__.py\", line 326, in iter\n    raise retry_exc from fut.exception()\ntenacity.RetryError: RetryError[<Future at 0x14ac6eb26f50 state=finished raised UnexpectedAnswerException>]\n",
      "Traceback (most recent call last):\n  File \"/home/fd15hava/.cache/pypoetry/virtualenvs/non-package-mode-zjkKA0Ca-py3.11/lib/python3.11/site-packages/tenacity/__init__.py\", line 382, in __call__\n    result = fn(*args, **kwargs)\n             ^^^^^^^^^^^^^^^^^^^\n  File \"/work/home/fd15hava/tinypaper-mpt/src/agent.py\", line 26, in play\n    answer = self._prompt(self._make_prompt(scenario))\n             ^^^^^^^^^^^^^^^^^^^^^^^^^^^^^^^^^^^^^^^^^\n  File \"/work/home/fd15hava/tinypaper-mpt/src/agent.py\", line 40, in _prompt\n    raise UnexpectedAnswerException(f\"expected 1 or 2, got {result}\")\nutil.UnexpectedAnswerException: expected 1 or 2, got  \n\nThe above exception was the direct cause of the following exception:\n\nTraceback (most recent call last):\n  File \"/work/home/fd15hava/tinypaper-mpt/scripts/experiments/run.py\", line 16, in _run_session\n    result = agent.play(session)\n             ^^^^^^^^^^^^^^^^^^^\n  File \"/home/fd15hava/.cache/pypoetry/virtualenvs/non-package-mode-zjkKA0Ca-py3.11/lib/python3.11/site-packages/tenacity/__init__.py\", line 289, in wrapped_f\n    return self(f, *args, **kw)\n           ^^^^^^^^^^^^^^^^^^^^\n  File \"/home/fd15hava/.cache/pypoetry/virtualenvs/non-package-mode-zjkKA0Ca-py3.11/lib/python3.11/site-packages/tenacity/__init__.py\", line 379, in __call__\n    do = self.iter(retry_state=retry_state)\n         ^^^^^^^^^^^^^^^^^^^^^^^^^^^^^^^^^^\n  File \"/home/fd15hava/.cache/pypoetry/virtualenvs/non-package-mode-zjkKA0Ca-py3.11/lib/python3.11/site-packages/tenacity/__init__.py\", line 326, in iter\n    raise retry_exc from fut.exception()\ntenacity.RetryError: RetryError[<Future at 0x14ac6413c050 state=finished raised UnexpectedAnswerException>]\n",
      "Traceback (most recent call last):\n  File \"/home/fd15hava/.cache/pypoetry/virtualenvs/non-package-mode-zjkKA0Ca-py3.11/lib/python3.11/site-packages/tenacity/__init__.py\", line 382, in __call__\n    result = fn(*args, **kwargs)\n             ^^^^^^^^^^^^^^^^^^^\n  File \"/work/home/fd15hava/tinypaper-mpt/src/agent.py\", line 26, in play\n    answer = self._prompt(self._make_prompt(scenario))\n             ^^^^^^^^^^^^^^^^^^^^^^^^^^^^^^^^^^^^^^^^^\n  File \"/work/home/fd15hava/tinypaper-mpt/src/agent.py\", line 40, in _prompt\n    raise UnexpectedAnswerException(f\"expected 1 or 2, got {result}\")\nutil.UnexpectedAnswerException: expected 1 or 2, got  \n\nThe above exception was the direct cause of the following exception:\n\nTraceback (most recent call last):\n  File \"/work/home/fd15hava/tinypaper-mpt/scripts/experiments/run.py\", line 16, in _run_session\n    result = agent.play(session)\n             ^^^^^^^^^^^^^^^^^^^\n  File \"/home/fd15hava/.cache/pypoetry/virtualenvs/non-package-mode-zjkKA0Ca-py3.11/lib/python3.11/site-packages/tenacity/__init__.py\", line 289, in wrapped_f\n    return self(f, *args, **kw)\n           ^^^^^^^^^^^^^^^^^^^^\n  File \"/home/fd15hava/.cache/pypoetry/virtualenvs/non-package-mode-zjkKA0Ca-py3.11/lib/python3.11/site-packages/tenacity/__init__.py\", line 379, in __call__\n    do = self.iter(retry_state=retry_state)\n         ^^^^^^^^^^^^^^^^^^^^^^^^^^^^^^^^^^\n  File \"/home/fd15hava/.cache/pypoetry/virtualenvs/non-package-mode-zjkKA0Ca-py3.11/lib/python3.11/site-packages/tenacity/__init__.py\", line 326, in iter\n    raise retry_exc from fut.exception()\ntenacity.RetryError: RetryError[<Future at 0x14abe60a4b10 state=finished raised UnexpectedAnswerException>]\n",
      "Traceback (most recent call last):\n  File \"/home/fd15hava/.cache/pypoetry/virtualenvs/non-package-mode-zjkKA0Ca-py3.11/lib/python3.11/site-packages/tenacity/__init__.py\", line 382, in __call__\n    result = fn(*args, **kwargs)\n             ^^^^^^^^^^^^^^^^^^^\n  File \"/work/home/fd15hava/tinypaper-mpt/src/agent.py\", line 26, in play\n    answer = self._prompt(self._make_prompt(scenario))\n             ^^^^^^^^^^^^^^^^^^^^^^^^^^^^^^^^^^^^^^^^^\n  File \"/work/home/fd15hava/tinypaper-mpt/src/agent.py\", line 40, in _prompt\n    raise UnexpectedAnswerException(f\"expected 1 or 2, got {result}\")\nutil.UnexpectedAnswerException: expected 1 or 2, got  \n\nThe above exception was the direct cause of the following exception:\n\nTraceback (most recent call last):\n  File \"/work/home/fd15hava/tinypaper-mpt/scripts/experiments/run.py\", line 16, in _run_session\n    result = agent.play(session)\n             ^^^^^^^^^^^^^^^^^^^\n  File \"/home/fd15hava/.cache/pypoetry/virtualenvs/non-package-mode-zjkKA0Ca-py3.11/lib/python3.11/site-packages/tenacity/__init__.py\", line 289, in wrapped_f\n    return self(f, *args, **kw)\n           ^^^^^^^^^^^^^^^^^^^^\n  File \"/home/fd15hava/.cache/pypoetry/virtualenvs/non-package-mode-zjkKA0Ca-py3.11/lib/python3.11/site-packages/tenacity/__init__.py\", line 379, in __call__\n    do = self.iter(retry_state=retry_state)\n         ^^^^^^^^^^^^^^^^^^^^^^^^^^^^^^^^^^\n  File \"/home/fd15hava/.cache/pypoetry/virtualenvs/non-package-mode-zjkKA0Ca-py3.11/lib/python3.11/site-packages/tenacity/__init__.py\", line 326, in iter\n    raise retry_exc from fut.exception()\ntenacity.RetryError: RetryError[<Future at 0x14ac64111e10 state=finished raised UnexpectedAnswerException>]\n",
      "Traceback (most recent call last):\n  File \"/home/fd15hava/.cache/pypoetry/virtualenvs/non-package-mode-zjkKA0Ca-py3.11/lib/python3.11/site-packages/tenacity/__init__.py\", line 382, in __call__\n    result = fn(*args, **kwargs)\n             ^^^^^^^^^^^^^^^^^^^\n  File \"/work/home/fd15hava/tinypaper-mpt/src/agent.py\", line 26, in play\n    answer = self._prompt(self._make_prompt(scenario))\n             ^^^^^^^^^^^^^^^^^^^^^^^^^^^^^^^^^^^^^^^^^\n  File \"/work/home/fd15hava/tinypaper-mpt/src/agent.py\", line 40, in _prompt\n    raise UnexpectedAnswerException(f\"expected 1 or 2, got {result}\")\nutil.UnexpectedAnswerException: expected 1 or 2, got  \n\nThe above exception was the direct cause of the following exception:\n\nTraceback (most recent call last):\n  File \"/work/home/fd15hava/tinypaper-mpt/scripts/experiments/run.py\", line 16, in _run_session\n    result = agent.play(session)\n             ^^^^^^^^^^^^^^^^^^^\n  File \"/home/fd15hava/.cache/pypoetry/virtualenvs/non-package-mode-zjkKA0Ca-py3.11/lib/python3.11/site-packages/tenacity/__init__.py\", line 289, in wrapped_f\n    return self(f, *args, **kw)\n           ^^^^^^^^^^^^^^^^^^^^\n  File \"/home/fd15hava/.cache/pypoetry/virtualenvs/non-package-mode-zjkKA0Ca-py3.11/lib/python3.11/site-packages/tenacity/__init__.py\", line 379, in __call__\n    do = self.iter(retry_state=retry_state)\n         ^^^^^^^^^^^^^^^^^^^^^^^^^^^^^^^^^^\n  File \"/home/fd15hava/.cache/pypoetry/virtualenvs/non-package-mode-zjkKA0Ca-py3.11/lib/python3.11/site-packages/tenacity/__init__.py\", line 326, in iter\n    raise retry_exc from fut.exception()\ntenacity.RetryError: RetryError[<Future at 0x14ac6c0a3fd0 state=finished raised UnexpectedAnswerException>]\n",
      "Traceback (most recent call last):\n  File \"/home/fd15hava/.cache/pypoetry/virtualenvs/non-package-mode-zjkKA0Ca-py3.11/lib/python3.11/site-packages/tenacity/__init__.py\", line 382, in __call__\n    result = fn(*args, **kwargs)\n             ^^^^^^^^^^^^^^^^^^^\n  File \"/work/home/fd15hava/tinypaper-mpt/src/agent.py\", line 26, in play\n    answer = self._prompt(self._make_prompt(scenario))\n             ^^^^^^^^^^^^^^^^^^^^^^^^^^^^^^^^^^^^^^^^^\n  File \"/work/home/fd15hava/tinypaper-mpt/src/agent.py\", line 40, in _prompt\n    raise UnexpectedAnswerException(f\"expected 1 or 2, got {result}\")\nutil.UnexpectedAnswerException: expected 1 or 2, got  \n\nThe above exception was the direct cause of the following exception:\n\nTraceback (most recent call last):\n  File \"/work/home/fd15hava/tinypaper-mpt/scripts/experiments/run.py\", line 16, in _run_session\n    result = agent.play(session)\n             ^^^^^^^^^^^^^^^^^^^\n  File \"/home/fd15hava/.cache/pypoetry/virtualenvs/non-package-mode-zjkKA0Ca-py3.11/lib/python3.11/site-packages/tenacity/__init__.py\", line 289, in wrapped_f\n    return self(f, *args, **kw)\n           ^^^^^^^^^^^^^^^^^^^^\n  File \"/home/fd15hava/.cache/pypoetry/virtualenvs/non-package-mode-zjkKA0Ca-py3.11/lib/python3.11/site-packages/tenacity/__init__.py\", line 379, in __call__\n    do = self.iter(retry_state=retry_state)\n         ^^^^^^^^^^^^^^^^^^^^^^^^^^^^^^^^^^\n  File \"/home/fd15hava/.cache/pypoetry/virtualenvs/non-package-mode-zjkKA0Ca-py3.11/lib/python3.11/site-packages/tenacity/__init__.py\", line 326, in iter\n    raise retry_exc from fut.exception()\ntenacity.RetryError: RetryError[<Future at 0x14ac6c080a50 state=finished raised UnexpectedAnswerException>]\n",
      "Traceback (most recent call last):\n  File \"/home/fd15hava/.cache/pypoetry/virtualenvs/non-package-mode-zjkKA0Ca-py3.11/lib/python3.11/site-packages/tenacity/__init__.py\", line 382, in __call__\n    result = fn(*args, **kwargs)\n             ^^^^^^^^^^^^^^^^^^^\n  File \"/work/home/fd15hava/tinypaper-mpt/src/agent.py\", line 26, in play\n    answer = self._prompt(self._make_prompt(scenario))\n             ^^^^^^^^^^^^^^^^^^^^^^^^^^^^^^^^^^^^^^^^^\n  File \"/work/home/fd15hava/tinypaper-mpt/src/agent.py\", line 40, in _prompt\n    raise UnexpectedAnswerException(f\"expected 1 or 2, got {result}\")\nutil.UnexpectedAnswerException: expected 1 or 2, got  \n\nThe above exception was the direct cause of the following exception:\n\nTraceback (most recent call last):\n  File \"/work/home/fd15hava/tinypaper-mpt/scripts/experiments/run.py\", line 16, in _run_session\n    result = agent.play(session)\n             ^^^^^^^^^^^^^^^^^^^\n  File \"/home/fd15hava/.cache/pypoetry/virtualenvs/non-package-mode-zjkKA0Ca-py3.11/lib/python3.11/site-packages/tenacity/__init__.py\", line 289, in wrapped_f\n    return self(f, *args, **kw)\n           ^^^^^^^^^^^^^^^^^^^^\n  File \"/home/fd15hava/.cache/pypoetry/virtualenvs/non-package-mode-zjkKA0Ca-py3.11/lib/python3.11/site-packages/tenacity/__init__.py\", line 379, in __call__\n    do = self.iter(retry_state=retry_state)\n         ^^^^^^^^^^^^^^^^^^^^^^^^^^^^^^^^^^\n  File \"/home/fd15hava/.cache/pypoetry/virtualenvs/non-package-mode-zjkKA0Ca-py3.11/lib/python3.11/site-packages/tenacity/__init__.py\", line 326, in iter\n    raise retry_exc from fut.exception()\ntenacity.RetryError: RetryError[<Future at 0x14ac641126d0 state=finished raised UnexpectedAnswerException>]\n",
      "Traceback (most recent call last):\n  File \"/home/fd15hava/.cache/pypoetry/virtualenvs/non-package-mode-zjkKA0Ca-py3.11/lib/python3.11/site-packages/tenacity/__init__.py\", line 382, in __call__\n    result = fn(*args, **kwargs)\n             ^^^^^^^^^^^^^^^^^^^\n  File \"/work/home/fd15hava/tinypaper-mpt/src/agent.py\", line 26, in play\n    answer = self._prompt(self._make_prompt(scenario))\n             ^^^^^^^^^^^^^^^^^^^^^^^^^^^^^^^^^^^^^^^^^\n  File \"/work/home/fd15hava/tinypaper-mpt/src/agent.py\", line 40, in _prompt\n    raise UnexpectedAnswerException(f\"expected 1 or 2, got {result}\")\nutil.UnexpectedAnswerException: expected 1 or 2, got  \n\nThe above exception was the direct cause of the following exception:\n\nTraceback (most recent call last):\n  File \"/work/home/fd15hava/tinypaper-mpt/scripts/experiments/run.py\", line 16, in _run_session\n    result = agent.play(session)\n             ^^^^^^^^^^^^^^^^^^^\n  File \"/home/fd15hava/.cache/pypoetry/virtualenvs/non-package-mode-zjkKA0Ca-py3.11/lib/python3.11/site-packages/tenacity/__init__.py\", line 289, in wrapped_f\n    return self(f, *args, **kw)\n           ^^^^^^^^^^^^^^^^^^^^\n  File \"/home/fd15hava/.cache/pypoetry/virtualenvs/non-package-mode-zjkKA0Ca-py3.11/lib/python3.11/site-packages/tenacity/__init__.py\", line 379, in __call__\n    do = self.iter(retry_state=retry_state)\n         ^^^^^^^^^^^^^^^^^^^^^^^^^^^^^^^^^^\n  File \"/home/fd15hava/.cache/pypoetry/virtualenvs/non-package-mode-zjkKA0Ca-py3.11/lib/python3.11/site-packages/tenacity/__init__.py\", line 326, in iter\n    raise retry_exc from fut.exception()\ntenacity.RetryError: RetryError[<Future at 0x14ac64112650 state=finished raised UnexpectedAnswerException>]\n",
      "Traceback (most recent call last):\n  File \"/home/fd15hava/.cache/pypoetry/virtualenvs/non-package-mode-zjkKA0Ca-py3.11/lib/python3.11/site-packages/tenacity/__init__.py\", line 382, in __call__\n    result = fn(*args, **kwargs)\n             ^^^^^^^^^^^^^^^^^^^\n  File \"/work/home/fd15hava/tinypaper-mpt/src/agent.py\", line 26, in play\n    answer = self._prompt(self._make_prompt(scenario))\n             ^^^^^^^^^^^^^^^^^^^^^^^^^^^^^^^^^^^^^^^^^\n  File \"/work/home/fd15hava/tinypaper-mpt/src/agent.py\", line 40, in _prompt\n    raise UnexpectedAnswerException(f\"expected 1 or 2, got {result}\")\nutil.UnexpectedAnswerException: expected 1 or 2, got  \n\nThe above exception was the direct cause of the following exception:\n\nTraceback (most recent call last):\n  File \"/work/home/fd15hava/tinypaper-mpt/scripts/experiments/run.py\", line 16, in _run_session\n    result = agent.play(session)\n             ^^^^^^^^^^^^^^^^^^^\n  File \"/home/fd15hava/.cache/pypoetry/virtualenvs/non-package-mode-zjkKA0Ca-py3.11/lib/python3.11/site-packages/tenacity/__init__.py\", line 289, in wrapped_f\n    return self(f, *args, **kw)\n           ^^^^^^^^^^^^^^^^^^^^\n  File \"/home/fd15hava/.cache/pypoetry/virtualenvs/non-package-mode-zjkKA0Ca-py3.11/lib/python3.11/site-packages/tenacity/__init__.py\", line 379, in __call__\n    do = self.iter(retry_state=retry_state)\n         ^^^^^^^^^^^^^^^^^^^^^^^^^^^^^^^^^^\n  File \"/home/fd15hava/.cache/pypoetry/virtualenvs/non-package-mode-zjkKA0Ca-py3.11/lib/python3.11/site-packages/tenacity/__init__.py\", line 326, in iter\n    raise retry_exc from fut.exception()\ntenacity.RetryError: RetryError[<Future at 0x14ac6f010f10 state=finished raised UnexpectedAnswerException>]\n",
      "Traceback (most recent call last):\n  File \"/home/fd15hava/.cache/pypoetry/virtualenvs/non-package-mode-zjkKA0Ca-py3.11/lib/python3.11/site-packages/tenacity/__init__.py\", line 382, in __call__\n    result = fn(*args, **kwargs)\n             ^^^^^^^^^^^^^^^^^^^\n  File \"/work/home/fd15hava/tinypaper-mpt/src/agent.py\", line 26, in play\n    answer = self._prompt(self._make_prompt(scenario))\n             ^^^^^^^^^^^^^^^^^^^^^^^^^^^^^^^^^^^^^^^^^\n  File \"/work/home/fd15hava/tinypaper-mpt/src/agent.py\", line 40, in _prompt\n    raise UnexpectedAnswerException(f\"expected 1 or 2, got {result}\")\nutil.UnexpectedAnswerException: expected 1 or 2, got  \n\nThe above exception was the direct cause of the following exception:\n\nTraceback (most recent call last):\n  File \"/work/home/fd15hava/tinypaper-mpt/scripts/experiments/run.py\", line 16, in _run_session\n    result = agent.play(session)\n             ^^^^^^^^^^^^^^^^^^^\n  File \"/home/fd15hava/.cache/pypoetry/virtualenvs/non-package-mode-zjkKA0Ca-py3.11/lib/python3.11/site-packages/tenacity/__init__.py\", line 289, in wrapped_f\n    return self(f, *args, **kw)\n           ^^^^^^^^^^^^^^^^^^^^\n  File \"/home/fd15hava/.cache/pypoetry/virtualenvs/non-package-mode-zjkKA0Ca-py3.11/lib/python3.11/site-packages/tenacity/__init__.py\", line 379, in __call__\n    do = self.iter(retry_state=retry_state)\n         ^^^^^^^^^^^^^^^^^^^^^^^^^^^^^^^^^^\n  File \"/home/fd15hava/.cache/pypoetry/virtualenvs/non-package-mode-zjkKA0Ca-py3.11/lib/python3.11/site-packages/tenacity/__init__.py\", line 326, in iter\n    raise retry_exc from fut.exception()\ntenacity.RetryError: RetryError[<Future at 0x14ac64127510 state=finished raised UnexpectedAnswerException>]\n",
      "Traceback (most recent call last):\n  File \"/home/fd15hava/.cache/pypoetry/virtualenvs/non-package-mode-zjkKA0Ca-py3.11/lib/python3.11/site-packages/tenacity/__init__.py\", line 382, in __call__\n    result = fn(*args, **kwargs)\n             ^^^^^^^^^^^^^^^^^^^\n  File \"/work/home/fd15hava/tinypaper-mpt/src/agent.py\", line 26, in play\n    answer = self._prompt(self._make_prompt(scenario))\n             ^^^^^^^^^^^^^^^^^^^^^^^^^^^^^^^^^^^^^^^^^\n  File \"/work/home/fd15hava/tinypaper-mpt/src/agent.py\", line 40, in _prompt\n    raise UnexpectedAnswerException(f\"expected 1 or 2, got {result}\")\nutil.UnexpectedAnswerException: expected 1 or 2, got  \n\nThe above exception was the direct cause of the following exception:\n\nTraceback (most recent call last):\n  File \"/work/home/fd15hava/tinypaper-mpt/scripts/experiments/run.py\", line 16, in _run_session\n    result = agent.play(session)\n             ^^^^^^^^^^^^^^^^^^^\n  File \"/home/fd15hava/.cache/pypoetry/virtualenvs/non-package-mode-zjkKA0Ca-py3.11/lib/python3.11/site-packages/tenacity/__init__.py\", line 289, in wrapped_f\n    return self(f, *args, **kw)\n           ^^^^^^^^^^^^^^^^^^^^\n  File \"/home/fd15hava/.cache/pypoetry/virtualenvs/non-package-mode-zjkKA0Ca-py3.11/lib/python3.11/site-packages/tenacity/__init__.py\", line 379, in __call__\n    do = self.iter(retry_state=retry_state)\n         ^^^^^^^^^^^^^^^^^^^^^^^^^^^^^^^^^^\n  File \"/home/fd15hava/.cache/pypoetry/virtualenvs/non-package-mode-zjkKA0Ca-py3.11/lib/python3.11/site-packages/tenacity/__init__.py\", line 326, in iter\n    raise retry_exc from fut.exception()\ntenacity.RetryError: RetryError[<Future at 0x14ac6c0ec0d0 state=finished raised UnexpectedAnswerException>]\n",
      "Traceback (most recent call last):\n  File \"/home/fd15hava/.cache/pypoetry/virtualenvs/non-package-mode-zjkKA0Ca-py3.11/lib/python3.11/site-packages/tenacity/__init__.py\", line 382, in __call__\n    result = fn(*args, **kwargs)\n             ^^^^^^^^^^^^^^^^^^^\n  File \"/work/home/fd15hava/tinypaper-mpt/src/agent.py\", line 26, in play\n    answer = self._prompt(self._make_prompt(scenario))\n             ^^^^^^^^^^^^^^^^^^^^^^^^^^^^^^^^^^^^^^^^^\n  File \"/work/home/fd15hava/tinypaper-mpt/src/agent.py\", line 40, in _prompt\n    raise UnexpectedAnswerException(f\"expected 1 or 2, got {result}\")\nutil.UnexpectedAnswerException: expected 1 or 2, got  \n\nThe above exception was the direct cause of the following exception:\n\nTraceback (most recent call last):\n  File \"/work/home/fd15hava/tinypaper-mpt/scripts/experiments/run.py\", line 16, in _run_session\n    result = agent.play(session)\n             ^^^^^^^^^^^^^^^^^^^\n  File \"/home/fd15hava/.cache/pypoetry/virtualenvs/non-package-mode-zjkKA0Ca-py3.11/lib/python3.11/site-packages/tenacity/__init__.py\", line 289, in wrapped_f\n    return self(f, *args, **kw)\n           ^^^^^^^^^^^^^^^^^^^^\n  File \"/home/fd15hava/.cache/pypoetry/virtualenvs/non-package-mode-zjkKA0Ca-py3.11/lib/python3.11/site-packages/tenacity/__init__.py\", line 379, in __call__\n    do = self.iter(retry_state=retry_state)\n         ^^^^^^^^^^^^^^^^^^^^^^^^^^^^^^^^^^\n  File \"/home/fd15hava/.cache/pypoetry/virtualenvs/non-package-mode-zjkKA0Ca-py3.11/lib/python3.11/site-packages/tenacity/__init__.py\", line 326, in iter\n    raise retry_exc from fut.exception()\ntenacity.RetryError: RetryError[<Future at 0x14ac64112a90 state=finished raised UnexpectedAnswerException>]\n",
      "Traceback (most recent call last):\n  File \"/home/fd15hava/.cache/pypoetry/virtualenvs/non-package-mode-zjkKA0Ca-py3.11/lib/python3.11/site-packages/tenacity/__init__.py\", line 382, in __call__\n    result = fn(*args, **kwargs)\n             ^^^^^^^^^^^^^^^^^^^\n  File \"/work/home/fd15hava/tinypaper-mpt/src/agent.py\", line 26, in play\n    answer = self._prompt(self._make_prompt(scenario))\n             ^^^^^^^^^^^^^^^^^^^^^^^^^^^^^^^^^^^^^^^^^\n  File \"/work/home/fd15hava/tinypaper-mpt/src/agent.py\", line 40, in _prompt\n    raise UnexpectedAnswerException(f\"expected 1 or 2, got {result}\")\nutil.UnexpectedAnswerException: expected 1 or 2, got  \n\nThe above exception was the direct cause of the following exception:\n\nTraceback (most recent call last):\n  File \"/work/home/fd15hava/tinypaper-mpt/scripts/experiments/run.py\", line 16, in _run_session\n    result = agent.play(session)\n             ^^^^^^^^^^^^^^^^^^^\n  File \"/home/fd15hava/.cache/pypoetry/virtualenvs/non-package-mode-zjkKA0Ca-py3.11/lib/python3.11/site-packages/tenacity/__init__.py\", line 289, in wrapped_f\n    return self(f, *args, **kw)\n           ^^^^^^^^^^^^^^^^^^^^\n  File \"/home/fd15hava/.cache/pypoetry/virtualenvs/non-package-mode-zjkKA0Ca-py3.11/lib/python3.11/site-packages/tenacity/__init__.py\", line 379, in __call__\n    do = self.iter(retry_state=retry_state)\n         ^^^^^^^^^^^^^^^^^^^^^^^^^^^^^^^^^^\n  File \"/home/fd15hava/.cache/pypoetry/virtualenvs/non-package-mode-zjkKA0Ca-py3.11/lib/python3.11/site-packages/tenacity/__init__.py\", line 326, in iter\n    raise retry_exc from fut.exception()\ntenacity.RetryError: RetryError[<Future at 0x14ac64110750 state=finished raised UnexpectedAnswerException>]\n",
      "Traceback (most recent call last):\n  File \"/home/fd15hava/.cache/pypoetry/virtualenvs/non-package-mode-zjkKA0Ca-py3.11/lib/python3.11/site-packages/tenacity/__init__.py\", line 382, in __call__\n    result = fn(*args, **kwargs)\n             ^^^^^^^^^^^^^^^^^^^\n  File \"/work/home/fd15hava/tinypaper-mpt/src/agent.py\", line 26, in play\n    answer = self._prompt(self._make_prompt(scenario))\n             ^^^^^^^^^^^^^^^^^^^^^^^^^^^^^^^^^^^^^^^^^\n  File \"/work/home/fd15hava/tinypaper-mpt/src/agent.py\", line 40, in _prompt\n    raise UnexpectedAnswerException(f\"expected 1 or 2, got {result}\")\nutil.UnexpectedAnswerException: expected 1 or 2, got  \n\nThe above exception was the direct cause of the following exception:\n\nTraceback (most recent call last):\n  File \"/work/home/fd15hava/tinypaper-mpt/scripts/experiments/run.py\", line 16, in _run_session\n    result = agent.play(session)\n             ^^^^^^^^^^^^^^^^^^^\n  File \"/home/fd15hava/.cache/pypoetry/virtualenvs/non-package-mode-zjkKA0Ca-py3.11/lib/python3.11/site-packages/tenacity/__init__.py\", line 289, in wrapped_f\n    return self(f, *args, **kw)\n           ^^^^^^^^^^^^^^^^^^^^\n  File \"/home/fd15hava/.cache/pypoetry/virtualenvs/non-package-mode-zjkKA0Ca-py3.11/lib/python3.11/site-packages/tenacity/__init__.py\", line 379, in __call__\n    do = self.iter(retry_state=retry_state)\n         ^^^^^^^^^^^^^^^^^^^^^^^^^^^^^^^^^^\n  File \"/home/fd15hava/.cache/pypoetry/virtualenvs/non-package-mode-zjkKA0Ca-py3.11/lib/python3.11/site-packages/tenacity/__init__.py\", line 326, in iter\n    raise retry_exc from fut.exception()\ntenacity.RetryError: RetryError[<Future at 0x14ac641b39d0 state=finished raised UnexpectedAnswerException>]\n",
      "Traceback (most recent call last):\n  File \"/home/fd15hava/.cache/pypoetry/virtualenvs/non-package-mode-zjkKA0Ca-py3.11/lib/python3.11/site-packages/tenacity/__init__.py\", line 382, in __call__\n    result = fn(*args, **kwargs)\n             ^^^^^^^^^^^^^^^^^^^\n  File \"/work/home/fd15hava/tinypaper-mpt/src/agent.py\", line 26, in play\n    answer = self._prompt(self._make_prompt(scenario))\n             ^^^^^^^^^^^^^^^^^^^^^^^^^^^^^^^^^^^^^^^^^\n  File \"/work/home/fd15hava/tinypaper-mpt/src/agent.py\", line 40, in _prompt\n    raise UnexpectedAnswerException(f\"expected 1 or 2, got {result}\")\nutil.UnexpectedAnswerException: expected 1 or 2, got  \n\nThe above exception was the direct cause of the following exception:\n\nTraceback (most recent call last):\n  File \"/work/home/fd15hava/tinypaper-mpt/scripts/experiments/run.py\", line 16, in _run_session\n    result = agent.play(session)\n             ^^^^^^^^^^^^^^^^^^^\n  File \"/home/fd15hava/.cache/pypoetry/virtualenvs/non-package-mode-zjkKA0Ca-py3.11/lib/python3.11/site-packages/tenacity/__init__.py\", line 289, in wrapped_f\n    return self(f, *args, **kw)\n           ^^^^^^^^^^^^^^^^^^^^\n  File \"/home/fd15hava/.cache/pypoetry/virtualenvs/non-package-mode-zjkKA0Ca-py3.11/lib/python3.11/site-packages/tenacity/__init__.py\", line 379, in __call__\n    do = self.iter(retry_state=retry_state)\n         ^^^^^^^^^^^^^^^^^^^^^^^^^^^^^^^^^^\n  File \"/home/fd15hava/.cache/pypoetry/virtualenvs/non-package-mode-zjkKA0Ca-py3.11/lib/python3.11/site-packages/tenacity/__init__.py\", line 326, in iter\n    raise retry_exc from fut.exception()\ntenacity.RetryError: RetryError[<Future at 0x14ac641b0f50 state=finished raised UnexpectedAnswerException>]\n",
      "Traceback (most recent call last):\n  File \"/home/fd15hava/.cache/pypoetry/virtualenvs/non-package-mode-zjkKA0Ca-py3.11/lib/python3.11/site-packages/tenacity/__init__.py\", line 382, in __call__\n    result = fn(*args, **kwargs)\n             ^^^^^^^^^^^^^^^^^^^\n  File \"/work/home/fd15hava/tinypaper-mpt/src/agent.py\", line 26, in play\n    answer = self._prompt(self._make_prompt(scenario))\n             ^^^^^^^^^^^^^^^^^^^^^^^^^^^^^^^^^^^^^^^^^\n  File \"/work/home/fd15hava/tinypaper-mpt/src/agent.py\", line 40, in _prompt\n    raise UnexpectedAnswerException(f\"expected 1 or 2, got {result}\")\nutil.UnexpectedAnswerException: expected 1 or 2, got  \n\nThe above exception was the direct cause of the following exception:\n\nTraceback (most recent call last):\n  File \"/work/home/fd15hava/tinypaper-mpt/scripts/experiments/run.py\", line 16, in _run_session\n    result = agent.play(session)\n             ^^^^^^^^^^^^^^^^^^^\n  File \"/home/fd15hava/.cache/pypoetry/virtualenvs/non-package-mode-zjkKA0Ca-py3.11/lib/python3.11/site-packages/tenacity/__init__.py\", line 289, in wrapped_f\n    return self(f, *args, **kw)\n           ^^^^^^^^^^^^^^^^^^^^\n  File \"/home/fd15hava/.cache/pypoetry/virtualenvs/non-package-mode-zjkKA0Ca-py3.11/lib/python3.11/site-packages/tenacity/__init__.py\", line 379, in __call__\n    do = self.iter(retry_state=retry_state)\n         ^^^^^^^^^^^^^^^^^^^^^^^^^^^^^^^^^^\n  File \"/home/fd15hava/.cache/pypoetry/virtualenvs/non-package-mode-zjkKA0Ca-py3.11/lib/python3.11/site-packages/tenacity/__init__.py\", line 326, in iter\n    raise retry_exc from fut.exception()\ntenacity.RetryError: RetryError[<Future at 0x14ac6f03dc50 state=finished raised UnexpectedAnswerException>]\n",
      "Traceback (most recent call last):\n  File \"/home/fd15hava/.cache/pypoetry/virtualenvs/non-package-mode-zjkKA0Ca-py3.11/lib/python3.11/site-packages/tenacity/__init__.py\", line 382, in __call__\n    result = fn(*args, **kwargs)\n             ^^^^^^^^^^^^^^^^^^^\n  File \"/work/home/fd15hava/tinypaper-mpt/src/agent.py\", line 26, in play\n    answer = self._prompt(self._make_prompt(scenario))\n             ^^^^^^^^^^^^^^^^^^^^^^^^^^^^^^^^^^^^^^^^^\n  File \"/work/home/fd15hava/tinypaper-mpt/src/agent.py\", line 40, in _prompt\n    raise UnexpectedAnswerException(f\"expected 1 or 2, got {result}\")\nutil.UnexpectedAnswerException: expected 1 or 2, got  \n\nThe above exception was the direct cause of the following exception:\n\nTraceback (most recent call last):\n  File \"/work/home/fd15hava/tinypaper-mpt/scripts/experiments/run.py\", line 16, in _run_session\n    result = agent.play(session)\n             ^^^^^^^^^^^^^^^^^^^\n  File \"/home/fd15hava/.cache/pypoetry/virtualenvs/non-package-mode-zjkKA0Ca-py3.11/lib/python3.11/site-packages/tenacity/__init__.py\", line 289, in wrapped_f\n    return self(f, *args, **kw)\n           ^^^^^^^^^^^^^^^^^^^^\n  File \"/home/fd15hava/.cache/pypoetry/virtualenvs/non-package-mode-zjkKA0Ca-py3.11/lib/python3.11/site-packages/tenacity/__init__.py\", line 379, in __call__\n    do = self.iter(retry_state=retry_state)\n         ^^^^^^^^^^^^^^^^^^^^^^^^^^^^^^^^^^\n  File \"/home/fd15hava/.cache/pypoetry/virtualenvs/non-package-mode-zjkKA0Ca-py3.11/lib/python3.11/site-packages/tenacity/__init__.py\", line 326, in iter\n    raise retry_exc from fut.exception()\ntenacity.RetryError: RetryError[<Future at 0x14ac64199290 state=finished raised UnexpectedAnswerException>]\n",
      "Traceback (most recent call last):\n  File \"/home/fd15hava/.cache/pypoetry/virtualenvs/non-package-mode-zjkKA0Ca-py3.11/lib/python3.11/site-packages/tenacity/__init__.py\", line 382, in __call__\n    result = fn(*args, **kwargs)\n             ^^^^^^^^^^^^^^^^^^^\n  File \"/work/home/fd15hava/tinypaper-mpt/src/agent.py\", line 26, in play\n    answer = self._prompt(self._make_prompt(scenario))\n             ^^^^^^^^^^^^^^^^^^^^^^^^^^^^^^^^^^^^^^^^^\n  File \"/work/home/fd15hava/tinypaper-mpt/src/agent.py\", line 40, in _prompt\n    raise UnexpectedAnswerException(f\"expected 1 or 2, got {result}\")\nutil.UnexpectedAnswerException: expected 1 or 2, got  \n\nThe above exception was the direct cause of the following exception:\n\nTraceback (most recent call last):\n  File \"/work/home/fd15hava/tinypaper-mpt/scripts/experiments/run.py\", line 16, in _run_session\n    result = agent.play(session)\n             ^^^^^^^^^^^^^^^^^^^\n  File \"/home/fd15hava/.cache/pypoetry/virtualenvs/non-package-mode-zjkKA0Ca-py3.11/lib/python3.11/site-packages/tenacity/__init__.py\", line 289, in wrapped_f\n    return self(f, *args, **kw)\n           ^^^^^^^^^^^^^^^^^^^^\n  File \"/home/fd15hava/.cache/pypoetry/virtualenvs/non-package-mode-zjkKA0Ca-py3.11/lib/python3.11/site-packages/tenacity/__init__.py\", line 379, in __call__\n    do = self.iter(retry_state=retry_state)\n         ^^^^^^^^^^^^^^^^^^^^^^^^^^^^^^^^^^\n  File \"/home/fd15hava/.cache/pypoetry/virtualenvs/non-package-mode-zjkKA0Ca-py3.11/lib/python3.11/site-packages/tenacity/__init__.py\", line 326, in iter\n    raise retry_exc from fut.exception()\ntenacity.RetryError: RetryError[<Future at 0x14ac6f1c17d0 state=finished raised UnexpectedAnswerException>]\n",
      "Traceback (most recent call last):\n  File \"/home/fd15hava/.cache/pypoetry/virtualenvs/non-package-mode-zjkKA0Ca-py3.11/lib/python3.11/site-packages/tenacity/__init__.py\", line 382, in __call__\n    result = fn(*args, **kwargs)\n             ^^^^^^^^^^^^^^^^^^^\n  File \"/work/home/fd15hava/tinypaper-mpt/src/agent.py\", line 26, in play\n    answer = self._prompt(self._make_prompt(scenario))\n             ^^^^^^^^^^^^^^^^^^^^^^^^^^^^^^^^^^^^^^^^^\n  File \"/work/home/fd15hava/tinypaper-mpt/src/agent.py\", line 40, in _prompt\n    raise UnexpectedAnswerException(f\"expected 1 or 2, got {result}\")\nutil.UnexpectedAnswerException: expected 1 or 2, got  \n\nThe above exception was the direct cause of the following exception:\n\nTraceback (most recent call last):\n  File \"/work/home/fd15hava/tinypaper-mpt/scripts/experiments/run.py\", line 16, in _run_session\n    result = agent.play(session)\n             ^^^^^^^^^^^^^^^^^^^\n  File \"/home/fd15hava/.cache/pypoetry/virtualenvs/non-package-mode-zjkKA0Ca-py3.11/lib/python3.11/site-packages/tenacity/__init__.py\", line 289, in wrapped_f\n    return self(f, *args, **kw)\n           ^^^^^^^^^^^^^^^^^^^^\n  File \"/home/fd15hava/.cache/pypoetry/virtualenvs/non-package-mode-zjkKA0Ca-py3.11/lib/python3.11/site-packages/tenacity/__init__.py\", line 379, in __call__\n    do = self.iter(retry_state=retry_state)\n         ^^^^^^^^^^^^^^^^^^^^^^^^^^^^^^^^^^\n  File \"/home/fd15hava/.cache/pypoetry/virtualenvs/non-package-mode-zjkKA0Ca-py3.11/lib/python3.11/site-packages/tenacity/__init__.py\", line 326, in iter\n    raise retry_exc from fut.exception()\ntenacity.RetryError: RetryError[<Future at 0x14ac641100d0 state=finished raised UnexpectedAnswerException>]\n",
      "Traceback (most recent call last):\n  File \"/home/fd15hava/.cache/pypoetry/virtualenvs/non-package-mode-zjkKA0Ca-py3.11/lib/python3.11/site-packages/tenacity/__init__.py\", line 382, in __call__\n    result = fn(*args, **kwargs)\n             ^^^^^^^^^^^^^^^^^^^\n  File \"/work/home/fd15hava/tinypaper-mpt/src/agent.py\", line 26, in play\n    answer = self._prompt(self._make_prompt(scenario))\n             ^^^^^^^^^^^^^^^^^^^^^^^^^^^^^^^^^^^^^^^^^\n  File \"/work/home/fd15hava/tinypaper-mpt/src/agent.py\", line 40, in _prompt\n    raise UnexpectedAnswerException(f\"expected 1 or 2, got {result}\")\nutil.UnexpectedAnswerException: expected 1 or 2, got  \n\nThe above exception was the direct cause of the following exception:\n\nTraceback (most recent call last):\n  File \"/work/home/fd15hava/tinypaper-mpt/scripts/experiments/run.py\", line 16, in _run_session\n    result = agent.play(session)\n             ^^^^^^^^^^^^^^^^^^^\n  File \"/home/fd15hava/.cache/pypoetry/virtualenvs/non-package-mode-zjkKA0Ca-py3.11/lib/python3.11/site-packages/tenacity/__init__.py\", line 289, in wrapped_f\n    return self(f, *args, **kw)\n           ^^^^^^^^^^^^^^^^^^^^\n  File \"/home/fd15hava/.cache/pypoetry/virtualenvs/non-package-mode-zjkKA0Ca-py3.11/lib/python3.11/site-packages/tenacity/__init__.py\", line 379, in __call__\n    do = self.iter(retry_state=retry_state)\n         ^^^^^^^^^^^^^^^^^^^^^^^^^^^^^^^^^^\n  File \"/home/fd15hava/.cache/pypoetry/virtualenvs/non-package-mode-zjkKA0Ca-py3.11/lib/python3.11/site-packages/tenacity/__init__.py\", line 326, in iter\n    raise retry_exc from fut.exception()\ntenacity.RetryError: RetryError[<Future at 0x14ac6e925bd0 state=finished raised UnexpectedAnswerException>]\n",
      "Traceback (most recent call last):\n  File \"/home/fd15hava/.cache/pypoetry/virtualenvs/non-package-mode-zjkKA0Ca-py3.11/lib/python3.11/site-packages/tenacity/__init__.py\", line 382, in __call__\n    result = fn(*args, **kwargs)\n             ^^^^^^^^^^^^^^^^^^^\n  File \"/work/home/fd15hava/tinypaper-mpt/src/agent.py\", line 26, in play\n    answer = self._prompt(self._make_prompt(scenario))\n             ^^^^^^^^^^^^^^^^^^^^^^^^^^^^^^^^^^^^^^^^^\n  File \"/work/home/fd15hava/tinypaper-mpt/src/agent.py\", line 40, in _prompt\n    raise UnexpectedAnswerException(f\"expected 1 or 2, got {result}\")\nutil.UnexpectedAnswerException: expected 1 or 2, got  \n\nThe above exception was the direct cause of the following exception:\n\nTraceback (most recent call last):\n  File \"/work/home/fd15hava/tinypaper-mpt/scripts/experiments/run.py\", line 16, in _run_session\n    result = agent.play(session)\n             ^^^^^^^^^^^^^^^^^^^\n  File \"/home/fd15hava/.cache/pypoetry/virtualenvs/non-package-mode-zjkKA0Ca-py3.11/lib/python3.11/site-packages/tenacity/__init__.py\", line 289, in wrapped_f\n    return self(f, *args, **kw)\n           ^^^^^^^^^^^^^^^^^^^^\n  File \"/home/fd15hava/.cache/pypoetry/virtualenvs/non-package-mode-zjkKA0Ca-py3.11/lib/python3.11/site-packages/tenacity/__init__.py\", line 379, in __call__\n    do = self.iter(retry_state=retry_state)\n         ^^^^^^^^^^^^^^^^^^^^^^^^^^^^^^^^^^\n  File \"/home/fd15hava/.cache/pypoetry/virtualenvs/non-package-mode-zjkKA0Ca-py3.11/lib/python3.11/site-packages/tenacity/__init__.py\", line 326, in iter\n    raise retry_exc from fut.exception()\ntenacity.RetryError: RetryError[<Future at 0x14ac6e7c73d0 state=finished raised UnexpectedAnswerException>]\n",
      "Traceback (most recent call last):\n  File \"/home/fd15hava/.cache/pypoetry/virtualenvs/non-package-mode-zjkKA0Ca-py3.11/lib/python3.11/site-packages/tenacity/__init__.py\", line 382, in __call__\n    result = fn(*args, **kwargs)\n             ^^^^^^^^^^^^^^^^^^^\n  File \"/work/home/fd15hava/tinypaper-mpt/src/agent.py\", line 26, in play\n    answer = self._prompt(self._make_prompt(scenario))\n             ^^^^^^^^^^^^^^^^^^^^^^^^^^^^^^^^^^^^^^^^^\n  File \"/work/home/fd15hava/tinypaper-mpt/src/agent.py\", line 40, in _prompt\n    raise UnexpectedAnswerException(f\"expected 1 or 2, got {result}\")\nutil.UnexpectedAnswerException: expected 1 or 2, got  \n\nThe above exception was the direct cause of the following exception:\n\nTraceback (most recent call last):\n  File \"/work/home/fd15hava/tinypaper-mpt/scripts/experiments/run.py\", line 16, in _run_session\n    result = agent.play(session)\n             ^^^^^^^^^^^^^^^^^^^\n  File \"/home/fd15hava/.cache/pypoetry/virtualenvs/non-package-mode-zjkKA0Ca-py3.11/lib/python3.11/site-packages/tenacity/__init__.py\", line 289, in wrapped_f\n    return self(f, *args, **kw)\n           ^^^^^^^^^^^^^^^^^^^^\n  File \"/home/fd15hava/.cache/pypoetry/virtualenvs/non-package-mode-zjkKA0Ca-py3.11/lib/python3.11/site-packages/tenacity/__init__.py\", line 379, in __call__\n    do = self.iter(retry_state=retry_state)\n         ^^^^^^^^^^^^^^^^^^^^^^^^^^^^^^^^^^\n  File \"/home/fd15hava/.cache/pypoetry/virtualenvs/non-package-mode-zjkKA0Ca-py3.11/lib/python3.11/site-packages/tenacity/__init__.py\", line 326, in iter\n    raise retry_exc from fut.exception()\ntenacity.RetryError: RetryError[<Future at 0x14ac64127e90 state=finished raised UnexpectedAnswerException>]\n",
      "Traceback (most recent call last):\n  File \"/home/fd15hava/.cache/pypoetry/virtualenvs/non-package-mode-zjkKA0Ca-py3.11/lib/python3.11/site-packages/tenacity/__init__.py\", line 382, in __call__\n    result = fn(*args, **kwargs)\n             ^^^^^^^^^^^^^^^^^^^\n  File \"/work/home/fd15hava/tinypaper-mpt/src/agent.py\", line 26, in play\n    answer = self._prompt(self._make_prompt(scenario))\n             ^^^^^^^^^^^^^^^^^^^^^^^^^^^^^^^^^^^^^^^^^\n  File \"/work/home/fd15hava/tinypaper-mpt/src/agent.py\", line 40, in _prompt\n    raise UnexpectedAnswerException(f\"expected 1 or 2, got {result}\")\nutil.UnexpectedAnswerException: expected 1 or 2, got  \n\nThe above exception was the direct cause of the following exception:\n\nTraceback (most recent call last):\n  File \"/work/home/fd15hava/tinypaper-mpt/scripts/experiments/run.py\", line 16, in _run_session\n    result = agent.play(session)\n             ^^^^^^^^^^^^^^^^^^^\n  File \"/home/fd15hava/.cache/pypoetry/virtualenvs/non-package-mode-zjkKA0Ca-py3.11/lib/python3.11/site-packages/tenacity/__init__.py\", line 289, in wrapped_f\n    return self(f, *args, **kw)\n           ^^^^^^^^^^^^^^^^^^^^\n  File \"/home/fd15hava/.cache/pypoetry/virtualenvs/non-package-mode-zjkKA0Ca-py3.11/lib/python3.11/site-packages/tenacity/__init__.py\", line 379, in __call__\n    do = self.iter(retry_state=retry_state)\n         ^^^^^^^^^^^^^^^^^^^^^^^^^^^^^^^^^^\n  File \"/home/fd15hava/.cache/pypoetry/virtualenvs/non-package-mode-zjkKA0Ca-py3.11/lib/python3.11/site-packages/tenacity/__init__.py\", line 326, in iter\n    raise retry_exc from fut.exception()\ntenacity.RetryError: RetryError[<Future at 0x14ac6e8b5f90 state=finished raised UnexpectedAnswerException>]\n",
      "Traceback (most recent call last):\n  File \"/home/fd15hava/.cache/pypoetry/virtualenvs/non-package-mode-zjkKA0Ca-py3.11/lib/python3.11/site-packages/tenacity/__init__.py\", line 382, in __call__\n    result = fn(*args, **kwargs)\n             ^^^^^^^^^^^^^^^^^^^\n  File \"/work/home/fd15hava/tinypaper-mpt/src/agent.py\", line 26, in play\n    answer = self._prompt(self._make_prompt(scenario))\n             ^^^^^^^^^^^^^^^^^^^^^^^^^^^^^^^^^^^^^^^^^\n  File \"/work/home/fd15hava/tinypaper-mpt/src/agent.py\", line 40, in _prompt\n    raise UnexpectedAnswerException(f\"expected 1 or 2, got {result}\")\nutil.UnexpectedAnswerException: expected 1 or 2, got  \n\nThe above exception was the direct cause of the following exception:\n\nTraceback (most recent call last):\n  File \"/work/home/fd15hava/tinypaper-mpt/scripts/experiments/run.py\", line 16, in _run_session\n    result = agent.play(session)\n             ^^^^^^^^^^^^^^^^^^^\n  File \"/home/fd15hava/.cache/pypoetry/virtualenvs/non-package-mode-zjkKA0Ca-py3.11/lib/python3.11/site-packages/tenacity/__init__.py\", line 289, in wrapped_f\n    return self(f, *args, **kw)\n           ^^^^^^^^^^^^^^^^^^^^\n  File \"/home/fd15hava/.cache/pypoetry/virtualenvs/non-package-mode-zjkKA0Ca-py3.11/lib/python3.11/site-packages/tenacity/__init__.py\", line 379, in __call__\n    do = self.iter(retry_state=retry_state)\n         ^^^^^^^^^^^^^^^^^^^^^^^^^^^^^^^^^^\n  File \"/home/fd15hava/.cache/pypoetry/virtualenvs/non-package-mode-zjkKA0Ca-py3.11/lib/python3.11/site-packages/tenacity/__init__.py\", line 326, in iter\n    raise retry_exc from fut.exception()\ntenacity.RetryError: RetryError[<Future at 0x14ac6c0a37d0 state=finished raised UnexpectedAnswerException>]\n",
      "Traceback (most recent call last):\n  File \"/home/fd15hava/.cache/pypoetry/virtualenvs/non-package-mode-zjkKA0Ca-py3.11/lib/python3.11/site-packages/tenacity/__init__.py\", line 382, in __call__\n    result = fn(*args, **kwargs)\n             ^^^^^^^^^^^^^^^^^^^\n  File \"/work/home/fd15hava/tinypaper-mpt/src/agent.py\", line 26, in play\n    answer = self._prompt(self._make_prompt(scenario))\n             ^^^^^^^^^^^^^^^^^^^^^^^^^^^^^^^^^^^^^^^^^\n  File \"/work/home/fd15hava/tinypaper-mpt/src/agent.py\", line 40, in _prompt\n    raise UnexpectedAnswerException(f\"expected 1 or 2, got {result}\")\nutil.UnexpectedAnswerException: expected 1 or 2, got  \n\nThe above exception was the direct cause of the following exception:\n\nTraceback (most recent call last):\n  File \"/work/home/fd15hava/tinypaper-mpt/scripts/experiments/run.py\", line 16, in _run_session\n    result = agent.play(session)\n             ^^^^^^^^^^^^^^^^^^^\n  File \"/home/fd15hava/.cache/pypoetry/virtualenvs/non-package-mode-zjkKA0Ca-py3.11/lib/python3.11/site-packages/tenacity/__init__.py\", line 289, in wrapped_f\n    return self(f, *args, **kw)\n           ^^^^^^^^^^^^^^^^^^^^\n  File \"/home/fd15hava/.cache/pypoetry/virtualenvs/non-package-mode-zjkKA0Ca-py3.11/lib/python3.11/site-packages/tenacity/__init__.py\", line 379, in __call__\n    do = self.iter(retry_state=retry_state)\n         ^^^^^^^^^^^^^^^^^^^^^^^^^^^^^^^^^^\n  File \"/home/fd15hava/.cache/pypoetry/virtualenvs/non-package-mode-zjkKA0Ca-py3.11/lib/python3.11/site-packages/tenacity/__init__.py\", line 326, in iter\n    raise retry_exc from fut.exception()\ntenacity.RetryError: RetryError[<Future at 0x14ac641b3950 state=finished raised UnexpectedAnswerException>]\n",
      "Traceback (most recent call last):\n  File \"/home/fd15hava/.cache/pypoetry/virtualenvs/non-package-mode-zjkKA0Ca-py3.11/lib/python3.11/site-packages/tenacity/__init__.py\", line 382, in __call__\n    result = fn(*args, **kwargs)\n             ^^^^^^^^^^^^^^^^^^^\n  File \"/work/home/fd15hava/tinypaper-mpt/src/agent.py\", line 26, in play\n    answer = self._prompt(self._make_prompt(scenario))\n             ^^^^^^^^^^^^^^^^^^^^^^^^^^^^^^^^^^^^^^^^^\n  File \"/work/home/fd15hava/tinypaper-mpt/src/agent.py\", line 40, in _prompt\n    raise UnexpectedAnswerException(f\"expected 1 or 2, got {result}\")\nutil.UnexpectedAnswerException: expected 1 or 2, got  \n\nThe above exception was the direct cause of the following exception:\n\nTraceback (most recent call last):\n  File \"/work/home/fd15hava/tinypaper-mpt/scripts/experiments/run.py\", line 16, in _run_session\n    result = agent.play(session)\n             ^^^^^^^^^^^^^^^^^^^\n  File \"/home/fd15hava/.cache/pypoetry/virtualenvs/non-package-mode-zjkKA0Ca-py3.11/lib/python3.11/site-packages/tenacity/__init__.py\", line 289, in wrapped_f\n    return self(f, *args, **kw)\n           ^^^^^^^^^^^^^^^^^^^^\n  File \"/home/fd15hava/.cache/pypoetry/virtualenvs/non-package-mode-zjkKA0Ca-py3.11/lib/python3.11/site-packages/tenacity/__init__.py\", line 379, in __call__\n    do = self.iter(retry_state=retry_state)\n         ^^^^^^^^^^^^^^^^^^^^^^^^^^^^^^^^^^\n  File \"/home/fd15hava/.cache/pypoetry/virtualenvs/non-package-mode-zjkKA0Ca-py3.11/lib/python3.11/site-packages/tenacity/__init__.py\", line 326, in iter\n    raise retry_exc from fut.exception()\ntenacity.RetryError: RetryError[<Future at 0x14ac6c0a3950 state=finished raised UnexpectedAnswerException>]\n",
      "Traceback (most recent call last):\n  File \"/home/fd15hava/.cache/pypoetry/virtualenvs/non-package-mode-zjkKA0Ca-py3.11/lib/python3.11/site-packages/tenacity/__init__.py\", line 382, in __call__\n    result = fn(*args, **kwargs)\n             ^^^^^^^^^^^^^^^^^^^\n  File \"/work/home/fd15hava/tinypaper-mpt/src/agent.py\", line 26, in play\n    answer = self._prompt(self._make_prompt(scenario))\n             ^^^^^^^^^^^^^^^^^^^^^^^^^^^^^^^^^^^^^^^^^\n  File \"/work/home/fd15hava/tinypaper-mpt/src/agent.py\", line 40, in _prompt\n    raise UnexpectedAnswerException(f\"expected 1 or 2, got {result}\")\nutil.UnexpectedAnswerException: expected 1 or 2, got  \n\nThe above exception was the direct cause of the following exception:\n\nTraceback (most recent call last):\n  File \"/work/home/fd15hava/tinypaper-mpt/scripts/experiments/run.py\", line 16, in _run_session\n    result = agent.play(session)\n             ^^^^^^^^^^^^^^^^^^^\n  File \"/home/fd15hava/.cache/pypoetry/virtualenvs/non-package-mode-zjkKA0Ca-py3.11/lib/python3.11/site-packages/tenacity/__init__.py\", line 289, in wrapped_f\n    return self(f, *args, **kw)\n           ^^^^^^^^^^^^^^^^^^^^\n  File \"/home/fd15hava/.cache/pypoetry/virtualenvs/non-package-mode-zjkKA0Ca-py3.11/lib/python3.11/site-packages/tenacity/__init__.py\", line 379, in __call__\n    do = self.iter(retry_state=retry_state)\n         ^^^^^^^^^^^^^^^^^^^^^^^^^^^^^^^^^^\n  File \"/home/fd15hava/.cache/pypoetry/virtualenvs/non-package-mode-zjkKA0Ca-py3.11/lib/python3.11/site-packages/tenacity/__init__.py\", line 326, in iter\n    raise retry_exc from fut.exception()\ntenacity.RetryError: RetryError[<Future at 0x14ac64110750 state=finished raised UnexpectedAnswerException>]\n",
      "Traceback (most recent call last):\n  File \"/home/fd15hava/.cache/pypoetry/virtualenvs/non-package-mode-zjkKA0Ca-py3.11/lib/python3.11/site-packages/tenacity/__init__.py\", line 382, in __call__\n    result = fn(*args, **kwargs)\n             ^^^^^^^^^^^^^^^^^^^\n  File \"/work/home/fd15hava/tinypaper-mpt/src/agent.py\", line 26, in play\n    answer = self._prompt(self._make_prompt(scenario))\n             ^^^^^^^^^^^^^^^^^^^^^^^^^^^^^^^^^^^^^^^^^\n  File \"/work/home/fd15hava/tinypaper-mpt/src/agent.py\", line 40, in _prompt\n    raise UnexpectedAnswerException(f\"expected 1 or 2, got {result}\")\nutil.UnexpectedAnswerException: expected 1 or 2, got  \n\nThe above exception was the direct cause of the following exception:\n\nTraceback (most recent call last):\n  File \"/work/home/fd15hava/tinypaper-mpt/scripts/experiments/run.py\", line 16, in _run_session\n    result = agent.play(session)\n             ^^^^^^^^^^^^^^^^^^^\n  File \"/home/fd15hava/.cache/pypoetry/virtualenvs/non-package-mode-zjkKA0Ca-py3.11/lib/python3.11/site-packages/tenacity/__init__.py\", line 289, in wrapped_f\n    return self(f, *args, **kw)\n           ^^^^^^^^^^^^^^^^^^^^\n  File \"/home/fd15hava/.cache/pypoetry/virtualenvs/non-package-mode-zjkKA0Ca-py3.11/lib/python3.11/site-packages/tenacity/__init__.py\", line 379, in __call__\n    do = self.iter(retry_state=retry_state)\n         ^^^^^^^^^^^^^^^^^^^^^^^^^^^^^^^^^^\n  File \"/home/fd15hava/.cache/pypoetry/virtualenvs/non-package-mode-zjkKA0Ca-py3.11/lib/python3.11/site-packages/tenacity/__init__.py\", line 326, in iter\n    raise retry_exc from fut.exception()\ntenacity.RetryError: RetryError[<Future at 0x14ac64135150 state=finished raised UnexpectedAnswerException>]\n",
      "Traceback (most recent call last):\n  File \"/home/fd15hava/.cache/pypoetry/virtualenvs/non-package-mode-zjkKA0Ca-py3.11/lib/python3.11/site-packages/tenacity/__init__.py\", line 382, in __call__\n    result = fn(*args, **kwargs)\n             ^^^^^^^^^^^^^^^^^^^\n  File \"/work/home/fd15hava/tinypaper-mpt/src/agent.py\", line 26, in play\n    answer = self._prompt(self._make_prompt(scenario))\n             ^^^^^^^^^^^^^^^^^^^^^^^^^^^^^^^^^^^^^^^^^\n  File \"/work/home/fd15hava/tinypaper-mpt/src/agent.py\", line 40, in _prompt\n    raise UnexpectedAnswerException(f\"expected 1 or 2, got {result}\")\nutil.UnexpectedAnswerException: expected 1 or 2, got  \n\nThe above exception was the direct cause of the following exception:\n\nTraceback (most recent call last):\n  File \"/work/home/fd15hava/tinypaper-mpt/scripts/experiments/run.py\", line 16, in _run_session\n    result = agent.play(session)\n             ^^^^^^^^^^^^^^^^^^^\n  File \"/home/fd15hava/.cache/pypoetry/virtualenvs/non-package-mode-zjkKA0Ca-py3.11/lib/python3.11/site-packages/tenacity/__init__.py\", line 289, in wrapped_f\n    return self(f, *args, **kw)\n           ^^^^^^^^^^^^^^^^^^^^\n  File \"/home/fd15hava/.cache/pypoetry/virtualenvs/non-package-mode-zjkKA0Ca-py3.11/lib/python3.11/site-packages/tenacity/__init__.py\", line 379, in __call__\n    do = self.iter(retry_state=retry_state)\n         ^^^^^^^^^^^^^^^^^^^^^^^^^^^^^^^^^^\n  File \"/home/fd15hava/.cache/pypoetry/virtualenvs/non-package-mode-zjkKA0Ca-py3.11/lib/python3.11/site-packages/tenacity/__init__.py\", line 326, in iter\n    raise retry_exc from fut.exception()\ntenacity.RetryError: RetryError[<Future at 0x14ac641b3d90 state=finished raised UnexpectedAnswerException>]\n",
      "Traceback (most recent call last):\n  File \"/home/fd15hava/.cache/pypoetry/virtualenvs/non-package-mode-zjkKA0Ca-py3.11/lib/python3.11/site-packages/tenacity/__init__.py\", line 382, in __call__\n    result = fn(*args, **kwargs)\n             ^^^^^^^^^^^^^^^^^^^\n  File \"/work/home/fd15hava/tinypaper-mpt/src/agent.py\", line 26, in play\n    answer = self._prompt(self._make_prompt(scenario))\n             ^^^^^^^^^^^^^^^^^^^^^^^^^^^^^^^^^^^^^^^^^\n  File \"/work/home/fd15hava/tinypaper-mpt/src/agent.py\", line 40, in _prompt\n    raise UnexpectedAnswerException(f\"expected 1 or 2, got {result}\")\nutil.UnexpectedAnswerException: expected 1 or 2, got  \n\nThe above exception was the direct cause of the following exception:\n\nTraceback (most recent call last):\n  File \"/work/home/fd15hava/tinypaper-mpt/scripts/experiments/run.py\", line 16, in _run_session\n    result = agent.play(session)\n             ^^^^^^^^^^^^^^^^^^^\n  File \"/home/fd15hava/.cache/pypoetry/virtualenvs/non-package-mode-zjkKA0Ca-py3.11/lib/python3.11/site-packages/tenacity/__init__.py\", line 289, in wrapped_f\n    return self(f, *args, **kw)\n           ^^^^^^^^^^^^^^^^^^^^\n  File \"/home/fd15hava/.cache/pypoetry/virtualenvs/non-package-mode-zjkKA0Ca-py3.11/lib/python3.11/site-packages/tenacity/__init__.py\", line 379, in __call__\n    do = self.iter(retry_state=retry_state)\n         ^^^^^^^^^^^^^^^^^^^^^^^^^^^^^^^^^^\n  File \"/home/fd15hava/.cache/pypoetry/virtualenvs/non-package-mode-zjkKA0Ca-py3.11/lib/python3.11/site-packages/tenacity/__init__.py\", line 326, in iter\n    raise retry_exc from fut.exception()\ntenacity.RetryError: RetryError[<Future at 0x14ac64136c50 state=finished raised UnexpectedAnswerException>]\n",
      "Traceback (most recent call last):\n  File \"/home/fd15hava/.cache/pypoetry/virtualenvs/non-package-mode-zjkKA0Ca-py3.11/lib/python3.11/site-packages/tenacity/__init__.py\", line 382, in __call__\n    result = fn(*args, **kwargs)\n             ^^^^^^^^^^^^^^^^^^^\n  File \"/work/home/fd15hava/tinypaper-mpt/src/agent.py\", line 26, in play\n    answer = self._prompt(self._make_prompt(scenario))\n             ^^^^^^^^^^^^^^^^^^^^^^^^^^^^^^^^^^^^^^^^^\n  File \"/work/home/fd15hava/tinypaper-mpt/src/agent.py\", line 40, in _prompt\n    raise UnexpectedAnswerException(f\"expected 1 or 2, got {result}\")\nutil.UnexpectedAnswerException: expected 1 or 2, got  \n\nThe above exception was the direct cause of the following exception:\n\nTraceback (most recent call last):\n  File \"/work/home/fd15hava/tinypaper-mpt/scripts/experiments/run.py\", line 16, in _run_session\n    result = agent.play(session)\n             ^^^^^^^^^^^^^^^^^^^\n  File \"/home/fd15hava/.cache/pypoetry/virtualenvs/non-package-mode-zjkKA0Ca-py3.11/lib/python3.11/site-packages/tenacity/__init__.py\", line 289, in wrapped_f\n    return self(f, *args, **kw)\n           ^^^^^^^^^^^^^^^^^^^^\n  File \"/home/fd15hava/.cache/pypoetry/virtualenvs/non-package-mode-zjkKA0Ca-py3.11/lib/python3.11/site-packages/tenacity/__init__.py\", line 379, in __call__\n    do = self.iter(retry_state=retry_state)\n         ^^^^^^^^^^^^^^^^^^^^^^^^^^^^^^^^^^\n  File \"/home/fd15hava/.cache/pypoetry/virtualenvs/non-package-mode-zjkKA0Ca-py3.11/lib/python3.11/site-packages/tenacity/__init__.py\", line 326, in iter\n    raise retry_exc from fut.exception()\ntenacity.RetryError: RetryError[<Future at 0x14ac6e8a6490 state=finished raised UnexpectedAnswerException>]\n",
      "Traceback (most recent call last):\n  File \"/home/fd15hava/.cache/pypoetry/virtualenvs/non-package-mode-zjkKA0Ca-py3.11/lib/python3.11/site-packages/tenacity/__init__.py\", line 382, in __call__\n    result = fn(*args, **kwargs)\n             ^^^^^^^^^^^^^^^^^^^\n  File \"/work/home/fd15hava/tinypaper-mpt/src/agent.py\", line 26, in play\n    answer = self._prompt(self._make_prompt(scenario))\n             ^^^^^^^^^^^^^^^^^^^^^^^^^^^^^^^^^^^^^^^^^\n  File \"/work/home/fd15hava/tinypaper-mpt/src/agent.py\", line 40, in _prompt\n    raise UnexpectedAnswerException(f\"expected 1 or 2, got {result}\")\nutil.UnexpectedAnswerException: expected 1 or 2, got  \n\nThe above exception was the direct cause of the following exception:\n\nTraceback (most recent call last):\n  File \"/work/home/fd15hava/tinypaper-mpt/scripts/experiments/run.py\", line 16, in _run_session\n    result = agent.play(session)\n             ^^^^^^^^^^^^^^^^^^^\n  File \"/home/fd15hava/.cache/pypoetry/virtualenvs/non-package-mode-zjkKA0Ca-py3.11/lib/python3.11/site-packages/tenacity/__init__.py\", line 289, in wrapped_f\n    return self(f, *args, **kw)\n           ^^^^^^^^^^^^^^^^^^^^\n  File \"/home/fd15hava/.cache/pypoetry/virtualenvs/non-package-mode-zjkKA0Ca-py3.11/lib/python3.11/site-packages/tenacity/__init__.py\", line 379, in __call__\n    do = self.iter(retry_state=retry_state)\n         ^^^^^^^^^^^^^^^^^^^^^^^^^^^^^^^^^^\n  File \"/home/fd15hava/.cache/pypoetry/virtualenvs/non-package-mode-zjkKA0Ca-py3.11/lib/python3.11/site-packages/tenacity/__init__.py\", line 326, in iter\n    raise retry_exc from fut.exception()\ntenacity.RetryError: RetryError[<Future at 0x14ac641b1650 state=finished raised UnexpectedAnswerException>]\n",
      "Traceback (most recent call last):\n  File \"/home/fd15hava/.cache/pypoetry/virtualenvs/non-package-mode-zjkKA0Ca-py3.11/lib/python3.11/site-packages/tenacity/__init__.py\", line 382, in __call__\n    result = fn(*args, **kwargs)\n             ^^^^^^^^^^^^^^^^^^^\n  File \"/work/home/fd15hava/tinypaper-mpt/src/agent.py\", line 26, in play\n    answer = self._prompt(self._make_prompt(scenario))\n             ^^^^^^^^^^^^^^^^^^^^^^^^^^^^^^^^^^^^^^^^^\n  File \"/work/home/fd15hava/tinypaper-mpt/src/agent.py\", line 40, in _prompt\n    raise UnexpectedAnswerException(f\"expected 1 or 2, got {result}\")\nutil.UnexpectedAnswerException: expected 1 or 2, got  \n\nThe above exception was the direct cause of the following exception:\n\nTraceback (most recent call last):\n  File \"/work/home/fd15hava/tinypaper-mpt/scripts/experiments/run.py\", line 16, in _run_session\n    result = agent.play(session)\n             ^^^^^^^^^^^^^^^^^^^\n  File \"/home/fd15hava/.cache/pypoetry/virtualenvs/non-package-mode-zjkKA0Ca-py3.11/lib/python3.11/site-packages/tenacity/__init__.py\", line 289, in wrapped_f\n    return self(f, *args, **kw)\n           ^^^^^^^^^^^^^^^^^^^^\n  File \"/home/fd15hava/.cache/pypoetry/virtualenvs/non-package-mode-zjkKA0Ca-py3.11/lib/python3.11/site-packages/tenacity/__init__.py\", line 379, in __call__\n    do = self.iter(retry_state=retry_state)\n         ^^^^^^^^^^^^^^^^^^^^^^^^^^^^^^^^^^\n  File \"/home/fd15hava/.cache/pypoetry/virtualenvs/non-package-mode-zjkKA0Ca-py3.11/lib/python3.11/site-packages/tenacity/__init__.py\", line 326, in iter\n    raise retry_exc from fut.exception()\ntenacity.RetryError: RetryError[<Future at 0x14ac6e925bd0 state=finished raised UnexpectedAnswerException>]\n",
      "Traceback (most recent call last):\n  File \"/home/fd15hava/.cache/pypoetry/virtualenvs/non-package-mode-zjkKA0Ca-py3.11/lib/python3.11/site-packages/tenacity/__init__.py\", line 382, in __call__\n    result = fn(*args, **kwargs)\n             ^^^^^^^^^^^^^^^^^^^\n  File \"/work/home/fd15hava/tinypaper-mpt/src/agent.py\", line 26, in play\n    answer = self._prompt(self._make_prompt(scenario))\n             ^^^^^^^^^^^^^^^^^^^^^^^^^^^^^^^^^^^^^^^^^\n  File \"/work/home/fd15hava/tinypaper-mpt/src/agent.py\", line 40, in _prompt\n    raise UnexpectedAnswerException(f\"expected 1 or 2, got {result}\")\nutil.UnexpectedAnswerException: expected 1 or 2, got  \n\nThe above exception was the direct cause of the following exception:\n\nTraceback (most recent call last):\n  File \"/work/home/fd15hava/tinypaper-mpt/scripts/experiments/run.py\", line 16, in _run_session\n    result = agent.play(session)\n             ^^^^^^^^^^^^^^^^^^^\n  File \"/home/fd15hava/.cache/pypoetry/virtualenvs/non-package-mode-zjkKA0Ca-py3.11/lib/python3.11/site-packages/tenacity/__init__.py\", line 289, in wrapped_f\n    return self(f, *args, **kw)\n           ^^^^^^^^^^^^^^^^^^^^\n  File \"/home/fd15hava/.cache/pypoetry/virtualenvs/non-package-mode-zjkKA0Ca-py3.11/lib/python3.11/site-packages/tenacity/__init__.py\", line 379, in __call__\n    do = self.iter(retry_state=retry_state)\n         ^^^^^^^^^^^^^^^^^^^^^^^^^^^^^^^^^^\n  File \"/home/fd15hava/.cache/pypoetry/virtualenvs/non-package-mode-zjkKA0Ca-py3.11/lib/python3.11/site-packages/tenacity/__init__.py\", line 326, in iter\n    raise retry_exc from fut.exception()\ntenacity.RetryError: RetryError[<Future at 0x14ac6e8b5f90 state=finished raised UnexpectedAnswerException>]\n",
      "Traceback (most recent call last):\n  File \"/home/fd15hava/.cache/pypoetry/virtualenvs/non-package-mode-zjkKA0Ca-py3.11/lib/python3.11/site-packages/tenacity/__init__.py\", line 382, in __call__\n    result = fn(*args, **kwargs)\n             ^^^^^^^^^^^^^^^^^^^\n  File \"/work/home/fd15hava/tinypaper-mpt/src/agent.py\", line 26, in play\n    answer = self._prompt(self._make_prompt(scenario))\n             ^^^^^^^^^^^^^^^^^^^^^^^^^^^^^^^^^^^^^^^^^\n  File \"/work/home/fd15hava/tinypaper-mpt/src/agent.py\", line 40, in _prompt\n    raise UnexpectedAnswerException(f\"expected 1 or 2, got {result}\")\nutil.UnexpectedAnswerException: expected 1 or 2, got  \n\nThe above exception was the direct cause of the following exception:\n\nTraceback (most recent call last):\n  File \"/work/home/fd15hava/tinypaper-mpt/scripts/experiments/run.py\", line 16, in _run_session\n    result = agent.play(session)\n             ^^^^^^^^^^^^^^^^^^^\n  File \"/home/fd15hava/.cache/pypoetry/virtualenvs/non-package-mode-zjkKA0Ca-py3.11/lib/python3.11/site-packages/tenacity/__init__.py\", line 289, in wrapped_f\n    return self(f, *args, **kw)\n           ^^^^^^^^^^^^^^^^^^^^\n  File \"/home/fd15hava/.cache/pypoetry/virtualenvs/non-package-mode-zjkKA0Ca-py3.11/lib/python3.11/site-packages/tenacity/__init__.py\", line 379, in __call__\n    do = self.iter(retry_state=retry_state)\n         ^^^^^^^^^^^^^^^^^^^^^^^^^^^^^^^^^^\n  File \"/home/fd15hava/.cache/pypoetry/virtualenvs/non-package-mode-zjkKA0Ca-py3.11/lib/python3.11/site-packages/tenacity/__init__.py\", line 326, in iter\n    raise retry_exc from fut.exception()\ntenacity.RetryError: RetryError[<Future at 0x14ac64112a90 state=finished raised UnexpectedAnswerException>]\n",
      "Traceback (most recent call last):\n  File \"/home/fd15hava/.cache/pypoetry/virtualenvs/non-package-mode-zjkKA0Ca-py3.11/lib/python3.11/site-packages/tenacity/__init__.py\", line 382, in __call__\n    result = fn(*args, **kwargs)\n             ^^^^^^^^^^^^^^^^^^^\n  File \"/work/home/fd15hava/tinypaper-mpt/src/agent.py\", line 26, in play\n    answer = self._prompt(self._make_prompt(scenario))\n             ^^^^^^^^^^^^^^^^^^^^^^^^^^^^^^^^^^^^^^^^^\n  File \"/work/home/fd15hava/tinypaper-mpt/src/agent.py\", line 40, in _prompt\n    raise UnexpectedAnswerException(f\"expected 1 or 2, got {result}\")\nutil.UnexpectedAnswerException: expected 1 or 2, got  \n\nThe above exception was the direct cause of the following exception:\n\nTraceback (most recent call last):\n  File \"/work/home/fd15hava/tinypaper-mpt/scripts/experiments/run.py\", line 16, in _run_session\n    result = agent.play(session)\n             ^^^^^^^^^^^^^^^^^^^\n  File \"/home/fd15hava/.cache/pypoetry/virtualenvs/non-package-mode-zjkKA0Ca-py3.11/lib/python3.11/site-packages/tenacity/__init__.py\", line 289, in wrapped_f\n    return self(f, *args, **kw)\n           ^^^^^^^^^^^^^^^^^^^^\n  File \"/home/fd15hava/.cache/pypoetry/virtualenvs/non-package-mode-zjkKA0Ca-py3.11/lib/python3.11/site-packages/tenacity/__init__.py\", line 379, in __call__\n    do = self.iter(retry_state=retry_state)\n         ^^^^^^^^^^^^^^^^^^^^^^^^^^^^^^^^^^\n  File \"/home/fd15hava/.cache/pypoetry/virtualenvs/non-package-mode-zjkKA0Ca-py3.11/lib/python3.11/site-packages/tenacity/__init__.py\", line 326, in iter\n    raise retry_exc from fut.exception()\ntenacity.RetryError: RetryError[<Future at 0x14ac641b1290 state=finished raised UnexpectedAnswerException>]\n",
      "Traceback (most recent call last):\n  File \"/home/fd15hava/.cache/pypoetry/virtualenvs/non-package-mode-zjkKA0Ca-py3.11/lib/python3.11/site-packages/tenacity/__init__.py\", line 382, in __call__\n    result = fn(*args, **kwargs)\n             ^^^^^^^^^^^^^^^^^^^\n  File \"/work/home/fd15hava/tinypaper-mpt/src/agent.py\", line 26, in play\n    answer = self._prompt(self._make_prompt(scenario))\n             ^^^^^^^^^^^^^^^^^^^^^^^^^^^^^^^^^^^^^^^^^\n  File \"/work/home/fd15hava/tinypaper-mpt/src/agent.py\", line 40, in _prompt\n    raise UnexpectedAnswerException(f\"expected 1 or 2, got {result}\")\nutil.UnexpectedAnswerException: expected 1 or 2, got  \n\nThe above exception was the direct cause of the following exception:\n\nTraceback (most recent call last):\n  File \"/work/home/fd15hava/tinypaper-mpt/scripts/experiments/run.py\", line 16, in _run_session\n    result = agent.play(session)\n             ^^^^^^^^^^^^^^^^^^^\n  File \"/home/fd15hava/.cache/pypoetry/virtualenvs/non-package-mode-zjkKA0Ca-py3.11/lib/python3.11/site-packages/tenacity/__init__.py\", line 289, in wrapped_f\n    return self(f, *args, **kw)\n           ^^^^^^^^^^^^^^^^^^^^\n  File \"/home/fd15hava/.cache/pypoetry/virtualenvs/non-package-mode-zjkKA0Ca-py3.11/lib/python3.11/site-packages/tenacity/__init__.py\", line 379, in __call__\n    do = self.iter(retry_state=retry_state)\n         ^^^^^^^^^^^^^^^^^^^^^^^^^^^^^^^^^^\n  File \"/home/fd15hava/.cache/pypoetry/virtualenvs/non-package-mode-zjkKA0Ca-py3.11/lib/python3.11/site-packages/tenacity/__init__.py\", line 326, in iter\n    raise retry_exc from fut.exception()\ntenacity.RetryError: RetryError[<Future at 0x14ac641b24d0 state=finished raised UnexpectedAnswerException>]\n",
      "Traceback (most recent call last):\n  File \"/home/fd15hava/.cache/pypoetry/virtualenvs/non-package-mode-zjkKA0Ca-py3.11/lib/python3.11/site-packages/tenacity/__init__.py\", line 382, in __call__\n    result = fn(*args, **kwargs)\n             ^^^^^^^^^^^^^^^^^^^\n  File \"/work/home/fd15hava/tinypaper-mpt/src/agent.py\", line 26, in play\n    answer = self._prompt(self._make_prompt(scenario))\n             ^^^^^^^^^^^^^^^^^^^^^^^^^^^^^^^^^^^^^^^^^\n  File \"/work/home/fd15hava/tinypaper-mpt/src/agent.py\", line 40, in _prompt\n    raise UnexpectedAnswerException(f\"expected 1 or 2, got {result}\")\nutil.UnexpectedAnswerException: expected 1 or 2, got  \n\nThe above exception was the direct cause of the following exception:\n\nTraceback (most recent call last):\n  File \"/work/home/fd15hava/tinypaper-mpt/scripts/experiments/run.py\", line 16, in _run_session\n    result = agent.play(session)\n             ^^^^^^^^^^^^^^^^^^^\n  File \"/home/fd15hava/.cache/pypoetry/virtualenvs/non-package-mode-zjkKA0Ca-py3.11/lib/python3.11/site-packages/tenacity/__init__.py\", line 289, in wrapped_f\n    return self(f, *args, **kw)\n           ^^^^^^^^^^^^^^^^^^^^\n  File \"/home/fd15hava/.cache/pypoetry/virtualenvs/non-package-mode-zjkKA0Ca-py3.11/lib/python3.11/site-packages/tenacity/__init__.py\", line 379, in __call__\n    do = self.iter(retry_state=retry_state)\n         ^^^^^^^^^^^^^^^^^^^^^^^^^^^^^^^^^^\n  File \"/home/fd15hava/.cache/pypoetry/virtualenvs/non-package-mode-zjkKA0Ca-py3.11/lib/python3.11/site-packages/tenacity/__init__.py\", line 326, in iter\n    raise retry_exc from fut.exception()\ntenacity.RetryError: RetryError[<Future at 0x14ac64136150 state=finished raised UnexpectedAnswerException>]\n",
      "Traceback (most recent call last):\n  File \"/home/fd15hava/.cache/pypoetry/virtualenvs/non-package-mode-zjkKA0Ca-py3.11/lib/python3.11/site-packages/tenacity/__init__.py\", line 382, in __call__\n    result = fn(*args, **kwargs)\n             ^^^^^^^^^^^^^^^^^^^\n  File \"/work/home/fd15hava/tinypaper-mpt/src/agent.py\", line 26, in play\n    answer = self._prompt(self._make_prompt(scenario))\n             ^^^^^^^^^^^^^^^^^^^^^^^^^^^^^^^^^^^^^^^^^\n  File \"/work/home/fd15hava/tinypaper-mpt/src/agent.py\", line 40, in _prompt\n    raise UnexpectedAnswerException(f\"expected 1 or 2, got {result}\")\nutil.UnexpectedAnswerException: expected 1 or 2, got  \n\nThe above exception was the direct cause of the following exception:\n\nTraceback (most recent call last):\n  File \"/work/home/fd15hava/tinypaper-mpt/scripts/experiments/run.py\", line 16, in _run_session\n    result = agent.play(session)\n             ^^^^^^^^^^^^^^^^^^^\n  File \"/home/fd15hava/.cache/pypoetry/virtualenvs/non-package-mode-zjkKA0Ca-py3.11/lib/python3.11/site-packages/tenacity/__init__.py\", line 289, in wrapped_f\n    return self(f, *args, **kw)\n           ^^^^^^^^^^^^^^^^^^^^\n  File \"/home/fd15hava/.cache/pypoetry/virtualenvs/non-package-mode-zjkKA0Ca-py3.11/lib/python3.11/site-packages/tenacity/__init__.py\", line 379, in __call__\n    do = self.iter(retry_state=retry_state)\n         ^^^^^^^^^^^^^^^^^^^^^^^^^^^^^^^^^^\n  File \"/home/fd15hava/.cache/pypoetry/virtualenvs/non-package-mode-zjkKA0Ca-py3.11/lib/python3.11/site-packages/tenacity/__init__.py\", line 326, in iter\n    raise retry_exc from fut.exception()\ntenacity.RetryError: RetryError[<Future at 0x14ac6c0ec2d0 state=finished raised UnexpectedAnswerException>]\n",
      "Traceback (most recent call last):\n  File \"/home/fd15hava/.cache/pypoetry/virtualenvs/non-package-mode-zjkKA0Ca-py3.11/lib/python3.11/site-packages/tenacity/__init__.py\", line 382, in __call__\n    result = fn(*args, **kwargs)\n             ^^^^^^^^^^^^^^^^^^^\n  File \"/work/home/fd15hava/tinypaper-mpt/src/agent.py\", line 26, in play\n    answer = self._prompt(self._make_prompt(scenario))\n             ^^^^^^^^^^^^^^^^^^^^^^^^^^^^^^^^^^^^^^^^^\n  File \"/work/home/fd15hava/tinypaper-mpt/src/agent.py\", line 40, in _prompt\n    raise UnexpectedAnswerException(f\"expected 1 or 2, got {result}\")\nutil.UnexpectedAnswerException: expected 1 or 2, got  \n\nThe above exception was the direct cause of the following exception:\n\nTraceback (most recent call last):\n  File \"/work/home/fd15hava/tinypaper-mpt/scripts/experiments/run.py\", line 16, in _run_session\n    result = agent.play(session)\n             ^^^^^^^^^^^^^^^^^^^\n  File \"/home/fd15hava/.cache/pypoetry/virtualenvs/non-package-mode-zjkKA0Ca-py3.11/lib/python3.11/site-packages/tenacity/__init__.py\", line 289, in wrapped_f\n    return self(f, *args, **kw)\n           ^^^^^^^^^^^^^^^^^^^^\n  File \"/home/fd15hava/.cache/pypoetry/virtualenvs/non-package-mode-zjkKA0Ca-py3.11/lib/python3.11/site-packages/tenacity/__init__.py\", line 379, in __call__\n    do = self.iter(retry_state=retry_state)\n         ^^^^^^^^^^^^^^^^^^^^^^^^^^^^^^^^^^\n  File \"/home/fd15hava/.cache/pypoetry/virtualenvs/non-package-mode-zjkKA0Ca-py3.11/lib/python3.11/site-packages/tenacity/__init__.py\", line 326, in iter\n    raise retry_exc from fut.exception()\ntenacity.RetryError: RetryError[<Future at 0x14ac6f013490 state=finished raised UnexpectedAnswerException>]\n",
      "Traceback (most recent call last):\n  File \"/home/fd15hava/.cache/pypoetry/virtualenvs/non-package-mode-zjkKA0Ca-py3.11/lib/python3.11/site-packages/tenacity/__init__.py\", line 382, in __call__\n    result = fn(*args, **kwargs)\n             ^^^^^^^^^^^^^^^^^^^\n  File \"/work/home/fd15hava/tinypaper-mpt/src/agent.py\", line 26, in play\n    answer = self._prompt(self._make_prompt(scenario))\n             ^^^^^^^^^^^^^^^^^^^^^^^^^^^^^^^^^^^^^^^^^\n  File \"/work/home/fd15hava/tinypaper-mpt/src/agent.py\", line 40, in _prompt\n    raise UnexpectedAnswerException(f\"expected 1 or 2, got {result}\")\nutil.UnexpectedAnswerException: expected 1 or 2, got  \n\nThe above exception was the direct cause of the following exception:\n\nTraceback (most recent call last):\n  File \"/work/home/fd15hava/tinypaper-mpt/scripts/experiments/run.py\", line 16, in _run_session\n    result = agent.play(session)\n             ^^^^^^^^^^^^^^^^^^^\n  File \"/home/fd15hava/.cache/pypoetry/virtualenvs/non-package-mode-zjkKA0Ca-py3.11/lib/python3.11/site-packages/tenacity/__init__.py\", line 289, in wrapped_f\n    return self(f, *args, **kw)\n           ^^^^^^^^^^^^^^^^^^^^\n  File \"/home/fd15hava/.cache/pypoetry/virtualenvs/non-package-mode-zjkKA0Ca-py3.11/lib/python3.11/site-packages/tenacity/__init__.py\", line 379, in __call__\n    do = self.iter(retry_state=retry_state)\n         ^^^^^^^^^^^^^^^^^^^^^^^^^^^^^^^^^^\n  File \"/home/fd15hava/.cache/pypoetry/virtualenvs/non-package-mode-zjkKA0Ca-py3.11/lib/python3.11/site-packages/tenacity/__init__.py\", line 326, in iter\n    raise retry_exc from fut.exception()\ntenacity.RetryError: RetryError[<Future at 0x14ac64134b90 state=finished raised UnexpectedAnswerException>]\n",
      "Traceback (most recent call last):\n  File \"/home/fd15hava/.cache/pypoetry/virtualenvs/non-package-mode-zjkKA0Ca-py3.11/lib/python3.11/site-packages/tenacity/__init__.py\", line 382, in __call__\n    result = fn(*args, **kwargs)\n             ^^^^^^^^^^^^^^^^^^^\n  File \"/work/home/fd15hava/tinypaper-mpt/src/agent.py\", line 26, in play\n    answer = self._prompt(self._make_prompt(scenario))\n             ^^^^^^^^^^^^^^^^^^^^^^^^^^^^^^^^^^^^^^^^^\n  File \"/work/home/fd15hava/tinypaper-mpt/src/agent.py\", line 40, in _prompt\n    raise UnexpectedAnswerException(f\"expected 1 or 2, got {result}\")\nutil.UnexpectedAnswerException: expected 1 or 2, got  \n\nThe above exception was the direct cause of the following exception:\n\nTraceback (most recent call last):\n  File \"/work/home/fd15hava/tinypaper-mpt/scripts/experiments/run.py\", line 16, in _run_session\n    result = agent.play(session)\n             ^^^^^^^^^^^^^^^^^^^\n  File \"/home/fd15hava/.cache/pypoetry/virtualenvs/non-package-mode-zjkKA0Ca-py3.11/lib/python3.11/site-packages/tenacity/__init__.py\", line 289, in wrapped_f\n    return self(f, *args, **kw)\n           ^^^^^^^^^^^^^^^^^^^^\n  File \"/home/fd15hava/.cache/pypoetry/virtualenvs/non-package-mode-zjkKA0Ca-py3.11/lib/python3.11/site-packages/tenacity/__init__.py\", line 379, in __call__\n    do = self.iter(retry_state=retry_state)\n         ^^^^^^^^^^^^^^^^^^^^^^^^^^^^^^^^^^\n  File \"/home/fd15hava/.cache/pypoetry/virtualenvs/non-package-mode-zjkKA0Ca-py3.11/lib/python3.11/site-packages/tenacity/__init__.py\", line 326, in iter\n    raise retry_exc from fut.exception()\ntenacity.RetryError: RetryError[<Future at 0x14ac64135650 state=finished raised UnexpectedAnswerException>]\n",
      "Traceback (most recent call last):\n  File \"/home/fd15hava/.cache/pypoetry/virtualenvs/non-package-mode-zjkKA0Ca-py3.11/lib/python3.11/site-packages/tenacity/__init__.py\", line 382, in __call__\n    result = fn(*args, **kwargs)\n             ^^^^^^^^^^^^^^^^^^^\n  File \"/work/home/fd15hava/tinypaper-mpt/src/agent.py\", line 26, in play\n    answer = self._prompt(self._make_prompt(scenario))\n             ^^^^^^^^^^^^^^^^^^^^^^^^^^^^^^^^^^^^^^^^^\n  File \"/work/home/fd15hava/tinypaper-mpt/src/agent.py\", line 40, in _prompt\n    raise UnexpectedAnswerException(f\"expected 1 or 2, got {result}\")\nutil.UnexpectedAnswerException: expected 1 or 2, got  \n\nThe above exception was the direct cause of the following exception:\n\nTraceback (most recent call last):\n  File \"/work/home/fd15hava/tinypaper-mpt/scripts/experiments/run.py\", line 16, in _run_session\n    result = agent.play(session)\n             ^^^^^^^^^^^^^^^^^^^\n  File \"/home/fd15hava/.cache/pypoetry/virtualenvs/non-package-mode-zjkKA0Ca-py3.11/lib/python3.11/site-packages/tenacity/__init__.py\", line 289, in wrapped_f\n    return self(f, *args, **kw)\n           ^^^^^^^^^^^^^^^^^^^^\n  File \"/home/fd15hava/.cache/pypoetry/virtualenvs/non-package-mode-zjkKA0Ca-py3.11/lib/python3.11/site-packages/tenacity/__init__.py\", line 379, in __call__\n    do = self.iter(retry_state=retry_state)\n         ^^^^^^^^^^^^^^^^^^^^^^^^^^^^^^^^^^\n  File \"/home/fd15hava/.cache/pypoetry/virtualenvs/non-package-mode-zjkKA0Ca-py3.11/lib/python3.11/site-packages/tenacity/__init__.py\", line 326, in iter\n    raise retry_exc from fut.exception()\ntenacity.RetryError: RetryError[<Future at 0x14ac6417ad50 state=finished raised UnexpectedAnswerException>]\n",
      "Traceback (most recent call last):\n  File \"/home/fd15hava/.cache/pypoetry/virtualenvs/non-package-mode-zjkKA0Ca-py3.11/lib/python3.11/site-packages/tenacity/__init__.py\", line 382, in __call__\n    result = fn(*args, **kwargs)\n             ^^^^^^^^^^^^^^^^^^^\n  File \"/work/home/fd15hava/tinypaper-mpt/src/agent.py\", line 26, in play\n    answer = self._prompt(self._make_prompt(scenario))\n             ^^^^^^^^^^^^^^^^^^^^^^^^^^^^^^^^^^^^^^^^^\n  File \"/work/home/fd15hava/tinypaper-mpt/src/agent.py\", line 40, in _prompt\n    raise UnexpectedAnswerException(f\"expected 1 or 2, got {result}\")\nutil.UnexpectedAnswerException: expected 1 or 2, got  \n\nThe above exception was the direct cause of the following exception:\n\nTraceback (most recent call last):\n  File \"/work/home/fd15hava/tinypaper-mpt/scripts/experiments/run.py\", line 16, in _run_session\n    result = agent.play(session)\n             ^^^^^^^^^^^^^^^^^^^\n  File \"/home/fd15hava/.cache/pypoetry/virtualenvs/non-package-mode-zjkKA0Ca-py3.11/lib/python3.11/site-packages/tenacity/__init__.py\", line 289, in wrapped_f\n    return self(f, *args, **kw)\n           ^^^^^^^^^^^^^^^^^^^^\n  File \"/home/fd15hava/.cache/pypoetry/virtualenvs/non-package-mode-zjkKA0Ca-py3.11/lib/python3.11/site-packages/tenacity/__init__.py\", line 379, in __call__\n    do = self.iter(retry_state=retry_state)\n         ^^^^^^^^^^^^^^^^^^^^^^^^^^^^^^^^^^\n  File \"/home/fd15hava/.cache/pypoetry/virtualenvs/non-package-mode-zjkKA0Ca-py3.11/lib/python3.11/site-packages/tenacity/__init__.py\", line 326, in iter\n    raise retry_exc from fut.exception()\ntenacity.RetryError: RetryError[<Future at 0x14ac64188f10 state=finished raised UnexpectedAnswerException>]\n",
      "Traceback (most recent call last):\n  File \"/home/fd15hava/.cache/pypoetry/virtualenvs/non-package-mode-zjkKA0Ca-py3.11/lib/python3.11/site-packages/tenacity/__init__.py\", line 382, in __call__\n    result = fn(*args, **kwargs)\n             ^^^^^^^^^^^^^^^^^^^\n  File \"/work/home/fd15hava/tinypaper-mpt/src/agent.py\", line 26, in play\n    answer = self._prompt(self._make_prompt(scenario))\n             ^^^^^^^^^^^^^^^^^^^^^^^^^^^^^^^^^^^^^^^^^\n  File \"/work/home/fd15hava/tinypaper-mpt/src/agent.py\", line 40, in _prompt\n    raise UnexpectedAnswerException(f\"expected 1 or 2, got {result}\")\nutil.UnexpectedAnswerException: expected 1 or 2, got  \n\nThe above exception was the direct cause of the following exception:\n\nTraceback (most recent call last):\n  File \"/work/home/fd15hava/tinypaper-mpt/scripts/experiments/run.py\", line 16, in _run_session\n    result = agent.play(session)\n             ^^^^^^^^^^^^^^^^^^^\n  File \"/home/fd15hava/.cache/pypoetry/virtualenvs/non-package-mode-zjkKA0Ca-py3.11/lib/python3.11/site-packages/tenacity/__init__.py\", line 289, in wrapped_f\n    return self(f, *args, **kw)\n           ^^^^^^^^^^^^^^^^^^^^\n  File \"/home/fd15hava/.cache/pypoetry/virtualenvs/non-package-mode-zjkKA0Ca-py3.11/lib/python3.11/site-packages/tenacity/__init__.py\", line 379, in __call__\n    do = self.iter(retry_state=retry_state)\n         ^^^^^^^^^^^^^^^^^^^^^^^^^^^^^^^^^^\n  File \"/home/fd15hava/.cache/pypoetry/virtualenvs/non-package-mode-zjkKA0Ca-py3.11/lib/python3.11/site-packages/tenacity/__init__.py\", line 326, in iter\n    raise retry_exc from fut.exception()\ntenacity.RetryError: RetryError[<Future at 0x14ac64189810 state=finished raised UnexpectedAnswerException>]\n",
      "Traceback (most recent call last):\n  File \"/home/fd15hava/.cache/pypoetry/virtualenvs/non-package-mode-zjkKA0Ca-py3.11/lib/python3.11/site-packages/tenacity/__init__.py\", line 382, in __call__\n    result = fn(*args, **kwargs)\n             ^^^^^^^^^^^^^^^^^^^\n  File \"/work/home/fd15hava/tinypaper-mpt/src/agent.py\", line 26, in play\n    answer = self._prompt(self._make_prompt(scenario))\n             ^^^^^^^^^^^^^^^^^^^^^^^^^^^^^^^^^^^^^^^^^\n  File \"/work/home/fd15hava/tinypaper-mpt/src/agent.py\", line 40, in _prompt\n    raise UnexpectedAnswerException(f\"expected 1 or 2, got {result}\")\nutil.UnexpectedAnswerException: expected 1 or 2, got  \n\nThe above exception was the direct cause of the following exception:\n\nTraceback (most recent call last):\n  File \"/work/home/fd15hava/tinypaper-mpt/scripts/experiments/run.py\", line 16, in _run_session\n    result = agent.play(session)\n             ^^^^^^^^^^^^^^^^^^^\n  File \"/home/fd15hava/.cache/pypoetry/virtualenvs/non-package-mode-zjkKA0Ca-py3.11/lib/python3.11/site-packages/tenacity/__init__.py\", line 289, in wrapped_f\n    return self(f, *args, **kw)\n           ^^^^^^^^^^^^^^^^^^^^\n  File \"/home/fd15hava/.cache/pypoetry/virtualenvs/non-package-mode-zjkKA0Ca-py3.11/lib/python3.11/site-packages/tenacity/__init__.py\", line 379, in __call__\n    do = self.iter(retry_state=retry_state)\n         ^^^^^^^^^^^^^^^^^^^^^^^^^^^^^^^^^^\n  File \"/home/fd15hava/.cache/pypoetry/virtualenvs/non-package-mode-zjkKA0Ca-py3.11/lib/python3.11/site-packages/tenacity/__init__.py\", line 326, in iter\n    raise retry_exc from fut.exception()\ntenacity.RetryError: RetryError[<Future at 0x14ac6417a610 state=finished raised UnexpectedAnswerException>]\n",
      "Traceback (most recent call last):\n  File \"/home/fd15hava/.cache/pypoetry/virtualenvs/non-package-mode-zjkKA0Ca-py3.11/lib/python3.11/site-packages/tenacity/__init__.py\", line 382, in __call__\n    result = fn(*args, **kwargs)\n             ^^^^^^^^^^^^^^^^^^^\n  File \"/work/home/fd15hava/tinypaper-mpt/src/agent.py\", line 26, in play\n    answer = self._prompt(self._make_prompt(scenario))\n             ^^^^^^^^^^^^^^^^^^^^^^^^^^^^^^^^^^^^^^^^^\n  File \"/work/home/fd15hava/tinypaper-mpt/src/agent.py\", line 40, in _prompt\n    raise UnexpectedAnswerException(f\"expected 1 or 2, got {result}\")\nutil.UnexpectedAnswerException: expected 1 or 2, got  \n\nThe above exception was the direct cause of the following exception:\n\nTraceback (most recent call last):\n  File \"/work/home/fd15hava/tinypaper-mpt/scripts/experiments/run.py\", line 16, in _run_session\n    result = agent.play(session)\n             ^^^^^^^^^^^^^^^^^^^\n  File \"/home/fd15hava/.cache/pypoetry/virtualenvs/non-package-mode-zjkKA0Ca-py3.11/lib/python3.11/site-packages/tenacity/__init__.py\", line 289, in wrapped_f\n    return self(f, *args, **kw)\n           ^^^^^^^^^^^^^^^^^^^^\n  File \"/home/fd15hava/.cache/pypoetry/virtualenvs/non-package-mode-zjkKA0Ca-py3.11/lib/python3.11/site-packages/tenacity/__init__.py\", line 379, in __call__\n    do = self.iter(retry_state=retry_state)\n         ^^^^^^^^^^^^^^^^^^^^^^^^^^^^^^^^^^\n  File \"/home/fd15hava/.cache/pypoetry/virtualenvs/non-package-mode-zjkKA0Ca-py3.11/lib/python3.11/site-packages/tenacity/__init__.py\", line 326, in iter\n    raise retry_exc from fut.exception()\ntenacity.RetryError: RetryError[<Future at 0x14ac6e911010 state=finished raised UnexpectedAnswerException>]\n",
      "Traceback (most recent call last):\n  File \"/home/fd15hava/.cache/pypoetry/virtualenvs/non-package-mode-zjkKA0Ca-py3.11/lib/python3.11/site-packages/tenacity/__init__.py\", line 382, in __call__\n    result = fn(*args, **kwargs)\n             ^^^^^^^^^^^^^^^^^^^\n  File \"/work/home/fd15hava/tinypaper-mpt/src/agent.py\", line 26, in play\n    answer = self._prompt(self._make_prompt(scenario))\n             ^^^^^^^^^^^^^^^^^^^^^^^^^^^^^^^^^^^^^^^^^\n  File \"/work/home/fd15hava/tinypaper-mpt/src/agent.py\", line 40, in _prompt\n    raise UnexpectedAnswerException(f\"expected 1 or 2, got {result}\")\nutil.UnexpectedAnswerException: expected 1 or 2, got  \n\nThe above exception was the direct cause of the following exception:\n\nTraceback (most recent call last):\n  File \"/work/home/fd15hava/tinypaper-mpt/scripts/experiments/run.py\", line 16, in _run_session\n    result = agent.play(session)\n             ^^^^^^^^^^^^^^^^^^^\n  File \"/home/fd15hava/.cache/pypoetry/virtualenvs/non-package-mode-zjkKA0Ca-py3.11/lib/python3.11/site-packages/tenacity/__init__.py\", line 289, in wrapped_f\n    return self(f, *args, **kw)\n           ^^^^^^^^^^^^^^^^^^^^\n  File \"/home/fd15hava/.cache/pypoetry/virtualenvs/non-package-mode-zjkKA0Ca-py3.11/lib/python3.11/site-packages/tenacity/__init__.py\", line 379, in __call__\n    do = self.iter(retry_state=retry_state)\n         ^^^^^^^^^^^^^^^^^^^^^^^^^^^^^^^^^^\n  File \"/home/fd15hava/.cache/pypoetry/virtualenvs/non-package-mode-zjkKA0Ca-py3.11/lib/python3.11/site-packages/tenacity/__init__.py\", line 326, in iter\n    raise retry_exc from fut.exception()\ntenacity.RetryError: RetryError[<Future at 0x14ac6e912110 state=finished raised UnexpectedAnswerException>]\n",
      "Traceback (most recent call last):\n  File \"/home/fd15hava/.cache/pypoetry/virtualenvs/non-package-mode-zjkKA0Ca-py3.11/lib/python3.11/site-packages/tenacity/__init__.py\", line 382, in __call__\n    result = fn(*args, **kwargs)\n             ^^^^^^^^^^^^^^^^^^^\n  File \"/work/home/fd15hava/tinypaper-mpt/src/agent.py\", line 26, in play\n    answer = self._prompt(self._make_prompt(scenario))\n             ^^^^^^^^^^^^^^^^^^^^^^^^^^^^^^^^^^^^^^^^^\n  File \"/work/home/fd15hava/tinypaper-mpt/src/agent.py\", line 40, in _prompt\n    raise UnexpectedAnswerException(f\"expected 1 or 2, got {result}\")\nutil.UnexpectedAnswerException: expected 1 or 2, got  \n\nThe above exception was the direct cause of the following exception:\n\nTraceback (most recent call last):\n  File \"/work/home/fd15hava/tinypaper-mpt/scripts/experiments/run.py\", line 16, in _run_session\n    result = agent.play(session)\n             ^^^^^^^^^^^^^^^^^^^\n  File \"/home/fd15hava/.cache/pypoetry/virtualenvs/non-package-mode-zjkKA0Ca-py3.11/lib/python3.11/site-packages/tenacity/__init__.py\", line 289, in wrapped_f\n    return self(f, *args, **kw)\n           ^^^^^^^^^^^^^^^^^^^^\n  File \"/home/fd15hava/.cache/pypoetry/virtualenvs/non-package-mode-zjkKA0Ca-py3.11/lib/python3.11/site-packages/tenacity/__init__.py\", line 379, in __call__\n    do = self.iter(retry_state=retry_state)\n         ^^^^^^^^^^^^^^^^^^^^^^^^^^^^^^^^^^\n  File \"/home/fd15hava/.cache/pypoetry/virtualenvs/non-package-mode-zjkKA0Ca-py3.11/lib/python3.11/site-packages/tenacity/__init__.py\", line 326, in iter\n    raise retry_exc from fut.exception()\ntenacity.RetryError: RetryError[<Future at 0x14ac64134e50 state=finished raised UnexpectedAnswerException>]\n"
    ],
    "api_usage": [
      {
        "cost": 0.0,
        "name": "falcon-180B-chat",
        "num_input_tokens": -1,
        "num_output_tokens": -1,
        "py/object": "api_usage.APIUsage"
      },
      {
        "cost": 0.0,
        "name": "falcon-180B-chat",
        "num_input_tokens": -1,
        "num_output_tokens": -1,
        "py/object": "api_usage.APIUsage"
      },
      {
        "cost": 0.0,
        "name": "falcon-180B-chat",
        "num_input_tokens": -1,
        "num_output_tokens": -1,
        "py/object": "api_usage.APIUsage"
      },
      {
        "cost": 0.0,
        "name": "falcon-180B-chat",
        "num_input_tokens": -1,
        "num_output_tokens": -1,
        "py/object": "api_usage.APIUsage"
      },
      {
        "cost": 0.0,
        "name": "falcon-180B-chat",
        "num_input_tokens": -1,
        "num_output_tokens": -1,
        "py/object": "api_usage.APIUsage"
      },
      {
        "cost": 0.0,
        "name": "falcon-180B-chat",
        "num_input_tokens": -1,
        "num_output_tokens": -1,
        "py/object": "api_usage.APIUsage"
      },
      {
        "cost": 0.0,
        "name": "falcon-180B-chat",
        "num_input_tokens": -1,
        "num_output_tokens": -1,
        "py/object": "api_usage.APIUsage"
      },
      {
        "cost": 0.0,
        "name": "falcon-180B-chat",
        "num_input_tokens": -1,
        "num_output_tokens": -1,
        "py/object": "api_usage.APIUsage"
      },
      {
        "cost": 0.0,
        "name": "falcon-180B-chat",
        "num_input_tokens": -1,
        "num_output_tokens": -1,
        "py/object": "api_usage.APIUsage"
      },
      {
        "cost": 0.0,
        "name": "falcon-180B-chat",
        "num_input_tokens": -1,
        "num_output_tokens": -1,
        "py/object": "api_usage.APIUsage"
      },
      {
        "cost": 0.0,
        "name": "falcon-180B-chat",
        "num_input_tokens": -1,
        "num_output_tokens": -1,
        "py/object": "api_usage.APIUsage"
      },
      {
        "cost": 0.0,
        "name": "falcon-180B-chat",
        "num_input_tokens": -1,
        "num_output_tokens": -1,
        "py/object": "api_usage.APIUsage"
      },
      {
        "cost": 0.0,
        "name": "falcon-180B-chat",
        "num_input_tokens": -1,
        "num_output_tokens": -1,
        "py/object": "api_usage.APIUsage"
      },
      {
        "cost": 0.0,
        "name": "falcon-180B-chat",
        "num_input_tokens": -1,
        "num_output_tokens": -1,
        "py/object": "api_usage.APIUsage"
      },
      {
        "cost": 0.0,
        "name": "falcon-180B-chat",
        "num_input_tokens": -1,
        "num_output_tokens": -1,
        "py/object": "api_usage.APIUsage"
      },
      {
        "cost": 0.0,
        "name": "falcon-180B-chat",
        "num_input_tokens": -1,
        "num_output_tokens": -1,
        "py/object": "api_usage.APIUsage"
      },
      {
        "cost": 0.0,
        "name": "falcon-180B-chat",
        "num_input_tokens": -1,
        "num_output_tokens": -1,
        "py/object": "api_usage.APIUsage"
      },
      {
        "cost": 0.0,
        "name": "falcon-180B-chat",
        "num_input_tokens": -1,
        "num_output_tokens": -1,
        "py/object": "api_usage.APIUsage"
      },
      {
        "cost": 0.0,
        "name": "falcon-180B-chat",
        "num_input_tokens": -1,
        "num_output_tokens": -1,
        "py/object": "api_usage.APIUsage"
      },
      {
        "cost": 0.0,
        "name": "falcon-180B-chat",
        "num_input_tokens": -1,
        "num_output_tokens": -1,
        "py/object": "api_usage.APIUsage"
      },
      {
        "cost": 0.0,
        "name": "falcon-180B-chat",
        "num_input_tokens": -1,
        "num_output_tokens": -1,
        "py/object": "api_usage.APIUsage"
      },
      {
        "cost": 0.0,
        "name": "falcon-180B-chat",
        "num_input_tokens": -1,
        "num_output_tokens": -1,
        "py/object": "api_usage.APIUsage"
      },
      {
        "cost": 0.0,
        "name": "falcon-180B-chat",
        "num_input_tokens": -1,
        "num_output_tokens": -1,
        "py/object": "api_usage.APIUsage"
      },
      {
        "cost": 0.0,
        "name": "falcon-180B-chat",
        "num_input_tokens": -1,
        "num_output_tokens": -1,
        "py/object": "api_usage.APIUsage"
      },
      {
        "cost": 0.0,
        "name": "falcon-180B-chat",
        "num_input_tokens": -1,
        "num_output_tokens": -1,
        "py/object": "api_usage.APIUsage"
      },
      {
        "cost": 0.0,
        "name": "falcon-180B-chat",
        "num_input_tokens": -1,
        "num_output_tokens": -1,
        "py/object": "api_usage.APIUsage"
      },
      {
        "cost": 0.0,
        "name": "falcon-180B-chat",
        "num_input_tokens": -1,
        "num_output_tokens": -1,
        "py/object": "api_usage.APIUsage"
      },
      {
        "cost": 0.0,
        "name": "falcon-180B-chat",
        "num_input_tokens": -1,
        "num_output_tokens": -1,
        "py/object": "api_usage.APIUsage"
      },
      {
        "cost": 0.0,
        "name": "falcon-180B-chat",
        "num_input_tokens": -1,
        "num_output_tokens": -1,
        "py/object": "api_usage.APIUsage"
      },
      {
        "cost": 0.0,
        "name": "falcon-180B-chat",
        "num_input_tokens": -1,
        "num_output_tokens": -1,
        "py/object": "api_usage.APIUsage"
      },
      {
        "cost": 0.0,
        "name": "falcon-180B-chat",
        "num_input_tokens": -1,
        "num_output_tokens": -1,
        "py/object": "api_usage.APIUsage"
      },
      {
        "cost": 0.0,
        "name": "falcon-180B-chat",
        "num_input_tokens": -1,
        "num_output_tokens": -1,
        "py/object": "api_usage.APIUsage"
      },
      {
        "cost": 0.0,
        "name": "falcon-180B-chat",
        "num_input_tokens": -1,
        "num_output_tokens": -1,
        "py/object": "api_usage.APIUsage"
      },
      {
        "cost": 0.0,
        "name": "falcon-180B-chat",
        "num_input_tokens": -1,
        "num_output_tokens": -1,
        "py/object": "api_usage.APIUsage"
      },
      {
        "cost": 0.0,
        "name": "falcon-180B-chat",
        "num_input_tokens": -1,
        "num_output_tokens": -1,
        "py/object": "api_usage.APIUsage"
      },
      {
        "cost": 0.0,
        "name": "falcon-180B-chat",
        "num_input_tokens": -1,
        "num_output_tokens": -1,
        "py/object": "api_usage.APIUsage"
      },
      {
        "cost": 0.0,
        "name": "falcon-180B-chat",
        "num_input_tokens": -1,
        "num_output_tokens": -1,
        "py/object": "api_usage.APIUsage"
      },
      {
        "cost": 0.0,
        "name": "falcon-180B-chat",
        "num_input_tokens": -1,
        "num_output_tokens": -1,
        "py/object": "api_usage.APIUsage"
      },
      {
        "cost": 0.0,
        "name": "falcon-180B-chat",
        "num_input_tokens": -1,
        "num_output_tokens": -1,
        "py/object": "api_usage.APIUsage"
      },
      {
        "cost": 0.0,
        "name": "falcon-180B-chat",
        "num_input_tokens": -1,
        "num_output_tokens": -1,
        "py/object": "api_usage.APIUsage"
      },
      {
        "cost": 0.0,
        "name": "falcon-180B-chat",
        "num_input_tokens": -1,
        "num_output_tokens": -1,
        "py/object": "api_usage.APIUsage"
      },
      {
        "cost": 0.0,
        "name": "falcon-180B-chat",
        "num_input_tokens": -1,
        "num_output_tokens": -1,
        "py/object": "api_usage.APIUsage"
      },
      {
        "cost": 0.0,
        "name": "falcon-180B-chat",
        "num_input_tokens": -1,
        "num_output_tokens": -1,
        "py/object": "api_usage.APIUsage"
      },
      {
        "cost": 0.0,
        "name": "falcon-180B-chat",
        "num_input_tokens": -1,
        "num_output_tokens": -1,
        "py/object": "api_usage.APIUsage"
      },
      {
        "cost": 0.0,
        "name": "falcon-180B-chat",
        "num_input_tokens": -1,
        "num_output_tokens": -1,
        "py/object": "api_usage.APIUsage"
      },
      {
        "cost": 0.0,
        "name": "falcon-180B-chat",
        "num_input_tokens": -1,
        "num_output_tokens": -1,
        "py/object": "api_usage.APIUsage"
      },
      {
        "cost": 0.0,
        "name": "falcon-180B-chat",
        "num_input_tokens": -1,
        "num_output_tokens": -1,
        "py/object": "api_usage.APIUsage"
      },
      {
        "cost": 0.0,
        "name": "falcon-180B-chat",
        "num_input_tokens": -1,
        "num_output_tokens": -1,
        "py/object": "api_usage.APIUsage"
      },
      {
        "cost": 0.0,
        "name": "falcon-180B-chat",
        "num_input_tokens": -1,
        "num_output_tokens": -1,
        "py/object": "api_usage.APIUsage"
      },
      {
        "cost": 0.0,
        "name": "falcon-180B-chat",
        "num_input_tokens": -1,
        "num_output_tokens": -1,
        "py/object": "api_usage.APIUsage"
      }
    ],
    "api_usage_total": {
      "cost": 0.0,
      "name": "falcon-180B-chat",
      "num_input_tokens": -50,
      "num_output_tokens": -50,
      "py/object": "api_usage.APIUsage"
    }
  },
  "start_time": "2024-04-30T02:10:45.797278",
  "status": "COMPLETED",
  "stop_time": "2024-04-30T03:11:38.777271"
}