{
  "artifacts": [],
  "command": "main",
  "experiment": {
    "base_dir": "/work/home/fd15hava/tinypaper-mpt/src",
    "dependencies": [
      "numpy==1.26.4",
      "sacred==0.8.5"
    ],
    "mainfile": "experiment.py",
    "name": "tinypaper",
    "repositories": [
      {
        "commit": "83ebc21b46932da830ceff1fef51511962253d6b",
        "dirty": false,
        "url": "ssh://github/fdamken/tinypaper_code.git"
      },
      {
        "commit": "83ebc21b46932da830ceff1fef51511962253d6b",
        "dirty": false,
        "url": "ssh://github/fdamken/tinypaper_code.git"
      }
    ],
    "sources": [
      [
        "experiment.py",
        "_sources/experiment_7ab7c4f9e536be33bd5f71ad8c083f8f.py"
      ],
      [
        "path_util.py",
        "_sources/path_util_ce5f4012c098f79adf2c1204811dca0a.py"
      ]
    ]
  },
  "heartbeat": "2024-04-30T03:20:48.742671",
  "host": {
    "ENV": {},
    "cpu": "Intel(R) Xeon(R) Platinum 8470Q",
    "hostname": "mpsd0313",
    "os": [
      "Linux",
      "Linux-4.18.0-477.27.1.el8_8.x86_64-x86_64-with-glibc2.28"
    ],
    "python_version": "3.11.9"
  },
  "meta": {
    "command": "main",
    "config_updates": {
      "from_session_id": 400,
      "language": "de",
      "model_name": "Llama-2-70b-chat-hf",
      "to_session_id": 450
    },
    "named_configs": [],
    "options": {
      "--beat-interval": null,
      "--capture": null,
      "--comment": null,
      "--debug": false,
      "--enforce_clean": false,
      "--file_storage": null,
      "--force": false,
      "--help": false,
      "--id": null,
      "--loglevel": null,
      "--mongo_db": null,
      "--name": null,
      "--pdb": false,
      "--print-config": false,
      "--priority": null,
      "--queue": false,
      "--s3": null,
      "--sql": null,
      "--tiny_db": null,
      "--unobserved": false,
      "COMMAND": null,
      "UPDATE": [
        "from_session_id=400",
        "to_session_id=450",
        "model_name=Llama-2-70b-chat-hf",
        "language=de"
      ],
      "help": false,
      "with": true
    }
  },
  "resources": [],
  "result": {
    "answers": [
      "Traceback (most recent call last):\n  File \"/home/fd15hava/.cache/pypoetry/virtualenvs/non-package-mode-zjkKA0Ca-py3.11/lib/python3.11/site-packages/tenacity/__init__.py\", line 382, in __call__\n    result = fn(*args, **kwargs)\n             ^^^^^^^^^^^^^^^^^^^\n  File \"/work/home/fd15hava/tinypaper-mpt/src/agent.py\", line 26, in play\n    answer = self._prompt(self._make_prompt(scenario))\n             ^^^^^^^^^^^^^^^^^^^^^^^^^^^^^^^^^^^^^^^^^\n  File \"/work/home/fd15hava/tinypaper-mpt/src/agent.py\", line 40, in _prompt\n    raise UnexpectedAnswerException(f\"expected 1 or 2, got {result}\")\nutil.UnexpectedAnswerException: expected 1 or 2, got  \n\nThe above exception was the direct cause of the following exception:\n\nTraceback (most recent call last):\n  File \"/work/home/fd15hava/tinypaper-mpt/scripts/experiments/run.py\", line 16, in _run_session\n    result = agent.play(session)\n             ^^^^^^^^^^^^^^^^^^^\n  File \"/home/fd15hava/.cache/pypoetry/virtualenvs/non-package-mode-zjkKA0Ca-py3.11/lib/python3.11/site-packages/tenacity/__init__.py\", line 289, in wrapped_f\n    return self(f, *args, **kw)\n           ^^^^^^^^^^^^^^^^^^^^\n  File \"/home/fd15hava/.cache/pypoetry/virtualenvs/non-package-mode-zjkKA0Ca-py3.11/lib/python3.11/site-packages/tenacity/__init__.py\", line 379, in __call__\n    do = self.iter(retry_state=retry_state)\n         ^^^^^^^^^^^^^^^^^^^^^^^^^^^^^^^^^^\n  File \"/home/fd15hava/.cache/pypoetry/virtualenvs/non-package-mode-zjkKA0Ca-py3.11/lib/python3.11/site-packages/tenacity/__init__.py\", line 326, in iter\n    raise retry_exc from fut.exception()\ntenacity.RetryError: RetryError[<Future at 0x148460d43390 state=finished raised UnexpectedAnswerException>]\n",
      "Traceback (most recent call last):\n  File \"/home/fd15hava/.cache/pypoetry/virtualenvs/non-package-mode-zjkKA0Ca-py3.11/lib/python3.11/site-packages/tenacity/__init__.py\", line 382, in __call__\n    result = fn(*args, **kwargs)\n             ^^^^^^^^^^^^^^^^^^^\n  File \"/work/home/fd15hava/tinypaper-mpt/src/agent.py\", line 26, in play\n    answer = self._prompt(self._make_prompt(scenario))\n             ^^^^^^^^^^^^^^^^^^^^^^^^^^^^^^^^^^^^^^^^^\n  File \"/work/home/fd15hava/tinypaper-mpt/src/agent.py\", line 40, in _prompt\n    raise UnexpectedAnswerException(f\"expected 1 or 2, got {result}\")\nutil.UnexpectedAnswerException: expected 1 or 2, got  \n\nThe above exception was the direct cause of the following exception:\n\nTraceback (most recent call last):\n  File \"/work/home/fd15hava/tinypaper-mpt/scripts/experiments/run.py\", line 16, in _run_session\n    result = agent.play(session)\n             ^^^^^^^^^^^^^^^^^^^\n  File \"/home/fd15hava/.cache/pypoetry/virtualenvs/non-package-mode-zjkKA0Ca-py3.11/lib/python3.11/site-packages/tenacity/__init__.py\", line 289, in wrapped_f\n    return self(f, *args, **kw)\n           ^^^^^^^^^^^^^^^^^^^^\n  File \"/home/fd15hava/.cache/pypoetry/virtualenvs/non-package-mode-zjkKA0Ca-py3.11/lib/python3.11/site-packages/tenacity/__init__.py\", line 379, in __call__\n    do = self.iter(retry_state=retry_state)\n         ^^^^^^^^^^^^^^^^^^^^^^^^^^^^^^^^^^\n  File \"/home/fd15hava/.cache/pypoetry/virtualenvs/non-package-mode-zjkKA0Ca-py3.11/lib/python3.11/site-packages/tenacity/__init__.py\", line 326, in iter\n    raise retry_exc from fut.exception()\ntenacity.RetryError: RetryError[<Future at 0x1484a949b650 state=finished raised UnexpectedAnswerException>]\n",
      "Traceback (most recent call last):\n  File \"/home/fd15hava/.cache/pypoetry/virtualenvs/non-package-mode-zjkKA0Ca-py3.11/lib/python3.11/site-packages/tenacity/__init__.py\", line 382, in __call__\n    result = fn(*args, **kwargs)\n             ^^^^^^^^^^^^^^^^^^^\n  File \"/work/home/fd15hava/tinypaper-mpt/src/agent.py\", line 26, in play\n    answer = self._prompt(self._make_prompt(scenario))\n             ^^^^^^^^^^^^^^^^^^^^^^^^^^^^^^^^^^^^^^^^^\n  File \"/work/home/fd15hava/tinypaper-mpt/src/agent.py\", line 40, in _prompt\n    raise UnexpectedAnswerException(f\"expected 1 or 2, got {result}\")\nutil.UnexpectedAnswerException: expected 1 or 2, got  \n\nThe above exception was the direct cause of the following exception:\n\nTraceback (most recent call last):\n  File \"/work/home/fd15hava/tinypaper-mpt/scripts/experiments/run.py\", line 16, in _run_session\n    result = agent.play(session)\n             ^^^^^^^^^^^^^^^^^^^\n  File \"/home/fd15hava/.cache/pypoetry/virtualenvs/non-package-mode-zjkKA0Ca-py3.11/lib/python3.11/site-packages/tenacity/__init__.py\", line 289, in wrapped_f\n    return self(f, *args, **kw)\n           ^^^^^^^^^^^^^^^^^^^^\n  File \"/home/fd15hava/.cache/pypoetry/virtualenvs/non-package-mode-zjkKA0Ca-py3.11/lib/python3.11/site-packages/tenacity/__init__.py\", line 379, in __call__\n    do = self.iter(retry_state=retry_state)\n         ^^^^^^^^^^^^^^^^^^^^^^^^^^^^^^^^^^\n  File \"/home/fd15hava/.cache/pypoetry/virtualenvs/non-package-mode-zjkKA0Ca-py3.11/lib/python3.11/site-packages/tenacity/__init__.py\", line 326, in iter\n    raise retry_exc from fut.exception()\ntenacity.RetryError: RetryError[<Future at 0x1484a01ccb10 state=finished raised UnexpectedAnswerException>]\n",
      "Traceback (most recent call last):\n  File \"/home/fd15hava/.cache/pypoetry/virtualenvs/non-package-mode-zjkKA0Ca-py3.11/lib/python3.11/site-packages/tenacity/__init__.py\", line 382, in __call__\n    result = fn(*args, **kwargs)\n             ^^^^^^^^^^^^^^^^^^^\n  File \"/work/home/fd15hava/tinypaper-mpt/src/agent.py\", line 26, in play\n    answer = self._prompt(self._make_prompt(scenario))\n             ^^^^^^^^^^^^^^^^^^^^^^^^^^^^^^^^^^^^^^^^^\n  File \"/work/home/fd15hava/tinypaper-mpt/src/agent.py\", line 40, in _prompt\n    raise UnexpectedAnswerException(f\"expected 1 or 2, got {result}\")\nutil.UnexpectedAnswerException: expected 1 or 2, got  \n\nThe above exception was the direct cause of the following exception:\n\nTraceback (most recent call last):\n  File \"/work/home/fd15hava/tinypaper-mpt/scripts/experiments/run.py\", line 16, in _run_session\n    result = agent.play(session)\n             ^^^^^^^^^^^^^^^^^^^\n  File \"/home/fd15hava/.cache/pypoetry/virtualenvs/non-package-mode-zjkKA0Ca-py3.11/lib/python3.11/site-packages/tenacity/__init__.py\", line 289, in wrapped_f\n    return self(f, *args, **kw)\n           ^^^^^^^^^^^^^^^^^^^^\n  File \"/home/fd15hava/.cache/pypoetry/virtualenvs/non-package-mode-zjkKA0Ca-py3.11/lib/python3.11/site-packages/tenacity/__init__.py\", line 379, in __call__\n    do = self.iter(retry_state=retry_state)\n         ^^^^^^^^^^^^^^^^^^^^^^^^^^^^^^^^^^\n  File \"/home/fd15hava/.cache/pypoetry/virtualenvs/non-package-mode-zjkKA0Ca-py3.11/lib/python3.11/site-packages/tenacity/__init__.py\", line 326, in iter\n    raise retry_exc from fut.exception()\ntenacity.RetryError: RetryError[<Future at 0x148460bd4ed0 state=finished raised UnexpectedAnswerException>]\n",
      "Traceback (most recent call last):\n  File \"/home/fd15hava/.cache/pypoetry/virtualenvs/non-package-mode-zjkKA0Ca-py3.11/lib/python3.11/site-packages/tenacity/__init__.py\", line 382, in __call__\n    result = fn(*args, **kwargs)\n             ^^^^^^^^^^^^^^^^^^^\n  File \"/work/home/fd15hava/tinypaper-mpt/src/agent.py\", line 26, in play\n    answer = self._prompt(self._make_prompt(scenario))\n             ^^^^^^^^^^^^^^^^^^^^^^^^^^^^^^^^^^^^^^^^^\n  File \"/work/home/fd15hava/tinypaper-mpt/src/agent.py\", line 40, in _prompt\n    raise UnexpectedAnswerException(f\"expected 1 or 2, got {result}\")\nutil.UnexpectedAnswerException: expected 1 or 2, got  \n\nThe above exception was the direct cause of the following exception:\n\nTraceback (most recent call last):\n  File \"/work/home/fd15hava/tinypaper-mpt/scripts/experiments/run.py\", line 16, in _run_session\n    result = agent.play(session)\n             ^^^^^^^^^^^^^^^^^^^\n  File \"/home/fd15hava/.cache/pypoetry/virtualenvs/non-package-mode-zjkKA0Ca-py3.11/lib/python3.11/site-packages/tenacity/__init__.py\", line 289, in wrapped_f\n    return self(f, *args, **kw)\n           ^^^^^^^^^^^^^^^^^^^^\n  File \"/home/fd15hava/.cache/pypoetry/virtualenvs/non-package-mode-zjkKA0Ca-py3.11/lib/python3.11/site-packages/tenacity/__init__.py\", line 379, in __call__\n    do = self.iter(retry_state=retry_state)\n         ^^^^^^^^^^^^^^^^^^^^^^^^^^^^^^^^^^\n  File \"/home/fd15hava/.cache/pypoetry/virtualenvs/non-package-mode-zjkKA0Ca-py3.11/lib/python3.11/site-packages/tenacity/__init__.py\", line 326, in iter\n    raise retry_exc from fut.exception()\ntenacity.RetryError: RetryError[<Future at 0x148460bb0790 state=finished raised UnexpectedAnswerException>]\n",
      "Traceback (most recent call last):\n  File \"/home/fd15hava/.cache/pypoetry/virtualenvs/non-package-mode-zjkKA0Ca-py3.11/lib/python3.11/site-packages/tenacity/__init__.py\", line 382, in __call__\n    result = fn(*args, **kwargs)\n             ^^^^^^^^^^^^^^^^^^^\n  File \"/work/home/fd15hava/tinypaper-mpt/src/agent.py\", line 26, in play\n    answer = self._prompt(self._make_prompt(scenario))\n             ^^^^^^^^^^^^^^^^^^^^^^^^^^^^^^^^^^^^^^^^^\n  File \"/work/home/fd15hava/tinypaper-mpt/src/agent.py\", line 40, in _prompt\n    raise UnexpectedAnswerException(f\"expected 1 or 2, got {result}\")\nutil.UnexpectedAnswerException: expected 1 or 2, got  \n\nThe above exception was the direct cause of the following exception:\n\nTraceback (most recent call last):\n  File \"/work/home/fd15hava/tinypaper-mpt/scripts/experiments/run.py\", line 16, in _run_session\n    result = agent.play(session)\n             ^^^^^^^^^^^^^^^^^^^\n  File \"/home/fd15hava/.cache/pypoetry/virtualenvs/non-package-mode-zjkKA0Ca-py3.11/lib/python3.11/site-packages/tenacity/__init__.py\", line 289, in wrapped_f\n    return self(f, *args, **kw)\n           ^^^^^^^^^^^^^^^^^^^^\n  File \"/home/fd15hava/.cache/pypoetry/virtualenvs/non-package-mode-zjkKA0Ca-py3.11/lib/python3.11/site-packages/tenacity/__init__.py\", line 379, in __call__\n    do = self.iter(retry_state=retry_state)\n         ^^^^^^^^^^^^^^^^^^^^^^^^^^^^^^^^^^\n  File \"/home/fd15hava/.cache/pypoetry/virtualenvs/non-package-mode-zjkKA0Ca-py3.11/lib/python3.11/site-packages/tenacity/__init__.py\", line 326, in iter\n    raise retry_exc from fut.exception()\ntenacity.RetryError: RetryError[<Future at 0x1484a01cf510 state=finished raised UnexpectedAnswerException>]\n",
      "Traceback (most recent call last):\n  File \"/home/fd15hava/.cache/pypoetry/virtualenvs/non-package-mode-zjkKA0Ca-py3.11/lib/python3.11/site-packages/tenacity/__init__.py\", line 382, in __call__\n    result = fn(*args, **kwargs)\n             ^^^^^^^^^^^^^^^^^^^\n  File \"/work/home/fd15hava/tinypaper-mpt/src/agent.py\", line 26, in play\n    answer = self._prompt(self._make_prompt(scenario))\n             ^^^^^^^^^^^^^^^^^^^^^^^^^^^^^^^^^^^^^^^^^\n  File \"/work/home/fd15hava/tinypaper-mpt/src/agent.py\", line 40, in _prompt\n    raise UnexpectedAnswerException(f\"expected 1 or 2, got {result}\")\nutil.UnexpectedAnswerException: expected 1 or 2, got  \n\nThe above exception was the direct cause of the following exception:\n\nTraceback (most recent call last):\n  File \"/work/home/fd15hava/tinypaper-mpt/scripts/experiments/run.py\", line 16, in _run_session\n    result = agent.play(session)\n             ^^^^^^^^^^^^^^^^^^^\n  File \"/home/fd15hava/.cache/pypoetry/virtualenvs/non-package-mode-zjkKA0Ca-py3.11/lib/python3.11/site-packages/tenacity/__init__.py\", line 289, in wrapped_f\n    return self(f, *args, **kw)\n           ^^^^^^^^^^^^^^^^^^^^\n  File \"/home/fd15hava/.cache/pypoetry/virtualenvs/non-package-mode-zjkKA0Ca-py3.11/lib/python3.11/site-packages/tenacity/__init__.py\", line 379, in __call__\n    do = self.iter(retry_state=retry_state)\n         ^^^^^^^^^^^^^^^^^^^^^^^^^^^^^^^^^^\n  File \"/home/fd15hava/.cache/pypoetry/virtualenvs/non-package-mode-zjkKA0Ca-py3.11/lib/python3.11/site-packages/tenacity/__init__.py\", line 326, in iter\n    raise retry_exc from fut.exception()\ntenacity.RetryError: RetryError[<Future at 0x148460b0be50 state=finished raised UnexpectedAnswerException>]\n",
      "Traceback (most recent call last):\n  File \"/home/fd15hava/.cache/pypoetry/virtualenvs/non-package-mode-zjkKA0Ca-py3.11/lib/python3.11/site-packages/tenacity/__init__.py\", line 382, in __call__\n    result = fn(*args, **kwargs)\n             ^^^^^^^^^^^^^^^^^^^\n  File \"/work/home/fd15hava/tinypaper-mpt/src/agent.py\", line 26, in play\n    answer = self._prompt(self._make_prompt(scenario))\n             ^^^^^^^^^^^^^^^^^^^^^^^^^^^^^^^^^^^^^^^^^\n  File \"/work/home/fd15hava/tinypaper-mpt/src/agent.py\", line 40, in _prompt\n    raise UnexpectedAnswerException(f\"expected 1 or 2, got {result}\")\nutil.UnexpectedAnswerException: expected 1 or 2, got  \n\nThe above exception was the direct cause of the following exception:\n\nTraceback (most recent call last):\n  File \"/work/home/fd15hava/tinypaper-mpt/scripts/experiments/run.py\", line 16, in _run_session\n    result = agent.play(session)\n             ^^^^^^^^^^^^^^^^^^^\n  File \"/home/fd15hava/.cache/pypoetry/virtualenvs/non-package-mode-zjkKA0Ca-py3.11/lib/python3.11/site-packages/tenacity/__init__.py\", line 289, in wrapped_f\n    return self(f, *args, **kw)\n           ^^^^^^^^^^^^^^^^^^^^\n  File \"/home/fd15hava/.cache/pypoetry/virtualenvs/non-package-mode-zjkKA0Ca-py3.11/lib/python3.11/site-packages/tenacity/__init__.py\", line 379, in __call__\n    do = self.iter(retry_state=retry_state)\n         ^^^^^^^^^^^^^^^^^^^^^^^^^^^^^^^^^^\n  File \"/home/fd15hava/.cache/pypoetry/virtualenvs/non-package-mode-zjkKA0Ca-py3.11/lib/python3.11/site-packages/tenacity/__init__.py\", line 326, in iter\n    raise retry_exc from fut.exception()\ntenacity.RetryError: RetryError[<Future at 0x1484a01ce010 state=finished raised UnexpectedAnswerException>]\n",
      "Traceback (most recent call last):\n  File \"/home/fd15hava/.cache/pypoetry/virtualenvs/non-package-mode-zjkKA0Ca-py3.11/lib/python3.11/site-packages/tenacity/__init__.py\", line 382, in __call__\n    result = fn(*args, **kwargs)\n             ^^^^^^^^^^^^^^^^^^^\n  File \"/work/home/fd15hava/tinypaper-mpt/src/agent.py\", line 26, in play\n    answer = self._prompt(self._make_prompt(scenario))\n             ^^^^^^^^^^^^^^^^^^^^^^^^^^^^^^^^^^^^^^^^^\n  File \"/work/home/fd15hava/tinypaper-mpt/src/agent.py\", line 40, in _prompt\n    raise UnexpectedAnswerException(f\"expected 1 or 2, got {result}\")\nutil.UnexpectedAnswerException: expected 1 or 2, got  \n\nThe above exception was the direct cause of the following exception:\n\nTraceback (most recent call last):\n  File \"/work/home/fd15hava/tinypaper-mpt/scripts/experiments/run.py\", line 16, in _run_session\n    result = agent.play(session)\n             ^^^^^^^^^^^^^^^^^^^\n  File \"/home/fd15hava/.cache/pypoetry/virtualenvs/non-package-mode-zjkKA0Ca-py3.11/lib/python3.11/site-packages/tenacity/__init__.py\", line 289, in wrapped_f\n    return self(f, *args, **kw)\n           ^^^^^^^^^^^^^^^^^^^^\n  File \"/home/fd15hava/.cache/pypoetry/virtualenvs/non-package-mode-zjkKA0Ca-py3.11/lib/python3.11/site-packages/tenacity/__init__.py\", line 379, in __call__\n    do = self.iter(retry_state=retry_state)\n         ^^^^^^^^^^^^^^^^^^^^^^^^^^^^^^^^^^\n  File \"/home/fd15hava/.cache/pypoetry/virtualenvs/non-package-mode-zjkKA0Ca-py3.11/lib/python3.11/site-packages/tenacity/__init__.py\", line 326, in iter\n    raise retry_exc from fut.exception()\ntenacity.RetryError: RetryError[<Future at 0x148460c0a790 state=finished raised UnexpectedAnswerException>]\n",
      "Traceback (most recent call last):\n  File \"/home/fd15hava/.cache/pypoetry/virtualenvs/non-package-mode-zjkKA0Ca-py3.11/lib/python3.11/site-packages/tenacity/__init__.py\", line 382, in __call__\n    result = fn(*args, **kwargs)\n             ^^^^^^^^^^^^^^^^^^^\n  File \"/work/home/fd15hava/tinypaper-mpt/src/agent.py\", line 26, in play\n    answer = self._prompt(self._make_prompt(scenario))\n             ^^^^^^^^^^^^^^^^^^^^^^^^^^^^^^^^^^^^^^^^^\n  File \"/work/home/fd15hava/tinypaper-mpt/src/agent.py\", line 40, in _prompt\n    raise UnexpectedAnswerException(f\"expected 1 or 2, got {result}\")\nutil.UnexpectedAnswerException: expected 1 or 2, got  \n\nThe above exception was the direct cause of the following exception:\n\nTraceback (most recent call last):\n  File \"/work/home/fd15hava/tinypaper-mpt/scripts/experiments/run.py\", line 16, in _run_session\n    result = agent.play(session)\n             ^^^^^^^^^^^^^^^^^^^\n  File \"/home/fd15hava/.cache/pypoetry/virtualenvs/non-package-mode-zjkKA0Ca-py3.11/lib/python3.11/site-packages/tenacity/__init__.py\", line 289, in wrapped_f\n    return self(f, *args, **kw)\n           ^^^^^^^^^^^^^^^^^^^^\n  File \"/home/fd15hava/.cache/pypoetry/virtualenvs/non-package-mode-zjkKA0Ca-py3.11/lib/python3.11/site-packages/tenacity/__init__.py\", line 379, in __call__\n    do = self.iter(retry_state=retry_state)\n         ^^^^^^^^^^^^^^^^^^^^^^^^^^^^^^^^^^\n  File \"/home/fd15hava/.cache/pypoetry/virtualenvs/non-package-mode-zjkKA0Ca-py3.11/lib/python3.11/site-packages/tenacity/__init__.py\", line 326, in iter\n    raise retry_exc from fut.exception()\ntenacity.RetryError: RetryError[<Future at 0x148460c90890 state=finished raised UnexpectedAnswerException>]\n",
      "Traceback (most recent call last):\n  File \"/home/fd15hava/.cache/pypoetry/virtualenvs/non-package-mode-zjkKA0Ca-py3.11/lib/python3.11/site-packages/tenacity/__init__.py\", line 382, in __call__\n    result = fn(*args, **kwargs)\n             ^^^^^^^^^^^^^^^^^^^\n  File \"/work/home/fd15hava/tinypaper-mpt/src/agent.py\", line 26, in play\n    answer = self._prompt(self._make_prompt(scenario))\n             ^^^^^^^^^^^^^^^^^^^^^^^^^^^^^^^^^^^^^^^^^\n  File \"/work/home/fd15hava/tinypaper-mpt/src/agent.py\", line 40, in _prompt\n    raise UnexpectedAnswerException(f\"expected 1 or 2, got {result}\")\nutil.UnexpectedAnswerException: expected 1 or 2, got  \n\nThe above exception was the direct cause of the following exception:\n\nTraceback (most recent call last):\n  File \"/work/home/fd15hava/tinypaper-mpt/scripts/experiments/run.py\", line 16, in _run_session\n    result = agent.play(session)\n             ^^^^^^^^^^^^^^^^^^^\n  File \"/home/fd15hava/.cache/pypoetry/virtualenvs/non-package-mode-zjkKA0Ca-py3.11/lib/python3.11/site-packages/tenacity/__init__.py\", line 289, in wrapped_f\n    return self(f, *args, **kw)\n           ^^^^^^^^^^^^^^^^^^^^\n  File \"/home/fd15hava/.cache/pypoetry/virtualenvs/non-package-mode-zjkKA0Ca-py3.11/lib/python3.11/site-packages/tenacity/__init__.py\", line 379, in __call__\n    do = self.iter(retry_state=retry_state)\n         ^^^^^^^^^^^^^^^^^^^^^^^^^^^^^^^^^^\n  File \"/home/fd15hava/.cache/pypoetry/virtualenvs/non-package-mode-zjkKA0Ca-py3.11/lib/python3.11/site-packages/tenacity/__init__.py\", line 326, in iter\n    raise retry_exc from fut.exception()\ntenacity.RetryError: RetryError[<Future at 0x148460c70150 state=finished raised UnexpectedAnswerException>]\n",
      "Traceback (most recent call last):\n  File \"/home/fd15hava/.cache/pypoetry/virtualenvs/non-package-mode-zjkKA0Ca-py3.11/lib/python3.11/site-packages/tenacity/__init__.py\", line 382, in __call__\n    result = fn(*args, **kwargs)\n             ^^^^^^^^^^^^^^^^^^^\n  File \"/work/home/fd15hava/tinypaper-mpt/src/agent.py\", line 26, in play\n    answer = self._prompt(self._make_prompt(scenario))\n             ^^^^^^^^^^^^^^^^^^^^^^^^^^^^^^^^^^^^^^^^^\n  File \"/work/home/fd15hava/tinypaper-mpt/src/agent.py\", line 40, in _prompt\n    raise UnexpectedAnswerException(f\"expected 1 or 2, got {result}\")\nutil.UnexpectedAnswerException: expected 1 or 2, got  \n\nThe above exception was the direct cause of the following exception:\n\nTraceback (most recent call last):\n  File \"/work/home/fd15hava/tinypaper-mpt/scripts/experiments/run.py\", line 16, in _run_session\n    result = agent.play(session)\n             ^^^^^^^^^^^^^^^^^^^\n  File \"/home/fd15hava/.cache/pypoetry/virtualenvs/non-package-mode-zjkKA0Ca-py3.11/lib/python3.11/site-packages/tenacity/__init__.py\", line 289, in wrapped_f\n    return self(f, *args, **kw)\n           ^^^^^^^^^^^^^^^^^^^^\n  File \"/home/fd15hava/.cache/pypoetry/virtualenvs/non-package-mode-zjkKA0Ca-py3.11/lib/python3.11/site-packages/tenacity/__init__.py\", line 379, in __call__\n    do = self.iter(retry_state=retry_state)\n         ^^^^^^^^^^^^^^^^^^^^^^^^^^^^^^^^^^\n  File \"/home/fd15hava/.cache/pypoetry/virtualenvs/non-package-mode-zjkKA0Ca-py3.11/lib/python3.11/site-packages/tenacity/__init__.py\", line 326, in iter\n    raise retry_exc from fut.exception()\ntenacity.RetryError: RetryError[<Future at 0x148460bd6350 state=finished raised UnexpectedAnswerException>]\n",
      "Traceback (most recent call last):\n  File \"/home/fd15hava/.cache/pypoetry/virtualenvs/non-package-mode-zjkKA0Ca-py3.11/lib/python3.11/site-packages/tenacity/__init__.py\", line 382, in __call__\n    result = fn(*args, **kwargs)\n             ^^^^^^^^^^^^^^^^^^^\n  File \"/work/home/fd15hava/tinypaper-mpt/src/agent.py\", line 26, in play\n    answer = self._prompt(self._make_prompt(scenario))\n             ^^^^^^^^^^^^^^^^^^^^^^^^^^^^^^^^^^^^^^^^^\n  File \"/work/home/fd15hava/tinypaper-mpt/src/agent.py\", line 40, in _prompt\n    raise UnexpectedAnswerException(f\"expected 1 or 2, got {result}\")\nutil.UnexpectedAnswerException: expected 1 or 2, got  \n\nThe above exception was the direct cause of the following exception:\n\nTraceback (most recent call last):\n  File \"/work/home/fd15hava/tinypaper-mpt/scripts/experiments/run.py\", line 16, in _run_session\n    result = agent.play(session)\n             ^^^^^^^^^^^^^^^^^^^\n  File \"/home/fd15hava/.cache/pypoetry/virtualenvs/non-package-mode-zjkKA0Ca-py3.11/lib/python3.11/site-packages/tenacity/__init__.py\", line 289, in wrapped_f\n    return self(f, *args, **kw)\n           ^^^^^^^^^^^^^^^^^^^^\n  File \"/home/fd15hava/.cache/pypoetry/virtualenvs/non-package-mode-zjkKA0Ca-py3.11/lib/python3.11/site-packages/tenacity/__init__.py\", line 379, in __call__\n    do = self.iter(retry_state=retry_state)\n         ^^^^^^^^^^^^^^^^^^^^^^^^^^^^^^^^^^\n  File \"/home/fd15hava/.cache/pypoetry/virtualenvs/non-package-mode-zjkKA0Ca-py3.11/lib/python3.11/site-packages/tenacity/__init__.py\", line 326, in iter\n    raise retry_exc from fut.exception()\ntenacity.RetryError: RetryError[<Future at 0x148460c16610 state=finished raised UnexpectedAnswerException>]\n",
      "Traceback (most recent call last):\n  File \"/home/fd15hava/.cache/pypoetry/virtualenvs/non-package-mode-zjkKA0Ca-py3.11/lib/python3.11/site-packages/tenacity/__init__.py\", line 382, in __call__\n    result = fn(*args, **kwargs)\n             ^^^^^^^^^^^^^^^^^^^\n  File \"/work/home/fd15hava/tinypaper-mpt/src/agent.py\", line 26, in play\n    answer = self._prompt(self._make_prompt(scenario))\n             ^^^^^^^^^^^^^^^^^^^^^^^^^^^^^^^^^^^^^^^^^\n  File \"/work/home/fd15hava/tinypaper-mpt/src/agent.py\", line 40, in _prompt\n    raise UnexpectedAnswerException(f\"expected 1 or 2, got {result}\")\nutil.UnexpectedAnswerException: expected 1 or 2, got  \n\nThe above exception was the direct cause of the following exception:\n\nTraceback (most recent call last):\n  File \"/work/home/fd15hava/tinypaper-mpt/scripts/experiments/run.py\", line 16, in _run_session\n    result = agent.play(session)\n             ^^^^^^^^^^^^^^^^^^^\n  File \"/home/fd15hava/.cache/pypoetry/virtualenvs/non-package-mode-zjkKA0Ca-py3.11/lib/python3.11/site-packages/tenacity/__init__.py\", line 289, in wrapped_f\n    return self(f, *args, **kw)\n           ^^^^^^^^^^^^^^^^^^^^\n  File \"/home/fd15hava/.cache/pypoetry/virtualenvs/non-package-mode-zjkKA0Ca-py3.11/lib/python3.11/site-packages/tenacity/__init__.py\", line 379, in __call__\n    do = self.iter(retry_state=retry_state)\n         ^^^^^^^^^^^^^^^^^^^^^^^^^^^^^^^^^^\n  File \"/home/fd15hava/.cache/pypoetry/virtualenvs/non-package-mode-zjkKA0Ca-py3.11/lib/python3.11/site-packages/tenacity/__init__.py\", line 326, in iter\n    raise retry_exc from fut.exception()\ntenacity.RetryError: RetryError[<Future at 0x1484a0164cd0 state=finished raised UnexpectedAnswerException>]\n",
      "Traceback (most recent call last):\n  File \"/home/fd15hava/.cache/pypoetry/virtualenvs/non-package-mode-zjkKA0Ca-py3.11/lib/python3.11/site-packages/tenacity/__init__.py\", line 382, in __call__\n    result = fn(*args, **kwargs)\n             ^^^^^^^^^^^^^^^^^^^\n  File \"/work/home/fd15hava/tinypaper-mpt/src/agent.py\", line 26, in play\n    answer = self._prompt(self._make_prompt(scenario))\n             ^^^^^^^^^^^^^^^^^^^^^^^^^^^^^^^^^^^^^^^^^\n  File \"/work/home/fd15hava/tinypaper-mpt/src/agent.py\", line 40, in _prompt\n    raise UnexpectedAnswerException(f\"expected 1 or 2, got {result}\")\nutil.UnexpectedAnswerException: expected 1 or 2, got  \n\nThe above exception was the direct cause of the following exception:\n\nTraceback (most recent call last):\n  File \"/work/home/fd15hava/tinypaper-mpt/scripts/experiments/run.py\", line 16, in _run_session\n    result = agent.play(session)\n             ^^^^^^^^^^^^^^^^^^^\n  File \"/home/fd15hava/.cache/pypoetry/virtualenvs/non-package-mode-zjkKA0Ca-py3.11/lib/python3.11/site-packages/tenacity/__init__.py\", line 289, in wrapped_f\n    return self(f, *args, **kw)\n           ^^^^^^^^^^^^^^^^^^^^\n  File \"/home/fd15hava/.cache/pypoetry/virtualenvs/non-package-mode-zjkKA0Ca-py3.11/lib/python3.11/site-packages/tenacity/__init__.py\", line 379, in __call__\n    do = self.iter(retry_state=retry_state)\n         ^^^^^^^^^^^^^^^^^^^^^^^^^^^^^^^^^^\n  File \"/home/fd15hava/.cache/pypoetry/virtualenvs/non-package-mode-zjkKA0Ca-py3.11/lib/python3.11/site-packages/tenacity/__init__.py\", line 326, in iter\n    raise retry_exc from fut.exception()\ntenacity.RetryError: RetryError[<Future at 0x148460c72a50 state=finished raised UnexpectedAnswerException>]\n",
      "Traceback (most recent call last):\n  File \"/home/fd15hava/.cache/pypoetry/virtualenvs/non-package-mode-zjkKA0Ca-py3.11/lib/python3.11/site-packages/tenacity/__init__.py\", line 382, in __call__\n    result = fn(*args, **kwargs)\n             ^^^^^^^^^^^^^^^^^^^\n  File \"/work/home/fd15hava/tinypaper-mpt/src/agent.py\", line 26, in play\n    answer = self._prompt(self._make_prompt(scenario))\n             ^^^^^^^^^^^^^^^^^^^^^^^^^^^^^^^^^^^^^^^^^\n  File \"/work/home/fd15hava/tinypaper-mpt/src/agent.py\", line 40, in _prompt\n    raise UnexpectedAnswerException(f\"expected 1 or 2, got {result}\")\nutil.UnexpectedAnswerException: expected 1 or 2, got  \n\nThe above exception was the direct cause of the following exception:\n\nTraceback (most recent call last):\n  File \"/work/home/fd15hava/tinypaper-mpt/scripts/experiments/run.py\", line 16, in _run_session\n    result = agent.play(session)\n             ^^^^^^^^^^^^^^^^^^^\n  File \"/home/fd15hava/.cache/pypoetry/virtualenvs/non-package-mode-zjkKA0Ca-py3.11/lib/python3.11/site-packages/tenacity/__init__.py\", line 289, in wrapped_f\n    return self(f, *args, **kw)\n           ^^^^^^^^^^^^^^^^^^^^\n  File \"/home/fd15hava/.cache/pypoetry/virtualenvs/non-package-mode-zjkKA0Ca-py3.11/lib/python3.11/site-packages/tenacity/__init__.py\", line 379, in __call__\n    do = self.iter(retry_state=retry_state)\n         ^^^^^^^^^^^^^^^^^^^^^^^^^^^^^^^^^^\n  File \"/home/fd15hava/.cache/pypoetry/virtualenvs/non-package-mode-zjkKA0Ca-py3.11/lib/python3.11/site-packages/tenacity/__init__.py\", line 326, in iter\n    raise retry_exc from fut.exception()\ntenacity.RetryError: RetryError[<Future at 0x148460c4dd90 state=finished raised UnexpectedAnswerException>]\n",
      "Traceback (most recent call last):\n  File \"/home/fd15hava/.cache/pypoetry/virtualenvs/non-package-mode-zjkKA0Ca-py3.11/lib/python3.11/site-packages/tenacity/__init__.py\", line 382, in __call__\n    result = fn(*args, **kwargs)\n             ^^^^^^^^^^^^^^^^^^^\n  File \"/work/home/fd15hava/tinypaper-mpt/src/agent.py\", line 26, in play\n    answer = self._prompt(self._make_prompt(scenario))\n             ^^^^^^^^^^^^^^^^^^^^^^^^^^^^^^^^^^^^^^^^^\n  File \"/work/home/fd15hava/tinypaper-mpt/src/agent.py\", line 40, in _prompt\n    raise UnexpectedAnswerException(f\"expected 1 or 2, got {result}\")\nutil.UnexpectedAnswerException: expected 1 or 2, got  \n\nThe above exception was the direct cause of the following exception:\n\nTraceback (most recent call last):\n  File \"/work/home/fd15hava/tinypaper-mpt/scripts/experiments/run.py\", line 16, in _run_session\n    result = agent.play(session)\n             ^^^^^^^^^^^^^^^^^^^\n  File \"/home/fd15hava/.cache/pypoetry/virtualenvs/non-package-mode-zjkKA0Ca-py3.11/lib/python3.11/site-packages/tenacity/__init__.py\", line 289, in wrapped_f\n    return self(f, *args, **kw)\n           ^^^^^^^^^^^^^^^^^^^^\n  File \"/home/fd15hava/.cache/pypoetry/virtualenvs/non-package-mode-zjkKA0Ca-py3.11/lib/python3.11/site-packages/tenacity/__init__.py\", line 379, in __call__\n    do = self.iter(retry_state=retry_state)\n         ^^^^^^^^^^^^^^^^^^^^^^^^^^^^^^^^^^\n  File \"/home/fd15hava/.cache/pypoetry/virtualenvs/non-package-mode-zjkKA0Ca-py3.11/lib/python3.11/site-packages/tenacity/__init__.py\", line 326, in iter\n    raise retry_exc from fut.exception()\ntenacity.RetryError: RetryError[<Future at 0x148460b8d450 state=finished raised UnexpectedAnswerException>]\n",
      "Traceback (most recent call last):\n  File \"/home/fd15hava/.cache/pypoetry/virtualenvs/non-package-mode-zjkKA0Ca-py3.11/lib/python3.11/site-packages/tenacity/__init__.py\", line 382, in __call__\n    result = fn(*args, **kwargs)\n             ^^^^^^^^^^^^^^^^^^^\n  File \"/work/home/fd15hava/tinypaper-mpt/src/agent.py\", line 26, in play\n    answer = self._prompt(self._make_prompt(scenario))\n             ^^^^^^^^^^^^^^^^^^^^^^^^^^^^^^^^^^^^^^^^^\n  File \"/work/home/fd15hava/tinypaper-mpt/src/agent.py\", line 40, in _prompt\n    raise UnexpectedAnswerException(f\"expected 1 or 2, got {result}\")\nutil.UnexpectedAnswerException: expected 1 or 2, got  \n\nThe above exception was the direct cause of the following exception:\n\nTraceback (most recent call last):\n  File \"/work/home/fd15hava/tinypaper-mpt/scripts/experiments/run.py\", line 16, in _run_session\n    result = agent.play(session)\n             ^^^^^^^^^^^^^^^^^^^\n  File \"/home/fd15hava/.cache/pypoetry/virtualenvs/non-package-mode-zjkKA0Ca-py3.11/lib/python3.11/site-packages/tenacity/__init__.py\", line 289, in wrapped_f\n    return self(f, *args, **kw)\n           ^^^^^^^^^^^^^^^^^^^^\n  File \"/home/fd15hava/.cache/pypoetry/virtualenvs/non-package-mode-zjkKA0Ca-py3.11/lib/python3.11/site-packages/tenacity/__init__.py\", line 379, in __call__\n    do = self.iter(retry_state=retry_state)\n         ^^^^^^^^^^^^^^^^^^^^^^^^^^^^^^^^^^\n  File \"/home/fd15hava/.cache/pypoetry/virtualenvs/non-package-mode-zjkKA0Ca-py3.11/lib/python3.11/site-packages/tenacity/__init__.py\", line 326, in iter\n    raise retry_exc from fut.exception()\ntenacity.RetryError: RetryError[<Future at 0x148460c4e010 state=finished raised UnexpectedAnswerException>]\n",
      "Traceback (most recent call last):\n  File \"/home/fd15hava/.cache/pypoetry/virtualenvs/non-package-mode-zjkKA0Ca-py3.11/lib/python3.11/site-packages/tenacity/__init__.py\", line 382, in __call__\n    result = fn(*args, **kwargs)\n             ^^^^^^^^^^^^^^^^^^^\n  File \"/work/home/fd15hava/tinypaper-mpt/src/agent.py\", line 26, in play\n    answer = self._prompt(self._make_prompt(scenario))\n             ^^^^^^^^^^^^^^^^^^^^^^^^^^^^^^^^^^^^^^^^^\n  File \"/work/home/fd15hava/tinypaper-mpt/src/agent.py\", line 40, in _prompt\n    raise UnexpectedAnswerException(f\"expected 1 or 2, got {result}\")\nutil.UnexpectedAnswerException: expected 1 or 2, got  \n\nThe above exception was the direct cause of the following exception:\n\nTraceback (most recent call last):\n  File \"/work/home/fd15hava/tinypaper-mpt/scripts/experiments/run.py\", line 16, in _run_session\n    result = agent.play(session)\n             ^^^^^^^^^^^^^^^^^^^\n  File \"/home/fd15hava/.cache/pypoetry/virtualenvs/non-package-mode-zjkKA0Ca-py3.11/lib/python3.11/site-packages/tenacity/__init__.py\", line 289, in wrapped_f\n    return self(f, *args, **kw)\n           ^^^^^^^^^^^^^^^^^^^^\n  File \"/home/fd15hava/.cache/pypoetry/virtualenvs/non-package-mode-zjkKA0Ca-py3.11/lib/python3.11/site-packages/tenacity/__init__.py\", line 379, in __call__\n    do = self.iter(retry_state=retry_state)\n         ^^^^^^^^^^^^^^^^^^^^^^^^^^^^^^^^^^\n  File \"/home/fd15hava/.cache/pypoetry/virtualenvs/non-package-mode-zjkKA0Ca-py3.11/lib/python3.11/site-packages/tenacity/__init__.py\", line 326, in iter\n    raise retry_exc from fut.exception()\ntenacity.RetryError: RetryError[<Future at 0x148460b8d050 state=finished raised UnexpectedAnswerException>]\n",
      "Traceback (most recent call last):\n  File \"/home/fd15hava/.cache/pypoetry/virtualenvs/non-package-mode-zjkKA0Ca-py3.11/lib/python3.11/site-packages/tenacity/__init__.py\", line 382, in __call__\n    result = fn(*args, **kwargs)\n             ^^^^^^^^^^^^^^^^^^^\n  File \"/work/home/fd15hava/tinypaper-mpt/src/agent.py\", line 26, in play\n    answer = self._prompt(self._make_prompt(scenario))\n             ^^^^^^^^^^^^^^^^^^^^^^^^^^^^^^^^^^^^^^^^^\n  File \"/work/home/fd15hava/tinypaper-mpt/src/agent.py\", line 40, in _prompt\n    raise UnexpectedAnswerException(f\"expected 1 or 2, got {result}\")\nutil.UnexpectedAnswerException: expected 1 or 2, got  \n\nThe above exception was the direct cause of the following exception:\n\nTraceback (most recent call last):\n  File \"/work/home/fd15hava/tinypaper-mpt/scripts/experiments/run.py\", line 16, in _run_session\n    result = agent.play(session)\n             ^^^^^^^^^^^^^^^^^^^\n  File \"/home/fd15hava/.cache/pypoetry/virtualenvs/non-package-mode-zjkKA0Ca-py3.11/lib/python3.11/site-packages/tenacity/__init__.py\", line 289, in wrapped_f\n    return self(f, *args, **kw)\n           ^^^^^^^^^^^^^^^^^^^^\n  File \"/home/fd15hava/.cache/pypoetry/virtualenvs/non-package-mode-zjkKA0Ca-py3.11/lib/python3.11/site-packages/tenacity/__init__.py\", line 379, in __call__\n    do = self.iter(retry_state=retry_state)\n         ^^^^^^^^^^^^^^^^^^^^^^^^^^^^^^^^^^\n  File \"/home/fd15hava/.cache/pypoetry/virtualenvs/non-package-mode-zjkKA0Ca-py3.11/lib/python3.11/site-packages/tenacity/__init__.py\", line 326, in iter\n    raise retry_exc from fut.exception()\ntenacity.RetryError: RetryError[<Future at 0x1484a8fb2b50 state=finished raised UnexpectedAnswerException>]\n",
      "Traceback (most recent call last):\n  File \"/home/fd15hava/.cache/pypoetry/virtualenvs/non-package-mode-zjkKA0Ca-py3.11/lib/python3.11/site-packages/tenacity/__init__.py\", line 382, in __call__\n    result = fn(*args, **kwargs)\n             ^^^^^^^^^^^^^^^^^^^\n  File \"/work/home/fd15hava/tinypaper-mpt/src/agent.py\", line 26, in play\n    answer = self._prompt(self._make_prompt(scenario))\n             ^^^^^^^^^^^^^^^^^^^^^^^^^^^^^^^^^^^^^^^^^\n  File \"/work/home/fd15hava/tinypaper-mpt/src/agent.py\", line 40, in _prompt\n    raise UnexpectedAnswerException(f\"expected 1 or 2, got {result}\")\nutil.UnexpectedAnswerException: expected 1 or 2, got  \n\nThe above exception was the direct cause of the following exception:\n\nTraceback (most recent call last):\n  File \"/work/home/fd15hava/tinypaper-mpt/scripts/experiments/run.py\", line 16, in _run_session\n    result = agent.play(session)\n             ^^^^^^^^^^^^^^^^^^^\n  File \"/home/fd15hava/.cache/pypoetry/virtualenvs/non-package-mode-zjkKA0Ca-py3.11/lib/python3.11/site-packages/tenacity/__init__.py\", line 289, in wrapped_f\n    return self(f, *args, **kw)\n           ^^^^^^^^^^^^^^^^^^^^\n  File \"/home/fd15hava/.cache/pypoetry/virtualenvs/non-package-mode-zjkKA0Ca-py3.11/lib/python3.11/site-packages/tenacity/__init__.py\", line 379, in __call__\n    do = self.iter(retry_state=retry_state)\n         ^^^^^^^^^^^^^^^^^^^^^^^^^^^^^^^^^^\n  File \"/home/fd15hava/.cache/pypoetry/virtualenvs/non-package-mode-zjkKA0Ca-py3.11/lib/python3.11/site-packages/tenacity/__init__.py\", line 326, in iter\n    raise retry_exc from fut.exception()\ntenacity.RetryError: RetryError[<Future at 0x148460c4dd90 state=finished raised UnexpectedAnswerException>]\n",
      "Traceback (most recent call last):\n  File \"/home/fd15hava/.cache/pypoetry/virtualenvs/non-package-mode-zjkKA0Ca-py3.11/lib/python3.11/site-packages/tenacity/__init__.py\", line 382, in __call__\n    result = fn(*args, **kwargs)\n             ^^^^^^^^^^^^^^^^^^^\n  File \"/work/home/fd15hava/tinypaper-mpt/src/agent.py\", line 26, in play\n    answer = self._prompt(self._make_prompt(scenario))\n             ^^^^^^^^^^^^^^^^^^^^^^^^^^^^^^^^^^^^^^^^^\n  File \"/work/home/fd15hava/tinypaper-mpt/src/agent.py\", line 40, in _prompt\n    raise UnexpectedAnswerException(f\"expected 1 or 2, got {result}\")\nutil.UnexpectedAnswerException: expected 1 or 2, got  \n\nThe above exception was the direct cause of the following exception:\n\nTraceback (most recent call last):\n  File \"/work/home/fd15hava/tinypaper-mpt/scripts/experiments/run.py\", line 16, in _run_session\n    result = agent.play(session)\n             ^^^^^^^^^^^^^^^^^^^\n  File \"/home/fd15hava/.cache/pypoetry/virtualenvs/non-package-mode-zjkKA0Ca-py3.11/lib/python3.11/site-packages/tenacity/__init__.py\", line 289, in wrapped_f\n    return self(f, *args, **kw)\n           ^^^^^^^^^^^^^^^^^^^^\n  File \"/home/fd15hava/.cache/pypoetry/virtualenvs/non-package-mode-zjkKA0Ca-py3.11/lib/python3.11/site-packages/tenacity/__init__.py\", line 379, in __call__\n    do = self.iter(retry_state=retry_state)\n         ^^^^^^^^^^^^^^^^^^^^^^^^^^^^^^^^^^\n  File \"/home/fd15hava/.cache/pypoetry/virtualenvs/non-package-mode-zjkKA0Ca-py3.11/lib/python3.11/site-packages/tenacity/__init__.py\", line 326, in iter\n    raise retry_exc from fut.exception()\ntenacity.RetryError: RetryError[<Future at 0x148460b8f9d0 state=finished raised UnexpectedAnswerException>]\n",
      "Traceback (most recent call last):\n  File \"/home/fd15hava/.cache/pypoetry/virtualenvs/non-package-mode-zjkKA0Ca-py3.11/lib/python3.11/site-packages/tenacity/__init__.py\", line 382, in __call__\n    result = fn(*args, **kwargs)\n             ^^^^^^^^^^^^^^^^^^^\n  File \"/work/home/fd15hava/tinypaper-mpt/src/agent.py\", line 26, in play\n    answer = self._prompt(self._make_prompt(scenario))\n             ^^^^^^^^^^^^^^^^^^^^^^^^^^^^^^^^^^^^^^^^^\n  File \"/work/home/fd15hava/tinypaper-mpt/src/agent.py\", line 40, in _prompt\n    raise UnexpectedAnswerException(f\"expected 1 or 2, got {result}\")\nutil.UnexpectedAnswerException: expected 1 or 2, got  \n\nThe above exception was the direct cause of the following exception:\n\nTraceback (most recent call last):\n  File \"/work/home/fd15hava/tinypaper-mpt/scripts/experiments/run.py\", line 16, in _run_session\n    result = agent.play(session)\n             ^^^^^^^^^^^^^^^^^^^\n  File \"/home/fd15hava/.cache/pypoetry/virtualenvs/non-package-mode-zjkKA0Ca-py3.11/lib/python3.11/site-packages/tenacity/__init__.py\", line 289, in wrapped_f\n    return self(f, *args, **kw)\n           ^^^^^^^^^^^^^^^^^^^^\n  File \"/home/fd15hava/.cache/pypoetry/virtualenvs/non-package-mode-zjkKA0Ca-py3.11/lib/python3.11/site-packages/tenacity/__init__.py\", line 379, in __call__\n    do = self.iter(retry_state=retry_state)\n         ^^^^^^^^^^^^^^^^^^^^^^^^^^^^^^^^^^\n  File \"/home/fd15hava/.cache/pypoetry/virtualenvs/non-package-mode-zjkKA0Ca-py3.11/lib/python3.11/site-packages/tenacity/__init__.py\", line 326, in iter\n    raise retry_exc from fut.exception()\ntenacity.RetryError: RetryError[<Future at 0x148460b73890 state=finished raised UnexpectedAnswerException>]\n",
      "Traceback (most recent call last):\n  File \"/home/fd15hava/.cache/pypoetry/virtualenvs/non-package-mode-zjkKA0Ca-py3.11/lib/python3.11/site-packages/tenacity/__init__.py\", line 382, in __call__\n    result = fn(*args, **kwargs)\n             ^^^^^^^^^^^^^^^^^^^\n  File \"/work/home/fd15hava/tinypaper-mpt/src/agent.py\", line 26, in play\n    answer = self._prompt(self._make_prompt(scenario))\n             ^^^^^^^^^^^^^^^^^^^^^^^^^^^^^^^^^^^^^^^^^\n  File \"/work/home/fd15hava/tinypaper-mpt/src/agent.py\", line 40, in _prompt\n    raise UnexpectedAnswerException(f\"expected 1 or 2, got {result}\")\nutil.UnexpectedAnswerException: expected 1 or 2, got  \n\nThe above exception was the direct cause of the following exception:\n\nTraceback (most recent call last):\n  File \"/work/home/fd15hava/tinypaper-mpt/scripts/experiments/run.py\", line 16, in _run_session\n    result = agent.play(session)\n             ^^^^^^^^^^^^^^^^^^^\n  File \"/home/fd15hava/.cache/pypoetry/virtualenvs/non-package-mode-zjkKA0Ca-py3.11/lib/python3.11/site-packages/tenacity/__init__.py\", line 289, in wrapped_f\n    return self(f, *args, **kw)\n           ^^^^^^^^^^^^^^^^^^^^\n  File \"/home/fd15hava/.cache/pypoetry/virtualenvs/non-package-mode-zjkKA0Ca-py3.11/lib/python3.11/site-packages/tenacity/__init__.py\", line 379, in __call__\n    do = self.iter(retry_state=retry_state)\n         ^^^^^^^^^^^^^^^^^^^^^^^^^^^^^^^^^^\n  File \"/home/fd15hava/.cache/pypoetry/virtualenvs/non-package-mode-zjkKA0Ca-py3.11/lib/python3.11/site-packages/tenacity/__init__.py\", line 326, in iter\n    raise retry_exc from fut.exception()\ntenacity.RetryError: RetryError[<Future at 0x148460c43550 state=finished raised UnexpectedAnswerException>]\n",
      "Traceback (most recent call last):\n  File \"/home/fd15hava/.cache/pypoetry/virtualenvs/non-package-mode-zjkKA0Ca-py3.11/lib/python3.11/site-packages/tenacity/__init__.py\", line 382, in __call__\n    result = fn(*args, **kwargs)\n             ^^^^^^^^^^^^^^^^^^^\n  File \"/work/home/fd15hava/tinypaper-mpt/src/agent.py\", line 26, in play\n    answer = self._prompt(self._make_prompt(scenario))\n             ^^^^^^^^^^^^^^^^^^^^^^^^^^^^^^^^^^^^^^^^^\n  File \"/work/home/fd15hava/tinypaper-mpt/src/agent.py\", line 40, in _prompt\n    raise UnexpectedAnswerException(f\"expected 1 or 2, got {result}\")\nutil.UnexpectedAnswerException: expected 1 or 2, got  \n\nThe above exception was the direct cause of the following exception:\n\nTraceback (most recent call last):\n  File \"/work/home/fd15hava/tinypaper-mpt/scripts/experiments/run.py\", line 16, in _run_session\n    result = agent.play(session)\n             ^^^^^^^^^^^^^^^^^^^\n  File \"/home/fd15hava/.cache/pypoetry/virtualenvs/non-package-mode-zjkKA0Ca-py3.11/lib/python3.11/site-packages/tenacity/__init__.py\", line 289, in wrapped_f\n    return self(f, *args, **kw)\n           ^^^^^^^^^^^^^^^^^^^^\n  File \"/home/fd15hava/.cache/pypoetry/virtualenvs/non-package-mode-zjkKA0Ca-py3.11/lib/python3.11/site-packages/tenacity/__init__.py\", line 379, in __call__\n    do = self.iter(retry_state=retry_state)\n         ^^^^^^^^^^^^^^^^^^^^^^^^^^^^^^^^^^\n  File \"/home/fd15hava/.cache/pypoetry/virtualenvs/non-package-mode-zjkKA0Ca-py3.11/lib/python3.11/site-packages/tenacity/__init__.py\", line 326, in iter\n    raise retry_exc from fut.exception()\ntenacity.RetryError: RetryError[<Future at 0x1484a94b6210 state=finished raised UnexpectedAnswerException>]\n",
      "Traceback (most recent call last):\n  File \"/home/fd15hava/.cache/pypoetry/virtualenvs/non-package-mode-zjkKA0Ca-py3.11/lib/python3.11/site-packages/tenacity/__init__.py\", line 382, in __call__\n    result = fn(*args, **kwargs)\n             ^^^^^^^^^^^^^^^^^^^\n  File \"/work/home/fd15hava/tinypaper-mpt/src/agent.py\", line 26, in play\n    answer = self._prompt(self._make_prompt(scenario))\n             ^^^^^^^^^^^^^^^^^^^^^^^^^^^^^^^^^^^^^^^^^\n  File \"/work/home/fd15hava/tinypaper-mpt/src/agent.py\", line 40, in _prompt\n    raise UnexpectedAnswerException(f\"expected 1 or 2, got {result}\")\nutil.UnexpectedAnswerException: expected 1 or 2, got  \n\nThe above exception was the direct cause of the following exception:\n\nTraceback (most recent call last):\n  File \"/work/home/fd15hava/tinypaper-mpt/scripts/experiments/run.py\", line 16, in _run_session\n    result = agent.play(session)\n             ^^^^^^^^^^^^^^^^^^^\n  File \"/home/fd15hava/.cache/pypoetry/virtualenvs/non-package-mode-zjkKA0Ca-py3.11/lib/python3.11/site-packages/tenacity/__init__.py\", line 289, in wrapped_f\n    return self(f, *args, **kw)\n           ^^^^^^^^^^^^^^^^^^^^\n  File \"/home/fd15hava/.cache/pypoetry/virtualenvs/non-package-mode-zjkKA0Ca-py3.11/lib/python3.11/site-packages/tenacity/__init__.py\", line 379, in __call__\n    do = self.iter(retry_state=retry_state)\n         ^^^^^^^^^^^^^^^^^^^^^^^^^^^^^^^^^^\n  File \"/home/fd15hava/.cache/pypoetry/virtualenvs/non-package-mode-zjkKA0Ca-py3.11/lib/python3.11/site-packages/tenacity/__init__.py\", line 326, in iter\n    raise retry_exc from fut.exception()\ntenacity.RetryError: RetryError[<Future at 0x148460c0aed0 state=finished raised UnexpectedAnswerException>]\n",
      "Traceback (most recent call last):\n  File \"/home/fd15hava/.cache/pypoetry/virtualenvs/non-package-mode-zjkKA0Ca-py3.11/lib/python3.11/site-packages/tenacity/__init__.py\", line 382, in __call__\n    result = fn(*args, **kwargs)\n             ^^^^^^^^^^^^^^^^^^^\n  File \"/work/home/fd15hava/tinypaper-mpt/src/agent.py\", line 26, in play\n    answer = self._prompt(self._make_prompt(scenario))\n             ^^^^^^^^^^^^^^^^^^^^^^^^^^^^^^^^^^^^^^^^^\n  File \"/work/home/fd15hava/tinypaper-mpt/src/agent.py\", line 40, in _prompt\n    raise UnexpectedAnswerException(f\"expected 1 or 2, got {result}\")\nutil.UnexpectedAnswerException: expected 1 or 2, got  \n\nThe above exception was the direct cause of the following exception:\n\nTraceback (most recent call last):\n  File \"/work/home/fd15hava/tinypaper-mpt/scripts/experiments/run.py\", line 16, in _run_session\n    result = agent.play(session)\n             ^^^^^^^^^^^^^^^^^^^\n  File \"/home/fd15hava/.cache/pypoetry/virtualenvs/non-package-mode-zjkKA0Ca-py3.11/lib/python3.11/site-packages/tenacity/__init__.py\", line 289, in wrapped_f\n    return self(f, *args, **kw)\n           ^^^^^^^^^^^^^^^^^^^^\n  File \"/home/fd15hava/.cache/pypoetry/virtualenvs/non-package-mode-zjkKA0Ca-py3.11/lib/python3.11/site-packages/tenacity/__init__.py\", line 379, in __call__\n    do = self.iter(retry_state=retry_state)\n         ^^^^^^^^^^^^^^^^^^^^^^^^^^^^^^^^^^\n  File \"/home/fd15hava/.cache/pypoetry/virtualenvs/non-package-mode-zjkKA0Ca-py3.11/lib/python3.11/site-packages/tenacity/__init__.py\", line 326, in iter\n    raise retry_exc from fut.exception()\ntenacity.RetryError: RetryError[<Future at 0x148460c43550 state=finished raised UnexpectedAnswerException>]\n",
      "Traceback (most recent call last):\n  File \"/home/fd15hava/.cache/pypoetry/virtualenvs/non-package-mode-zjkKA0Ca-py3.11/lib/python3.11/site-packages/tenacity/__init__.py\", line 382, in __call__\n    result = fn(*args, **kwargs)\n             ^^^^^^^^^^^^^^^^^^^\n  File \"/work/home/fd15hava/tinypaper-mpt/src/agent.py\", line 26, in play\n    answer = self._prompt(self._make_prompt(scenario))\n             ^^^^^^^^^^^^^^^^^^^^^^^^^^^^^^^^^^^^^^^^^\n  File \"/work/home/fd15hava/tinypaper-mpt/src/agent.py\", line 40, in _prompt\n    raise UnexpectedAnswerException(f\"expected 1 or 2, got {result}\")\nutil.UnexpectedAnswerException: expected 1 or 2, got  \n\nThe above exception was the direct cause of the following exception:\n\nTraceback (most recent call last):\n  File \"/work/home/fd15hava/tinypaper-mpt/scripts/experiments/run.py\", line 16, in _run_session\n    result = agent.play(session)\n             ^^^^^^^^^^^^^^^^^^^\n  File \"/home/fd15hava/.cache/pypoetry/virtualenvs/non-package-mode-zjkKA0Ca-py3.11/lib/python3.11/site-packages/tenacity/__init__.py\", line 289, in wrapped_f\n    return self(f, *args, **kw)\n           ^^^^^^^^^^^^^^^^^^^^\n  File \"/home/fd15hava/.cache/pypoetry/virtualenvs/non-package-mode-zjkKA0Ca-py3.11/lib/python3.11/site-packages/tenacity/__init__.py\", line 379, in __call__\n    do = self.iter(retry_state=retry_state)\n         ^^^^^^^^^^^^^^^^^^^^^^^^^^^^^^^^^^\n  File \"/home/fd15hava/.cache/pypoetry/virtualenvs/non-package-mode-zjkKA0Ca-py3.11/lib/python3.11/site-packages/tenacity/__init__.py\", line 326, in iter\n    raise retry_exc from fut.exception()\ntenacity.RetryError: RetryError[<Future at 0x148460bd51d0 state=finished raised UnexpectedAnswerException>]\n",
      "Traceback (most recent call last):\n  File \"/home/fd15hava/.cache/pypoetry/virtualenvs/non-package-mode-zjkKA0Ca-py3.11/lib/python3.11/site-packages/tenacity/__init__.py\", line 382, in __call__\n    result = fn(*args, **kwargs)\n             ^^^^^^^^^^^^^^^^^^^\n  File \"/work/home/fd15hava/tinypaper-mpt/src/agent.py\", line 26, in play\n    answer = self._prompt(self._make_prompt(scenario))\n             ^^^^^^^^^^^^^^^^^^^^^^^^^^^^^^^^^^^^^^^^^\n  File \"/work/home/fd15hava/tinypaper-mpt/src/agent.py\", line 40, in _prompt\n    raise UnexpectedAnswerException(f\"expected 1 or 2, got {result}\")\nutil.UnexpectedAnswerException: expected 1 or 2, got  \n\nThe above exception was the direct cause of the following exception:\n\nTraceback (most recent call last):\n  File \"/work/home/fd15hava/tinypaper-mpt/scripts/experiments/run.py\", line 16, in _run_session\n    result = agent.play(session)\n             ^^^^^^^^^^^^^^^^^^^\n  File \"/home/fd15hava/.cache/pypoetry/virtualenvs/non-package-mode-zjkKA0Ca-py3.11/lib/python3.11/site-packages/tenacity/__init__.py\", line 289, in wrapped_f\n    return self(f, *args, **kw)\n           ^^^^^^^^^^^^^^^^^^^^\n  File \"/home/fd15hava/.cache/pypoetry/virtualenvs/non-package-mode-zjkKA0Ca-py3.11/lib/python3.11/site-packages/tenacity/__init__.py\", line 379, in __call__\n    do = self.iter(retry_state=retry_state)\n         ^^^^^^^^^^^^^^^^^^^^^^^^^^^^^^^^^^\n  File \"/home/fd15hava/.cache/pypoetry/virtualenvs/non-package-mode-zjkKA0Ca-py3.11/lib/python3.11/site-packages/tenacity/__init__.py\", line 326, in iter\n    raise retry_exc from fut.exception()\ntenacity.RetryError: RetryError[<Future at 0x148460acf610 state=finished raised UnexpectedAnswerException>]\n",
      "Traceback (most recent call last):\n  File \"/home/fd15hava/.cache/pypoetry/virtualenvs/non-package-mode-zjkKA0Ca-py3.11/lib/python3.11/site-packages/tenacity/__init__.py\", line 382, in __call__\n    result = fn(*args, **kwargs)\n             ^^^^^^^^^^^^^^^^^^^\n  File \"/work/home/fd15hava/tinypaper-mpt/src/agent.py\", line 26, in play\n    answer = self._prompt(self._make_prompt(scenario))\n             ^^^^^^^^^^^^^^^^^^^^^^^^^^^^^^^^^^^^^^^^^\n  File \"/work/home/fd15hava/tinypaper-mpt/src/agent.py\", line 40, in _prompt\n    raise UnexpectedAnswerException(f\"expected 1 or 2, got {result}\")\nutil.UnexpectedAnswerException: expected 1 or 2, got  \n\nThe above exception was the direct cause of the following exception:\n\nTraceback (most recent call last):\n  File \"/work/home/fd15hava/tinypaper-mpt/scripts/experiments/run.py\", line 16, in _run_session\n    result = agent.play(session)\n             ^^^^^^^^^^^^^^^^^^^\n  File \"/home/fd15hava/.cache/pypoetry/virtualenvs/non-package-mode-zjkKA0Ca-py3.11/lib/python3.11/site-packages/tenacity/__init__.py\", line 289, in wrapped_f\n    return self(f, *args, **kw)\n           ^^^^^^^^^^^^^^^^^^^^\n  File \"/home/fd15hava/.cache/pypoetry/virtualenvs/non-package-mode-zjkKA0Ca-py3.11/lib/python3.11/site-packages/tenacity/__init__.py\", line 379, in __call__\n    do = self.iter(retry_state=retry_state)\n         ^^^^^^^^^^^^^^^^^^^^^^^^^^^^^^^^^^\n  File \"/home/fd15hava/.cache/pypoetry/virtualenvs/non-package-mode-zjkKA0Ca-py3.11/lib/python3.11/site-packages/tenacity/__init__.py\", line 326, in iter\n    raise retry_exc from fut.exception()\ntenacity.RetryError: RetryError[<Future at 0x148460c0b050 state=finished raised UnexpectedAnswerException>]\n",
      "Traceback (most recent call last):\n  File \"/home/fd15hava/.cache/pypoetry/virtualenvs/non-package-mode-zjkKA0Ca-py3.11/lib/python3.11/site-packages/tenacity/__init__.py\", line 382, in __call__\n    result = fn(*args, **kwargs)\n             ^^^^^^^^^^^^^^^^^^^\n  File \"/work/home/fd15hava/tinypaper-mpt/src/agent.py\", line 26, in play\n    answer = self._prompt(self._make_prompt(scenario))\n             ^^^^^^^^^^^^^^^^^^^^^^^^^^^^^^^^^^^^^^^^^\n  File \"/work/home/fd15hava/tinypaper-mpt/src/agent.py\", line 40, in _prompt\n    raise UnexpectedAnswerException(f\"expected 1 or 2, got {result}\")\nutil.UnexpectedAnswerException: expected 1 or 2, got  \n\nThe above exception was the direct cause of the following exception:\n\nTraceback (most recent call last):\n  File \"/work/home/fd15hava/tinypaper-mpt/scripts/experiments/run.py\", line 16, in _run_session\n    result = agent.play(session)\n             ^^^^^^^^^^^^^^^^^^^\n  File \"/home/fd15hava/.cache/pypoetry/virtualenvs/non-package-mode-zjkKA0Ca-py3.11/lib/python3.11/site-packages/tenacity/__init__.py\", line 289, in wrapped_f\n    return self(f, *args, **kw)\n           ^^^^^^^^^^^^^^^^^^^^\n  File \"/home/fd15hava/.cache/pypoetry/virtualenvs/non-package-mode-zjkKA0Ca-py3.11/lib/python3.11/site-packages/tenacity/__init__.py\", line 379, in __call__\n    do = self.iter(retry_state=retry_state)\n         ^^^^^^^^^^^^^^^^^^^^^^^^^^^^^^^^^^\n  File \"/home/fd15hava/.cache/pypoetry/virtualenvs/non-package-mode-zjkKA0Ca-py3.11/lib/python3.11/site-packages/tenacity/__init__.py\", line 326, in iter\n    raise retry_exc from fut.exception()\ntenacity.RetryError: RetryError[<Future at 0x1484a94b7990 state=finished raised UnexpectedAnswerException>]\n",
      "Traceback (most recent call last):\n  File \"/home/fd15hava/.cache/pypoetry/virtualenvs/non-package-mode-zjkKA0Ca-py3.11/lib/python3.11/site-packages/tenacity/__init__.py\", line 382, in __call__\n    result = fn(*args, **kwargs)\n             ^^^^^^^^^^^^^^^^^^^\n  File \"/work/home/fd15hava/tinypaper-mpt/src/agent.py\", line 26, in play\n    answer = self._prompt(self._make_prompt(scenario))\n             ^^^^^^^^^^^^^^^^^^^^^^^^^^^^^^^^^^^^^^^^^\n  File \"/work/home/fd15hava/tinypaper-mpt/src/agent.py\", line 40, in _prompt\n    raise UnexpectedAnswerException(f\"expected 1 or 2, got {result}\")\nutil.UnexpectedAnswerException: expected 1 or 2, got  \n\nThe above exception was the direct cause of the following exception:\n\nTraceback (most recent call last):\n  File \"/work/home/fd15hava/tinypaper-mpt/scripts/experiments/run.py\", line 16, in _run_session\n    result = agent.play(session)\n             ^^^^^^^^^^^^^^^^^^^\n  File \"/home/fd15hava/.cache/pypoetry/virtualenvs/non-package-mode-zjkKA0Ca-py3.11/lib/python3.11/site-packages/tenacity/__init__.py\", line 289, in wrapped_f\n    return self(f, *args, **kw)\n           ^^^^^^^^^^^^^^^^^^^^\n  File \"/home/fd15hava/.cache/pypoetry/virtualenvs/non-package-mode-zjkKA0Ca-py3.11/lib/python3.11/site-packages/tenacity/__init__.py\", line 379, in __call__\n    do = self.iter(retry_state=retry_state)\n         ^^^^^^^^^^^^^^^^^^^^^^^^^^^^^^^^^^\n  File \"/home/fd15hava/.cache/pypoetry/virtualenvs/non-package-mode-zjkKA0Ca-py3.11/lib/python3.11/site-packages/tenacity/__init__.py\", line 326, in iter\n    raise retry_exc from fut.exception()\ntenacity.RetryError: RetryError[<Future at 0x148460c0a810 state=finished raised UnexpectedAnswerException>]\n",
      "Traceback (most recent call last):\n  File \"/home/fd15hava/.cache/pypoetry/virtualenvs/non-package-mode-zjkKA0Ca-py3.11/lib/python3.11/site-packages/tenacity/__init__.py\", line 382, in __call__\n    result = fn(*args, **kwargs)\n             ^^^^^^^^^^^^^^^^^^^\n  File \"/work/home/fd15hava/tinypaper-mpt/src/agent.py\", line 26, in play\n    answer = self._prompt(self._make_prompt(scenario))\n             ^^^^^^^^^^^^^^^^^^^^^^^^^^^^^^^^^^^^^^^^^\n  File \"/work/home/fd15hava/tinypaper-mpt/src/agent.py\", line 40, in _prompt\n    raise UnexpectedAnswerException(f\"expected 1 or 2, got {result}\")\nutil.UnexpectedAnswerException: expected 1 or 2, got  \n\nThe above exception was the direct cause of the following exception:\n\nTraceback (most recent call last):\n  File \"/work/home/fd15hava/tinypaper-mpt/scripts/experiments/run.py\", line 16, in _run_session\n    result = agent.play(session)\n             ^^^^^^^^^^^^^^^^^^^\n  File \"/home/fd15hava/.cache/pypoetry/virtualenvs/non-package-mode-zjkKA0Ca-py3.11/lib/python3.11/site-packages/tenacity/__init__.py\", line 289, in wrapped_f\n    return self(f, *args, **kw)\n           ^^^^^^^^^^^^^^^^^^^^\n  File \"/home/fd15hava/.cache/pypoetry/virtualenvs/non-package-mode-zjkKA0Ca-py3.11/lib/python3.11/site-packages/tenacity/__init__.py\", line 379, in __call__\n    do = self.iter(retry_state=retry_state)\n         ^^^^^^^^^^^^^^^^^^^^^^^^^^^^^^^^^^\n  File \"/home/fd15hava/.cache/pypoetry/virtualenvs/non-package-mode-zjkKA0Ca-py3.11/lib/python3.11/site-packages/tenacity/__init__.py\", line 326, in iter\n    raise retry_exc from fut.exception()\ntenacity.RetryError: RetryError[<Future at 0x1484a949b250 state=finished raised UnexpectedAnswerException>]\n",
      "Traceback (most recent call last):\n  File \"/home/fd15hava/.cache/pypoetry/virtualenvs/non-package-mode-zjkKA0Ca-py3.11/lib/python3.11/site-packages/tenacity/__init__.py\", line 382, in __call__\n    result = fn(*args, **kwargs)\n             ^^^^^^^^^^^^^^^^^^^\n  File \"/work/home/fd15hava/tinypaper-mpt/src/agent.py\", line 26, in play\n    answer = self._prompt(self._make_prompt(scenario))\n             ^^^^^^^^^^^^^^^^^^^^^^^^^^^^^^^^^^^^^^^^^\n  File \"/work/home/fd15hava/tinypaper-mpt/src/agent.py\", line 40, in _prompt\n    raise UnexpectedAnswerException(f\"expected 1 or 2, got {result}\")\nutil.UnexpectedAnswerException: expected 1 or 2, got  \n\nThe above exception was the direct cause of the following exception:\n\nTraceback (most recent call last):\n  File \"/work/home/fd15hava/tinypaper-mpt/scripts/experiments/run.py\", line 16, in _run_session\n    result = agent.play(session)\n             ^^^^^^^^^^^^^^^^^^^\n  File \"/home/fd15hava/.cache/pypoetry/virtualenvs/non-package-mode-zjkKA0Ca-py3.11/lib/python3.11/site-packages/tenacity/__init__.py\", line 289, in wrapped_f\n    return self(f, *args, **kw)\n           ^^^^^^^^^^^^^^^^^^^^\n  File \"/home/fd15hava/.cache/pypoetry/virtualenvs/non-package-mode-zjkKA0Ca-py3.11/lib/python3.11/site-packages/tenacity/__init__.py\", line 379, in __call__\n    do = self.iter(retry_state=retry_state)\n         ^^^^^^^^^^^^^^^^^^^^^^^^^^^^^^^^^^\n  File \"/home/fd15hava/.cache/pypoetry/virtualenvs/non-package-mode-zjkKA0Ca-py3.11/lib/python3.11/site-packages/tenacity/__init__.py\", line 326, in iter\n    raise retry_exc from fut.exception()\ntenacity.RetryError: RetryError[<Future at 0x148460c92ad0 state=finished raised UnexpectedAnswerException>]\n",
      "Traceback (most recent call last):\n  File \"/home/fd15hava/.cache/pypoetry/virtualenvs/non-package-mode-zjkKA0Ca-py3.11/lib/python3.11/site-packages/tenacity/__init__.py\", line 382, in __call__\n    result = fn(*args, **kwargs)\n             ^^^^^^^^^^^^^^^^^^^\n  File \"/work/home/fd15hava/tinypaper-mpt/src/agent.py\", line 26, in play\n    answer = self._prompt(self._make_prompt(scenario))\n             ^^^^^^^^^^^^^^^^^^^^^^^^^^^^^^^^^^^^^^^^^\n  File \"/work/home/fd15hava/tinypaper-mpt/src/agent.py\", line 40, in _prompt\n    raise UnexpectedAnswerException(f\"expected 1 or 2, got {result}\")\nutil.UnexpectedAnswerException: expected 1 or 2, got  \n\nThe above exception was the direct cause of the following exception:\n\nTraceback (most recent call last):\n  File \"/work/home/fd15hava/tinypaper-mpt/scripts/experiments/run.py\", line 16, in _run_session\n    result = agent.play(session)\n             ^^^^^^^^^^^^^^^^^^^\n  File \"/home/fd15hava/.cache/pypoetry/virtualenvs/non-package-mode-zjkKA0Ca-py3.11/lib/python3.11/site-packages/tenacity/__init__.py\", line 289, in wrapped_f\n    return self(f, *args, **kw)\n           ^^^^^^^^^^^^^^^^^^^^\n  File \"/home/fd15hava/.cache/pypoetry/virtualenvs/non-package-mode-zjkKA0Ca-py3.11/lib/python3.11/site-packages/tenacity/__init__.py\", line 379, in __call__\n    do = self.iter(retry_state=retry_state)\n         ^^^^^^^^^^^^^^^^^^^^^^^^^^^^^^^^^^\n  File \"/home/fd15hava/.cache/pypoetry/virtualenvs/non-package-mode-zjkKA0Ca-py3.11/lib/python3.11/site-packages/tenacity/__init__.py\", line 326, in iter\n    raise retry_exc from fut.exception()\ntenacity.RetryError: RetryError[<Future at 0x148460b8c7d0 state=finished raised UnexpectedAnswerException>]\n",
      "Traceback (most recent call last):\n  File \"/home/fd15hava/.cache/pypoetry/virtualenvs/non-package-mode-zjkKA0Ca-py3.11/lib/python3.11/site-packages/tenacity/__init__.py\", line 382, in __call__\n    result = fn(*args, **kwargs)\n             ^^^^^^^^^^^^^^^^^^^\n  File \"/work/home/fd15hava/tinypaper-mpt/src/agent.py\", line 26, in play\n    answer = self._prompt(self._make_prompt(scenario))\n             ^^^^^^^^^^^^^^^^^^^^^^^^^^^^^^^^^^^^^^^^^\n  File \"/work/home/fd15hava/tinypaper-mpt/src/agent.py\", line 40, in _prompt\n    raise UnexpectedAnswerException(f\"expected 1 or 2, got {result}\")\nutil.UnexpectedAnswerException: expected 1 or 2, got  \n\nThe above exception was the direct cause of the following exception:\n\nTraceback (most recent call last):\n  File \"/work/home/fd15hava/tinypaper-mpt/scripts/experiments/run.py\", line 16, in _run_session\n    result = agent.play(session)\n             ^^^^^^^^^^^^^^^^^^^\n  File \"/home/fd15hava/.cache/pypoetry/virtualenvs/non-package-mode-zjkKA0Ca-py3.11/lib/python3.11/site-packages/tenacity/__init__.py\", line 289, in wrapped_f\n    return self(f, *args, **kw)\n           ^^^^^^^^^^^^^^^^^^^^\n  File \"/home/fd15hava/.cache/pypoetry/virtualenvs/non-package-mode-zjkKA0Ca-py3.11/lib/python3.11/site-packages/tenacity/__init__.py\", line 379, in __call__\n    do = self.iter(retry_state=retry_state)\n         ^^^^^^^^^^^^^^^^^^^^^^^^^^^^^^^^^^\n  File \"/home/fd15hava/.cache/pypoetry/virtualenvs/non-package-mode-zjkKA0Ca-py3.11/lib/python3.11/site-packages/tenacity/__init__.py\", line 326, in iter\n    raise retry_exc from fut.exception()\ntenacity.RetryError: RetryError[<Future at 0x148460c4d910 state=finished raised UnexpectedAnswerException>]\n",
      "Traceback (most recent call last):\n  File \"/home/fd15hava/.cache/pypoetry/virtualenvs/non-package-mode-zjkKA0Ca-py3.11/lib/python3.11/site-packages/tenacity/__init__.py\", line 382, in __call__\n    result = fn(*args, **kwargs)\n             ^^^^^^^^^^^^^^^^^^^\n  File \"/work/home/fd15hava/tinypaper-mpt/src/agent.py\", line 26, in play\n    answer = self._prompt(self._make_prompt(scenario))\n             ^^^^^^^^^^^^^^^^^^^^^^^^^^^^^^^^^^^^^^^^^\n  File \"/work/home/fd15hava/tinypaper-mpt/src/agent.py\", line 40, in _prompt\n    raise UnexpectedAnswerException(f\"expected 1 or 2, got {result}\")\nutil.UnexpectedAnswerException: expected 1 or 2, got  \n\nThe above exception was the direct cause of the following exception:\n\nTraceback (most recent call last):\n  File \"/work/home/fd15hava/tinypaper-mpt/scripts/experiments/run.py\", line 16, in _run_session\n    result = agent.play(session)\n             ^^^^^^^^^^^^^^^^^^^\n  File \"/home/fd15hava/.cache/pypoetry/virtualenvs/non-package-mode-zjkKA0Ca-py3.11/lib/python3.11/site-packages/tenacity/__init__.py\", line 289, in wrapped_f\n    return self(f, *args, **kw)\n           ^^^^^^^^^^^^^^^^^^^^\n  File \"/home/fd15hava/.cache/pypoetry/virtualenvs/non-package-mode-zjkKA0Ca-py3.11/lib/python3.11/site-packages/tenacity/__init__.py\", line 379, in __call__\n    do = self.iter(retry_state=retry_state)\n         ^^^^^^^^^^^^^^^^^^^^^^^^^^^^^^^^^^\n  File \"/home/fd15hava/.cache/pypoetry/virtualenvs/non-package-mode-zjkKA0Ca-py3.11/lib/python3.11/site-packages/tenacity/__init__.py\", line 326, in iter\n    raise retry_exc from fut.exception()\ntenacity.RetryError: RetryError[<Future at 0x148460b8d710 state=finished raised UnexpectedAnswerException>]\n",
      "Traceback (most recent call last):\n  File \"/home/fd15hava/.cache/pypoetry/virtualenvs/non-package-mode-zjkKA0Ca-py3.11/lib/python3.11/site-packages/tenacity/__init__.py\", line 382, in __call__\n    result = fn(*args, **kwargs)\n             ^^^^^^^^^^^^^^^^^^^\n  File \"/work/home/fd15hava/tinypaper-mpt/src/agent.py\", line 26, in play\n    answer = self._prompt(self._make_prompt(scenario))\n             ^^^^^^^^^^^^^^^^^^^^^^^^^^^^^^^^^^^^^^^^^\n  File \"/work/home/fd15hava/tinypaper-mpt/src/agent.py\", line 40, in _prompt\n    raise UnexpectedAnswerException(f\"expected 1 or 2, got {result}\")\nutil.UnexpectedAnswerException: expected 1 or 2, got  \n\nThe above exception was the direct cause of the following exception:\n\nTraceback (most recent call last):\n  File \"/work/home/fd15hava/tinypaper-mpt/scripts/experiments/run.py\", line 16, in _run_session\n    result = agent.play(session)\n             ^^^^^^^^^^^^^^^^^^^\n  File \"/home/fd15hava/.cache/pypoetry/virtualenvs/non-package-mode-zjkKA0Ca-py3.11/lib/python3.11/site-packages/tenacity/__init__.py\", line 289, in wrapped_f\n    return self(f, *args, **kw)\n           ^^^^^^^^^^^^^^^^^^^^\n  File \"/home/fd15hava/.cache/pypoetry/virtualenvs/non-package-mode-zjkKA0Ca-py3.11/lib/python3.11/site-packages/tenacity/__init__.py\", line 379, in __call__\n    do = self.iter(retry_state=retry_state)\n         ^^^^^^^^^^^^^^^^^^^^^^^^^^^^^^^^^^\n  File \"/home/fd15hava/.cache/pypoetry/virtualenvs/non-package-mode-zjkKA0Ca-py3.11/lib/python3.11/site-packages/tenacity/__init__.py\", line 326, in iter\n    raise retry_exc from fut.exception()\ntenacity.RetryError: RetryError[<Future at 0x148460b8fbd0 state=finished raised UnexpectedAnswerException>]\n",
      "Traceback (most recent call last):\n  File \"/home/fd15hava/.cache/pypoetry/virtualenvs/non-package-mode-zjkKA0Ca-py3.11/lib/python3.11/site-packages/tenacity/__init__.py\", line 382, in __call__\n    result = fn(*args, **kwargs)\n             ^^^^^^^^^^^^^^^^^^^\n  File \"/work/home/fd15hava/tinypaper-mpt/src/agent.py\", line 26, in play\n    answer = self._prompt(self._make_prompt(scenario))\n             ^^^^^^^^^^^^^^^^^^^^^^^^^^^^^^^^^^^^^^^^^\n  File \"/work/home/fd15hava/tinypaper-mpt/src/agent.py\", line 40, in _prompt\n    raise UnexpectedAnswerException(f\"expected 1 or 2, got {result}\")\nutil.UnexpectedAnswerException: expected 1 or 2, got  \n\nThe above exception was the direct cause of the following exception:\n\nTraceback (most recent call last):\n  File \"/work/home/fd15hava/tinypaper-mpt/scripts/experiments/run.py\", line 16, in _run_session\n    result = agent.play(session)\n             ^^^^^^^^^^^^^^^^^^^\n  File \"/home/fd15hava/.cache/pypoetry/virtualenvs/non-package-mode-zjkKA0Ca-py3.11/lib/python3.11/site-packages/tenacity/__init__.py\", line 289, in wrapped_f\n    return self(f, *args, **kw)\n           ^^^^^^^^^^^^^^^^^^^^\n  File \"/home/fd15hava/.cache/pypoetry/virtualenvs/non-package-mode-zjkKA0Ca-py3.11/lib/python3.11/site-packages/tenacity/__init__.py\", line 379, in __call__\n    do = self.iter(retry_state=retry_state)\n         ^^^^^^^^^^^^^^^^^^^^^^^^^^^^^^^^^^\n  File \"/home/fd15hava/.cache/pypoetry/virtualenvs/non-package-mode-zjkKA0Ca-py3.11/lib/python3.11/site-packages/tenacity/__init__.py\", line 326, in iter\n    raise retry_exc from fut.exception()\ntenacity.RetryError: RetryError[<Future at 0x148460c93a90 state=finished raised UnexpectedAnswerException>]\n",
      "Traceback (most recent call last):\n  File \"/home/fd15hava/.cache/pypoetry/virtualenvs/non-package-mode-zjkKA0Ca-py3.11/lib/python3.11/site-packages/tenacity/__init__.py\", line 382, in __call__\n    result = fn(*args, **kwargs)\n             ^^^^^^^^^^^^^^^^^^^\n  File \"/work/home/fd15hava/tinypaper-mpt/src/agent.py\", line 26, in play\n    answer = self._prompt(self._make_prompt(scenario))\n             ^^^^^^^^^^^^^^^^^^^^^^^^^^^^^^^^^^^^^^^^^\n  File \"/work/home/fd15hava/tinypaper-mpt/src/agent.py\", line 40, in _prompt\n    raise UnexpectedAnswerException(f\"expected 1 or 2, got {result}\")\nutil.UnexpectedAnswerException: expected 1 or 2, got  \n\nThe above exception was the direct cause of the following exception:\n\nTraceback (most recent call last):\n  File \"/work/home/fd15hava/tinypaper-mpt/scripts/experiments/run.py\", line 16, in _run_session\n    result = agent.play(session)\n             ^^^^^^^^^^^^^^^^^^^\n  File \"/home/fd15hava/.cache/pypoetry/virtualenvs/non-package-mode-zjkKA0Ca-py3.11/lib/python3.11/site-packages/tenacity/__init__.py\", line 289, in wrapped_f\n    return self(f, *args, **kw)\n           ^^^^^^^^^^^^^^^^^^^^\n  File \"/home/fd15hava/.cache/pypoetry/virtualenvs/non-package-mode-zjkKA0Ca-py3.11/lib/python3.11/site-packages/tenacity/__init__.py\", line 379, in __call__\n    do = self.iter(retry_state=retry_state)\n         ^^^^^^^^^^^^^^^^^^^^^^^^^^^^^^^^^^\n  File \"/home/fd15hava/.cache/pypoetry/virtualenvs/non-package-mode-zjkKA0Ca-py3.11/lib/python3.11/site-packages/tenacity/__init__.py\", line 326, in iter\n    raise retry_exc from fut.exception()\ntenacity.RetryError: RetryError[<Future at 0x148460c92790 state=finished raised UnexpectedAnswerException>]\n",
      "Traceback (most recent call last):\n  File \"/home/fd15hava/.cache/pypoetry/virtualenvs/non-package-mode-zjkKA0Ca-py3.11/lib/python3.11/site-packages/tenacity/__init__.py\", line 382, in __call__\n    result = fn(*args, **kwargs)\n             ^^^^^^^^^^^^^^^^^^^\n  File \"/work/home/fd15hava/tinypaper-mpt/src/agent.py\", line 26, in play\n    answer = self._prompt(self._make_prompt(scenario))\n             ^^^^^^^^^^^^^^^^^^^^^^^^^^^^^^^^^^^^^^^^^\n  File \"/work/home/fd15hava/tinypaper-mpt/src/agent.py\", line 40, in _prompt\n    raise UnexpectedAnswerException(f\"expected 1 or 2, got {result}\")\nutil.UnexpectedAnswerException: expected 1 or 2, got  \n\nThe above exception was the direct cause of the following exception:\n\nTraceback (most recent call last):\n  File \"/work/home/fd15hava/tinypaper-mpt/scripts/experiments/run.py\", line 16, in _run_session\n    result = agent.play(session)\n             ^^^^^^^^^^^^^^^^^^^\n  File \"/home/fd15hava/.cache/pypoetry/virtualenvs/non-package-mode-zjkKA0Ca-py3.11/lib/python3.11/site-packages/tenacity/__init__.py\", line 289, in wrapped_f\n    return self(f, *args, **kw)\n           ^^^^^^^^^^^^^^^^^^^^\n  File \"/home/fd15hava/.cache/pypoetry/virtualenvs/non-package-mode-zjkKA0Ca-py3.11/lib/python3.11/site-packages/tenacity/__init__.py\", line 379, in __call__\n    do = self.iter(retry_state=retry_state)\n         ^^^^^^^^^^^^^^^^^^^^^^^^^^^^^^^^^^\n  File \"/home/fd15hava/.cache/pypoetry/virtualenvs/non-package-mode-zjkKA0Ca-py3.11/lib/python3.11/site-packages/tenacity/__init__.py\", line 326, in iter\n    raise retry_exc from fut.exception()\ntenacity.RetryError: RetryError[<Future at 0x1484a8b35cd0 state=finished raised UnexpectedAnswerException>]\n",
      "Traceback (most recent call last):\n  File \"/home/fd15hava/.cache/pypoetry/virtualenvs/non-package-mode-zjkKA0Ca-py3.11/lib/python3.11/site-packages/tenacity/__init__.py\", line 382, in __call__\n    result = fn(*args, **kwargs)\n             ^^^^^^^^^^^^^^^^^^^\n  File \"/work/home/fd15hava/tinypaper-mpt/src/agent.py\", line 26, in play\n    answer = self._prompt(self._make_prompt(scenario))\n             ^^^^^^^^^^^^^^^^^^^^^^^^^^^^^^^^^^^^^^^^^\n  File \"/work/home/fd15hava/tinypaper-mpt/src/agent.py\", line 40, in _prompt\n    raise UnexpectedAnswerException(f\"expected 1 or 2, got {result}\")\nutil.UnexpectedAnswerException: expected 1 or 2, got  \n\nThe above exception was the direct cause of the following exception:\n\nTraceback (most recent call last):\n  File \"/work/home/fd15hava/tinypaper-mpt/scripts/experiments/run.py\", line 16, in _run_session\n    result = agent.play(session)\n             ^^^^^^^^^^^^^^^^^^^\n  File \"/home/fd15hava/.cache/pypoetry/virtualenvs/non-package-mode-zjkKA0Ca-py3.11/lib/python3.11/site-packages/tenacity/__init__.py\", line 289, in wrapped_f\n    return self(f, *args, **kw)\n           ^^^^^^^^^^^^^^^^^^^^\n  File \"/home/fd15hava/.cache/pypoetry/virtualenvs/non-package-mode-zjkKA0Ca-py3.11/lib/python3.11/site-packages/tenacity/__init__.py\", line 379, in __call__\n    do = self.iter(retry_state=retry_state)\n         ^^^^^^^^^^^^^^^^^^^^^^^^^^^^^^^^^^\n  File \"/home/fd15hava/.cache/pypoetry/virtualenvs/non-package-mode-zjkKA0Ca-py3.11/lib/python3.11/site-packages/tenacity/__init__.py\", line 326, in iter\n    raise retry_exc from fut.exception()\ntenacity.RetryError: RetryError[<Future at 0x148460c4fc50 state=finished raised UnexpectedAnswerException>]\n",
      "Traceback (most recent call last):\n  File \"/home/fd15hava/.cache/pypoetry/virtualenvs/non-package-mode-zjkKA0Ca-py3.11/lib/python3.11/site-packages/tenacity/__init__.py\", line 382, in __call__\n    result = fn(*args, **kwargs)\n             ^^^^^^^^^^^^^^^^^^^\n  File \"/work/home/fd15hava/tinypaper-mpt/src/agent.py\", line 26, in play\n    answer = self._prompt(self._make_prompt(scenario))\n             ^^^^^^^^^^^^^^^^^^^^^^^^^^^^^^^^^^^^^^^^^\n  File \"/work/home/fd15hava/tinypaper-mpt/src/agent.py\", line 40, in _prompt\n    raise UnexpectedAnswerException(f\"expected 1 or 2, got {result}\")\nutil.UnexpectedAnswerException: expected 1 or 2, got  \n\nThe above exception was the direct cause of the following exception:\n\nTraceback (most recent call last):\n  File \"/work/home/fd15hava/tinypaper-mpt/scripts/experiments/run.py\", line 16, in _run_session\n    result = agent.play(session)\n             ^^^^^^^^^^^^^^^^^^^\n  File \"/home/fd15hava/.cache/pypoetry/virtualenvs/non-package-mode-zjkKA0Ca-py3.11/lib/python3.11/site-packages/tenacity/__init__.py\", line 289, in wrapped_f\n    return self(f, *args, **kw)\n           ^^^^^^^^^^^^^^^^^^^^\n  File \"/home/fd15hava/.cache/pypoetry/virtualenvs/non-package-mode-zjkKA0Ca-py3.11/lib/python3.11/site-packages/tenacity/__init__.py\", line 379, in __call__\n    do = self.iter(retry_state=retry_state)\n         ^^^^^^^^^^^^^^^^^^^^^^^^^^^^^^^^^^\n  File \"/home/fd15hava/.cache/pypoetry/virtualenvs/non-package-mode-zjkKA0Ca-py3.11/lib/python3.11/site-packages/tenacity/__init__.py\", line 326, in iter\n    raise retry_exc from fut.exception()\ntenacity.RetryError: RetryError[<Future at 0x1484a8a9f310 state=finished raised UnexpectedAnswerException>]\n",
      "Traceback (most recent call last):\n  File \"/home/fd15hava/.cache/pypoetry/virtualenvs/non-package-mode-zjkKA0Ca-py3.11/lib/python3.11/site-packages/tenacity/__init__.py\", line 382, in __call__\n    result = fn(*args, **kwargs)\n             ^^^^^^^^^^^^^^^^^^^\n  File \"/work/home/fd15hava/tinypaper-mpt/src/agent.py\", line 26, in play\n    answer = self._prompt(self._make_prompt(scenario))\n             ^^^^^^^^^^^^^^^^^^^^^^^^^^^^^^^^^^^^^^^^^\n  File \"/work/home/fd15hava/tinypaper-mpt/src/agent.py\", line 40, in _prompt\n    raise UnexpectedAnswerException(f\"expected 1 or 2, got {result}\")\nutil.UnexpectedAnswerException: expected 1 or 2, got  \n\nThe above exception was the direct cause of the following exception:\n\nTraceback (most recent call last):\n  File \"/work/home/fd15hava/tinypaper-mpt/scripts/experiments/run.py\", line 16, in _run_session\n    result = agent.play(session)\n             ^^^^^^^^^^^^^^^^^^^\n  File \"/home/fd15hava/.cache/pypoetry/virtualenvs/non-package-mode-zjkKA0Ca-py3.11/lib/python3.11/site-packages/tenacity/__init__.py\", line 289, in wrapped_f\n    return self(f, *args, **kw)\n           ^^^^^^^^^^^^^^^^^^^^\n  File \"/home/fd15hava/.cache/pypoetry/virtualenvs/non-package-mode-zjkKA0Ca-py3.11/lib/python3.11/site-packages/tenacity/__init__.py\", line 379, in __call__\n    do = self.iter(retry_state=retry_state)\n         ^^^^^^^^^^^^^^^^^^^^^^^^^^^^^^^^^^\n  File \"/home/fd15hava/.cache/pypoetry/virtualenvs/non-package-mode-zjkKA0Ca-py3.11/lib/python3.11/site-packages/tenacity/__init__.py\", line 326, in iter\n    raise retry_exc from fut.exception()\ntenacity.RetryError: RetryError[<Future at 0x148460c4d390 state=finished raised UnexpectedAnswerException>]\n",
      "Traceback (most recent call last):\n  File \"/home/fd15hava/.cache/pypoetry/virtualenvs/non-package-mode-zjkKA0Ca-py3.11/lib/python3.11/site-packages/tenacity/__init__.py\", line 382, in __call__\n    result = fn(*args, **kwargs)\n             ^^^^^^^^^^^^^^^^^^^\n  File \"/work/home/fd15hava/tinypaper-mpt/src/agent.py\", line 26, in play\n    answer = self._prompt(self._make_prompt(scenario))\n             ^^^^^^^^^^^^^^^^^^^^^^^^^^^^^^^^^^^^^^^^^\n  File \"/work/home/fd15hava/tinypaper-mpt/src/agent.py\", line 40, in _prompt\n    raise UnexpectedAnswerException(f\"expected 1 or 2, got {result}\")\nutil.UnexpectedAnswerException: expected 1 or 2, got  \n\nThe above exception was the direct cause of the following exception:\n\nTraceback (most recent call last):\n  File \"/work/home/fd15hava/tinypaper-mpt/scripts/experiments/run.py\", line 16, in _run_session\n    result = agent.play(session)\n             ^^^^^^^^^^^^^^^^^^^\n  File \"/home/fd15hava/.cache/pypoetry/virtualenvs/non-package-mode-zjkKA0Ca-py3.11/lib/python3.11/site-packages/tenacity/__init__.py\", line 289, in wrapped_f\n    return self(f, *args, **kw)\n           ^^^^^^^^^^^^^^^^^^^^\n  File \"/home/fd15hava/.cache/pypoetry/virtualenvs/non-package-mode-zjkKA0Ca-py3.11/lib/python3.11/site-packages/tenacity/__init__.py\", line 379, in __call__\n    do = self.iter(retry_state=retry_state)\n         ^^^^^^^^^^^^^^^^^^^^^^^^^^^^^^^^^^\n  File \"/home/fd15hava/.cache/pypoetry/virtualenvs/non-package-mode-zjkKA0Ca-py3.11/lib/python3.11/site-packages/tenacity/__init__.py\", line 326, in iter\n    raise retry_exc from fut.exception()\ntenacity.RetryError: RetryError[<Future at 0x148460bd4bd0 state=finished raised UnexpectedAnswerException>]\n",
      "Traceback (most recent call last):\n  File \"/home/fd15hava/.cache/pypoetry/virtualenvs/non-package-mode-zjkKA0Ca-py3.11/lib/python3.11/site-packages/tenacity/__init__.py\", line 382, in __call__\n    result = fn(*args, **kwargs)\n             ^^^^^^^^^^^^^^^^^^^\n  File \"/work/home/fd15hava/tinypaper-mpt/src/agent.py\", line 26, in play\n    answer = self._prompt(self._make_prompt(scenario))\n             ^^^^^^^^^^^^^^^^^^^^^^^^^^^^^^^^^^^^^^^^^\n  File \"/work/home/fd15hava/tinypaper-mpt/src/agent.py\", line 40, in _prompt\n    raise UnexpectedAnswerException(f\"expected 1 or 2, got {result}\")\nutil.UnexpectedAnswerException: expected 1 or 2, got  \n\nThe above exception was the direct cause of the following exception:\n\nTraceback (most recent call last):\n  File \"/work/home/fd15hava/tinypaper-mpt/scripts/experiments/run.py\", line 16, in _run_session\n    result = agent.play(session)\n             ^^^^^^^^^^^^^^^^^^^\n  File \"/home/fd15hava/.cache/pypoetry/virtualenvs/non-package-mode-zjkKA0Ca-py3.11/lib/python3.11/site-packages/tenacity/__init__.py\", line 289, in wrapped_f\n    return self(f, *args, **kw)\n           ^^^^^^^^^^^^^^^^^^^^\n  File \"/home/fd15hava/.cache/pypoetry/virtualenvs/non-package-mode-zjkKA0Ca-py3.11/lib/python3.11/site-packages/tenacity/__init__.py\", line 379, in __call__\n    do = self.iter(retry_state=retry_state)\n         ^^^^^^^^^^^^^^^^^^^^^^^^^^^^^^^^^^\n  File \"/home/fd15hava/.cache/pypoetry/virtualenvs/non-package-mode-zjkKA0Ca-py3.11/lib/python3.11/site-packages/tenacity/__init__.py\", line 326, in iter\n    raise retry_exc from fut.exception()\ntenacity.RetryError: RetryError[<Future at 0x148460b08ad0 state=finished raised UnexpectedAnswerException>]\n",
      "Traceback (most recent call last):\n  File \"/home/fd15hava/.cache/pypoetry/virtualenvs/non-package-mode-zjkKA0Ca-py3.11/lib/python3.11/site-packages/tenacity/__init__.py\", line 382, in __call__\n    result = fn(*args, **kwargs)\n             ^^^^^^^^^^^^^^^^^^^\n  File \"/work/home/fd15hava/tinypaper-mpt/src/agent.py\", line 26, in play\n    answer = self._prompt(self._make_prompt(scenario))\n             ^^^^^^^^^^^^^^^^^^^^^^^^^^^^^^^^^^^^^^^^^\n  File \"/work/home/fd15hava/tinypaper-mpt/src/agent.py\", line 40, in _prompt\n    raise UnexpectedAnswerException(f\"expected 1 or 2, got {result}\")\nutil.UnexpectedAnswerException: expected 1 or 2, got  \n\nThe above exception was the direct cause of the following exception:\n\nTraceback (most recent call last):\n  File \"/work/home/fd15hava/tinypaper-mpt/scripts/experiments/run.py\", line 16, in _run_session\n    result = agent.play(session)\n             ^^^^^^^^^^^^^^^^^^^\n  File \"/home/fd15hava/.cache/pypoetry/virtualenvs/non-package-mode-zjkKA0Ca-py3.11/lib/python3.11/site-packages/tenacity/__init__.py\", line 289, in wrapped_f\n    return self(f, *args, **kw)\n           ^^^^^^^^^^^^^^^^^^^^\n  File \"/home/fd15hava/.cache/pypoetry/virtualenvs/non-package-mode-zjkKA0Ca-py3.11/lib/python3.11/site-packages/tenacity/__init__.py\", line 379, in __call__\n    do = self.iter(retry_state=retry_state)\n         ^^^^^^^^^^^^^^^^^^^^^^^^^^^^^^^^^^\n  File \"/home/fd15hava/.cache/pypoetry/virtualenvs/non-package-mode-zjkKA0Ca-py3.11/lib/python3.11/site-packages/tenacity/__init__.py\", line 326, in iter\n    raise retry_exc from fut.exception()\ntenacity.RetryError: RetryError[<Future at 0x148460b8e690 state=finished raised UnexpectedAnswerException>]\n",
      "Traceback (most recent call last):\n  File \"/home/fd15hava/.cache/pypoetry/virtualenvs/non-package-mode-zjkKA0Ca-py3.11/lib/python3.11/site-packages/tenacity/__init__.py\", line 382, in __call__\n    result = fn(*args, **kwargs)\n             ^^^^^^^^^^^^^^^^^^^\n  File \"/work/home/fd15hava/tinypaper-mpt/src/agent.py\", line 26, in play\n    answer = self._prompt(self._make_prompt(scenario))\n             ^^^^^^^^^^^^^^^^^^^^^^^^^^^^^^^^^^^^^^^^^\n  File \"/work/home/fd15hava/tinypaper-mpt/src/agent.py\", line 40, in _prompt\n    raise UnexpectedAnswerException(f\"expected 1 or 2, got {result}\")\nutil.UnexpectedAnswerException: expected 1 or 2, got  \n\nThe above exception was the direct cause of the following exception:\n\nTraceback (most recent call last):\n  File \"/work/home/fd15hava/tinypaper-mpt/scripts/experiments/run.py\", line 16, in _run_session\n    result = agent.play(session)\n             ^^^^^^^^^^^^^^^^^^^\n  File \"/home/fd15hava/.cache/pypoetry/virtualenvs/non-package-mode-zjkKA0Ca-py3.11/lib/python3.11/site-packages/tenacity/__init__.py\", line 289, in wrapped_f\n    return self(f, *args, **kw)\n           ^^^^^^^^^^^^^^^^^^^^\n  File \"/home/fd15hava/.cache/pypoetry/virtualenvs/non-package-mode-zjkKA0Ca-py3.11/lib/python3.11/site-packages/tenacity/__init__.py\", line 379, in __call__\n    do = self.iter(retry_state=retry_state)\n         ^^^^^^^^^^^^^^^^^^^^^^^^^^^^^^^^^^\n  File \"/home/fd15hava/.cache/pypoetry/virtualenvs/non-package-mode-zjkKA0Ca-py3.11/lib/python3.11/site-packages/tenacity/__init__.py\", line 326, in iter\n    raise retry_exc from fut.exception()\ntenacity.RetryError: RetryError[<Future at 0x148460c4e850 state=finished raised UnexpectedAnswerException>]\n",
      "Traceback (most recent call last):\n  File \"/home/fd15hava/.cache/pypoetry/virtualenvs/non-package-mode-zjkKA0Ca-py3.11/lib/python3.11/site-packages/tenacity/__init__.py\", line 382, in __call__\n    result = fn(*args, **kwargs)\n             ^^^^^^^^^^^^^^^^^^^\n  File \"/work/home/fd15hava/tinypaper-mpt/src/agent.py\", line 26, in play\n    answer = self._prompt(self._make_prompt(scenario))\n             ^^^^^^^^^^^^^^^^^^^^^^^^^^^^^^^^^^^^^^^^^\n  File \"/work/home/fd15hava/tinypaper-mpt/src/agent.py\", line 40, in _prompt\n    raise UnexpectedAnswerException(f\"expected 1 or 2, got {result}\")\nutil.UnexpectedAnswerException: expected 1 or 2, got  \n\nThe above exception was the direct cause of the following exception:\n\nTraceback (most recent call last):\n  File \"/work/home/fd15hava/tinypaper-mpt/scripts/experiments/run.py\", line 16, in _run_session\n    result = agent.play(session)\n             ^^^^^^^^^^^^^^^^^^^\n  File \"/home/fd15hava/.cache/pypoetry/virtualenvs/non-package-mode-zjkKA0Ca-py3.11/lib/python3.11/site-packages/tenacity/__init__.py\", line 289, in wrapped_f\n    return self(f, *args, **kw)\n           ^^^^^^^^^^^^^^^^^^^^\n  File \"/home/fd15hava/.cache/pypoetry/virtualenvs/non-package-mode-zjkKA0Ca-py3.11/lib/python3.11/site-packages/tenacity/__init__.py\", line 379, in __call__\n    do = self.iter(retry_state=retry_state)\n         ^^^^^^^^^^^^^^^^^^^^^^^^^^^^^^^^^^\n  File \"/home/fd15hava/.cache/pypoetry/virtualenvs/non-package-mode-zjkKA0Ca-py3.11/lib/python3.11/site-packages/tenacity/__init__.py\", line 326, in iter\n    raise retry_exc from fut.exception()\ntenacity.RetryError: RetryError[<Future at 0x1484a949afd0 state=finished raised UnexpectedAnswerException>]\n",
      "Traceback (most recent call last):\n  File \"/home/fd15hava/.cache/pypoetry/virtualenvs/non-package-mode-zjkKA0Ca-py3.11/lib/python3.11/site-packages/tenacity/__init__.py\", line 382, in __call__\n    result = fn(*args, **kwargs)\n             ^^^^^^^^^^^^^^^^^^^\n  File \"/work/home/fd15hava/tinypaper-mpt/src/agent.py\", line 26, in play\n    answer = self._prompt(self._make_prompt(scenario))\n             ^^^^^^^^^^^^^^^^^^^^^^^^^^^^^^^^^^^^^^^^^\n  File \"/work/home/fd15hava/tinypaper-mpt/src/agent.py\", line 40, in _prompt\n    raise UnexpectedAnswerException(f\"expected 1 or 2, got {result}\")\nutil.UnexpectedAnswerException: expected 1 or 2, got  \n\nThe above exception was the direct cause of the following exception:\n\nTraceback (most recent call last):\n  File \"/work/home/fd15hava/tinypaper-mpt/scripts/experiments/run.py\", line 16, in _run_session\n    result = agent.play(session)\n             ^^^^^^^^^^^^^^^^^^^\n  File \"/home/fd15hava/.cache/pypoetry/virtualenvs/non-package-mode-zjkKA0Ca-py3.11/lib/python3.11/site-packages/tenacity/__init__.py\", line 289, in wrapped_f\n    return self(f, *args, **kw)\n           ^^^^^^^^^^^^^^^^^^^^\n  File \"/home/fd15hava/.cache/pypoetry/virtualenvs/non-package-mode-zjkKA0Ca-py3.11/lib/python3.11/site-packages/tenacity/__init__.py\", line 379, in __call__\n    do = self.iter(retry_state=retry_state)\n         ^^^^^^^^^^^^^^^^^^^^^^^^^^^^^^^^^^\n  File \"/home/fd15hava/.cache/pypoetry/virtualenvs/non-package-mode-zjkKA0Ca-py3.11/lib/python3.11/site-packages/tenacity/__init__.py\", line 326, in iter\n    raise retry_exc from fut.exception()\ntenacity.RetryError: RetryError[<Future at 0x148460c72850 state=finished raised UnexpectedAnswerException>]\n"
    ],
    "api_usage": [
      {
        "cost": 0.0,
        "name": "Llama-2-70b-chat-hf",
        "num_input_tokens": -1,
        "num_output_tokens": -1,
        "py/object": "api_usage.APIUsage"
      },
      {
        "cost": 0.0,
        "name": "Llama-2-70b-chat-hf",
        "num_input_tokens": -1,
        "num_output_tokens": -1,
        "py/object": "api_usage.APIUsage"
      },
      {
        "cost": 0.0,
        "name": "Llama-2-70b-chat-hf",
        "num_input_tokens": -1,
        "num_output_tokens": -1,
        "py/object": "api_usage.APIUsage"
      },
      {
        "cost": 0.0,
        "name": "Llama-2-70b-chat-hf",
        "num_input_tokens": -1,
        "num_output_tokens": -1,
        "py/object": "api_usage.APIUsage"
      },
      {
        "cost": 0.0,
        "name": "Llama-2-70b-chat-hf",
        "num_input_tokens": -1,
        "num_output_tokens": -1,
        "py/object": "api_usage.APIUsage"
      },
      {
        "cost": 0.0,
        "name": "Llama-2-70b-chat-hf",
        "num_input_tokens": -1,
        "num_output_tokens": -1,
        "py/object": "api_usage.APIUsage"
      },
      {
        "cost": 0.0,
        "name": "Llama-2-70b-chat-hf",
        "num_input_tokens": -1,
        "num_output_tokens": -1,
        "py/object": "api_usage.APIUsage"
      },
      {
        "cost": 0.0,
        "name": "Llama-2-70b-chat-hf",
        "num_input_tokens": -1,
        "num_output_tokens": -1,
        "py/object": "api_usage.APIUsage"
      },
      {
        "cost": 0.0,
        "name": "Llama-2-70b-chat-hf",
        "num_input_tokens": -1,
        "num_output_tokens": -1,
        "py/object": "api_usage.APIUsage"
      },
      {
        "cost": 0.0,
        "name": "Llama-2-70b-chat-hf",
        "num_input_tokens": -1,
        "num_output_tokens": -1,
        "py/object": "api_usage.APIUsage"
      },
      {
        "cost": 0.0,
        "name": "Llama-2-70b-chat-hf",
        "num_input_tokens": -1,
        "num_output_tokens": -1,
        "py/object": "api_usage.APIUsage"
      },
      {
        "cost": 0.0,
        "name": "Llama-2-70b-chat-hf",
        "num_input_tokens": -1,
        "num_output_tokens": -1,
        "py/object": "api_usage.APIUsage"
      },
      {
        "cost": 0.0,
        "name": "Llama-2-70b-chat-hf",
        "num_input_tokens": -1,
        "num_output_tokens": -1,
        "py/object": "api_usage.APIUsage"
      },
      {
        "cost": 0.0,
        "name": "Llama-2-70b-chat-hf",
        "num_input_tokens": -1,
        "num_output_tokens": -1,
        "py/object": "api_usage.APIUsage"
      },
      {
        "cost": 0.0,
        "name": "Llama-2-70b-chat-hf",
        "num_input_tokens": -1,
        "num_output_tokens": -1,
        "py/object": "api_usage.APIUsage"
      },
      {
        "cost": 0.0,
        "name": "Llama-2-70b-chat-hf",
        "num_input_tokens": -1,
        "num_output_tokens": -1,
        "py/object": "api_usage.APIUsage"
      },
      {
        "cost": 0.0,
        "name": "Llama-2-70b-chat-hf",
        "num_input_tokens": -1,
        "num_output_tokens": -1,
        "py/object": "api_usage.APIUsage"
      },
      {
        "cost": 0.0,
        "name": "Llama-2-70b-chat-hf",
        "num_input_tokens": -1,
        "num_output_tokens": -1,
        "py/object": "api_usage.APIUsage"
      },
      {
        "cost": 0.0,
        "name": "Llama-2-70b-chat-hf",
        "num_input_tokens": -1,
        "num_output_tokens": -1,
        "py/object": "api_usage.APIUsage"
      },
      {
        "cost": 0.0,
        "name": "Llama-2-70b-chat-hf",
        "num_input_tokens": -1,
        "num_output_tokens": -1,
        "py/object": "api_usage.APIUsage"
      },
      {
        "cost": 0.0,
        "name": "Llama-2-70b-chat-hf",
        "num_input_tokens": -1,
        "num_output_tokens": -1,
        "py/object": "api_usage.APIUsage"
      },
      {
        "cost": 0.0,
        "name": "Llama-2-70b-chat-hf",
        "num_input_tokens": -1,
        "num_output_tokens": -1,
        "py/object": "api_usage.APIUsage"
      },
      {
        "cost": 0.0,
        "name": "Llama-2-70b-chat-hf",
        "num_input_tokens": -1,
        "num_output_tokens": -1,
        "py/object": "api_usage.APIUsage"
      },
      {
        "cost": 0.0,
        "name": "Llama-2-70b-chat-hf",
        "num_input_tokens": -1,
        "num_output_tokens": -1,
        "py/object": "api_usage.APIUsage"
      },
      {
        "cost": 0.0,
        "name": "Llama-2-70b-chat-hf",
        "num_input_tokens": -1,
        "num_output_tokens": -1,
        "py/object": "api_usage.APIUsage"
      },
      {
        "cost": 0.0,
        "name": "Llama-2-70b-chat-hf",
        "num_input_tokens": -1,
        "num_output_tokens": -1,
        "py/object": "api_usage.APIUsage"
      },
      {
        "cost": 0.0,
        "name": "Llama-2-70b-chat-hf",
        "num_input_tokens": -1,
        "num_output_tokens": -1,
        "py/object": "api_usage.APIUsage"
      },
      {
        "cost": 0.0,
        "name": "Llama-2-70b-chat-hf",
        "num_input_tokens": -1,
        "num_output_tokens": -1,
        "py/object": "api_usage.APIUsage"
      },
      {
        "cost": 0.0,
        "name": "Llama-2-70b-chat-hf",
        "num_input_tokens": -1,
        "num_output_tokens": -1,
        "py/object": "api_usage.APIUsage"
      },
      {
        "cost": 0.0,
        "name": "Llama-2-70b-chat-hf",
        "num_input_tokens": -1,
        "num_output_tokens": -1,
        "py/object": "api_usage.APIUsage"
      },
      {
        "cost": 0.0,
        "name": "Llama-2-70b-chat-hf",
        "num_input_tokens": -1,
        "num_output_tokens": -1,
        "py/object": "api_usage.APIUsage"
      },
      {
        "cost": 0.0,
        "name": "Llama-2-70b-chat-hf",
        "num_input_tokens": -1,
        "num_output_tokens": -1,
        "py/object": "api_usage.APIUsage"
      },
      {
        "cost": 0.0,
        "name": "Llama-2-70b-chat-hf",
        "num_input_tokens": -1,
        "num_output_tokens": -1,
        "py/object": "api_usage.APIUsage"
      },
      {
        "cost": 0.0,
        "name": "Llama-2-70b-chat-hf",
        "num_input_tokens": -1,
        "num_output_tokens": -1,
        "py/object": "api_usage.APIUsage"
      },
      {
        "cost": 0.0,
        "name": "Llama-2-70b-chat-hf",
        "num_input_tokens": -1,
        "num_output_tokens": -1,
        "py/object": "api_usage.APIUsage"
      },
      {
        "cost": 0.0,
        "name": "Llama-2-70b-chat-hf",
        "num_input_tokens": -1,
        "num_output_tokens": -1,
        "py/object": "api_usage.APIUsage"
      },
      {
        "cost": 0.0,
        "name": "Llama-2-70b-chat-hf",
        "num_input_tokens": -1,
        "num_output_tokens": -1,
        "py/object": "api_usage.APIUsage"
      },
      {
        "cost": 0.0,
        "name": "Llama-2-70b-chat-hf",
        "num_input_tokens": -1,
        "num_output_tokens": -1,
        "py/object": "api_usage.APIUsage"
      },
      {
        "cost": 0.0,
        "name": "Llama-2-70b-chat-hf",
        "num_input_tokens": -1,
        "num_output_tokens": -1,
        "py/object": "api_usage.APIUsage"
      },
      {
        "cost": 0.0,
        "name": "Llama-2-70b-chat-hf",
        "num_input_tokens": -1,
        "num_output_tokens": -1,
        "py/object": "api_usage.APIUsage"
      },
      {
        "cost": 0.0,
        "name": "Llama-2-70b-chat-hf",
        "num_input_tokens": -1,
        "num_output_tokens": -1,
        "py/object": "api_usage.APIUsage"
      },
      {
        "cost": 0.0,
        "name": "Llama-2-70b-chat-hf",
        "num_input_tokens": -1,
        "num_output_tokens": -1,
        "py/object": "api_usage.APIUsage"
      },
      {
        "cost": 0.0,
        "name": "Llama-2-70b-chat-hf",
        "num_input_tokens": -1,
        "num_output_tokens": -1,
        "py/object": "api_usage.APIUsage"
      },
      {
        "cost": 0.0,
        "name": "Llama-2-70b-chat-hf",
        "num_input_tokens": -1,
        "num_output_tokens": -1,
        "py/object": "api_usage.APIUsage"
      },
      {
        "cost": 0.0,
        "name": "Llama-2-70b-chat-hf",
        "num_input_tokens": -1,
        "num_output_tokens": -1,
        "py/object": "api_usage.APIUsage"
      },
      {
        "cost": 0.0,
        "name": "Llama-2-70b-chat-hf",
        "num_input_tokens": -1,
        "num_output_tokens": -1,
        "py/object": "api_usage.APIUsage"
      },
      {
        "cost": 0.0,
        "name": "Llama-2-70b-chat-hf",
        "num_input_tokens": -1,
        "num_output_tokens": -1,
        "py/object": "api_usage.APIUsage"
      },
      {
        "cost": 0.0,
        "name": "Llama-2-70b-chat-hf",
        "num_input_tokens": -1,
        "num_output_tokens": -1,
        "py/object": "api_usage.APIUsage"
      },
      {
        "cost": 0.0,
        "name": "Llama-2-70b-chat-hf",
        "num_input_tokens": -1,
        "num_output_tokens": -1,
        "py/object": "api_usage.APIUsage"
      },
      {
        "cost": 0.0,
        "name": "Llama-2-70b-chat-hf",
        "num_input_tokens": -1,
        "num_output_tokens": -1,
        "py/object": "api_usage.APIUsage"
      }
    ],
    "api_usage_total": {
      "cost": 0.0,
      "name": "Llama-2-70b-chat-hf",
      "num_input_tokens": -50,
      "num_output_tokens": -50,
      "py/object": "api_usage.APIUsage"
    }
  },
  "start_time": "2024-04-30T02:46:21.736545",
  "status": "COMPLETED",
  "stop_time": "2024-04-30T03:20:48.740622"
}